2023-09-03T06:47:05.717597133+02:00 stderr F I0903 04:47:05.717431       1 eventhandlers.go:206] "Update event for scheduled pod" pod="default/kbench-deployment-oid-0-tid-2-cc4784d96-mh8hc"
2023-09-03T06:47:05.523401734+02:00 stderr F I0903 04:47:05.523320       1 eventhandlers.go:206] "Update event for scheduled pod" pod="kube-flannel/kube-flannel-ds-4wng4"
2023-09-03T06:47:32.93415059+02:00 stderr F I0903 04:47:32.933836       1 httplog.go:132] "HTTP" verb="GET" URI="/metrics" latency="14.333981ms" userAgent="Prometheus/2.46.0" audit-ID="" srcIP="192.168.100.20:4645" resp=200
2023-09-03T06:47:05.58083082+02:00 stderr F I0903 04:47:05.580594       1 eventhandlers.go:206] "Update event for scheduled pod" pod="monitoring/node-exporter-s8bqq"
2023-09-03T06:46:47.612544472+02:00 stderr F I0903 04:46:47.612349       1 eventhandlers.go:206] "Update event for scheduled pod" pod="default/kbench-deployment-oid-0-tid-0-bdb979454-kf4kq"
2023-09-03T06:47:33.970369048+02:00 stderr F I0903 04:47:33.970269       1 leaderelection.go:276] successfully renewed lease kube-system/kube-scheduler
2023-09-03T06:47:02.920379124+02:00 stderr F I0903 04:47:02.919995       1 pathrecorder.go:241] kube-scheduler: "/metrics" satisfied by exact match
2023-09-03T06:46:46.808350255+02:00 stderr F I0903 04:46:46.807932       1 eventhandlers.go:206] "Update event for scheduled pod" pod="default/kbench-deployment-oid-0-tid-1-778f5d498c-ws7jt"
2023-09-03T06:47:36.649778817+02:00 stderr F I0903 04:47:36.649616       1 eventhandlers.go:231] "Delete event for scheduled pod" pod="default/kbench-deployment-oid-0-tid-0-bdb979454-bd7vn"
2023-09-03T06:47:14.919929489+02:00 stderr F I0903 04:47:14.919513       1 pathrecorder.go:241] kube-scheduler: "/metrics" satisfied by exact match
2023-09-03T06:46:46.76767082+02:00 stderr F I0903 04:46:46.767545       1 schedule_one.go:252] "Successfully bound pod to node" pod="default/kbench-deployment-oid-0-tid-0-bdb979454-kf4kq" node="w02" evaluatedNodes=5 feasibleNodes=3
2023-09-03T06:47:02.935050084+02:00 stderr F I0903 04:47:02.934773       1 httplog.go:132] "HTTP" verb="GET" URI="/metrics" latency="14.909509ms" userAgent="Prometheus/2.46.0" audit-ID="" srcIP="192.168.100.20:4645" resp=200
2023-09-03T06:46:53.925440322+02:00 stderr F I0903 04:46:53.925140       1 pathrecorder.go:241] kube-scheduler: "/metrics" satisfied by exact match
2023-09-03T06:47:27.90866032+02:00 stderr F I0903 04:47:27.908421       1 round_trippers.go:553] PUT https://192.168.100.1:6443/apis/coordination.k8s.io/v1/namespaces/kube-system/leases/kube-scheduler?timeout=5s 200 OK in 23 milliseconds
2023-09-03T06:46:47.486885091+02:00 stderr F I0903 04:46:47.486729       1 leaderelection.go:276] successfully renewed lease kube-system/kube-scheduler
2023-09-03T06:47:05.592817584+02:00 stderr F I0903 04:47:05.592653       1 eventhandlers.go:206] "Update event for scheduled pod" pod="default/kbench-deployment-oid-0-tid-0-bdb979454-b2mrc"
2023-09-03T06:47:05.616883819+02:00 stderr F I0903 04:47:05.616816       1 scheduling_queue.go:419] "Pod moved to an internal scheduling queue" pod="default/kbench-deployment-oid-0-tid-2-cc4784d96-kp5fp" event="PodAdd" queue="Active"
2023-09-03T06:47:33.66517418+02:00 stderr F I0903 04:47:33.664515       1 httplog.go:132] "HTTP" verb="GET" URI="/healthz" latency="211.871µs" userAgent="kube-probe/1.27" audit-ID="" srcIP="127.0.0.1:43944" resp=200
2023-09-03T06:46:46.738230079+02:00 stderr F I0903 04:46:46.738089       1 scheduling_queue.go:419] "Pod moved to an internal scheduling queue" pod="default/kbench-deployment-oid-0-tid-1-778f5d498c-ws7jt" event="PodAdd" queue="Active"
2023-09-03T06:47:17.810711344+02:00 stderr F I0903 04:47:17.810562       1 leaderelection.go:276] successfully renewed lease kube-system/kube-scheduler
2023-09-03T06:46:46.814399749+02:00 stderr F I0903 04:46:46.814303       1 eventhandlers.go:161] "Delete event for unscheduled pod" pod="default/kbench-deployment-oid-0-tid-1-778f5d498c-7lp58"
2023-09-03T06:47:26.921326704+02:00 stderr F I0903 04:47:26.920895       1 pathrecorder.go:241] kube-scheduler: "/metrics" satisfied by exact match
2023-09-03T06:46:47.486449751+02:00 stderr F I0903 04:46:47.486299       1 round_trippers.go:553] PUT https://192.168.100.1:6443/apis/coordination.k8s.io/v1/namespaces/kube-system/leases/kube-scheduler?timeout=5s 200 OK in 10 milliseconds
2023-09-03T06:47:07.573090597+02:00 stderr F I0903 04:47:07.572338       1 cache.go:401] "Finished binding for pod, can be expired" podKey="2322ef6c-6d72-4217-a948-587622d00acd" pod="default/kbench-deployment-oid-0-tid-1-db946cf6f-nhd4n"
2023-09-03T06:47:36.668059334+02:00 stderr F I0903 04:47:36.667800       1 eventhandlers.go:206] "Update event for scheduled pod" pod="default/kbench-deployment-oid-0-tid-1-778f5d498c-ws7jt"
2023-09-03T06:47:17.810584162+02:00 stderr F I0903 04:47:17.810368       1 round_trippers.go:553] PUT https://192.168.100.1:6443/apis/coordination.k8s.io/v1/namespaces/kube-system/leases/kube-scheduler?timeout=5s 200 OK in 8 milliseconds
2023-09-03T06:47:36.702122111+02:00 stderr F I0903 04:47:36.701990       1 eventhandlers.go:231] "Delete event for scheduled pod" pod="default/kbench-deployment-oid-0-tid-1-778f5d498c-sc9lm"
2023-09-03T06:47:05.684292225+02:00 stderr F I0903 04:47:05.684180       1 leaderelection.go:276] successfully renewed lease kube-system/kube-scheduler
2023-09-03T06:47:05.748857305+02:00 stderr F I0903 04:47:05.748685       1 round_trippers.go:553] POST https://192.168.100.1:6443/apis/events.k8s.io/v1/namespaces/default/events 201 Created in 16 milliseconds
2023-09-03T06:47:05.68414335+02:00 stderr F I0903 04:47:05.684009       1 round_trippers.go:553] PUT https://192.168.100.1:6443/apis/coordination.k8s.io/v1/namespaces/kube-system/leases/kube-scheduler?timeout=5s 200 OK in 13 milliseconds
2023-09-03T06:47:28.555500403+02:00 stderr F I0903 04:47:28.555387       1 eventhandlers.go:206] "Update event for scheduled pod" pod="default/kbench-deployment-oid-0-tid-2-cc4784d96-x5f9h"
2023-09-03T06:47:05.731495866+02:00 stderr F I0903 04:47:05.731295       1 round_trippers.go:553] POST https://192.168.100.1:6443/api/v1/namespaces/default/pods/kbench-deployment-oid-0-tid-1-db946cf6f-ltps7/binding 201 Created in 17 milliseconds
2023-09-03T06:47:07.554039932+02:00 stderr F I0903 04:47:07.553985       1 schedule_one.go:80] "Attempting to schedule pod" pod="default/kbench-deployment-oid-0-tid-1-db946cf6f-nhd4n"
2023-09-03T06:46:55.553376214+02:00 stderr F I0903 04:46:55.553148       1 leaderelection.go:276] successfully renewed lease kube-system/kube-scheduler
2023-09-03T06:46:55.552661431+02:00 stderr F I0903 04:46:55.552375       1 round_trippers.go:553] PUT https://192.168.100.1:6443/apis/coordination.k8s.io/v1/namespaces/kube-system/leases/kube-scheduler?timeout=5s 200 OK in 8 milliseconds
2023-09-03T06:46:46.813784437+02:00 stderr F I0903 04:46:46.813661       1 cache.go:401] "Finished binding for pod, can be expired" podKey="4bc0cd6c-e95a-44fc-b7e9-f3708de46bd2" pod="default/kbench-deployment-oid-0-tid-0-bdb979454-b2mrc"
2023-09-03T06:46:46.775967484+02:00 stderr F I0903 04:46:46.775856       1 eventhandlers.go:161] "Delete event for unscheduled pod" pod="default/kbench-deployment-oid-0-tid-1-778f5d498c-ws7jt"
2023-09-03T06:46:46.7656474+02:00 stderr F I0903 04:46:46.765480       1 eventhandlers.go:186] "Add event for scheduled pod" pod="default/kbench-deployment-oid-0-tid-0-bdb979454-kf4kq"
2023-09-03T06:46:53.526852557+02:00 stderr F I0903 04:46:53.526635       1 round_trippers.go:553] GET https://192.168.100.1:6443/apis/coordination.k8s.io/v1/namespaces/kube-system/leases/kube-scheduler?timeout=5s 200 OK in 4 milliseconds
2023-09-03T06:47:07.698479114+02:00 stderr F I0903 04:47:07.698282       1 leaderelection.go:276] successfully renewed lease kube-system/kube-scheduler
2023-09-03T06:47:05.61766522+02:00 stderr F I0903 04:47:05.617602       1 schedule_one.go:80] "Attempting to schedule pod" pod="default/kbench-deployment-oid-0-tid-2-cc4784d96-kp5fp"
2023-09-03T06:47:36.745892196+02:00 stderr F I0903 04:47:36.745713       1 eventhandlers.go:231] "Delete event for scheduled pod" pod="default/kbench-deployment-oid-0-tid-1-db946cf6f-nhd4n"
2023-09-03T06:47:28.544061073+02:00 stderr F I0903 04:47:28.543452       1 eventhandlers.go:206] "Update event for scheduled pod" pod="default/kbench-deployment-oid-0-tid-2-cc4784d96-kp5fp"
2023-09-03T06:46:53.66461071+02:00 stderr F I0903 04:46:53.664391       1 httplog.go:132] "HTTP" verb="GET" URI="/healthz" latency="216.259µs" userAgent="kube-probe/1.27" audit-ID="" srcIP="127.0.0.1:34002" resp=200
2023-09-03T06:46:46.730971424+02:00 stderr F I0903 04:46:46.730566       1 scheduling_queue.go:1133] "About to try and schedule pod" pod="default/kbench-deployment-oid-0-tid-2-cc4784d96-mh8hc"
2023-09-03T06:47:07.69810432+02:00 stderr F I0903 04:47:07.697861       1 round_trippers.go:553] PUT https://192.168.100.1:6443/apis/coordination.k8s.io/v1/namespaces/kube-system/leases/kube-scheduler?timeout=5s 200 OK in 7 milliseconds
2023-09-03T06:47:07.528758019+02:00 stderr F I0903 04:47:07.528513       1 eventhandlers.go:206] "Update event for scheduled pod" pod="default/kbench-deployment-oid-0-tid-1-778f5d498c-ws7jt"
2023-09-03T06:47:35.985078482+02:00 stderr F I0903 04:47:35.984839       1 leaderelection.go:276] successfully renewed lease kube-system/kube-scheduler
2023-09-03T06:46:46.730904301+02:00 stderr F I0903 04:46:46.730395       1 eventhandlers.go:118] "Add event for unscheduled pod" pod="default/kbench-deployment-oid-0-tid-2-cc4784d96-mh8hc"
2023-09-03T06:46:46.81182213+02:00 stderr F I0903 04:46:46.811685       1 round_trippers.go:553] POST https://192.168.100.1:6443/api/v1/namespaces/default/pods/kbench-deployment-oid-0-tid-0-bdb979454-b2mrc/binding 201 Created in 19 milliseconds
2023-09-03T06:47:29.916233789+02:00 stderr F I0903 04:47:29.915994       1 round_trippers.go:553] GET https://192.168.100.1:6443/apis/coordination.k8s.io/v1/namespaces/kube-system/leases/kube-scheduler?timeout=5s 200 OK in 5 milliseconds
2023-09-03T06:46:46.774931628+02:00 stderr F I0903 04:46:46.774705       1 round_trippers.go:553] POST https://192.168.100.1:6443/api/v1/namespaces/default/pods/kbench-deployment-oid-0-tid-1-778f5d498c-ws7jt/binding 201 Created in 31 milliseconds
2023-09-03T06:47:11.731657898+02:00 stderr F I0903 04:47:11.731334       1 round_trippers.go:553] PUT https://192.168.100.1:6443/apis/coordination.k8s.io/v1/namespaces/kube-system/leases/kube-scheduler?timeout=5s 200 OK in 9 milliseconds
2023-09-03T06:46:59.942173547+02:00 stderr F I0903 04:46:59.941979       1 httplog.go:132] "HTTP" verb="GET" URI="/metrics" latency="21.49686ms" userAgent="Prometheus/2.46.0" audit-ID="" srcIP="192.168.100.20:4645" resp=200
2023-09-03T06:46:46.754787972+02:00 stderr F I0903 04:46:46.754518       1 cache.go:401] "Finished binding for pod, can be expired" podKey="e2031128-95cb-4af1-9aca-3e0572f8a2fb" pod="default/kbench-deployment-oid-0-tid-2-cc4784d96-mh8hc"
2023-09-03T06:46:46.740246285+02:00 stderr F I0903 04:46:46.740169       1 default_binder.go:53] "Attempting to bind pod to node" pod="default/kbench-deployment-oid-0-tid-1-778f5d498c-ws7jt" node="w03"
2023-09-03T06:47:36.661110294+02:00 stderr F I0903 04:47:36.660742       1 eventhandlers.go:231] "Delete event for scheduled pod" pod="default/kbench-deployment-oid-0-tid-0-bdb979454-kf4kq"
2023-09-03T06:47:05.629761588+02:00 stderr F I0903 04:47:05.629641       1 eventhandlers.go:206] "Update event for scheduled pod" pod="default/kbench-deployment-oid-0-tid-0-bdb979454-b2mrc"
2023-09-03T06:47:17.802111687+02:00 stderr F I0903 04:47:17.801934       1 round_trippers.go:553] GET https://192.168.100.1:6443/apis/coordination.k8s.io/v1/namespaces/kube-system/leases/kube-scheduler?timeout=5s 200 OK in 5 milliseconds
2023-09-03T06:47:25.879327038+02:00 stderr F I0903 04:47:25.879061       1 round_trippers.go:553] PUT https://192.168.100.1:6443/apis/coordination.k8s.io/v1/namespaces/kube-system/leases/kube-scheduler?timeout=5s 200 OK in 10 milliseconds
2023-09-03T06:46:46.811928754+02:00 stderr F I0903 04:46:46.811867       1 cache.go:401] "Finished binding for pod, can be expired" podKey="2be76881-1ed8-4d6a-a81c-8eb9826916f5" pod="default/kbench-deployment-oid-0-tid-1-778f5d498c-7lp58"
2023-09-03T06:47:36.696918872+02:00 stderr F I0903 04:47:36.696807       1 eventhandlers.go:231] "Delete event for scheduled pod" pod="default/kbench-deployment-oid-0-tid-1-778f5d498c-ws7jt"
2023-09-03T06:47:33.665116557+02:00 stderr F I0903 04:47:33.664348       1 pathrecorder.go:241] kube-scheduler: "/healthz" satisfied by exact match
2023-09-03T06:47:29.924834431+02:00 stderr F I0903 04:47:29.924690       1 round_trippers.go:553] PUT https://192.168.100.1:6443/apis/coordination.k8s.io/v1/namespaces/kube-system/leases/kube-scheduler?timeout=5s 200 OK in 8 milliseconds
2023-09-03T06:46:57.599253178+02:00 stderr F I0903 04:46:57.599092       1 leaderelection.go:276] successfully renewed lease kube-system/kube-scheduler
2023-09-03T06:46:46.84517499+02:00 stderr F I0903 04:46:46.844978       1 eventhandlers.go:206] "Update event for scheduled pod" pod="default/kbench-deployment-oid-0-tid-0-bdb979454-b2mrc"
2023-09-03T06:47:35.943350861+02:00 stderr F I0903 04:47:35.943085       1 httplog.go:132] "HTTP" verb="GET" URI="/metrics" latency="22.742397ms" userAgent="Prometheus/2.46.0" audit-ID="" srcIP="192.168.100.20:4645" resp=200
2023-09-03T06:47:36.774610953+02:00 stderr F I0903 04:47:36.774447       1 eventhandlers.go:231] "Delete event for scheduled pod" pod="default/kbench-deployment-oid-0-tid-2-cc4784d96-kp5fp"
2023-09-03T06:47:07.553984457+02:00 stderr F I0903 04:47:07.553824       1 eventhandlers.go:118] "Add event for unscheduled pod" pod="default/kbench-deployment-oid-0-tid-1-db946cf6f-nhd4n"
2023-09-03T06:47:11.929765301+02:00 stderr F I0903 04:47:11.929545       1 round_trippers.go:553] POST https://192.168.100.1:6443/apis/authorization.k8s.io/v1/subjectaccessreviews?timeout=10s 201 Created in 3 milliseconds
2023-09-03T06:46:56.919769401+02:00 stderr F I0903 04:46:56.919406       1 pathrecorder.go:241] kube-scheduler: "/metrics" satisfied by exact match
2023-09-03T06:47:27.88464329+02:00 stderr F I0903 04:47:27.884456       1 round_trippers.go:553] GET https://192.168.100.1:6443/apis/coordination.k8s.io/v1/namespaces/kube-system/leases/kube-scheduler?timeout=5s 200 OK in 4 milliseconds
2023-09-03T06:47:05.73015431+02:00 stderr F I0903 04:47:05.729970       1 eventhandlers.go:161] "Delete event for unscheduled pod" pod="default/kbench-deployment-oid-0-tid-1-db946cf6f-ltps7"
2023-09-03T06:46:56.931588248+02:00 stderr F I0903 04:46:56.931391       1 httplog.go:132] "HTTP" verb="GET" URI="/metrics" latency="12.20049ms" userAgent="Prometheus/2.46.0" audit-ID="" srcIP="192.168.100.20:4645" resp=200
2023-09-03T06:47:36.689289796+02:00 stderr F I0903 04:47:36.689076       1 eventhandlers.go:206] "Update event for scheduled pod" pod="default/kbench-deployment-oid-0-tid-1-db946cf6f-nhd4n"
2023-09-03T06:47:13.777114393+02:00 stderr F I0903 04:47:13.776818       1 round_trippers.go:553] PUT https://192.168.100.1:6443/apis/coordination.k8s.io/v1/namespaces/kube-system/leases/kube-scheduler?timeout=5s 200 OK in 37 milliseconds
2023-09-03T06:46:49.501871668+02:00 stderr F I0903 04:46:49.501598       1 leaderelection.go:276] successfully renewed lease kube-system/kube-scheduler
2023-09-03T06:47:05.617444524+02:00 stderr F I0903 04:47:05.617337       1 scheduling_queue.go:419] "Pod moved to an internal scheduling queue" pod="default/kbench-deployment-oid-0-tid-0-bdb979454-bd7vn" event="PodAdd" queue="Active"
2023-09-03T06:47:11.732242286+02:00 stderr F I0903 04:47:11.732099       1 leaderelection.go:276] successfully renewed lease kube-system/kube-scheduler
2023-09-03T06:47:11.926082466+02:00 stderr F I0903 04:47:11.925006       1 round_trippers.go:553] POST https://192.168.100.1:6443/apis/authentication.k8s.io/v1/tokenreviews 201 Created in 5 milliseconds
2023-09-03T06:46:46.774955699+02:00 stderr F I0903 04:46:46.774812       1 cache.go:401] "Finished binding for pod, can be expired" podKey="13d98df4-df93-40fb-b13c-d343694fa7e3" pod="default/kbench-deployment-oid-0-tid-1-778f5d498c-ws7jt"
2023-09-03T06:47:23.925921918+02:00 stderr F I0903 04:47:23.925622       1 round_trippers.go:553] POST https://192.168.100.1:6443/apis/authentication.k8s.io/v1/tokenreviews 201 Created in 4 milliseconds
2023-09-03T06:47:05.562949244+02:00 stderr F I0903 04:47:05.562870       1 eventhandlers.go:206] "Update event for scheduled pod" pod="default/kbench-deployment-oid-0-tid-1-778f5d498c-7lp58"
2023-09-03T06:47:13.777186679+02:00 stderr F I0903 04:47:13.776977       1 leaderelection.go:276] successfully renewed lease kube-system/kube-scheduler
2023-09-03T06:46:49.501847076+02:00 stderr F I0903 04:46:49.501416       1 round_trippers.go:553] PUT https://192.168.100.1:6443/apis/coordination.k8s.io/v1/namespaces/kube-system/leases/kube-scheduler?timeout=5s 200 OK in 8 milliseconds
2023-09-03T06:47:05.623360136+02:00 stderr F I0903 04:47:05.623118       1 default_binder.go:53] "Attempting to bind pod to node" pod="default/kbench-deployment-oid-0-tid-1-778f5d498c-sc9lm" node="w02"
2023-09-03T06:47:05.563042514+02:00 stderr F I0903 04:47:05.562980       1 eventhandlers.go:206] "Update event for scheduled pod" pod="default/kbench-deployment-oid-0-tid-2-cc4784d96-mh8hc"
2023-09-03T06:47:31.946925845+02:00 stderr F I0903 04:47:31.946680       1 leaderelection.go:276] successfully renewed lease kube-system/kube-scheduler
2023-09-03T06:47:36.739377045+02:00 stderr F I0903 04:47:36.739281       1 eventhandlers.go:231] "Delete event for scheduled pod" pod="default/kbench-deployment-oid-0-tid-1-db946cf6f-ltps7"
2023-09-03T06:46:50.968890288+02:00 stderr F I0903 04:46:50.968586       1 httplog.go:132] "HTTP" verb="GET" URI="/metrics" latency="47.731662ms" userAgent="Prometheus/2.46.0" audit-ID="" srcIP="192.168.100.20:4645" resp=200
2023-09-03T06:47:23.665427957+02:00 stderr F I0903 04:47:23.665189       1 pathrecorder.go:241] kube-scheduler: "/healthz" satisfied by exact match
2023-09-03T06:46:51.521435886+02:00 stderr F I0903 04:46:51.521111       1 leaderelection.go:276] successfully renewed lease kube-system/kube-scheduler
2023-09-03T06:47:05.650275132+02:00 stderr F I0903 04:47:05.650198       1 eventhandlers.go:186] "Add event for scheduled pod" pod="default/kbench-deployment-oid-0-tid-1-778f5d498c-sc9lm"
2023-09-03T06:46:46.782851951+02:00 stderr F I0903 04:46:46.782783       1 scheduling_queue.go:419] "Pod moved to an internal scheduling queue" pod="default/kbench-deployment-oid-0-tid-0-bdb979454-b2mrc" event="PodAdd" queue="Active"
2023-09-03T06:46:59.931302368+02:00 stderr F I0903 04:46:59.931080       1 round_trippers.go:553] POST https://192.168.100.1:6443/apis/authorization.k8s.io/v1/subjectaccessreviews?timeout=10s 201 Created in 5 milliseconds
2023-09-03T06:46:49.493387416+02:00 stderr F I0903 04:46:49.493018       1 round_trippers.go:553] GET https://192.168.100.1:6443/apis/coordination.k8s.io/v1/namespaces/kube-system/leases/kube-scheduler?timeout=5s 200 OK in 5 milliseconds
2023-09-03T06:46:46.754802452+02:00 stderr F I0903 04:46:46.754777       1 schedule_one.go:252] "Successfully bound pod to node" pod="default/kbench-deployment-oid-0-tid-2-cc4784d96-mh8hc" node="w01" evaluatedNodes=5 feasibleNodes=3
2023-09-03T06:46:46.766627958+02:00 stderr F I0903 04:46:46.766469       1 round_trippers.go:553] POST https://192.168.100.1:6443/api/v1/namespaces/default/pods/kbench-deployment-oid-0-tid-0-bdb979454-kf4kq/binding 201 Created in 23 milliseconds
2023-09-03T06:47:28.566298903+02:00 stderr F I0903 04:47:28.566015       1 eventhandlers.go:206] "Update event for scheduled pod" pod="default/kbench-deployment-oid-0-tid-0-bdb979454-kf4kq"
2023-09-03T06:47:07.573082825+02:00 stderr F I0903 04:47:07.571813       1 round_trippers.go:553] POST https://192.168.100.1:6443/api/v1/namespaces/default/pods/kbench-deployment-oid-0-tid-1-db946cf6f-nhd4n/binding 201 Created in 14 milliseconds
2023-09-03T06:47:05.623905525+02:00 stderr F I0903 04:47:05.623751       1 default_binder.go:53] "Attempting to bind pod to node" pod="default/kbench-deployment-oid-0-tid-0-bdb979454-bd7vn" node="w03"
2023-09-03T06:47:07.690387913+02:00 stderr F I0903 04:47:07.690117       1 round_trippers.go:553] GET https://192.168.100.1:6443/apis/coordination.k8s.io/v1/namespaces/kube-system/leases/kube-scheduler?timeout=5s 200 OK in 4 milliseconds
2023-09-03T06:47:36.020682797+02:00 stderr F I0903 04:47:36.020345       1 eventhandlers.go:231] "Delete event for scheduled pod" pod="default/kbench-deployment-oid-0-tid-1-778f5d498c-7lp58"
2023-09-03T06:46:46.803392577+02:00 stderr F I0903 04:46:46.803237       1 round_trippers.go:553] POST https://192.168.100.1:6443/apis/events.k8s.io/v1/namespaces/default/events 201 Created in 15 milliseconds
2023-09-03T06:46:48.011934299+02:00 stderr F I0903 04:46:48.011550       1 round_trippers.go:553] POST https://192.168.100.1:6443/apis/authorization.k8s.io/v1/subjectaccessreviews?timeout=10s 201 Created in 3 milliseconds
2023-09-03T06:47:33.955017339+02:00 stderr F I0903 04:47:33.954607       1 round_trippers.go:553] GET https://192.168.100.1:6443/apis/coordination.k8s.io/v1/namespaces/kube-system/leases/kube-scheduler?timeout=5s 200 OK in 6 milliseconds
2023-09-03T06:47:05.75439144+02:00 stderr F I0903 04:47:05.754206       1 eventhandlers.go:206] "Update event for scheduled pod" pod="default/kbench-deployment-oid-0-tid-1-db946cf6f-ltps7"
2023-09-03T06:47:23.946776294+02:00 stderr F I0903 04:47:23.946446       1 httplog.go:132] "HTTP" verb="GET" URI="/metrics" latency="25.966348ms" userAgent="Prometheus/2.46.0" audit-ID="" srcIP="192.168.100.20:4645" resp=200
2023-09-03T06:47:05.623081104+02:00 stderr F I0903 04:47:05.622939       1 schedule_one.go:80] "Attempting to schedule pod" pod="default/kbench-deployment-oid-0-tid-0-bdb979454-bd7vn"
2023-09-03T06:47:05.925482469+02:00 stderr F I0903 04:47:05.925232       1 pathrecorder.go:241] kube-scheduler: "/metrics" satisfied by exact match
2023-09-03T06:47:07.507787141+02:00 stderr F I0903 04:47:07.507269       1 eventhandlers.go:206] "Update event for scheduled pod" pod="default/kbench-deployment-oid-0-tid-0-bdb979454-bd7vn"
2023-09-03T06:47:23.931495875+02:00 stderr F I0903 04:47:23.931276       1 round_trippers.go:553] POST https://192.168.100.1:6443/apis/authorization.k8s.io/v1/subjectaccessreviews?timeout=10s 201 Created in 4 milliseconds
2023-09-03T06:47:05.731579941+02:00 stderr F I0903 04:47:05.731525       1 cache.go:401] "Finished binding for pod, can be expired" podKey="19728f4e-38c0-4134-8105-f4ce4e77dcf6" pod="default/kbench-deployment-oid-0-tid-1-db946cf6f-ltps7"
2023-09-03T06:47:23.932020639+02:00 stderr F I0903 04:47:23.931859       1 pathrecorder.go:241] kube-scheduler: "/metrics" satisfied by exact match
2023-09-03T06:47:07.537970384+02:00 stderr F I0903 04:47:07.537326       1 eventhandlers.go:206] "Update event for scheduled pod" pod="default/kbench-deployment-oid-0-tid-2-cc4784d96-kp5fp"
2023-09-03T06:47:20.935272254+02:00 stderr F I0903 04:47:20.935034       1 httplog.go:132] "HTTP" verb="GET" URI="/metrics" latency="15.356378ms" userAgent="Prometheus/2.46.0" audit-ID="" srcIP="192.168.100.20:4645" resp=200
2023-09-03T06:47:13.664103219+02:00 stderr F I0903 04:47:13.663819       1 httplog.go:132] "HTTP" verb="GET" URI="/healthz" latency="230.715µs" userAgent="kube-probe/1.27" audit-ID="" srcIP="127.0.0.1:48980" resp=200
2023-09-03T06:46:46.777134221+02:00 stderr F I0903 04:46:46.776249       1 round_trippers.go:553] POST https://192.168.100.1:6443/apis/events.k8s.io/v1/namespaces/default/events 201 Created in 21 milliseconds
2023-09-03T06:47:07.553997791+02:00 stderr F I0903 04:47:07.553902       1 scheduling_queue.go:419] "Pod moved to an internal scheduling queue" pod="default/kbench-deployment-oid-0-tid-1-db946cf6f-nhd4n" event="PodAdd" queue="Active"
2023-09-03T06:47:05.710741291+02:00 stderr F I0903 04:47:05.710547       1 eventhandlers.go:118] "Add event for unscheduled pod" pod="default/kbench-deployment-oid-0-tid-1-db946cf6f-ltps7"
2023-09-03T06:47:05.713268388+02:00 stderr F I0903 04:47:05.713143       1 default_binder.go:53] "Attempting to bind pod to node" pod="default/kbench-deployment-oid-0-tid-1-db946cf6f-ltps7" node="w03"
2023-09-03T06:47:05.622351732+02:00 stderr F I0903 04:47:05.622052       1 schedule_one.go:80] "Attempting to schedule pod" pod="default/kbench-deployment-oid-0-tid-1-778f5d498c-sc9lm"
2023-09-03T06:47:05.642686901+02:00 stderr F I0903 04:47:05.642526       1 schedule_one.go:252] "Successfully bound pod to node" pod="default/kbench-deployment-oid-0-tid-2-cc4784d96-kp5fp" node="w03" evaluatedNodes=5 feasibleNodes=2
2023-09-03T06:46:46.794388752+02:00 stderr F I0903 04:46:46.794190       1 round_trippers.go:553] POST https://192.168.100.1:6443/apis/events.k8s.io/v1/namespaces/default/events 201 Created in 19 milliseconds
2023-09-03T06:46:46.748172352+02:00 stderr F I0903 04:46:46.748084       1 scheduling_queue.go:1133] "About to try and schedule pod" pod="default/kbench-deployment-oid-0-tid-2-cc4784d96-x5f9h"
2023-09-03T06:47:17.935110036+02:00 stderr F I0903 04:47:17.934850       1 httplog.go:132] "HTTP" verb="GET" URI="/metrics" latency="14.545717ms" userAgent="Prometheus/2.46.0" audit-ID="" srcIP="192.168.100.20:4645" resp=200
2023-09-03T06:47:05.730320411+02:00 stderr F I0903 04:47:05.730168       1 eventhandlers.go:186] "Add event for scheduled pod" pod="default/kbench-deployment-oid-0-tid-1-db946cf6f-ltps7"
2023-09-03T06:47:07.484949617+02:00 stderr F I0903 04:47:07.484607       1 eventhandlers.go:206] "Update event for scheduled pod" pod="default/kbench-deployment-oid-0-tid-1-db946cf6f-ltps7"
2023-09-03T06:46:46.743281623+02:00 stderr F I0903 04:46:46.743171       1 default_binder.go:53] "Attempting to bind pod to node" pod="default/kbench-deployment-oid-0-tid-0-bdb979454-kf4kq" node="w02"
2023-09-03T06:47:35.925264799+02:00 stderr F I0903 04:47:35.925006       1 round_trippers.go:553] POST https://192.168.100.1:6443/apis/authentication.k8s.io/v1/tokenreviews 201 Created in 4 milliseconds
2023-09-03T06:47:05.595920612+02:00 stderr F I0903 04:47:05.595771       1 eventhandlers.go:206] "Update event for scheduled pod" pod="default/kbench-deployment-oid-0-tid-2-cc4784d96-mh8hc"
2023-09-03T06:46:48.006841454+02:00 stderr F I0903 04:46:48.006539       1 round_trippers.go:553] POST https://192.168.100.1:6443/apis/authentication.k8s.io/v1/tokenreviews 201 Created in 4 milliseconds
2023-09-03T06:47:05.649299686+02:00 stderr F I0903 04:47:05.649083       1 eventhandlers.go:186] "Add event for scheduled pod" pod="default/kbench-deployment-oid-0-tid-0-bdb979454-bd7vn"
2023-09-03T06:46:46.828260436+02:00 stderr F I0903 04:46:46.828099       1 round_trippers.go:553] POST https://192.168.100.1:6443/apis/events.k8s.io/v1/namespaces/default/events 201 Created in 13 milliseconds
2023-09-03T06:47:03.653894433+02:00 stderr F I0903 04:47:03.653768       1 round_trippers.go:553] PUT https://192.168.100.1:6443/apis/coordination.k8s.io/v1/namespaces/kube-system/leases/kube-scheduler?timeout=5s 200 OK in 13 milliseconds
2023-09-03T06:46:46.748129864+02:00 stderr F I0903 04:46:46.748043       1 scheduling_queue.go:419] "Pod moved to an internal scheduling queue" pod="default/kbench-deployment-oid-0-tid-2-cc4784d96-x5f9h" event="PodAdd" queue="Active"
2023-09-03T06:47:29.925124923+02:00 stderr F I0903 04:47:29.925028       1 leaderelection.go:276] successfully renewed lease kube-system/kube-scheduler
2023-09-03T06:47:05.668498541+02:00 stderr F I0903 04:47:05.668323       1 round_trippers.go:553] GET https://192.168.100.1:6443/apis/coordination.k8s.io/v1/namespaces/kube-system/leases/kube-scheduler?timeout=5s 200 OK in 13 milliseconds
2023-09-03T06:47:25.86885544+02:00 stderr F I0903 04:47:25.868496       1 round_trippers.go:553] GET https://192.168.100.1:6443/apis/coordination.k8s.io/v1/namespaces/kube-system/leases/kube-scheduler?timeout=5s 200 OK in 5 milliseconds
2023-09-03T06:46:48.334086839+02:00 stderr F I0903 04:46:48.333909       1 eventhandlers.go:206] "Update event for scheduled pod" pod="default/kbench-deployment-oid-0-tid-1-778f5d498c-7lp58"
2023-09-03T06:47:05.64965122+02:00 stderr F I0903 04:47:05.649453       1 eventhandlers.go:161] "Delete event for unscheduled pod" pod="default/kbench-deployment-oid-0-tid-0-bdb979454-bd7vn"
2023-09-03T06:46:48.311748582+02:00 stderr F I0903 04:46:48.311544       1 eventhandlers.go:206] "Update event for scheduled pod" pod="default/kbench-deployment-oid-0-tid-2-cc4784d96-mh8hc"
2023-09-03T06:46:46.865281528+02:00 stderr F I0903 04:46:46.865021       1 eventhandlers.go:206] "Update event for scheduled pod" pod="default/kbench-deployment-oid-0-tid-1-778f5d498c-7lp58"
2023-09-03T06:47:05.651572536+02:00 stderr F I0903 04:47:05.651393       1 schedule_one.go:252] "Successfully bound pod to node" pod="default/kbench-deployment-oid-0-tid-0-bdb979454-bd7vn" node="w03" evaluatedNodes=5 feasibleNodes=2
2023-09-03T06:47:08.936448729+02:00 stderr F I0903 04:47:08.936216       1 httplog.go:132] "HTTP" verb="GET" URI="/metrics" latency="16.431496ms" userAgent="Prometheus/2.46.0" audit-ID="" srcIP="192.168.100.20:4645" resp=200
2023-09-03T06:46:46.742966001+02:00 stderr F I0903 04:46:46.742353       1 scheduling_queue.go:1133] "About to try and schedule pod" pod="default/kbench-deployment-oid-0-tid-0-bdb979454-kf4kq"
2023-09-03T06:46:46.814947476+02:00 stderr F I0903 04:46:46.814877       1 eventhandlers.go:186] "Add event for scheduled pod" pod="default/kbench-deployment-oid-0-tid-1-778f5d498c-7lp58"
2023-09-03T06:46:46.787020234+02:00 stderr F I0903 04:46:46.786883       1 round_trippers.go:553] POST https://192.168.100.1:6443/apis/events.k8s.io/v1/namespaces/default/events 201 Created in 19 milliseconds
2023-09-03T06:47:19.82603676+02:00 stderr F I0903 04:47:19.825834       1 leaderelection.go:276] successfully renewed lease kube-system/kube-scheduler
2023-09-03T06:47:36.601476561+02:00 stderr F I0903 04:47:36.601184       1 eventhandlers.go:206] "Update event for scheduled pod" pod="default/kbench-deployment-oid-0-tid-0-bdb979454-bd7vn"
2023-09-03T06:46:46.791278231+02:00 stderr F I0903 04:46:46.791000       1 scheduling_queue.go:1133] "About to try and schedule pod" pod="default/kbench-deployment-oid-0-tid-1-778f5d498c-7lp58"
2023-09-03T06:47:05.523200639+02:00 stderr F I0903 04:47:05.523052       1 eventhandlers.go:206] "Update event for scheduled pod" pod="monitoring/node-exporter-s8bqq"
2023-09-03T06:47:01.62378208+02:00 stderr F I0903 04:47:01.622924       1 round_trippers.go:553] GET https://192.168.100.1:6443/apis/coordination.k8s.io/v1/namespaces/kube-system/leases/kube-scheduler?timeout=5s 200 OK in 4 milliseconds
2023-09-03T06:46:46.787803541+02:00 stderr F I0903 04:46:46.787709       1 eventhandlers.go:118] "Add event for unscheduled pod" pod="default/kbench-deployment-oid-0-tid-1-778f5d498c-7lp58"
2023-09-03T06:47:11.946763293+02:00 stderr F I0903 04:47:11.946324       1 httplog.go:132] "HTTP" verb="GET" URI="/metrics" latency="27.047169ms" userAgent="Prometheus/2.46.0" audit-ID="" srcIP="192.168.100.20:4645" resp=200
2023-09-03T06:46:46.765629794+02:00 stderr F I0903 04:46:46.765419       1 eventhandlers.go:161] "Delete event for unscheduled pod" pod="default/kbench-deployment-oid-0-tid-0-bdb979454-kf4kq"
2023-09-03T06:47:05.644821032+02:00 stderr F I0903 04:47:05.644678       1 cache.go:401] "Finished binding for pod, can be expired" podKey="515825e3-e780-4cff-8fee-920dd9c582f3" pod="default/kbench-deployment-oid-0-tid-1-778f5d498c-sc9lm"
2023-09-03T06:46:55.543184861+02:00 stderr F I0903 04:46:55.542941       1 round_trippers.go:553] GET https://192.168.100.1:6443/apis/coordination.k8s.io/v1/namespaces/kube-system/leases/kube-scheduler?timeout=5s 200 OK in 5 milliseconds
2023-09-03T06:47:14.933824671+02:00 stderr F I0903 04:47:14.933603       1 httplog.go:132] "HTTP" verb="GET" URI="/metrics" latency="14.291487ms" userAgent="Prometheus/2.46.0" audit-ID="" srcIP="192.168.100.20:4645" resp=200
2023-09-03T06:47:07.55403494+02:00 stderr F I0903 04:47:07.553950       1 scheduling_queue.go:1133] "About to try and schedule pod" pod="default/kbench-deployment-oid-0-tid-1-db946cf6f-nhd4n"
2023-09-03T06:46:50.921455744+02:00 stderr F I0903 04:46:50.921063       1 pathrecorder.go:241] kube-scheduler: "/metrics" satisfied by exact match
2023-09-03T06:46:46.742960555+02:00 stderr F I0903 04:46:46.742257       1 scheduling_queue.go:419] "Pod moved to an internal scheduling queue" pod="default/kbench-deployment-oid-0-tid-0-bdb979454-kf4kq" event="PodAdd" queue="Active"
2023-09-03T06:47:05.82479838+02:00 stderr F I0903 04:47:05.824582       1 eventhandlers.go:231] "Delete event for scheduled pod" pod="monitoring/node-exporter-s8bqq"
2023-09-03T06:46:46.811992127+02:00 stderr F I0903 04:46:46.811921       1 schedule_one.go:252] "Successfully bound pod to node" pod="default/kbench-deployment-oid-0-tid-1-778f5d498c-7lp58" node="w01" evaluatedNodes=5 feasibleNodes=3
2023-09-03T06:47:05.562828105+02:00 stderr F I0903 04:47:05.562046       1 eventhandlers.go:206] "Update event for scheduled pod" pod="default/kbench-deployment-oid-0-tid-0-bdb979454-b2mrc"
2023-09-03T06:46:59.924729593+02:00 stderr F I0903 04:46:59.924515       1 round_trippers.go:553] POST https://192.168.100.1:6443/apis/authentication.k8s.io/v1/tokenreviews 201 Created in 3 milliseconds
2023-09-03T06:47:26.935748438+02:00 stderr F I0903 04:47:26.935396       1 httplog.go:132] "HTTP" verb="GET" URI="/metrics" latency="14.674922ms" userAgent="Prometheus/2.46.0" audit-ID="" srcIP="192.168.100.20:4645" resp=200
2023-09-28T00:04:21.926897454+02:00 stderr F I0927 22:04:21.926738       1 eventhandlers.go:186] "Add event for scheduled pod" pod="default/kbench-deployment-oid-0-tid-1-778f5d498c-p5rq8"
2023-09-28T00:04:21.952718047+02:00 stderr F I0927 22:04:21.952513       1 schedule_one.go:252] "Successfully bound pod to node" pod="default/kbench-deployment-oid-0-tid-0-bdb979454-mgkc4" node="w02" evaluatedNodes=5 feasibleNodes=3
2023-09-28T00:04:00.422849659+02:00 stderr F I0927 22:04:00.422702       1 default_binder.go:53] "Attempting to bind pod to node" pod="default/kbench-deployment-oid-0-tid-0-bdb979454-tmk9w" node="w02"
2023-09-28T00:04:02.274372829+02:00 stderr F I0927 22:04:02.273848       1 eventhandlers.go:206] "Update event for scheduled pod" pod="default/kbench-deployment-oid-0-tid-0-bdb979454-k5988"
2023-09-28T00:04:09.036792787+02:00 stderr F I0927 22:04:09.036498       1 round_trippers.go:553] PUT https://192.168.100.1:6443/apis/coordination.k8s.io/v1/namespaces/kube-system/leases/kube-scheduler?timeout=5s 200 OK in 5 milliseconds
2023-09-28T00:04:19.129273915+02:00 stderr F I0927 22:04:19.129139       1 leaderelection.go:276] successfully renewed lease kube-system/kube-scheduler
2023-09-28T00:04:00.961737204+02:00 stderr F I0927 22:04:00.961363       1 round_trippers.go:553] PUT https://192.168.100.1:6443/apis/coordination.k8s.io/v1/namespaces/kube-system/leases/kube-scheduler?timeout=5s 200 OK in 14 milliseconds
2023-09-28T00:04:31.965904994+02:00 stderr F I0927 22:04:31.965760       1 eventhandlers.go:186] "Add event for scheduled pod" pod="default/kbench-deployment-oid-0-tid-1-778f5d498c-rn884"
2023-09-28T00:04:50.212441876+02:00 stderr F I0927 22:04:50.212301       1 eventhandlers.go:231] "Delete event for scheduled pod" pod="default/kbench-deployment-oid-0-tid-0-bdb979454-ddkph"
2023-09-28T00:04:47.411014838+02:00 stderr F I0927 22:04:47.410887       1 round_trippers.go:553] PUT https://192.168.100.1:6443/apis/coordination.k8s.io/v1/namespaces/kube-system/leases/kube-scheduler?timeout=5s 200 OK in 12 milliseconds
2023-09-28T00:04:11.227241468+02:00 stderr F I0927 22:04:11.226973       1 round_trippers.go:553] POST https://192.168.100.1:6443/apis/authentication.k8s.io/v1/tokenreviews 201 Created in 5 milliseconds
2023-09-28T00:04:25.187347598+02:00 stderr F I0927 22:04:25.187180       1 round_trippers.go:553] PUT https://192.168.100.1:6443/apis/coordination.k8s.io/v1/namespaces/kube-system/leases/kube-scheduler?timeout=5s 200 OK in 9 milliseconds
2023-09-28T00:04:33.271989793+02:00 stderr F I0927 22:04:33.271803       1 round_trippers.go:553] PUT https://192.168.100.1:6443/apis/coordination.k8s.io/v1/namespaces/kube-system/leases/kube-scheduler?timeout=5s 200 OK in 9 milliseconds
2023-09-28T00:04:00.43810805+02:00 stderr F I0927 22:04:00.438015       1 eventhandlers.go:118] "Add event for unscheduled pod" pod="default/kbench-deployment-oid-0-tid-0-bdb979454-k5988"
2023-09-28T00:04:50.272960007+02:00 stderr F I0927 22:04:50.271770       1 eventhandlers.go:231] "Delete event for scheduled pod" pod="default/kbench-deployment-oid-0-tid-0-bdb979454-tmk9w"
2023-09-28T00:04:41.349294291+02:00 stderr F I0927 22:04:41.349066       1 leaderelection.go:276] successfully renewed lease kube-system/kube-scheduler
2023-09-28T00:04:00.444685573+02:00 stderr F I0927 22:04:00.444566       1 eventhandlers.go:186] "Add event for scheduled pod" pod="default/kbench-deployment-oid-0-tid-1-778f5d498c-mkbcg"
2023-09-28T00:04:21.959471712+02:00 stderr F I0927 22:04:21.959054       1 round_trippers.go:553] POST https://192.168.100.1:6443/apis/events.k8s.io/v1/namespaces/default/events 201 Created in 6 milliseconds
2023-09-28T00:04:27.220900205+02:00 stderr F I0927 22:04:27.220753       1 leaderelection.go:276] successfully renewed lease kube-system/kube-scheduler
2023-09-28T00:04:38.235946161+02:00 stderr F I0927 22:04:38.235654       1 httplog.go:132] "HTTP" verb="GET" URI="/metrics" latency="14.025106ms" userAgent="Prometheus/2.47.0" audit-ID="" srcIP="192.168.100.20:57002" resp=200
2023-09-28T00:04:21.915831846+02:00 stderr F I0927 22:04:21.915700       1 default_binder.go:53] "Attempting to bind pod to node" pod="default/kbench-deployment-oid-0-tid-1-778f5d498c-p5rq8" node="w01"
2023-09-28T00:04:09.030457949+02:00 stderr F I0927 22:04:09.030321       1 round_trippers.go:553] GET https://192.168.100.1:6443/apis/coordination.k8s.io/v1/namespaces/kube-system/leases/kube-scheduler?timeout=5s 200 OK in 3 milliseconds
2023-09-28T00:04:11.233604083+02:00 stderr F I0927 22:04:11.233339       1 pathrecorder.go:241] kube-scheduler: "/metrics" satisfied by exact match
2023-09-28T00:04:35.230932904+02:00 stderr F I0927 22:04:35.230709       1 pathrecorder.go:241] kube-scheduler: "/metrics" satisfied by exact match
2023-09-28T00:04:19.422158702+02:00 stderr F I0927 22:04:19.421633       1 pathrecorder.go:241] kube-scheduler: "/healthz" satisfied by exact match
2023-09-28T00:04:17.094240699+02:00 stderr F I0927 22:04:17.094053       1 round_trippers.go:553] GET https://192.168.100.1:6443/apis/coordination.k8s.io/v1/namespaces/kube-system/leases/kube-scheduler?timeout=5s 200 OK in 5 milliseconds
2023-09-28T00:04:08.23514774+02:00 stderr F I0927 22:04:08.234855       1 httplog.go:132] "HTTP" verb="GET" URI="/metrics" latency="14.565846ms" userAgent="Prometheus/2.47.0" audit-ID="" srcIP="192.168.100.20:57002" resp=200
2023-09-28T00:04:31.972351134+02:00 stderr F I0927 22:04:31.972295       1 cache.go:401] "Finished binding for pod, can be expired" podKey="e7e0f5ff-d00d-4dae-bcbf-209d37a55cad" pod="default/kbench-deployment-oid-0-tid-0-bdb979454-ddkph"
2023-09-28T00:04:26.235057744+02:00 stderr F I0927 22:04:26.234686       1 httplog.go:132] "HTTP" verb="GET" URI="/metrics" latency="13.057092ms" userAgent="Prometheus/2.47.0" audit-ID="" srcIP="192.168.100.20:57002" resp=200
2023-09-28T00:04:04.990199027+02:00 stderr F I0927 22:04:04.990065       1 leaderelection.go:276] successfully renewed lease kube-system/kube-scheduler
2023-09-28T00:04:21.924570934+02:00 stderr F I0927 22:04:21.924454       1 default_binder.go:53] "Attempting to bind pod to node" pod="default/kbench-deployment-oid-0-tid-0-bdb979454-mgkc4" node="w02"
2023-09-28T00:04:31.951855086+02:00 stderr F I0927 22:04:31.951661       1 scheduling_queue.go:419] "Pod moved to an internal scheduling queue" pod="default/kbench-deployment-oid-0-tid-0-bdb979454-ddkph" event="PodAdd" queue="Active"
2023-09-28T00:04:17.10218493+02:00 stderr F I0927 22:04:17.102069       1 leaderelection.go:276] successfully renewed lease kube-system/kube-scheduler
2023-09-28T00:04:37.310358643+02:00 stderr F I0927 22:04:37.309941       1 round_trippers.go:553] PUT https://192.168.100.1:6443/apis/coordination.k8s.io/v1/namespaces/kube-system/leases/kube-scheduler?timeout=5s 200 OK in 11 milliseconds
2023-09-28T00:04:38.221993836+02:00 stderr F I0927 22:04:38.221725       1 pathrecorder.go:241] kube-scheduler: "/metrics" satisfied by exact match
2023-09-28T00:04:11.92159027+02:00 stderr F I0927 22:04:11.921215       1 round_trippers.go:553] POST https://192.168.100.1:6443/api/v1/namespaces/default/pods/kbench-deployment-oid-0-tid-0-bdb979454-jknbn/binding 201 Created in 21 milliseconds
2023-09-28T00:04:21.135261338+02:00 stderr F I0927 22:04:21.134936       1 round_trippers.go:553] GET https://192.168.100.1:6443/apis/coordination.k8s.io/v1/namespaces/kube-system/leases/kube-scheduler?timeout=5s 200 OK in 4 milliseconds
2023-09-28T00:04:11.891683555+02:00 stderr F I0927 22:04:11.888802       1 default_binder.go:53] "Attempting to bind pod to node" pod="default/kbench-deployment-oid-0-tid-1-778f5d498c-f6fwt" node="w02"
2023-09-28T00:04:44.233608471+02:00 stderr F I0927 22:04:44.233104       1 httplog.go:132] "HTTP" verb="GET" URI="/metrics" latency="12.175763ms" userAgent="Prometheus/2.47.0" audit-ID="" srcIP="192.168.100.20:57002" resp=200
2023-09-28T00:04:00.445055344+02:00 stderr F I0927 22:04:00.444888       1 eventhandlers.go:161] "Delete event for unscheduled pod" pod="default/kbench-deployment-oid-0-tid-1-778f5d498c-mkbcg"
2023-09-28T00:04:31.97329675+02:00 stderr F I0927 22:04:31.972905       1 eventhandlers.go:161] "Delete event for unscheduled pod" pod="default/kbench-deployment-oid-0-tid-0-bdb979454-ddkph"
2023-09-28T00:04:00.447542062+02:00 stderr F I0927 22:04:00.447404       1 cache.go:401] "Finished binding for pod, can be expired" podKey="5c07ffda-c3b8-4cf4-9417-497ee442d85e" pod="default/kbench-deployment-oid-0-tid-1-778f5d498c-mkbcg"
2023-09-28T00:04:47.229882017+02:00 stderr F I0927 22:04:47.229655       1 round_trippers.go:553] POST https://192.168.100.1:6443/apis/authentication.k8s.io/v1/tokenreviews 201 Created in 7 milliseconds
2023-09-28T00:04:11.921376536+02:00 stderr F I0927 22:04:11.921200       1 eventhandlers.go:186] "Add event for scheduled pod" pod="default/kbench-deployment-oid-0-tid-0-bdb979454-jknbn"
2023-09-28T00:04:31.954344313+02:00 stderr F I0927 22:04:31.954239       1 default_binder.go:53] "Attempting to bind pod to node" pod="default/kbench-deployment-oid-0-tid-1-778f5d498c-rn884" node="w02"
2023-09-28T00:04:23.366688429+02:00 stderr F I0927 22:04:23.366020       1 eventhandlers.go:206] "Update event for scheduled pod" pod="default/kbench-deployment-oid-0-tid-1-778f5d498c-p5rq8"
2023-09-28T00:04:00.415912518+02:00 stderr F I0927 22:04:00.415654       1 scheduling_queue.go:419] "Pod moved to an internal scheduling queue" pod="default/kbench-deployment-oid-0-tid-1-778f5d498c-ksdkt" event="PodAdd" queue="Active"
2023-09-28T00:04:00.452408083+02:00 stderr F I0927 22:04:00.452212       1 eventhandlers.go:186] "Add event for scheduled pod" pod="default/kbench-deployment-oid-0-tid-0-bdb979454-k5988"
2023-09-28T00:04:50.267053952+02:00 stderr F I0927 22:04:50.266795       1 eventhandlers.go:231] "Delete event for scheduled pod" pod="default/kbench-deployment-oid-0-tid-1-778f5d498c-f6fwt"
2023-09-28T00:04:29.23668214+02:00 stderr F I0927 22:04:29.236558       1 httplog.go:132] "HTTP" verb="GET" URI="/metrics" latency="15.391474ms" userAgent="Prometheus/2.47.0" audit-ID="" srcIP="192.168.100.20:57002" resp=200
2023-09-28T00:04:11.901871878+02:00 stderr F I0927 22:04:11.901746       1 round_trippers.go:553] POST https://192.168.100.1:6443/api/v1/namespaces/default/pods/kbench-deployment-oid-0-tid-1-778f5d498c-f6fwt/binding 201 Created in 12 milliseconds
2023-09-28T00:04:00.961779088+02:00 stderr F I0927 22:04:00.961569       1 leaderelection.go:276] successfully renewed lease kube-system/kube-scheduler
2023-09-28T00:04:31.982557855+02:00 stderr F I0927 22:04:31.981963       1 round_trippers.go:553] POST https://192.168.100.1:6443/apis/events.k8s.io/v1/namespaces/default/events 201 Created in 8 milliseconds
2023-09-28T00:04:21.154499498+02:00 stderr F I0927 22:04:21.154461       1 leaderelection.go:276] successfully renewed lease kube-system/kube-scheduler
2023-09-28T00:04:00.420672236+02:00 stderr F I0927 22:04:00.420563       1 scheduling_queue.go:1133] "About to try and schedule pod" pod="default/kbench-deployment-oid-0-tid-0-bdb979454-tmk9w"
2023-09-28T00:04:31.972356794+02:00 stderr F I0927 22:04:31.972330       1 schedule_one.go:252] "Successfully bound pod to node" pod="default/kbench-deployment-oid-0-tid-0-bdb979454-ddkph" node="w03" evaluatedNodes=5 feasibleNodes=3
2023-09-28T00:04:00.454877918+02:00 stderr F I0927 22:04:00.454753       1 cache.go:401] "Finished binding for pod, can be expired" podKey="e5fe6f6e-73d6-486e-99d5-a08f8a6ce838" pod="default/kbench-deployment-oid-0-tid-0-bdb979454-k5988"
2023-09-28T00:04:00.420712095+02:00 stderr F I0927 22:04:00.420640       1 default_binder.go:53] "Attempting to bind pod to node" pod="default/kbench-deployment-oid-0-tid-1-778f5d498c-ksdkt" node="w01"
2023-09-28T00:04:21.913297275+02:00 stderr F I0927 22:04:21.913204       1 scheduling_queue.go:1133] "About to try and schedule pod" pod="default/kbench-deployment-oid-0-tid-1-778f5d498c-p5rq8"
2023-09-28T00:04:31.993367457+02:00 stderr F I0927 22:04:31.993199       1 eventhandlers.go:206] "Update event for scheduled pod" pod="default/kbench-deployment-oid-0-tid-1-778f5d498c-rn884"
2023-09-28T00:04:00.427761789+02:00 stderr F I0927 22:04:00.427449       1 schedule_one.go:80] "Attempting to schedule pod" pod="default/kbench-deployment-oid-0-tid-1-778f5d498c-mkbcg"
2023-09-28T00:04:11.897605529+02:00 stderr F I0927 22:04:11.897468       1 default_binder.go:53] "Attempting to bind pod to node" pod="default/kbench-deployment-oid-0-tid-0-bdb979454-jknbn" node="w03"
2023-09-28T00:04:00.452390433+02:00 stderr F I0927 22:04:00.452156       1 eventhandlers.go:161] "Delete event for unscheduled pod" pod="default/kbench-deployment-oid-0-tid-0-bdb979454-k5988"
2023-09-28T00:04:26.222139194+02:00 stderr F I0927 22:04:26.221758       1 pathrecorder.go:241] kube-scheduler: "/metrics" satisfied by exact match
2023-09-28T00:04:21.913274217+02:00 stderr F I0927 22:04:21.913073       1 eventhandlers.go:118] "Add event for unscheduled pod" pod="default/kbench-deployment-oid-0-tid-1-778f5d498c-p5rq8"
2023-09-28T00:04:31.95349435+02:00 stderr F I0927 22:04:31.953247       1 scheduling_queue.go:1133] "About to try and schedule pod" pod="default/kbench-deployment-oid-0-tid-1-778f5d498c-rn884"
2023-09-28T00:04:19.422206635+02:00 stderr F I0927 22:04:19.421719       1 httplog.go:132] "HTTP" verb="GET" URI="/healthz" latency="153.941µs" userAgent="kube-probe/1.27" audit-ID="" srcIP="127.0.0.1:51220" resp=200
2023-09-28T00:04:47.39832739+02:00 stderr F I0927 22:04:47.398073       1 round_trippers.go:553] GET https://192.168.100.1:6443/apis/coordination.k8s.io/v1/namespaces/kube-system/leases/kube-scheduler?timeout=5s 200 OK in 5 milliseconds
2023-09-28T00:04:04.980937079+02:00 stderr F I0927 22:04:04.980689       1 round_trippers.go:553] GET https://192.168.100.1:6443/apis/coordination.k8s.io/v1/namespaces/kube-system/leases/kube-scheduler?timeout=5s 200 OK in 5 milliseconds
2023-09-28T00:04:47.234718783+02:00 stderr F I0927 22:04:47.234451       1 round_trippers.go:553] POST https://192.168.100.1:6443/apis/authorization.k8s.io/v1/subjectaccessreviews?timeout=10s 201 Created in 3 milliseconds
2023-09-28T00:04:50.220865288+02:00 stderr F I0927 22:04:50.220695       1 pathrecorder.go:241] kube-scheduler: "/metrics" satisfied by exact match
2023-09-28T00:04:50.234910396+02:00 stderr F I0927 22:04:50.234812       1 eventhandlers.go:206] "Update event for scheduled pod" pod="default/kbench-deployment-oid-0-tid-1-778f5d498c-f6fwt"
2023-09-28T00:04:05.238672203+02:00 stderr F I0927 22:04:05.238401       1 httplog.go:132] "HTTP" verb="GET" URI="/metrics" latency="12.940189ms" userAgent="Prometheus/2.47.0" audit-ID="" srcIP="192.168.100.20:57002" resp=200
2023-09-28T00:04:21.951958574+02:00 stderr F I0927 22:04:21.951689       1 eventhandlers.go:161] "Delete event for unscheduled pod" pod="default/kbench-deployment-oid-0-tid-0-bdb979454-mgkc4"
2023-09-28T00:04:29.221683622+02:00 stderr F I0927 22:04:29.221354       1 pathrecorder.go:241] kube-scheduler: "/metrics" satisfied by exact match
2023-09-28T00:04:11.895709399+02:00 stderr F I0927 22:04:11.895621       1 schedule_one.go:80] "Attempting to schedule pod" pod="default/kbench-deployment-oid-0-tid-0-bdb979454-jknbn"
2023-09-28T00:04:37.298514036+02:00 stderr F I0927 22:04:37.298179       1 round_trippers.go:553] GET https://192.168.100.1:6443/apis/coordination.k8s.io/v1/namespaces/kube-system/leases/kube-scheduler?timeout=5s 200 OK in 7 milliseconds
2023-09-28T00:04:31.951864768+02:00 stderr F I0927 22:04:31.951704       1 schedule_one.go:80] "Attempting to schedule pod" pod="default/kbench-deployment-oid-0-tid-0-bdb979454-ddkph"
2023-09-28T00:04:00.427757343+02:00 stderr F I0927 22:04:00.427440       1 scheduling_queue.go:1133] "About to try and schedule pod" pod="default/kbench-deployment-oid-0-tid-1-778f5d498c-mkbcg"
2023-09-28T00:04:11.895698587+02:00 stderr F I0927 22:04:11.895552       1 scheduling_queue.go:419] "Pod moved to an internal scheduling queue" pod="default/kbench-deployment-oid-0-tid-0-bdb979454-jknbn" event="PodAdd" queue="Active"
2023-09-28T00:04:11.908217178+02:00 stderr F I0927 22:04:11.907473       1 eventhandlers.go:186] "Add event for scheduled pod" pod="default/kbench-deployment-oid-0-tid-1-778f5d498c-f6fwt"
2023-09-28T00:04:00.501859372+02:00 stderr F I0927 22:04:00.501721       1 eventhandlers.go:206] "Update event for scheduled pod" pod="default/kbench-deployment-oid-0-tid-1-778f5d498c-ksdkt"
2023-09-28T00:04:13.067442335+02:00 stderr F I0927 22:04:13.067209       1 round_trippers.go:553] PUT https://192.168.100.1:6443/apis/coordination.k8s.io/v1/namespaces/kube-system/leases/kube-scheduler?timeout=5s 200 OK in 11 milliseconds
2023-09-28T00:04:02.228369929+02:00 stderr F I0927 22:04:02.228205       1 pathrecorder.go:241] kube-scheduler: "/metrics" satisfied by exact match
2023-09-28T00:04:23.169422867+02:00 stderr F I0927 22:04:23.169286       1 round_trippers.go:553] PUT https://192.168.100.1:6443/apis/coordination.k8s.io/v1/namespaces/kube-system/leases/kube-scheduler?timeout=5s 200 OK in 9 milliseconds
2023-09-28T00:04:21.923789712+02:00 stderr F I0927 22:04:21.923679       1 scheduling_queue.go:1133] "About to try and schedule pod" pod="default/kbench-deployment-oid-0-tid-0-bdb979454-mgkc4"
2023-09-28T00:04:02.975071633+02:00 stderr F I0927 22:04:02.974835       1 leaderelection.go:276] successfully renewed lease kube-system/kube-scheduler
2023-09-28T00:04:11.921673874+02:00 stderr F I0927 22:04:11.921389       1 schedule_one.go:252] "Successfully bound pod to node" pod="default/kbench-deployment-oid-0-tid-0-bdb979454-jknbn" node="w03" evaluatedNodes=5 feasibleNodes=3
2023-09-28T00:04:14.239989558+02:00 stderr F I0927 22:04:14.239704       1 httplog.go:132] "HTTP" verb="GET" URI="/metrics" latency="14.557896ms" userAgent="Prometheus/2.47.0" audit-ID="" srcIP="192.168.100.20:57002" resp=200
2023-09-28T00:04:47.411091109+02:00 stderr F I0927 22:04:47.411020       1 leaderelection.go:276] successfully renewed lease kube-system/kube-scheduler
2023-09-28T00:04:00.417441955+02:00 stderr F I0927 22:04:00.417337       1 eventhandlers.go:118] "Add event for unscheduled pod" pod="default/kbench-deployment-oid-0-tid-0-bdb979454-tmk9w"
2023-09-28T00:04:31.97230932+02:00 stderr F I0927 22:04:31.972208       1 round_trippers.go:553] POST https://192.168.100.1:6443/api/v1/namespaces/default/pods/kbench-deployment-oid-0-tid-0-bdb979454-ddkph/binding 201 Created in 18 milliseconds
2023-09-28T00:04:49.436759261+02:00 stderr F I0927 22:04:49.436615       1 leaderelection.go:276] successfully renewed lease kube-system/kube-scheduler
2023-09-28T00:04:47.247237378+02:00 stderr F I0927 22:04:47.246926       1 httplog.go:132] "HTTP" verb="GET" URI="/metrics" latency="25.194305ms" userAgent="Prometheus/2.47.0" audit-ID="" srcIP="192.168.100.20:57002" resp=200
2023-09-28T00:04:11.049963768+02:00 stderr F I0927 22:04:11.049781       1 leaderelection.go:276] successfully renewed lease kube-system/kube-scheduler
2023-09-28T00:04:00.427752279+02:00 stderr F I0927 22:04:00.427419       1 scheduling_queue.go:419] "Pod moved to an internal scheduling queue" pod="default/kbench-deployment-oid-0-tid-1-778f5d498c-mkbcg" event="PodAdd" queue="Active"
2023-09-28T00:04:21.975968283+02:00 stderr F I0927 22:04:21.975728       1 eventhandlers.go:206] "Update event for scheduled pod" pod="default/kbench-deployment-oid-0-tid-0-bdb979454-mgkc4"
2023-09-28T00:04:00.434129691+02:00 stderr F I0927 22:04:00.434021       1 eventhandlers.go:161] "Delete event for unscheduled pod" pod="default/kbench-deployment-oid-0-tid-0-bdb979454-tmk9w"
2023-09-28T00:04:21.923675541+02:00 stderr F I0927 22:04:21.923407       1 eventhandlers.go:118] "Add event for unscheduled pod" pod="default/kbench-deployment-oid-0-tid-0-bdb979454-mgkc4"
2023-09-28T00:04:23.169784805+02:00 stderr F I0927 22:04:23.169627       1 leaderelection.go:276] successfully renewed lease kube-system/kube-scheduler
2023-09-28T00:04:41.34909421+02:00 stderr F I0927 22:04:41.348896       1 round_trippers.go:553] PUT https://192.168.100.1:6443/apis/coordination.k8s.io/v1/namespaces/kube-system/leases/kube-scheduler?timeout=5s 200 OK in 10 milliseconds
2023-09-28T00:04:09.424866946+02:00 stderr F I0927 22:04:09.424445       1 httplog.go:132] "HTTP" verb="GET" URI="/healthz" latency="165.435µs" userAgent="kube-probe/1.27" audit-ID="" srcIP="127.0.0.1:47132" resp=200
2023-09-28T00:04:11.934308142+02:00 stderr F I0927 22:04:11.934196       1 eventhandlers.go:206] "Update event for scheduled pod" pod="default/kbench-deployment-oid-0-tid-1-778f5d498c-f6fwt"
2023-09-28T00:04:12.756528688+02:00 stderr F I0927 22:04:12.756192       1 eventhandlers.go:206] "Update event for scheduled pod" pod="default/kbench-deployment-oid-0-tid-0-bdb979454-jknbn"
2023-09-28T00:04:21.94020809+02:00 stderr F I0927 22:04:21.939947       1 round_trippers.go:553] POST https://192.168.100.1:6443/apis/events.k8s.io/v1/namespaces/default/events 201 Created in 13 milliseconds
2023-09-28T00:04:21.154476048+02:00 stderr F I0927 22:04:21.154300       1 round_trippers.go:553] PUT https://192.168.100.1:6443/apis/coordination.k8s.io/v1/namespaces/kube-system/leases/kube-scheduler?timeout=5s 200 OK in 18 milliseconds
2023-09-28T00:04:00.441182237+02:00 stderr F I0927 22:04:00.441073       1 round_trippers.go:553] POST https://192.168.100.1:6443/api/v1/namespaces/default/pods/kbench-deployment-oid-0-tid-1-778f5d498c-ksdkt/binding 201 Created in 20 milliseconds
2023-09-28T00:04:00.521111945+02:00 stderr F I0927 22:04:00.520907       1 eventhandlers.go:206] "Update event for scheduled pod" pod="default/kbench-deployment-oid-0-tid-0-bdb979454-k5988"
2023-09-28T00:04:31.247722263+02:00 stderr F I0927 22:04:31.247177       1 round_trippers.go:553] GET https://192.168.100.1:6443/apis/coordination.k8s.io/v1/namespaces/kube-system/leases/kube-scheduler?timeout=5s 200 OK in 6 milliseconds
2023-09-28T00:04:04.989934359+02:00 stderr F I0927 22:04:04.989791       1 round_trippers.go:553] PUT https://192.168.100.1:6443/apis/coordination.k8s.io/v1/namespaces/kube-system/leases/kube-scheduler?timeout=5s 200 OK in 8 milliseconds
2023-09-28T00:04:00.419661652+02:00 stderr F I0927 22:04:00.419317       1 schedule_one.go:80] "Attempting to schedule pod" pod="default/kbench-deployment-oid-0-tid-1-778f5d498c-ksdkt"
2023-09-28T00:04:42.15599701+02:00 stderr F I0927 22:04:42.155900       1 eventhandlers.go:206] "Update event for scheduled pod" pod="default/kbench-deployment-oid-0-tid-0-bdb979454-k5988"
2023-09-28T00:04:31.95391031+02:00 stderr F I0927 22:04:31.953728       1 default_binder.go:53] "Attempting to bind pod to node" pod="default/kbench-deployment-oid-0-tid-0-bdb979454-ddkph" node="w03"
2023-09-28T00:04:31.95184051+02:00 stderr F I0927 22:04:31.951448       1 eventhandlers.go:118] "Add event for unscheduled pod" pod="default/kbench-deployment-oid-0-tid-0-bdb979454-ddkph"
2023-09-28T00:04:00.43812725+02:00 stderr F I0927 22:04:00.438077       1 scheduling_queue.go:419] "Pod moved to an internal scheduling queue" pod="default/kbench-deployment-oid-0-tid-0-bdb979454-k5988" event="PodAdd" queue="Active"
2023-09-28T00:04:42.145356432+02:00 stderr F I0927 22:04:42.145190       1 eventhandlers.go:206] "Update event for scheduled pod" pod="default/kbench-deployment-oid-0-tid-1-778f5d498c-ksdkt"
2023-09-28T00:04:23.159221275+02:00 stderr F I0927 22:04:23.158956       1 round_trippers.go:553] GET https://192.168.100.1:6443/apis/coordination.k8s.io/v1/namespaces/kube-system/leases/kube-scheduler?timeout=5s 200 OK in 4 milliseconds
2023-09-28T00:04:14.225419274+02:00 stderr F I0927 22:04:14.225128       1 pathrecorder.go:241] kube-scheduler: "/metrics" satisfied by exact match
2023-09-28T00:04:05.225771697+02:00 stderr F I0927 22:04:05.225493       1 pathrecorder.go:241] kube-scheduler: "/metrics" satisfied by exact match
2023-09-28T00:04:21.952020896+02:00 stderr F I0927 22:04:21.951926       1 eventhandlers.go:186] "Add event for scheduled pod" pod="default/kbench-deployment-oid-0-tid-0-bdb979454-mgkc4"
2023-09-28T00:04:23.230360932+02:00 stderr F I0927 22:04:23.230164       1 pathrecorder.go:241] kube-scheduler: "/metrics" satisfied by exact match
2023-09-28T00:04:00.438950943+02:00 stderr F I0927 22:04:00.438843       1 default_binder.go:53] "Attempting to bind pod to node" pod="default/kbench-deployment-oid-0-tid-0-bdb979454-k5988" node="w01"
2023-09-28T00:04:09.037163295+02:00 stderr F I0927 22:04:09.036808       1 leaderelection.go:276] successfully renewed lease kube-system/kube-scheduler
2023-09-28T00:04:21.913291991+02:00 stderr F I0927 22:04:21.913157       1 scheduling_queue.go:419] "Pod moved to an internal scheduling queue" pod="default/kbench-deployment-oid-0-tid-1-778f5d498c-p5rq8" event="PodAdd" queue="Active"
2023-09-28T00:04:29.422084138+02:00 stderr F I0927 22:04:29.421878       1 httplog.go:132] "HTTP" verb="GET" URI="/healthz" latency="153.702µs" userAgent="kube-probe/1.27" audit-ID="" srcIP="127.0.0.1:59956" resp=200
2023-09-28T00:04:41.338274174+02:00 stderr F I0927 22:04:41.337970       1 round_trippers.go:553] GET https://192.168.100.1:6443/apis/coordination.k8s.io/v1/namespaces/kube-system/leases/kube-scheduler?timeout=5s 200 OK in 6 milliseconds
2023-09-28T00:04:35.230817135+02:00 stderr F I0927 22:04:35.230336       1 round_trippers.go:553] POST https://192.168.100.1:6443/apis/authorization.k8s.io/v1/subjectaccessreviews?timeout=10s 201 Created in 4 milliseconds
2023-09-28T00:04:00.445751722+02:00 stderr F I0927 22:04:00.445591       1 round_trippers.go:553] POST https://192.168.100.1:6443/api/v1/namespaces/default/pods/kbench-deployment-oid-0-tid-1-778f5d498c-mkbcg/binding 201 Created in 16 milliseconds
2023-09-28T00:04:11.886135556+02:00 stderr F I0927 22:04:11.886028       1 scheduling_queue.go:1133] "About to try and schedule pod" pod="default/kbench-deployment-oid-0-tid-1-778f5d498c-f6fwt"
2023-09-28T00:04:00.434479473+02:00 stderr F I0927 22:04:00.434037       1 round_trippers.go:553] POST https://192.168.100.1:6443/api/v1/namespaces/default/pods/kbench-deployment-oid-0-tid-0-bdb979454-tmk9w/binding 201 Created in 10 milliseconds
2023-09-28T00:04:45.391429742+02:00 stderr F I0927 22:04:45.391070       1 leaderelection.go:276] successfully renewed lease kube-system/kube-scheduler
2023-09-28T00:04:37.310465739+02:00 stderr F I0927 22:04:37.310353       1 leaderelection.go:276] successfully renewed lease kube-system/kube-scheduler
2023-09-28T00:04:50.246283372+02:00 stderr F I0927 22:04:50.246171       1 eventhandlers.go:206] "Update event for scheduled pod" pod="default/kbench-deployment-oid-0-tid-1-778f5d498c-ksdkt"
2023-09-28T00:04:15.087221141+02:00 stderr F I0927 22:04:15.086940       1 round_trippers.go:553] PUT https://192.168.100.1:6443/apis/coordination.k8s.io/v1/namespaces/kube-system/leases/kube-scheduler?timeout=5s 200 OK in 7 milliseconds
2023-09-28T00:04:31.973312654+02:00 stderr F I0927 22:04:31.973092       1 eventhandlers.go:186] "Add event for scheduled pod" pod="default/kbench-deployment-oid-0-tid-0-bdb979454-ddkph"
2023-09-28T00:04:31.952311285+02:00 stderr F I0927 22:04:31.951966       1 eventhandlers.go:118] "Add event for unscheduled pod" pod="default/kbench-deployment-oid-0-tid-1-778f5d498c-rn884"
2023-09-28T00:04:20.237282801+02:00 stderr F I0927 22:04:20.236896       1 httplog.go:132] "HTTP" verb="GET" URI="/metrics" latency="13.245601ms" userAgent="Prometheus/2.47.0" audit-ID="" srcIP="192.168.100.20:57002" resp=200
2023-09-28T00:04:00.435409742+02:00 stderr F I0927 22:04:00.434041       1 eventhandlers.go:186] "Add event for scheduled pod" pod="default/kbench-deployment-oid-0-tid-0-bdb979454-tmk9w"
2023-09-28T00:04:49.423761309+02:00 stderr F I0927 22:04:49.423370       1 pathrecorder.go:241] kube-scheduler: "/healthz" satisfied by exact match
2023-09-28T00:04:31.257548398+02:00 stderr F I0927 22:04:31.257507       1 leaderelection.go:276] successfully renewed lease kube-system/kube-scheduler
2023-09-28T00:04:21.913315761+02:00 stderr F I0927 22:04:21.913226       1 schedule_one.go:80] "Attempting to schedule pod" pod="default/kbench-deployment-oid-0-tid-1-778f5d498c-p5rq8"
2023-09-28T00:04:00.415919724+02:00 stderr F I0927 22:04:00.415723       1 scheduling_queue.go:1133] "About to try and schedule pod" pod="default/kbench-deployment-oid-0-tid-1-778f5d498c-ksdkt"
2023-09-28T00:04:50.237670477+02:00 stderr F I0927 22:04:50.237387       1 eventhandlers.go:231] "Delete event for scheduled pod" pod="default/kbench-deployment-oid-0-tid-0-bdb979454-mgkc4"
2023-09-28T00:04:00.454900474+02:00 stderr F I0927 22:04:00.454859       1 schedule_one.go:252] "Successfully bound pod to node" pod="default/kbench-deployment-oid-0-tid-0-bdb979454-k5988" node="w01" evaluatedNodes=5 feasibleNodes=3
2023-09-28T00:04:17.235157098+02:00 stderr F I0927 22:04:17.234965       1 httplog.go:132] "HTTP" verb="GET" URI="/metrics" latency="13.823387ms" userAgent="Prometheus/2.47.0" audit-ID="" srcIP="192.168.100.20:57002" resp=200
2023-09-28T00:04:11.895683453+02:00 stderr F I0927 22:04:11.895397       1 eventhandlers.go:118] "Add event for unscheduled pod" pod="default/kbench-deployment-oid-0-tid-0-bdb979454-jknbn"
2023-09-28T00:04:50.193473819+02:00 stderr F I0927 22:04:50.193261       1 eventhandlers.go:206] "Update event for scheduled pod" pod="default/kbench-deployment-oid-0-tid-0-bdb979454-k5988"
2023-09-28T00:04:39.328449324+02:00 stderr F I0927 22:04:39.328324       1 leaderelection.go:276] successfully renewed lease kube-system/kube-scheduler
2023-09-28T00:04:35.279368173+02:00 stderr F I0927 22:04:35.279014       1 round_trippers.go:553] GET https://192.168.100.1:6443/apis/coordination.k8s.io/v1/namespaces/kube-system/leases/kube-scheduler?timeout=5s 200 OK in 5 milliseconds
2023-09-28T00:04:02.24536952+02:00 stderr F I0927 22:04:02.245221       1 httplog.go:132] "HTTP" verb="GET" URI="/metrics" latency="17.100446ms" userAgent="Prometheus/2.47.0" audit-ID="" srcIP="192.168.100.20:57002" resp=200
2023-09-28T00:04:00.435190323+02:00 stderr F I0927 22:04:00.435096       1 schedule_one.go:252] "Successfully bound pod to node" pod="default/kbench-deployment-oid-0-tid-0-bdb979454-tmk9w" node="w02" evaluatedNodes=5 feasibleNodes=3
2023-09-28T00:04:00.438360548+02:00 stderr F I0927 22:04:00.438196       1 eventhandlers.go:186] "Add event for scheduled pod" pod="default/kbench-deployment-oid-0-tid-1-778f5d498c-ksdkt"
2023-09-28T00:04:42.173560086+02:00 stderr F I0927 22:04:42.173428       1 eventhandlers.go:206] "Update event for scheduled pod" pod="default/kbench-deployment-oid-0-tid-0-bdb979454-jknbn"
2023-09-28T00:04:02.24836332+02:00 stderr F I0927 22:04:02.248225       1 eventhandlers.go:206] "Update event for scheduled pod" pod="default/kbench-deployment-oid-0-tid-1-778f5d498c-ksdkt"
2023-09-28T00:04:00.462079854+02:00 stderr F I0927 22:04:00.461892       1 round_trippers.go:553] POST https://192.168.100.1:6443/apis/events.k8s.io/v1/namespaces/default/events 201 Created in 20 milliseconds
2023-09-28T00:04:50.301761583+02:00 stderr F I0927 22:04:50.301592       1 eventhandlers.go:231] "Delete event for scheduled pod" pod="default/kbench-deployment-oid-0-tid-1-778f5d498c-p5rq8"
2023-09-28T00:04:29.240771157+02:00 stderr F I0927 22:04:29.240630       1 round_trippers.go:553] PUT https://192.168.100.1:6443/apis/coordination.k8s.io/v1/namespaces/kube-system/leases/kube-scheduler?timeout=5s 200 OK in 11 milliseconds
2023-09-28T00:04:01.226950152+02:00 stderr F I0927 22:04:01.226732       1 eventhandlers.go:206] "Update event for scheduled pod" pod="default/kbench-deployment-oid-0-tid-0-bdb979454-tmk9w"
2023-09-28T00:04:49.436599492+02:00 stderr F I0927 22:04:49.436411       1 round_trippers.go:553] PUT https://192.168.100.1:6443/apis/coordination.k8s.io/v1/namespaces/kube-system/leases/kube-scheduler?timeout=5s 200 OK in 11 milliseconds
2023-09-28T00:04:11.243224571+02:00 stderr F I0927 22:04:11.242992       1 httplog.go:132] "HTTP" verb="GET" URI="/metrics" latency="21.82141ms" userAgent="Prometheus/2.47.0" audit-ID="" srcIP="192.168.100.20:57002" resp=200
2023-09-28T00:04:39.423342852+02:00 stderr F I0927 22:04:39.422990       1 pathrecorder.go:241] kube-scheduler: "/healthz" satisfied by exact match
2023-09-28T00:04:42.165487092+02:00 stderr F I0927 22:04:42.165287       1 eventhandlers.go:206] "Update event for scheduled pod" pod="default/kbench-deployment-oid-0-tid-1-778f5d498c-rn884"
2023-09-28T00:04:11.88614868+02:00 stderr F I0927 22:04:11.886050       1 schedule_one.go:80] "Attempting to schedule pod" pod="default/kbench-deployment-oid-0-tid-1-778f5d498c-f6fwt"
2023-09-28T00:04:23.308335209+02:00 stderr F I0927 22:04:23.307717       1 eventhandlers.go:206] "Update event for scheduled pod" pod="default/kbench-deployment-oid-0-tid-0-bdb979454-mgkc4"
2023-09-28T00:04:42.173543846+02:00 stderr F I0927 22:04:42.173330       1 eventhandlers.go:206] "Update event for scheduled pod" pod="default/kbench-deployment-oid-0-tid-0-bdb979454-mgkc4"
2023-09-28T00:04:11.921599704+02:00 stderr F I0927 22:04:11.921357       1 cache.go:401] "Finished binding for pod, can be expired" podKey="e813860e-eb3c-41ea-a282-acefe290f3f1" pod="default/kbench-deployment-oid-0-tid-0-bdb979454-jknbn"
2023-09-28T00:04:25.177550987+02:00 stderr F I0927 22:04:25.177224       1 round_trippers.go:553] GET https://192.168.100.1:6443/apis/coordination.k8s.io/v1/namespaces/kube-system/leases/kube-scheduler?timeout=5s 200 OK in 5 milliseconds
2023-08-24T23:43:07.93332498+02:00 stderr F I0824 21:43:07.932990       1 round_trippers.go:553] PUT https://192.168.100.1:6443/apis/coordination.k8s.io/v1/namespaces/kube-system/leases/kube-scheduler?timeout=5s 200 OK in 8 milliseconds
2023-08-24T23:43:29.490504187+02:00 stderr F I0824 21:43:29.490132       1 httplog.go:132] "HTTP" verb="GET" URI="/metrics" latency="10.174916ms" userAgent="Prometheus/2.46.0" audit-ID="" srcIP="192.168.100.20:1261" resp=200
2023-08-24T23:43:38.504275136+02:00 stderr F I0824 21:43:38.503949       1 httplog.go:132] "HTTP" verb="GET" URI="/metrics" latency="13.303696ms" userAgent="Prometheus/2.46.0" audit-ID="" srcIP="192.168.100.20:1261" resp=200
2023-08-24T23:43:38.491368189+02:00 stderr F I0824 21:43:38.490860       1 pathrecorder.go:241] kube-scheduler: "/metrics" satisfied by exact match
2023-08-24T23:43:44.847068262+02:00 stderr F I0824 21:43:44.846927       1 eventhandlers.go:231] "Delete event for scheduled pod" pod="default/kbench-deployment-oid-0-tid-2-cc4784d96-szzf5"
2023-08-24T23:43:35.494169021+02:00 stderr F I0824 21:43:35.493871       1 round_trippers.go:553] POST https://192.168.100.1:6443/apis/authorization.k8s.io/v1/subjectaccessreviews?timeout=10s 201 Created in 4 milliseconds
2023-08-24T23:43:38.181505131+02:00 stderr F I0824 21:43:38.181102       1 round_trippers.go:553] GET https://192.168.100.1:6443/apis/coordination.k8s.io/v1/namespaces/kube-system/leases/kube-scheduler?timeout=5s 200 OK in 5 milliseconds
2023-08-24T23:43:13.985250298+02:00 stderr F I0824 21:43:13.984954       1 round_trippers.go:553] PUT https://192.168.100.1:6443/apis/coordination.k8s.io/v1/namespaces/kube-system/leases/kube-scheduler?timeout=5s 200 OK in 6 milliseconds
2023-08-24T23:43:32.481336889+02:00 stderr F I0824 21:43:32.480929       1 pathrecorder.go:241] kube-scheduler: "/metrics" satisfied by exact match
2023-08-24T23:43:07.924634932+02:00 stderr F I0824 21:43:07.924398       1 round_trippers.go:553] GET https://192.168.100.1:6443/apis/coordination.k8s.io/v1/namespaces/kube-system/leases/kube-scheduler?timeout=5s 200 OK in 4 milliseconds
2023-08-24T23:43:23.491464067+02:00 stderr F I0824 21:43:23.491296       1 round_trippers.go:553] POST https://192.168.100.1:6443/apis/authorization.k8s.io/v1/subjectaccessreviews?timeout=10s 201 Created in 4 milliseconds
2023-08-24T23:43:13.815091604+02:00 stderr F I0824 21:43:13.815037       1 cache.go:401] "Finished binding for pod, can be expired" podKey="5a92de06-3701-48af-aec1-1aeb4b34d069" pod="default/kbench-deployment-oid-0-tid-1-778f5d498c-9wpxf"
2023-08-24T23:43:22.047415591+02:00 stderr F I0824 21:43:22.047242       1 round_trippers.go:553] PUT https://192.168.100.1:6443/apis/coordination.k8s.io/v1/namespaces/kube-system/leases/kube-scheduler?timeout=5s 200 OK in 8 milliseconds
2023-08-24T23:43:15.999499249+02:00 stderr F I0824 21:43:15.999337       1 round_trippers.go:553] PUT https://192.168.100.1:6443/apis/coordination.k8s.io/v1/namespaces/kube-system/leases/kube-scheduler?timeout=5s 200 OK in 7 milliseconds
2023-08-24T23:43:13.801227824+02:00 stderr F I0824 21:43:13.801083       1 round_trippers.go:553] POST https://192.168.100.1:6443/apis/events.k8s.io/v1/namespaces/default/events 201 Created in 18 milliseconds
2023-08-24T23:43:36.172424269+02:00 stderr F I0824 21:43:36.172340       1 leaderelection.go:276] successfully renewed lease kube-system/kube-scheduler
2023-08-24T23:43:13.787013515+02:00 stderr F I0824 21:43:13.786886       1 scheduling_queue.go:1133] "About to try and schedule pod" pod="default/kbench-deployment-oid-0-tid-1-778f5d498c-9wpxf"
2023-08-24T23:43:40.208753352+02:00 stderr F I0824 21:43:40.208555       1 leaderelection.go:276] successfully renewed lease kube-system/kube-scheduler
2023-08-24T23:43:38.190666097+02:00 stderr F I0824 21:43:38.190427       1 leaderelection.go:276] successfully renewed lease kube-system/kube-scheduler
2023-08-24T23:43:23.503436832+02:00 stderr F I0824 21:43:23.503180       1 httplog.go:132] "HTTP" verb="GET" URI="/metrics" latency="23.447244ms" userAgent="Prometheus/2.46.0" audit-ID="" srcIP="192.168.100.20:1261" resp=200
2023-08-24T23:43:11.50643331+02:00 stderr F I0824 21:43:11.506266       1 httplog.go:132] "HTTP" verb="GET" URI="/metrics" latency="25.73487ms" userAgent="Prometheus/2.46.0" audit-ID="" srcIP="192.168.100.20:1261" resp=200
2023-08-24T23:43:13.801801777+02:00 stderr F I0824 21:43:13.801649       1 eventhandlers.go:206] "Update event for scheduled pod" pod="default/kbench-deployment-oid-0-tid-0-bdb979454-7546h"
2023-08-24T23:43:41.482251946+02:00 stderr F I0824 21:43:41.481634       1 pathrecorder.go:241] kube-scheduler: "/metrics" satisfied by exact match
2023-08-24T23:43:13.782242932+02:00 stderr F I0824 21:43:13.782099       1 cache.go:401] "Finished binding for pod, can be expired" podKey="36749935-3007-457f-87d5-da8c1cb8bf3f" pod="default/kbench-deployment-oid-0-tid-0-bdb979454-7g7nw"
2023-08-24T23:43:07.933351403+02:00 stderr F I0824 21:43:07.933113       1 leaderelection.go:276] successfully renewed lease kube-system/kube-scheduler
2023-08-24T23:43:03.901170323+02:00 stderr F I0824 21:43:03.900940       1 round_trippers.go:553] PUT https://192.168.100.1:6443/apis/coordination.k8s.io/v1/namespaces/kube-system/leases/kube-scheduler?timeout=5s 200 OK in 9 milliseconds
2023-08-24T23:43:17.492558044+02:00 stderr F I0824 21:43:17.492352       1 httplog.go:132] "HTTP" verb="GET" URI="/metrics" latency="12.297866ms" userAgent="Prometheus/2.46.0" audit-ID="" srcIP="192.168.100.20:1261" resp=200
2023-08-24T23:43:44.229496972+02:00 stderr F I0824 21:43:44.229145       1 round_trippers.go:553] GET https://192.168.100.1:6443/apis/coordination.k8s.io/v1/namespaces/kube-system/leases/kube-scheduler?timeout=5s 200 OK in 3 milliseconds
2023-08-24T23:43:44.146521263+02:00 stderr F I0824 21:43:44.146192       1 eventhandlers.go:231] "Delete event for scheduled pod" pod="default/kbench-deployment-oid-0-tid-1-778f5d498c-7g8gq"
2023-08-24T23:43:36.721284114+02:00 stderr F I0824 21:43:36.721155       1 eventhandlers.go:206] "Update event for scheduled pod" pod="default/kbench-deployment-oid-0-tid-2-cc4784d96-szzf5"
2023-08-24T23:43:29.480458146+02:00 stderr F I0824 21:43:29.480110       1 pathrecorder.go:241] kube-scheduler: "/metrics" satisfied by exact match
2023-08-24T23:43:14.844393694+02:00 stderr F I0824 21:43:14.844183       1 eventhandlers.go:206] "Update event for scheduled pod" pod="default/kbench-deployment-oid-0-tid-0-bdb979454-7g7nw"
2023-08-24T23:43:13.780606878+02:00 stderr F I0824 21:43:13.780397       1 default_binder.go:53] "Attempting to bind pod to node" pod="default/kbench-deployment-oid-0-tid-2-cc4784d96-szzf5" node="w02"
2023-08-24T23:43:44.079380878+02:00 stderr F I0824 21:43:44.079077       1 eventhandlers.go:231] "Delete event for scheduled pod" pod="kube-flannel/kube-flannel-ds-l2mtb"
2023-08-24T23:43:17.480393711+02:00 stderr F I0824 21:43:17.480177       1 pathrecorder.go:241] kube-scheduler: "/metrics" satisfied by exact match
2023-08-24T23:43:26.4805056+02:00 stderr F I0824 21:43:26.480209       1 pathrecorder.go:241] kube-scheduler: "/metrics" satisfied by exact match
2023-08-24T23:43:23.491980078+02:00 stderr F I0824 21:43:23.491812       1 pathrecorder.go:241] kube-scheduler: "/metrics" satisfied by exact match
2023-08-24T23:43:09.953952647+02:00 stderr F I0824 21:43:09.953681       1 round_trippers.go:553] PUT https://192.168.100.1:6443/apis/coordination.k8s.io/v1/namespaces/kube-system/leases/kube-scheduler?timeout=5s 200 OK in 14 milliseconds
2023-08-24T23:43:40.197424553+02:00 stderr F I0824 21:43:40.197130       1 round_trippers.go:553] GET https://192.168.100.1:6443/apis/coordination.k8s.io/v1/namespaces/kube-system/leases/kube-scheduler?timeout=5s 200 OK in 6 milliseconds
2023-08-24T23:43:13.80336498+02:00 stderr F I0824 21:43:13.803193       1 cache.go:401] "Finished binding for pod, can be expired" podKey="969c0bc7-4aac-479a-b6e1-4f6cd1faf9eb" pod="default/kbench-deployment-oid-0-tid-2-cc4784d96-szzf5"
2023-08-24T23:43:14.823387292+02:00 stderr F I0824 21:43:14.823207       1 eventhandlers.go:206] "Update event for scheduled pod" pod="default/kbench-deployment-oid-0-tid-2-cc4784d96-szzf5"
2023-08-24T23:43:44.165248993+02:00 stderr F I0824 21:43:44.165118       1 eventhandlers.go:231] "Delete event for scheduled pod" pod="default/kbench-deployment-oid-0-tid-2-cc4784d96-99cqp"
2023-08-24T23:43:05.908003984+02:00 stderr F I0824 21:43:05.907650       1 round_trippers.go:553] GET https://192.168.100.1:6443/apis/coordination.k8s.io/v1/namespaces/kube-system/leases/kube-scheduler?timeout=5s 200 OK in 4 milliseconds
2023-08-24T23:43:13.803306465+02:00 stderr F I0824 21:43:13.803079       1 round_trippers.go:553] POST https://192.168.100.1:6443/api/v1/namespaces/default/pods/kbench-deployment-oid-0-tid-2-cc4784d96-szzf5/binding 201 Created in 22 milliseconds
2023-08-24T23:43:15.463232349+02:00 stderr F I0824 21:43:15.462735       1 httplog.go:132] "HTTP" verb="GET" URI="/healthz" latency="106.003µs" userAgent="kube-probe/1.27" audit-ID="" srcIP="127.0.0.1:57402" resp=200
2023-08-24T23:43:13.76997449+02:00 stderr F I0824 21:43:13.769773       1 default_binder.go:53] "Attempting to bind pod to node" pod="default/kbench-deployment-oid-0-tid-0-bdb979454-7g7nw" node="w02"
2023-08-24T23:43:44.798936719+02:00 stderr F I0824 21:43:44.798754       1 eventhandlers.go:231] "Delete event for scheduled pod" pod="default/kbench-deployment-oid-0-tid-0-bdb979454-6cv89"
2023-08-24T23:43:30.124390182+02:00 stderr F I0824 21:43:30.124256       1 leaderelection.go:276] successfully renewed lease kube-system/kube-scheduler
2023-08-24T23:43:42.223463648+02:00 stderr F I0824 21:43:42.223296       1 leaderelection.go:276] successfully renewed lease kube-system/kube-scheduler
2023-08-24T23:43:20.031475464+02:00 stderr F I0824 21:43:20.031330       1 round_trippers.go:553] PUT https://192.168.100.1:6443/apis/coordination.k8s.io/v1/namespaces/kube-system/leases/kube-scheduler?timeout=5s 200 OK in 9 milliseconds
2023-08-24T23:43:38.190115488+02:00 stderr F I0824 21:43:38.189876       1 round_trippers.go:553] PUT https://192.168.100.1:6443/apis/coordination.k8s.io/v1/namespaces/kube-system/leases/kube-scheduler?timeout=5s 200 OK in 8 milliseconds
2023-08-24T23:43:13.787008417+02:00 stderr F I0824 21:43:13.786861       1 scheduling_queue.go:419] "Pod moved to an internal scheduling queue" pod="default/kbench-deployment-oid-0-tid-1-778f5d498c-9wpxf" event="PodAdd" queue="Active"
2023-08-24T23:43:05.916006243+02:00 stderr F I0824 21:43:05.915835       1 round_trippers.go:553] PUT https://192.168.100.1:6443/apis/coordination.k8s.io/v1/namespaces/kube-system/leases/kube-scheduler?timeout=5s 200 OK in 7 milliseconds
2023-08-24T23:43:13.985330794+02:00 stderr F I0824 21:43:13.985186       1 leaderelection.go:276] successfully renewed lease kube-system/kube-scheduler
2023-08-24T23:43:44.816249682+02:00 stderr F I0824 21:43:44.816038       1 eventhandlers.go:231] "Delete event for scheduled pod" pod="default/kbench-deployment-oid-0-tid-1-778f5d498c-5c7mg"
2023-08-24T23:43:13.784059305+02:00 stderr F I0824 21:43:13.783778       1 eventhandlers.go:161] "Delete event for unscheduled pod" pod="default/kbench-deployment-oid-0-tid-0-bdb979454-7g7nw"
2023-08-24T23:43:20.480524261+02:00 stderr F I0824 21:43:20.480074       1 pathrecorder.go:241] kube-scheduler: "/metrics" satisfied by exact match
2023-08-24T23:43:13.762044456+02:00 stderr F I0824 21:43:13.761752       1 eventhandlers.go:206] "Update event for scheduled pod" pod="default/kbench-deployment-oid-0-tid-2-cc4784d96-99cqp"
2023-08-24T23:43:13.808073865+02:00 stderr F I0824 21:43:13.807727       1 eventhandlers.go:186] "Add event for scheduled pod" pod="default/kbench-deployment-oid-0-tid-1-778f5d498c-9wpxf"
2023-08-24T23:43:13.76690283+02:00 stderr F I0824 21:43:13.766740       1 schedule_one.go:80] "Attempting to schedule pod" pod="default/kbench-deployment-oid-0-tid-0-bdb979454-7g7nw"
2023-08-24T23:43:05.916610987+02:00 stderr F I0824 21:43:05.916428       1 leaderelection.go:276] successfully renewed lease kube-system/kube-scheduler
2023-08-24T23:43:44.816208243+02:00 stderr F I0824 21:43:44.815994       1 eventhandlers.go:231] "Delete event for scheduled pod" pod="default/kbench-deployment-oid-0-tid-0-bdb979454-7g7nw"
2023-08-24T23:43:28.096600976+02:00 stderr F I0824 21:43:28.096275       1 round_trippers.go:553] GET https://192.168.100.1:6443/apis/coordination.k8s.io/v1/namespaces/kube-system/leases/kube-scheduler?timeout=5s 200 OK in 4 milliseconds
2023-08-24T23:43:35.464826155+02:00 stderr F I0824 21:43:35.464040       1 httplog.go:132] "HTTP" verb="GET" URI="/healthz" latency="237.249µs" userAgent="kube-probe/1.27" audit-ID="" srcIP="127.0.0.1:36356" resp=200
2023-08-24T23:43:34.155387164+02:00 stderr F I0824 21:43:34.155162       1 leaderelection.go:276] successfully renewed lease kube-system/kube-scheduler
2023-08-24T23:43:09.938513695+02:00 stderr F I0824 21:43:09.938112       1 round_trippers.go:553] GET https://192.168.100.1:6443/apis/coordination.k8s.io/v1/namespaces/kube-system/leases/kube-scheduler?timeout=5s 200 OK in 4 milliseconds
2023-08-24T23:43:13.822777485+02:00 stderr F I0824 21:43:13.822570       1 round_trippers.go:553] POST https://192.168.100.1:6443/apis/events.k8s.io/v1/namespaces/default/events 201 Created in 19 milliseconds
2023-08-24T23:43:23.485750296+02:00 stderr F I0824 21:43:23.485531       1 round_trippers.go:553] POST https://192.168.100.1:6443/apis/authentication.k8s.io/v1/tokenreviews 201 Created in 5 milliseconds
2023-08-24T23:43:13.778826502+02:00 stderr F I0824 21:43:13.778752       1 scheduling_queue.go:1133] "About to try and schedule pod" pod="default/kbench-deployment-oid-0-tid-2-cc4784d96-szzf5"
2023-08-24T23:43:30.111905684+02:00 stderr F I0824 21:43:30.111645       1 round_trippers.go:553] GET https://192.168.100.1:6443/apis/coordination.k8s.io/v1/namespaces/kube-system/leases/kube-scheduler?timeout=5s 200 OK in 5 milliseconds
2023-08-24T23:43:32.136886529+02:00 stderr F I0824 21:43:32.136642       1 round_trippers.go:553] PUT https://192.168.100.1:6443/apis/coordination.k8s.io/v1/namespaces/kube-system/leases/kube-scheduler?timeout=5s 200 OK in 7 milliseconds
2023-08-24T23:43:25.464206912+02:00 stderr F I0824 21:43:25.463980       1 pathrecorder.go:241] kube-scheduler: "/healthz" satisfied by exact match
2023-08-24T23:43:13.782257154+02:00 stderr F I0824 21:43:13.782151       1 schedule_one.go:252] "Successfully bound pod to node" pod="default/kbench-deployment-oid-0-tid-0-bdb979454-7g7nw" node="w02" evaluatedNodes=5 feasibleNodes=2
2023-08-24T23:43:44.18663547+02:00 stderr F I0824 21:43:44.182123       1 eventhandlers.go:231] "Delete event for scheduled pod" pod="default/kbench-deployment-oid-0-tid-0-bdb979454-7546h"
2023-08-24T23:43:44.237331006+02:00 stderr F I0824 21:43:44.237184       1 leaderelection.go:276] successfully renewed lease kube-system/kube-scheduler
2023-08-24T23:43:44.811490917+02:00 stderr F I0824 21:43:44.811264       1 eventhandlers.go:206] "Update event for scheduled pod" pod="default/kbench-deployment-oid-0-tid-2-cc4784d96-szzf5"
2023-08-24T23:43:36.161768375+02:00 stderr F I0824 21:43:36.161498       1 round_trippers.go:553] GET https://192.168.100.1:6443/apis/coordination.k8s.io/v1/namespaces/kube-system/leases/kube-scheduler?timeout=5s 200 OK in 5 milliseconds
2023-08-24T23:43:26.493092763+02:00 stderr F I0824 21:43:26.492809       1 httplog.go:132] "HTTP" verb="GET" URI="/metrics" latency="12.711414ms" userAgent="Prometheus/2.46.0" audit-ID="" srcIP="192.168.100.20:1261" resp=200
2023-08-24T23:43:44.797391132+02:00 stderr F I0824 21:43:44.797111       1 eventhandlers.go:206] "Update event for scheduled pod" pod="default/kbench-deployment-oid-0-tid-1-778f5d498c-9wpxf"
2023-08-24T23:43:22.038114691+02:00 stderr F I0824 21:43:22.037900       1 round_trippers.go:553] GET https://192.168.100.1:6443/apis/coordination.k8s.io/v1/namespaces/kube-system/leases/kube-scheduler?timeout=5s 200 OK in 4 milliseconds
2023-08-24T23:43:13.722934415+02:00 stderr F I0824 21:43:13.722522       1 eventhandlers.go:206] "Update event for scheduled pod" pod="default/kbench-deployment-oid-0-tid-0-bdb979454-7546h"
2023-08-24T23:43:24.05339564+02:00 stderr F I0824 21:43:24.052810       1 round_trippers.go:553] GET https://192.168.100.1:6443/apis/coordination.k8s.io/v1/namespaces/kube-system/leases/kube-scheduler?timeout=5s 200 OK in 4 milliseconds
2023-08-24T23:43:30.123763894+02:00 stderr F I0824 21:43:30.123618       1 round_trippers.go:553] PUT https://192.168.100.1:6443/apis/coordination.k8s.io/v1/namespaces/kube-system/leases/kube-scheduler?timeout=5s 200 OK in 11 milliseconds
2023-08-24T23:43:22.047670154+02:00 stderr F I0824 21:43:22.047515       1 leaderelection.go:276] successfully renewed lease kube-system/kube-scheduler
2023-08-24T23:43:08.480799581+02:00 stderr F I0824 21:43:08.480549       1 pathrecorder.go:241] kube-scheduler: "/metrics" satisfied by exact match
2023-08-24T23:43:26.076888793+02:00 stderr F I0824 21:43:26.076686       1 round_trippers.go:553] GET https://192.168.100.1:6443/apis/coordination.k8s.io/v1/namespaces/kube-system/leases/kube-scheduler?timeout=5s 200 OK in 4 milliseconds
2023-08-24T23:43:13.781931938+02:00 stderr F I0824 21:43:13.781749       1 round_trippers.go:553] POST https://192.168.100.1:6443/api/v1/namespaces/default/pods/kbench-deployment-oid-0-tid-0-bdb979454-7g7nw/binding 201 Created in 11 milliseconds
2023-08-24T23:43:05.465076892+02:00 stderr F I0824 21:43:05.464725       1 pathrecorder.go:241] kube-scheduler: "/healthz" satisfied by exact match
2023-08-24T23:43:13.77881028+02:00 stderr F I0824 21:43:13.778710       1 scheduling_queue.go:419] "Pod moved to an internal scheduling queue" pod="default/kbench-deployment-oid-0-tid-2-cc4784d96-szzf5" event="PodAdd" queue="Active"
2023-08-24T23:43:13.856361139+02:00 stderr F I0824 21:43:13.856044       1 eventhandlers.go:206] "Update event for scheduled pod" pod="default/kbench-deployment-oid-0-tid-2-cc4784d96-99cqp"
2023-08-24T23:43:18.016274566+02:00 stderr F I0824 21:43:18.016159       1 leaderelection.go:276] successfully renewed lease kube-system/kube-scheduler
2023-08-24T23:43:13.764851451+02:00 stderr F I0824 21:43:13.764719       1 eventhandlers.go:206] "Update event for scheduled pod" pod="monitoring/node-exporter-vgf2d"
2023-08-24T23:43:11.487604794+02:00 stderr F I0824 21:43:11.487278       1 round_trippers.go:553] POST https://192.168.100.1:6443/apis/authentication.k8s.io/v1/tokenreviews 201 Created in 6 milliseconds
2023-08-24T23:43:36.756889715+02:00 stderr F I0824 21:43:36.756756       1 eventhandlers.go:206] "Update event for scheduled pod" pod="default/kbench-deployment-oid-0-tid-1-778f5d498c-9wpxf"
2023-08-24T23:43:44.773008694+02:00 stderr F I0824 21:43:44.772910       1 eventhandlers.go:206] "Update event for scheduled pod" pod="default/kbench-deployment-oid-0-tid-0-bdb979454-7g7nw"
2023-08-24T23:43:09.954165091+02:00 stderr F I0824 21:43:09.953961       1 leaderelection.go:276] successfully renewed lease kube-system/kube-scheduler
2023-08-24T23:43:13.787017542+02:00 stderr F I0824 21:43:13.786896       1 schedule_one.go:80] "Attempting to schedule pod" pod="default/kbench-deployment-oid-0-tid-1-778f5d498c-9wpxf"
2023-08-24T23:43:36.753675953+02:00 stderr F I0824 21:43:36.753441       1 eventhandlers.go:206] "Update event for scheduled pod" pod="default/kbench-deployment-oid-0-tid-1-778f5d498c-5c7mg"
2023-08-24T23:43:13.822793755+02:00 stderr F I0824 21:43:13.822581       1 eventhandlers.go:206] "Update event for scheduled pod" pod="default/kbench-deployment-oid-0-tid-0-bdb979454-7g7nw"
2023-08-24T23:43:28.104689832+02:00 stderr F I0824 21:43:28.104431       1 round_trippers.go:553] PUT https://192.168.100.1:6443/apis/coordination.k8s.io/v1/namespaces/kube-system/leases/kube-scheduler?timeout=5s 200 OK in 7 milliseconds
2023-08-24T23:43:11.971168841+02:00 stderr F I0824 21:43:11.970989       1 round_trippers.go:553] PUT https://192.168.100.1:6443/apis/coordination.k8s.io/v1/namespaces/kube-system/leases/kube-scheduler?timeout=5s 200 OK in 8 milliseconds
2023-08-24T23:43:35.464796007+02:00 stderr F I0824 21:43:35.463870       1 pathrecorder.go:241] kube-scheduler: "/healthz" satisfied by exact match
2023-08-24T23:43:36.172379647+02:00 stderr F I0824 21:43:36.172160       1 round_trippers.go:553] PUT https://192.168.100.1:6443/apis/coordination.k8s.io/v1/namespaces/kube-system/leases/kube-scheduler?timeout=5s 200 OK in 10 milliseconds
2023-08-24T23:43:03.901608238+02:00 stderr F I0824 21:43:03.901390       1 leaderelection.go:276] successfully renewed lease kube-system/kube-scheduler
2023-08-24T23:43:11.492969754+02:00 stderr F I0824 21:43:11.492760       1 pathrecorder.go:241] kube-scheduler: "/metrics" satisfied by exact match
2023-08-24T23:43:13.766681973+02:00 stderr F I0824 21:43:13.765391       1 eventhandlers.go:118] "Add event for unscheduled pod" pod="default/kbench-deployment-oid-0-tid-0-bdb979454-7g7nw"
2023-08-24T23:43:13.805270812+02:00 stderr F I0824 21:43:13.805174       1 eventhandlers.go:161] "Delete event for unscheduled pod" pod="default/kbench-deployment-oid-0-tid-2-cc4784d96-szzf5"
2023-08-24T23:43:13.784940272+02:00 stderr F I0824 21:43:13.784773       1 eventhandlers.go:186] "Add event for scheduled pod" pod="default/kbench-deployment-oid-0-tid-0-bdb979454-7g7nw"
2023-08-24T23:43:05.489960668+02:00 stderr F I0824 21:43:05.489582       1 httplog.go:132] "HTTP" verb="GET" URI="/metrics" latency="10.336078ms" userAgent="Prometheus/2.46.0" audit-ID="" srcIP="192.168.100.20:1261" resp=200
2023-08-24T23:43:08.49185368+02:00 stderr F I0824 21:43:08.491446       1 httplog.go:132] "HTTP" verb="GET" URI="/metrics" latency="11.023726ms" userAgent="Prometheus/2.46.0" audit-ID="" srcIP="192.168.100.20:1261" resp=200
2023-08-24T23:43:14.480918787+02:00 stderr F I0824 21:43:14.480541       1 pathrecorder.go:241] kube-scheduler: "/metrics" satisfied by exact match
2023-08-24T23:43:44.835851599+02:00 stderr F I0824 21:43:44.835613       1 eventhandlers.go:231] "Delete event for scheduled pod" pod="default/kbench-deployment-oid-0-tid-1-778f5d498c-9wpxf"
2023-08-24T23:43:13.786994363+02:00 stderr F I0824 21:43:13.786802       1 eventhandlers.go:118] "Add event for unscheduled pod" pod="default/kbench-deployment-oid-0-tid-1-778f5d498c-9wpxf"
2023-08-24T23:43:13.766712728+02:00 stderr F I0824 21:43:13.766632       1 scheduling_queue.go:419] "Pod moved to an internal scheduling queue" pod="default/kbench-deployment-oid-0-tid-0-bdb979454-7g7nw" event="PodAdd" queue="Active"
2023-08-24T23:43:24.07226079+02:00 stderr F I0824 21:43:24.071298       1 leaderelection.go:276] successfully renewed lease kube-system/kube-scheduler
2023-08-24T23:43:24.072239467+02:00 stderr F I0824 21:43:24.071134       1 round_trippers.go:553] PUT https://192.168.100.1:6443/apis/coordination.k8s.io/v1/namespaces/kube-system/leases/kube-scheduler?timeout=5s 200 OK in 17 milliseconds
2023-08-24T23:43:20.490267032+02:00 stderr F I0824 21:43:20.489923       1 httplog.go:132] "HTTP" verb="GET" URI="/metrics" latency="9.984286ms" userAgent="Prometheus/2.46.0" audit-ID="" srcIP="192.168.100.20:1261" resp=200
2023-08-24T23:43:44.763799833+02:00 stderr F I0824 21:43:44.763464       1 eventhandlers.go:206] "Update event for scheduled pod" pod="default/kbench-deployment-oid-0-tid-0-bdb979454-6cv89"
2023-08-24T23:43:13.803397291+02:00 stderr F I0824 21:43:13.803257       1 schedule_one.go:252] "Successfully bound pod to node" pod="default/kbench-deployment-oid-0-tid-2-cc4784d96-szzf5" node="w02" evaluatedNodes=5 feasibleNodes=2
2023-08-24T23:43:36.721316998+02:00 stderr F I0824 21:43:36.721204       1 eventhandlers.go:206] "Update event for scheduled pod" pod="default/kbench-deployment-oid-0-tid-0-bdb979454-7g7nw"
2023-08-24T23:43:26.084538793+02:00 stderr F I0824 21:43:26.084362       1 leaderelection.go:276] successfully renewed lease kube-system/kube-scheduler
2023-08-24T23:43:05.479759107+02:00 stderr F I0824 21:43:05.479363       1 pathrecorder.go:241] kube-scheduler: "/metrics" satisfied by exact match
2023-08-24T23:43:44.480449337+02:00 stderr F I0824 21:43:44.480090       1 pathrecorder.go:241] kube-scheduler: "/metrics" satisfied by exact match
2023-08-24T23:43:13.977587378+02:00 stderr F I0824 21:43:13.977398       1 round_trippers.go:553] GET https://192.168.100.1:6443/apis/coordination.k8s.io/v1/namespaces/kube-system/leases/kube-scheduler?timeout=5s 200 OK in 5 milliseconds
2023-08-24T23:43:13.730662699+02:00 stderr F I0824 21:43:13.730461       1 eventhandlers.go:206] "Update event for scheduled pod" pod="default/kbench-deployment-oid-0-tid-2-cc4784d96-99cqp"
2023-08-24T23:43:32.129443197+02:00 stderr F I0824 21:43:32.129150       1 round_trippers.go:553] GET https://192.168.100.1:6443/apis/coordination.k8s.io/v1/namespaces/kube-system/leases/kube-scheduler?timeout=5s 200 OK in 4 milliseconds
2023-08-24T23:43:11.97121833+02:00 stderr F I0824 21:43:11.971130       1 leaderelection.go:276] successfully renewed lease kube-system/kube-scheduler
2023-08-24T23:43:28.104759861+02:00 stderr F I0824 21:43:28.104623       1 leaderelection.go:276] successfully renewed lease kube-system/kube-scheduler
2023-08-24T23:43:13.74430202+02:00 stderr F I0824 21:43:13.744164       1 eventhandlers.go:206] "Update event for scheduled pod" pod="default/kbench-deployment-oid-0-tid-0-bdb979454-7546h"
2023-08-24T23:43:03.891696036+02:00 stderr F I0824 21:43:03.891362       1 round_trippers.go:553] GET https://192.168.100.1:6443/apis/coordination.k8s.io/v1/namespaces/kube-system/leases/kube-scheduler?timeout=5s 200 OK in 5 milliseconds
2023-08-24T23:43:13.836971545+02:00 stderr F I0824 21:43:13.836849       1 eventhandlers.go:206] "Update event for scheduled pod" pod="default/kbench-deployment-oid-0-tid-1-778f5d498c-7g8gq"
2023-08-24T23:43:15.463203515+02:00 stderr F I0824 21:43:15.462656       1 pathrecorder.go:241] kube-scheduler: "/healthz" satisfied by exact match
2023-08-24T23:43:18.007418468+02:00 stderr F I0824 21:43:18.007224       1 round_trippers.go:553] GET https://192.168.100.1:6443/apis/coordination.k8s.io/v1/namespaces/kube-system/leases/kube-scheduler?timeout=5s 200 OK in 6 milliseconds
2023-08-24T23:43:42.223436693+02:00 stderr F I0824 21:43:42.223161       1 round_trippers.go:553] PUT https://192.168.100.1:6443/apis/coordination.k8s.io/v1/namespaces/kube-system/leases/kube-scheduler?timeout=5s 200 OK in 8 milliseconds
2023-08-24T23:43:11.492612512+02:00 stderr F I0824 21:43:11.492399       1 round_trippers.go:553] POST https://192.168.100.1:6443/apis/authorization.k8s.io/v1/subjectaccessreviews?timeout=10s 201 Created in 3 milliseconds
2023-08-24T23:43:14.493579524+02:00 stderr F I0824 21:43:14.493378       1 httplog.go:132] "HTTP" verb="GET" URI="/metrics" latency="12.968338ms" userAgent="Prometheus/2.46.0" audit-ID="" srcIP="192.168.100.20:1261" resp=200
2023-08-24T23:43:26.084396576+02:00 stderr F I0824 21:43:26.084209       1 round_trippers.go:553] PUT https://192.168.100.1:6443/apis/coordination.k8s.io/v1/namespaces/kube-system/leases/kube-scheduler?timeout=5s 200 OK in 6 milliseconds
2023-08-24T23:43:25.464249965+02:00 stderr F I0824 21:43:25.464126       1 httplog.go:132] "HTTP" verb="GET" URI="/healthz" latency="160.358µs" userAgent="kube-probe/1.27" audit-ID="" srcIP="127.0.0.1:33982" resp=200
2023-08-24T23:43:13.722918423+02:00 stderr F I0824 21:43:13.722464       1 eventhandlers.go:206] "Update event for scheduled pod" pod="monitoring/node-exporter-vgf2d"
2023-08-24T23:43:13.840979483+02:00 stderr F I0824 21:43:13.840431       1 round_trippers.go:553] POST https://192.168.100.1:6443/apis/events.k8s.io/v1/namespaces/default/events 201 Created in 24 milliseconds
2023-08-24T23:43:15.991562585+02:00 stderr F I0824 21:43:15.991329       1 round_trippers.go:553] GET https://192.168.100.1:6443/apis/coordination.k8s.io/v1/namespaces/kube-system/leases/kube-scheduler?timeout=5s 200 OK in 4 milliseconds
2023-08-24T23:43:44.824560473+02:00 stderr F I0824 21:43:44.824088       1 eventhandlers.go:206] "Update event for scheduled pod" pod="default/kbench-deployment-oid-0-tid-2-cc4784d96-t2v6l"
2023-08-24T23:43:20.032293974+02:00 stderr F I0824 21:43:20.032009       1 leaderelection.go:276] successfully renewed lease kube-system/kube-scheduler
2023-08-24T23:43:44.783918201+02:00 stderr F I0824 21:43:44.783527       1 eventhandlers.go:206] "Update event for scheduled pod" pod="default/kbench-deployment-oid-0-tid-1-778f5d498c-5c7mg"
2023-08-24T23:43:13.764843573+02:00 stderr F I0824 21:43:13.764634       1 eventhandlers.go:206] "Update event for scheduled pod" pod="default/kbench-deployment-oid-0-tid-1-778f5d498c-7g8gq"
2023-08-24T23:43:32.136907139+02:00 stderr F I0824 21:43:32.136816       1 leaderelection.go:276] successfully renewed lease kube-system/kube-scheduler
2023-08-24T23:43:35.488163214+02:00 stderr F I0824 21:43:35.487718       1 round_trippers.go:553] POST https://192.168.100.1:6443/apis/authentication.k8s.io/v1/tokenreviews 201 Created in 4 milliseconds
2023-08-24T23:43:11.962685896+02:00 stderr F I0824 21:43:11.962492       1 round_trippers.go:553] GET https://192.168.100.1:6443/apis/coordination.k8s.io/v1/namespaces/kube-system/leases/kube-scheduler?timeout=5s 200 OK in 7 milliseconds
2023-08-24T23:43:05.465112886+02:00 stderr F I0824 21:43:05.464921       1 httplog.go:132] "HTTP" verb="GET" URI="/healthz" latency="224.133µs" userAgent="kube-probe/1.27" audit-ID="" srcIP="127.0.0.1:59712" resp=200
2023-08-24T23:43:13.703038126+02:00 stderr F I0824 21:43:13.702810       1 eventhandlers.go:206] "Update event for scheduled pod" pod="kube-flannel/kube-flannel-ds-l2mtb"
2023-08-24T23:43:15.999901152+02:00 stderr F I0824 21:43:15.999698       1 leaderelection.go:276] successfully renewed lease kube-system/kube-scheduler
2023-08-24T23:43:13.731979123+02:00 stderr F I0824 21:43:13.731802       1 eventhandlers.go:206] "Update event for scheduled pod" pod="default/kbench-deployment-oid-0-tid-1-778f5d498c-7g8gq"
2023-08-24T23:43:13.814632224+02:00 stderr F I0824 21:43:13.814505       1 round_trippers.go:553] POST https://192.168.100.1:6443/api/v1/namespaces/default/pods/kbench-deployment-oid-0-tid-1-778f5d498c-9wpxf/binding 201 Created in 24 milliseconds
2023-08-24T23:43:13.815163594+02:00 stderr F I0824 21:43:13.815084       1 schedule_one.go:252] "Successfully bound pod to node" pod="default/kbench-deployment-oid-0-tid-1-778f5d498c-9wpxf" node="w03" evaluatedNodes=5 feasibleNodes=2
2023-08-24T23:43:13.766890064+02:00 stderr F I0824 21:43:13.766720       1 scheduling_queue.go:1133] "About to try and schedule pod" pod="default/kbench-deployment-oid-0-tid-0-bdb979454-7g7nw"
2023-08-24T23:43:35.494769516+02:00 stderr F I0824 21:43:35.494558       1 pathrecorder.go:241] kube-scheduler: "/metrics" satisfied by exact match
2023-08-24T23:43:44.850060267+02:00 stderr F I0824 21:43:44.849816       1 eventhandlers.go:231] "Delete event for scheduled pod" pod="default/kbench-deployment-oid-0-tid-2-cc4784d96-t2v6l"
2023-08-24T23:43:13.778643106+02:00 stderr F I0824 21:43:13.778440       1 eventhandlers.go:118] "Add event for unscheduled pod" pod="default/kbench-deployment-oid-0-tid-2-cc4784d96-szzf5"
2023-08-24T23:43:13.808052516+02:00 stderr F I0824 21:43:13.807653       1 eventhandlers.go:161] "Delete event for unscheduled pod" pod="default/kbench-deployment-oid-0-tid-1-778f5d498c-9wpxf"
2023-08-24T23:43:15.131181399+02:00 stderr F I0824 21:43:15.130965       1 eventhandlers.go:206] "Update event for scheduled pod" pod="default/kbench-deployment-oid-0-tid-1-778f5d498c-9wpxf"
2023-08-24T23:43:13.762065504+02:00 stderr F I0824 21:43:13.761805       1 eventhandlers.go:206] "Update event for scheduled pod" pod="kube-flannel/kube-flannel-ds-l2mtb"
2023-08-24T23:43:13.789529963+02:00 stderr F I0824 21:43:13.789400       1 default_binder.go:53] "Attempting to bind pod to node" pod="default/kbench-deployment-oid-0-tid-1-778f5d498c-9wpxf" node="w03"
2023-08-24T23:43:40.208687719+02:00 stderr F I0824 21:43:40.208413       1 round_trippers.go:553] PUT https://192.168.100.1:6443/apis/coordination.k8s.io/v1/namespaces/kube-system/leases/kube-scheduler?timeout=5s 200 OK in 10 milliseconds
2023-08-24T23:43:36.716066141+02:00 stderr F I0824 21:43:36.715929       1 eventhandlers.go:206] "Update event for scheduled pod" pod="default/kbench-deployment-oid-0-tid-0-bdb979454-6cv89"
2023-08-24T23:43:44.493036623+02:00 stderr F I0824 21:43:44.492752       1 httplog.go:132] "HTTP" verb="GET" URI="/metrics" latency="12.788675ms" userAgent="Prometheus/2.46.0" audit-ID="" srcIP="192.168.100.20:1261" resp=200
2023-08-24T23:43:13.707513386+02:00 stderr F I0824 21:43:13.707031       1 eventhandlers.go:206] "Update event for scheduled pod" pod="monitoring/node-exporter-vgf2d"
2023-08-24T23:43:14.045996622+02:00 stderr F I0824 21:43:14.045821       1 eventhandlers.go:231] "Delete event for scheduled pod" pod="monitoring/node-exporter-vgf2d"
2023-09-28T00:07:18.416420175+02:00 stderr F I0927 22:07:18.416306       1 leaderelection.go:276] successfully renewed lease kube-system/kube-scheduler
2023-09-28T00:07:44.64663695+02:00 stderr F I0927 22:07:44.646451       1 leaderelection.go:276] successfully renewed lease kube-system/kube-scheduler
2023-09-28T00:08:00.80499688+02:00 stderr F I0927 22:08:00.804752       1 leaderelection.go:276] successfully renewed lease kube-system/kube-scheduler
2023-09-28T00:07:38.589270617+02:00 stderr F I0927 22:07:38.588938       1 round_trippers.go:553] GET https://192.168.100.1:6443/apis/coordination.k8s.io/v1/namespaces/kube-system/leases/kube-scheduler?timeout=5s 200 OK in 4 milliseconds
2023-09-28T00:07:46.726634201+02:00 stderr F I0927 22:07:46.726427       1 pathrecorder.go:241] kube-scheduler: "/metrics" satisfied by exact match
2023-09-28T00:07:32.533513028+02:00 stderr F I0927 22:07:32.533256       1 round_trippers.go:553] GET https://192.168.100.1:6443/apis/coordination.k8s.io/v1/namespaces/kube-system/leases/kube-scheduler?timeout=5s 200 OK in 5 milliseconds
2023-09-28T00:07:17.767922999+02:00 stderr F I0927 22:07:17.763907       1 eventhandlers.go:186] "Add event for scheduled pod" pod="default/kbench-deployment-oid-0-tid-1-778f5d498c-wm652"
2023-09-28T00:07:34.566346566+02:00 stderr F I0927 22:07:34.566203       1 round_trippers.go:553] PUT https://192.168.100.1:6443/apis/coordination.k8s.io/v1/namespaces/kube-system/leases/kube-scheduler?timeout=5s 200 OK in 9 milliseconds
2023-09-28T00:07:36.2035779+02:00 stderr F I0927 22:07:36.203245       1 eventhandlers.go:206] "Update event for scheduled pod" pod="monitoring/node-exporter-gbshn"
2023-09-28T00:07:36.582083039+02:00 stderr F I0927 22:07:36.581971       1 round_trippers.go:553] PUT https://192.168.100.1:6443/apis/coordination.k8s.io/v1/namespaces/kube-system/leases/kube-scheduler?timeout=5s 200 OK in 8 milliseconds
2023-09-28T00:08:07.281420228+02:00 stderr F I0927 22:08:07.281186       1 eventhandlers.go:231] "Delete event for scheduled pod" pod="default/kbench-deployment-oid-0-tid-0-bdb979454-rgxwg"
2023-09-28T00:07:31.734431498+02:00 stderr F I0927 22:07:31.734110       1 httplog.go:132] "HTTP" verb="GET" URI="/metrics" latency="17.943998ms" userAgent="Prometheus/2.47.0" audit-ID="" srcIP="192.168.100.20:44435" resp=200
2023-09-28T00:07:19.152769443+02:00 stderr F I0927 22:07:19.152638       1 eventhandlers.go:206] "Update event for scheduled pod" pod="default/kbench-deployment-oid-0-tid-1-778f5d498c-wm652"
2023-09-28T00:07:28.71683441+02:00 stderr F I0927 22:07:28.716523       1 pathrecorder.go:241] kube-scheduler: "/metrics" satisfied by exact match
2023-09-28T00:07:56.393601901+02:00 stderr F I0927 22:07:56.393394       1 httplog.go:132] "HTTP" verb="GET" URI="/healthz" latency="180.166µs" userAgent="kube-probe/1.27" audit-ID="" srcIP="127.0.0.1:57310" resp=200
2023-09-28T00:07:36.235601731+02:00 stderr F I0927 22:07:36.235261       1 eventhandlers.go:186] "Add event for scheduled pod" pod="default/kbench-deployment-oid-0-tid-0-bdb979454-ztd7s"
2023-09-28T00:07:20.434133877+02:00 stderr F I0927 22:07:20.433722       1 round_trippers.go:553] PUT https://192.168.100.1:6443/apis/coordination.k8s.io/v1/namespaces/kube-system/leases/kube-scheduler?timeout=5s 200 OK in 9 milliseconds
2023-09-28T00:07:59.194090395+02:00 stderr F I0927 22:07:59.193937       1 eventhandlers.go:206] "Update event for scheduled pod" pod="default/kbench-deployment-oid-0-tid-2-cc4784d96-tdhgd"
2023-09-28T00:07:42.629501945+02:00 stderr F I0927 22:07:42.629121       1 round_trippers.go:553] PUT https://192.168.100.1:6443/apis/coordination.k8s.io/v1/namespaces/kube-system/leases/kube-scheduler?timeout=5s 200 OK in 7 milliseconds
2023-09-28T00:08:07.316952024+02:00 stderr F I0927 22:08:07.316594       1 eventhandlers.go:206] "Update event for scheduled pod" pod="default/kbench-deployment-oid-0-tid-2-cc4784d96-tdhgd"
2023-09-28T00:07:17.733460943+02:00 stderr F I0927 22:07:17.733366       1 scheduling_queue.go:419] "Pod moved to an internal scheduling queue" pod="default/kbench-deployment-oid-0-tid-0-bdb979454-rgxwg" event="PodAdd" queue="Active"
2023-09-28T00:07:17.708048326+02:00 stderr F I0927 22:07:17.707864       1 schedule_one.go:80] "Attempting to schedule pod" pod="default/kbench-deployment-oid-0-tid-0-bdb979454-j4hbd"
2023-09-28T00:07:17.742323262+02:00 stderr F I0927 22:07:17.741141       1 eventhandlers.go:161] "Delete event for unscheduled pod" pod="default/kbench-deployment-oid-0-tid-1-778f5d498c-kg897"
2023-09-28T00:07:54.74890052+02:00 stderr F I0927 22:07:54.748764       1 leaderelection.go:276] successfully renewed lease kube-system/kube-scheduler
2023-09-28T00:08:07.306889188+02:00 stderr F I0927 22:08:07.306598       1 eventhandlers.go:206] "Update event for scheduled pod" pod="default/kbench-deployment-oid-0-tid-2-cc4784d96-82csv"
2023-09-28T00:08:01.717271562+02:00 stderr F I0927 22:08:01.716995       1 pathrecorder.go:241] kube-scheduler: "/metrics" satisfied by exact match
2023-09-28T00:07:44.637907331+02:00 stderr F I0927 22:07:44.637524       1 round_trippers.go:553] GET https://192.168.100.1:6443/apis/coordination.k8s.io/v1/namespaces/kube-system/leases/kube-scheduler?timeout=5s 200 OK in 7 milliseconds
2023-09-28T00:07:17.733199394+02:00 stderr F I0927 22:07:17.732933       1 cache.go:401] "Finished binding for pod, can be expired" podKey="cd2d1a71-9306-409f-91d7-18a8b2eb1b09" pod="default/kbench-deployment-oid-0-tid-0-bdb979454-j4hbd"
2023-09-28T00:08:04.860070729+02:00 stderr F I0927 22:08:04.859828       1 round_trippers.go:553] PUT https://192.168.100.1:6443/apis/coordination.k8s.io/v1/namespaces/kube-system/leases/kube-scheduler?timeout=5s 200 OK in 25 milliseconds
2023-09-28T00:07:17.724234362+02:00 stderr F I0927 22:07:17.723125       1 scheduling_queue.go:419] "Pod moved to an internal scheduling queue" pod="default/kbench-deployment-oid-0-tid-2-cc4784d96-cn9ql" event="PodAdd" queue="Active"
2023-09-28T00:07:36.188038578+02:00 stderr F I0927 22:07:36.187786       1 eventhandlers.go:206] "Update event for scheduled pod" pod="default/kbench-deployment-oid-0-tid-0-bdb979454-j4hbd"
2023-09-28T00:07:17.733187384+02:00 stderr F I0927 22:07:17.732873       1 round_trippers.go:553] POST https://192.168.100.1:6443/api/v1/namespaces/default/pods/kbench-deployment-oid-0-tid-0-bdb979454-j4hbd/binding 201 Created in 21 milliseconds
2023-09-28T00:07:17.762643491+02:00 stderr F I0927 22:07:17.761860       1 cache.go:401] "Finished binding for pod, can be expired" podKey="91a8c6d9-ba90-4960-a645-17afdeb8c5a8" pod="default/kbench-deployment-oid-0-tid-1-778f5d498c-wm652"
2023-09-28T00:07:52.719050275+02:00 stderr F I0927 22:07:52.718876       1 round_trippers.go:553] GET https://192.168.100.1:6443/apis/coordination.k8s.io/v1/namespaces/kube-system/leases/kube-scheduler?timeout=5s 200 OK in 7 milliseconds
2023-09-28T00:07:48.694716288+02:00 stderr F I0927 22:07:48.694563       1 round_trippers.go:553] PUT https://192.168.100.1:6443/apis/coordination.k8s.io/v1/namespaces/kube-system/leases/kube-scheduler?timeout=5s 200 OK in 9 milliseconds
2023-09-28T00:07:17.708384746+02:00 stderr F I0927 22:07:17.706956       1 eventhandlers.go:118] "Add event for unscheduled pod" pod="default/kbench-deployment-oid-0-tid-2-cc4784d96-82csv"
2023-09-28T00:08:02.815055626+02:00 stderr F I0927 22:08:02.814823       1 round_trippers.go:553] GET https://192.168.100.1:6443/apis/coordination.k8s.io/v1/namespaces/kube-system/leases/kube-scheduler?timeout=5s 200 OK in 9 milliseconds
2023-09-28T00:07:40.616354143+02:00 stderr F I0927 22:07:40.616266       1 leaderelection.go:276] successfully renewed lease kube-system/kube-scheduler
2023-09-28T00:07:36.264665766+02:00 stderr F I0927 22:07:36.264567       1 round_trippers.go:553] POST https://192.168.100.1:6443/apis/events.k8s.io/v1/namespaces/default/events 201 Created in 18 milliseconds
2023-09-28T00:07:56.775867986+02:00 stderr F I0927 22:07:56.775335       1 leaderelection.go:276] successfully renewed lease kube-system/kube-scheduler
2023-09-28T00:07:19.718642938+02:00 stderr F I0927 22:07:19.718164       1 pathrecorder.go:241] kube-scheduler: "/metrics" satisfied by exact match
2023-09-28T00:07:17.72423862+02:00 stderr F I0927 22:07:17.723146       1 scheduling_queue.go:1133] "About to try and schedule pod" pod="default/kbench-deployment-oid-0-tid-2-cc4784d96-cn9ql"
2023-09-28T00:07:36.274595328+02:00 stderr F I0927 22:07:36.274027       1 eventhandlers.go:206] "Update event for scheduled pod" pod="default/kbench-deployment-oid-0-tid-0-bdb979454-ztd7s"
2023-09-28T00:07:40.616262136+02:00 stderr F I0927 22:07:40.616113       1 round_trippers.go:553] PUT https://192.168.100.1:6443/apis/coordination.k8s.io/v1/namespaces/kube-system/leases/kube-scheduler?timeout=5s 200 OK in 7 milliseconds
2023-09-28T00:07:17.74234275+02:00 stderr F I0927 22:07:17.741671       1 default_binder.go:53] "Attempting to bind pod to node" pod="default/kbench-deployment-oid-0-tid-1-778f5d498c-wm652" node="w02"
2023-09-28T00:07:17.789388407+02:00 stderr F I0927 22:07:17.789302       1 eventhandlers.go:206] "Update event for scheduled pod" pod="default/kbench-deployment-oid-0-tid-0-bdb979454-j4hbd"
2023-09-28T00:07:17.762658713+02:00 stderr F I0927 22:07:17.762313       1 round_trippers.go:553] POST https://192.168.100.1:6443/apis/events.k8s.io/v1/namespaces/default/events 201 Created in 29 milliseconds
2023-09-28T00:07:36.392229767+02:00 stderr F I0927 22:07:36.392023       1 httplog.go:132] "HTTP" verb="GET" URI="/healthz" latency="167.942µs" userAgent="kube-probe/1.27" audit-ID="" srcIP="127.0.0.1:40400" resp=200
2023-09-28T00:07:36.208041043+02:00 stderr F I0927 22:07:36.207874       1 eventhandlers.go:206] "Update event for scheduled pod" pod="kube-flannel/kube-flannel-ds-kg95m"
2023-09-28T00:07:17.767879244+02:00 stderr F I0927 22:07:17.763729       1 eventhandlers.go:161] "Delete event for unscheduled pod" pod="default/kbench-deployment-oid-0-tid-0-bdb979454-rgxwg"
2023-09-28T00:07:36.172179355+02:00 stderr F I0927 22:07:36.169026       1 eventhandlers.go:206] "Update event for scheduled pod" pod="monitoring/node-exporter-gbshn"
2023-09-28T00:07:17.767937679+02:00 stderr F I0927 22:07:17.766002       1 round_trippers.go:553] POST https://192.168.100.1:6443/apis/events.k8s.io/v1/namespaces/default/events 201 Created in 25 milliseconds
2023-09-28T00:08:07.265964456+02:00 stderr F I0927 22:08:07.265738       1 eventhandlers.go:206] "Update event for scheduled pod" pod="default/kbench-deployment-oid-0-tid-1-778f5d498c-kg897"
2023-09-28T00:07:59.201261922+02:00 stderr F I0927 22:07:59.201062       1 eventhandlers.go:206] "Update event for scheduled pod" pod="default/kbench-deployment-oid-0-tid-1-778f5d498c-kg897"
2023-09-28T00:07:17.767930419+02:00 stderr F I0927 22:07:17.765209       1 schedule_one.go:252] "Successfully bound pod to node" pod="default/kbench-deployment-oid-0-tid-0-bdb979454-rgxwg" node="w03" evaluatedNodes=5 feasibleNodes=3
2023-09-28T00:07:37.258344017+02:00 stderr F I0927 22:07:37.258197       1 eventhandlers.go:206] "Update event for scheduled pod" pod="default/kbench-deployment-oid-0-tid-2-cc4784d96-tdhgd"
2023-09-28T00:07:34.722369933+02:00 stderr F I0927 22:07:34.722226       1 round_trippers.go:553] POST https://192.168.100.1:6443/apis/authentication.k8s.io/v1/tokenreviews 201 Created in 5 milliseconds
2023-09-28T00:07:17.740431841+02:00 stderr F I0927 22:07:17.740192       1 round_trippers.go:553] POST https://192.168.100.1:6443/api/v1/namespaces/default/pods/kbench-deployment-oid-0-tid-1-778f5d498c-kg897/binding 201 Created in 23 milliseconds
2023-09-28T00:07:17.815127876+02:00 stderr F I0927 22:07:17.814979       1 eventhandlers.go:206] "Update event for scheduled pod" pod="default/kbench-deployment-oid-0-tid-2-cc4784d96-cn9ql"
2023-09-28T00:07:26.395100053+02:00 stderr F I0927 22:07:26.394907       1 pathrecorder.go:241] kube-scheduler: "/healthz" satisfied by exact match
2023-09-28T00:07:32.546870297+02:00 stderr F I0927 22:07:32.546711       1 leaderelection.go:276] successfully renewed lease kube-system/kube-scheduler
2023-09-28T00:07:36.245239061+02:00 stderr F I0927 22:07:36.244940       1 eventhandlers.go:186] "Add event for scheduled pod" pod="default/kbench-deployment-oid-0-tid-2-cc4784d96-tdhgd"
2023-09-28T00:08:06.887887316+02:00 stderr F I0927 22:08:06.887779       1 leaderelection.go:276] successfully renewed lease kube-system/kube-scheduler
2023-09-28T00:07:36.226072436+02:00 stderr F I0927 22:07:36.225901       1 eventhandlers.go:118] "Add event for unscheduled pod" pod="default/kbench-deployment-oid-0-tid-0-bdb979454-ztd7s"
2023-09-28T00:07:28.50952239+02:00 stderr F I0927 22:07:28.509190       1 round_trippers.go:553] PUT https://192.168.100.1:6443/apis/coordination.k8s.io/v1/namespaces/kube-system/leases/kube-scheduler?timeout=5s 200 OK in 6 milliseconds
2023-09-28T00:07:40.73362854+02:00 stderr F I0927 22:07:40.733309       1 httplog.go:132] "HTTP" verb="GET" URI="/metrics" latency="14.879127ms" userAgent="Prometheus/2.47.0" audit-ID="" srcIP="192.168.100.20:44435" resp=200
2023-09-28T00:07:17.717858092+02:00 stderr F I0927 22:07:17.716348       1 default_binder.go:53] "Attempting to bind pod to node" pod="default/kbench-deployment-oid-0-tid-1-778f5d498c-kg897" node="w03"
2023-09-28T00:07:17.742334916+02:00 stderr F I0927 22:07:17.741182       1 scheduling_queue.go:1133] "About to try and schedule pod" pod="default/kbench-deployment-oid-0-tid-1-778f5d498c-wm652"
2023-09-28T00:07:17.74229395+02:00 stderr F I0927 22:07:17.740971       1 eventhandlers.go:186] "Add event for scheduled pod" pod="default/kbench-deployment-oid-0-tid-2-cc4784d96-82csv"
2023-09-28T00:07:17.733465511+02:00 stderr F I0927 22:07:17.733385       1 scheduling_queue.go:1133] "About to try and schedule pod" pod="default/kbench-deployment-oid-0-tid-0-bdb979454-rgxwg"
2023-09-28T00:08:04.860542234+02:00 stderr F I0927 22:08:04.860366       1 leaderelection.go:276] successfully renewed lease kube-system/kube-scheduler
2023-09-28T00:07:17.740439247+02:00 stderr F I0927 22:07:17.740263       1 cache.go:401] "Finished binding for pod, can be expired" podKey="078e35ac-6228-4c7d-af92-62a5fb7a28df" pod="default/kbench-deployment-oid-0-tid-1-778f5d498c-kg897"
2023-09-28T00:07:17.717764662+02:00 stderr F I0927 22:07:17.715798       1 scheduling_queue.go:1133] "About to try and schedule pod" pod="default/kbench-deployment-oid-0-tid-1-778f5d498c-kg897"
2023-09-28T00:07:17.724243236+02:00 stderr F I0927 22:07:17.723223       1 schedule_one.go:80] "Attempting to schedule pod" pod="default/kbench-deployment-oid-0-tid-2-cc4784d96-cn9ql"
2023-09-28T00:07:54.748709494+02:00 stderr F I0927 22:07:54.748544       1 round_trippers.go:553] PUT https://192.168.100.1:6443/apis/coordination.k8s.io/v1/namespaces/kube-system/leases/kube-scheduler?timeout=5s 200 OK in 10 milliseconds
2023-09-28T00:07:17.708403228+02:00 stderr F I0927 22:07:17.708291       1 scheduling_queue.go:419] "Pod moved to an internal scheduling queue" pod="default/kbench-deployment-oid-0-tid-2-cc4784d96-82csv" event="PodAdd" queue="Active"
2023-09-28T00:07:36.22627982+02:00 stderr F I0927 22:07:36.226103       1 eventhandlers.go:118] "Add event for unscheduled pod" pod="default/kbench-deployment-oid-0-tid-2-cc4784d96-tdhgd"
2023-09-28T00:08:06.499134263+02:00 stderr F I0927 22:08:06.498936       1 eventhandlers.go:231] "Delete event for scheduled pod" pod="kube-flannel/kube-flannel-ds-kg95m"
2023-09-28T00:07:17.747783631+02:00 stderr F I0927 22:07:17.745126       1 round_trippers.go:553] POST https://192.168.100.1:6443/api/v1/namespaces/default/pods/kbench-deployment-oid-0-tid-2-cc4784d96-cn9ql/binding 201 Created in 21 milliseconds
2023-09-28T00:08:07.293102617+02:00 stderr F I0927 22:08:07.292823       1 eventhandlers.go:231] "Delete event for scheduled pod" pod="default/kbench-deployment-oid-0-tid-0-bdb979454-ztd7s"
2023-09-28T00:07:17.742302264+02:00 stderr F I0927 22:07:17.741081       1 eventhandlers.go:118] "Add event for unscheduled pod" pod="default/kbench-deployment-oid-0-tid-1-778f5d498c-wm652"
2023-09-28T00:07:17.763661333+02:00 stderr F I0927 22:07:17.763225       1 cache.go:401] "Finished binding for pod, can be expired" podKey="d68a1188-b1ce-4435-abd0-4f6f64fb7e1e" pod="default/kbench-deployment-oid-0-tid-0-bdb979454-rgxwg"
2023-09-28T00:07:36.253894606+02:00 stderr F I0927 22:07:36.253685       1 round_trippers.go:553] POST https://192.168.100.1:6443/apis/events.k8s.io/v1/namespaces/default/events 201 Created in 17 milliseconds
2023-09-28T00:07:17.705475372+02:00 stderr F I0927 22:07:17.705245       1 eventhandlers.go:118] "Add event for unscheduled pod" pod="default/kbench-deployment-oid-0-tid-0-bdb979454-j4hbd"
2023-09-28T00:07:20.19647214+02:00 stderr F I0927 22:07:20.195300       1 eventhandlers.go:206] "Update event for scheduled pod" pod="default/kbench-deployment-oid-0-tid-1-778f5d498c-kg897"
2023-09-28T00:07:17.747800141+02:00 stderr F I0927 22:07:17.745209       1 schedule_one.go:252] "Successfully bound pod to node" pod="default/kbench-deployment-oid-0-tid-2-cc4784d96-cn9ql" node="w01" evaluatedNodes=5 feasibleNodes=3
2023-09-28T00:07:17.708426412+02:00 stderr F I0927 22:07:17.708356       1 eventhandlers.go:118] "Add event for unscheduled pod" pod="default/kbench-deployment-oid-0-tid-1-778f5d498c-kg897"
2023-09-28T00:07:17.73257254+02:00 stderr F I0927 22:07:17.732473       1 cache.go:401] "Finished binding for pod, can be expired" podKey="cf510c72-be89-4192-acee-2998353e508e" pod="default/kbench-deployment-oid-0-tid-2-cc4784d96-82csv"
2023-09-28T00:08:02.826456664+02:00 stderr F I0927 22:08:02.826260       1 leaderelection.go:276] successfully renewed lease kube-system/kube-scheduler
2023-09-28T00:07:17.82182472+02:00 stderr F I0927 22:07:17.821481       1 eventhandlers.go:206] "Update event for scheduled pod" pod="default/kbench-deployment-oid-0-tid-0-bdb979454-rgxwg"
2023-09-28T00:07:36.226984178+02:00 stderr F I0927 22:07:36.226833       1 default_binder.go:53] "Attempting to bind pod to node" pod="default/kbench-deployment-oid-0-tid-0-bdb979454-ztd7s" node="w02"
2023-09-28T00:07:17.761450122+02:00 stderr F I0927 22:07:17.761247       1 round_trippers.go:553] POST https://192.168.100.1:6443/apis/events.k8s.io/v1/namespaces/default/events 201 Created in 28 milliseconds
2023-09-28T00:07:17.762604623+02:00 stderr F I0927 22:07:17.761757       1 round_trippers.go:553] POST https://192.168.100.1:6443/api/v1/namespaces/default/pods/kbench-deployment-oid-0-tid-1-778f5d498c-wm652/binding 201 Created in 19 milliseconds
2023-09-28T00:07:36.230814595+02:00 stderr F I0927 22:07:36.230622       1 eventhandlers.go:206] "Update event for scheduled pod" pod="default/kbench-deployment-oid-0-tid-0-bdb979454-j4hbd"
2023-09-28T00:08:07.344336315+02:00 stderr F I0927 22:08:07.344177       1 eventhandlers.go:231] "Delete event for scheduled pod" pod="default/kbench-deployment-oid-0-tid-2-cc4784d96-tdhgd"
2023-09-28T00:07:36.572994208+02:00 stderr F I0927 22:07:36.572797       1 round_trippers.go:553] GET https://192.168.100.1:6443/apis/coordination.k8s.io/v1/namespaces/kube-system/leases/kube-scheduler?timeout=5s 200 OK in 5 milliseconds
2023-09-28T00:07:59.237934929+02:00 stderr F I0927 22:07:59.237728       1 eventhandlers.go:206] "Update event for scheduled pod" pod="default/kbench-deployment-oid-0-tid-0-bdb979454-ztd7s"
2023-09-28T00:07:36.226974556+02:00 stderr F I0927 22:07:36.226761       1 schedule_one.go:80] "Attempting to schedule pod" pod="default/kbench-deployment-oid-0-tid-2-cc4784d96-tdhgd"
2023-09-28T00:07:37.239018998+02:00 stderr F I0927 22:07:37.238734       1 eventhandlers.go:206] "Update event for scheduled pod" pod="default/kbench-deployment-oid-0-tid-0-bdb979454-ztd7s"
2023-09-28T00:07:17.74233878+02:00 stderr F I0927 22:07:17.741191       1 schedule_one.go:80] "Attempting to schedule pod" pod="default/kbench-deployment-oid-0-tid-1-778f5d498c-wm652"
2023-09-28T00:07:17.767916087+02:00 stderr F I0927 22:07:17.763731       1 eventhandlers.go:186] "Add event for scheduled pod" pod="default/kbench-deployment-oid-0-tid-0-bdb979454-rgxwg"
2023-09-28T00:07:58.739276976+02:00 stderr F I0927 22:07:58.739178       1 httplog.go:132] "HTTP" verb="GET" URI="/metrics" latency="23.281685ms" userAgent="Prometheus/2.47.0" audit-ID="" srcIP="192.168.100.20:44435" resp=200
2023-09-28T00:07:17.763682277+02:00 stderr F I0927 22:07:17.763372       1 round_trippers.go:553] POST https://192.168.100.1:6443/apis/events.k8s.io/v1/namespaces/default/events 201 Created in 18 milliseconds
2023-09-28T00:07:58.726133394+02:00 stderr F I0927 22:07:58.725896       1 round_trippers.go:553] POST https://192.168.100.1:6443/apis/authorization.k8s.io/v1/subjectaccessreviews?timeout=10s 201 Created in 4 milliseconds
2023-09-28T00:07:52.717808731+02:00 stderr F I0927 22:07:52.717519       1 pathrecorder.go:241] kube-scheduler: "/metrics" satisfied by exact match
2023-09-28T00:08:07.32577824+02:00 stderr F I0927 22:08:07.325637       1 eventhandlers.go:231] "Delete event for scheduled pod" pod="default/kbench-deployment-oid-0-tid-1-778f5d498c-wm652"
2023-09-28T00:07:46.392268742+02:00 stderr F I0927 22:07:46.391945       1 pathrecorder.go:241] kube-scheduler: "/healthz" satisfied by exact match
2023-09-28T00:07:56.755374415+02:00 stderr F I0927 22:07:56.754944       1 round_trippers.go:553] GET https://192.168.100.1:6443/apis/coordination.k8s.io/v1/namespaces/kube-system/leases/kube-scheduler?timeout=5s 200 OK in 5 milliseconds
2023-09-28T00:08:02.826226029+02:00 stderr F I0927 22:08:02.826090       1 round_trippers.go:553] PUT https://192.168.100.1:6443/apis/coordination.k8s.io/v1/namespaces/kube-system/leases/kube-scheduler?timeout=5s 200 OK in 10 milliseconds
2023-09-28T00:08:07.281130254+02:00 stderr F I0927 22:08:07.280918       1 eventhandlers.go:206] "Update event for scheduled pod" pod="default/kbench-deployment-oid-0-tid-1-778f5d498c-wm652"
2023-09-28T00:08:07.253009806+02:00 stderr F I0927 22:08:07.252593       1 eventhandlers.go:206] "Update event for scheduled pod" pod="default/kbench-deployment-oid-0-tid-0-bdb979454-ztd7s"
2023-09-28T00:07:36.169806423+02:00 stderr F I0927 22:07:36.164877       1 eventhandlers.go:206] "Update event for scheduled pod" pod="kube-flannel/kube-flannel-ds-kg95m"
2023-09-28T00:07:17.712551873+02:00 stderr F I0927 22:07:17.712427       1 default_binder.go:53] "Attempting to bind pod to node" pod="default/kbench-deployment-oid-0-tid-2-cc4784d96-82csv" node="w02"
2023-09-28T00:08:01.732871716+02:00 stderr F I0927 22:08:01.732645       1 httplog.go:132] "HTTP" verb="GET" URI="/metrics" latency="15.763742ms" userAgent="Prometheus/2.47.0" audit-ID="" srcIP="192.168.100.20:44435" resp=200
2023-09-28T00:07:46.741195812+02:00 stderr F I0927 22:07:46.740901       1 httplog.go:132] "HTTP" verb="GET" URI="/metrics" latency="24.477678ms" userAgent="Prometheus/2.47.0" audit-ID="" srcIP="192.168.100.20:44435" resp=200
2023-09-28T00:08:04.733976014+02:00 stderr F I0927 22:08:04.733797       1 httplog.go:132] "HTTP" verb="GET" URI="/metrics" latency="17.134562ms" userAgent="Prometheus/2.47.0" audit-ID="" srcIP="192.168.100.20:44435" resp=200
2023-09-28T00:07:17.786564788+02:00 stderr F I0927 22:07:17.785710       1 round_trippers.go:553] POST https://192.168.100.1:6443/apis/events.k8s.io/v1/namespaces/default/events 201 Created in 20 milliseconds
2023-09-28T00:07:17.747792875+02:00 stderr F I0927 22:07:17.745184       1 cache.go:401] "Finished binding for pod, can be expired" podKey="14075ba3-85ba-41f0-a7f7-948eb235d273" pod="default/kbench-deployment-oid-0-tid-2-cc4784d96-cn9ql"
2023-09-28T00:07:19.73234725+02:00 stderr F I0927 22:07:19.732096       1 httplog.go:132] "HTTP" verb="GET" URI="/metrics" latency="14.042336ms" userAgent="Prometheus/2.47.0" audit-ID="" srcIP="192.168.100.20:44435" resp=200
2023-09-28T00:07:52.728168799+02:00 stderr F I0927 22:07:52.728013       1 round_trippers.go:553] PUT https://192.168.100.1:6443/apis/coordination.k8s.io/v1/namespaces/kube-system/leases/kube-scheduler?timeout=5s 200 OK in 8 milliseconds
2023-09-28T00:07:42.62195082+02:00 stderr F I0927 22:07:42.621735       1 round_trippers.go:553] GET https://192.168.100.1:6443/apis/coordination.k8s.io/v1/namespaces/kube-system/leases/kube-scheduler?timeout=5s 200 OK in 4 milliseconds
2023-09-28T00:07:59.250333949+02:00 stderr F I0927 22:07:59.250065       1 eventhandlers.go:206] "Update event for scheduled pod" pod="default/kbench-deployment-oid-0-tid-0-bdb979454-rgxwg"
2023-09-28T00:07:26.491701852+02:00 stderr F I0927 22:07:26.491564       1 leaderelection.go:276] successfully renewed lease kube-system/kube-scheduler
2023-09-28T00:07:44.646187198+02:00 stderr F I0927 22:07:44.646048       1 round_trippers.go:553] PUT https://192.168.100.1:6443/apis/coordination.k8s.io/v1/namespaces/kube-system/leases/kube-scheduler?timeout=5s 200 OK in 7 milliseconds
2023-09-28T00:07:17.708514724+02:00 stderr F I0927 22:07:17.708405       1 scheduling_queue.go:419] "Pod moved to an internal scheduling queue" pod="default/kbench-deployment-oid-0-tid-1-778f5d498c-kg897" event="PodAdd" queue="Active"
2023-09-28T00:07:31.716493782+02:00 stderr F I0927 22:07:31.716282       1 pathrecorder.go:241] kube-scheduler: "/metrics" satisfied by exact match
2023-09-28T00:07:36.245218469+02:00 stderr F I0927 22:07:36.244841       1 eventhandlers.go:161] "Delete event for unscheduled pod" pod="default/kbench-deployment-oid-0-tid-2-cc4784d96-tdhgd"
2023-09-28T00:07:17.742310854+02:00 stderr F I0927 22:07:17.741123       1 eventhandlers.go:161] "Delete event for unscheduled pod" pod="default/kbench-deployment-oid-0-tid-0-bdb979454-j4hbd"
2023-09-28T00:07:59.19255536+02:00 stderr F I0927 22:07:59.190869       1 eventhandlers.go:206] "Update event for scheduled pod" pod="default/kbench-deployment-oid-0-tid-2-cc4784d96-82csv"
2023-09-28T00:07:42.629755686+02:00 stderr F I0927 22:07:42.629444       1 leaderelection.go:276] successfully renewed lease kube-system/kube-scheduler
2023-09-28T00:08:06.866620697+02:00 stderr F I0927 22:08:06.866372       1 round_trippers.go:553] GET https://192.168.100.1:6443/apis/coordination.k8s.io/v1/namespaces/kube-system/leases/kube-scheduler?timeout=5s 200 OK in 4 milliseconds
2023-09-28T00:07:30.527346503+02:00 stderr F I0927 22:07:30.527157       1 leaderelection.go:276] successfully renewed lease kube-system/kube-scheduler
2023-09-28T00:07:20.176741982+02:00 stderr F I0927 22:07:20.176460       1 eventhandlers.go:206] "Update event for scheduled pod" pod="default/kbench-deployment-oid-0-tid-0-bdb979454-rgxwg"
2023-09-28T00:07:17.747806851+02:00 stderr F I0927 22:07:17.745427       1 eventhandlers.go:186] "Add event for scheduled pod" pod="default/kbench-deployment-oid-0-tid-2-cc4784d96-cn9ql"
2023-09-28T00:07:34.556742216+02:00 stderr F I0927 22:07:34.556490       1 round_trippers.go:553] GET https://192.168.100.1:6443/apis/coordination.k8s.io/v1/namespaces/kube-system/leases/kube-scheduler?timeout=5s 200 OK in 5 milliseconds
2023-09-28T00:07:22.740372011+02:00 stderr F I0927 22:07:22.740142       1 pathrecorder.go:241] kube-scheduler: "/metrics" satisfied by exact match
2023-09-28T00:08:06.593776776+02:00 stderr F I0927 22:08:06.593339       1 eventhandlers.go:231] "Delete event for scheduled pod" pod="default/kbench-deployment-oid-0-tid-0-bdb979454-j4hbd"
2023-09-28T00:07:36.210589822+02:00 stderr F I0927 22:07:36.210461       1 eventhandlers.go:206] "Update event for scheduled pod" pod="default/kbench-deployment-oid-0-tid-2-cc4784d96-cn9ql"
2023-09-28T00:07:24.472545955+02:00 stderr F I0927 22:07:24.472277       1 round_trippers.go:553] PUT https://192.168.100.1:6443/apis/coordination.k8s.io/v1/namespaces/kube-system/leases/kube-scheduler?timeout=5s 200 OK in 9 milliseconds
2023-09-28T00:07:50.699957819+02:00 stderr F I0927 22:07:50.699774       1 round_trippers.go:553] GET https://192.168.100.1:6443/apis/coordination.k8s.io/v1/namespaces/kube-system/leases/kube-scheduler?timeout=5s 200 OK in 4 milliseconds
2023-09-28T00:07:17.71116163+02:00 stderr F I0927 22:07:17.711048       1 default_binder.go:53] "Attempting to bind pod to node" pod="default/kbench-deployment-oid-0-tid-0-bdb979454-j4hbd" node="w01"
2023-09-28T00:07:46.39229844+02:00 stderr F I0927 22:07:46.392074       1 httplog.go:132] "HTTP" verb="GET" URI="/healthz" latency="180.516µs" userAgent="kube-probe/1.27" audit-ID="" srcIP="127.0.0.1:34138" resp=200
2023-09-28T00:07:18.408763418+02:00 stderr F I0927 22:07:18.408598       1 round_trippers.go:553] GET https://192.168.100.1:6443/apis/coordination.k8s.io/v1/namespaces/kube-system/leases/kube-scheduler?timeout=5s 200 OK in 6 milliseconds
2023-09-28T00:07:19.122678773+02:00 stderr F I0927 22:07:19.122261       1 eventhandlers.go:206] "Update event for scheduled pod" pod="default/kbench-deployment-oid-0-tid-2-cc4784d96-82csv"
2023-09-28T00:07:20.434215339+02:00 stderr F I0927 22:07:20.434004       1 leaderelection.go:276] successfully renewed lease kube-system/kube-scheduler
2023-09-28T00:08:04.717197271+02:00 stderr F I0927 22:08:04.716797       1 pathrecorder.go:241] kube-scheduler: "/metrics" satisfied by exact match
2023-09-28T00:07:17.742298018+02:00 stderr F I0927 22:07:17.741036       1 eventhandlers.go:186] "Add event for scheduled pod" pod="default/kbench-deployment-oid-0-tid-0-bdb979454-j4hbd"
2023-09-28T00:07:28.502261637+02:00 stderr F I0927 22:07:28.501990       1 round_trippers.go:553] GET https://192.168.100.1:6443/apis/coordination.k8s.io/v1/namespaces/kube-system/leases/kube-scheduler?timeout=5s 200 OK in 5 milliseconds
2023-09-28T00:07:36.227921601+02:00 stderr F I0927 22:07:36.227668       1 default_binder.go:53] "Attempting to bind pod to node" pod="default/kbench-deployment-oid-0-tid-2-cc4784d96-tdhgd" node="w03"
2023-09-28T00:07:17.763499238+02:00 stderr F I0927 22:07:17.763035       1 round_trippers.go:553] POST https://192.168.100.1:6443/api/v1/namespaces/default/pods/kbench-deployment-oid-0-tid-0-bdb979454-rgxwg/binding 201 Created in 29 milliseconds
2023-09-28T00:07:48.684540019+02:00 stderr F I0927 22:07:48.684242       1 round_trippers.go:553] GET https://192.168.100.1:6443/apis/coordination.k8s.io/v1/namespaces/kube-system/leases/kube-scheduler?timeout=5s 200 OK in 4 milliseconds
2023-09-28T00:07:36.207383241+02:00 stderr F I0927 22:07:36.207224       1 eventhandlers.go:206] "Update event for scheduled pod" pod="default/kbench-deployment-oid-0-tid-0-bdb979454-j4hbd"
2023-09-28T00:07:26.491362944+02:00 stderr F I0927 22:07:26.491157       1 round_trippers.go:553] PUT https://192.168.100.1:6443/apis/coordination.k8s.io/v1/namespaces/kube-system/leases/kube-scheduler?timeout=5s 200 OK in 11 milliseconds
2023-09-28T00:07:36.245604849+02:00 stderr F I0927 22:07:36.245492       1 round_trippers.go:553] POST https://192.168.100.1:6443/api/v1/namespaces/default/pods/kbench-deployment-oid-0-tid-2-cc4784d96-tdhgd/binding 201 Created in 16 milliseconds
2023-09-28T00:07:36.226096799+02:00 stderr F I0927 22:07:36.225986       1 scheduling_queue.go:1133] "About to try and schedule pod" pod="default/kbench-deployment-oid-0-tid-0-bdb979454-ztd7s"
2023-09-28T00:07:17.740443599+02:00 stderr F I0927 22:07:17.740291       1 schedule_one.go:252] "Successfully bound pod to node" pod="default/kbench-deployment-oid-0-tid-1-778f5d498c-kg897" node="w03" evaluatedNodes=5 feasibleNodes=3
2023-09-28T00:07:58.789117153+02:00 stderr F I0927 22:07:58.788853       1 round_trippers.go:553] PUT https://192.168.100.1:6443/apis/coordination.k8s.io/v1/namespaces/kube-system/leases/kube-scheduler?timeout=5s 200 OK in 6 milliseconds
2023-09-28T00:07:38.597269679+02:00 stderr F I0927 22:07:38.597084       1 round_trippers.go:553] PUT https://192.168.100.1:6443/apis/coordination.k8s.io/v1/namespaces/kube-system/leases/kube-scheduler?timeout=5s 200 OK in 7 milliseconds
2023-09-28T00:07:56.393560391+02:00 stderr F I0927 22:07:56.393276       1 pathrecorder.go:241] kube-scheduler: "/healthz" satisfied by exact match
2023-09-28T00:07:24.462263751+02:00 stderr F I0927 22:07:24.461951       1 round_trippers.go:553] GET https://192.168.100.1:6443/apis/coordination.k8s.io/v1/namespaces/kube-system/leases/kube-scheduler?timeout=5s 200 OK in 6 milliseconds
2023-09-28T00:07:37.731347101+02:00 stderr F I0927 22:07:37.731090       1 httplog.go:132] "HTTP" verb="GET" URI="/metrics" latency="13.286419ms" userAgent="Prometheus/2.47.0" audit-ID="" srcIP="192.168.100.20:44435" resp=200
2023-09-28T00:07:36.237149818+02:00 stderr F I0927 22:07:36.235808       1 schedule_one.go:252] "Successfully bound pod to node" pod="default/kbench-deployment-oid-0-tid-0-bdb979454-ztd7s" node="w02" evaluatedNodes=5 feasibleNodes=2
2023-09-28T00:07:22.733821633+02:00 stderr F I0927 22:07:22.733350       1 round_trippers.go:553] POST https://192.168.100.1:6443/apis/authentication.k8s.io/v1/tokenreviews 201 Created in 5 milliseconds
2023-09-28T00:07:36.269410969+02:00 stderr F I0927 22:07:36.269013       1 eventhandlers.go:206] "Update event for scheduled pod" pod="default/kbench-deployment-oid-0-tid-2-cc4784d96-cn9ql"
2023-09-28T00:07:17.789369472+02:00 stderr F I0927 22:07:17.789226       1 eventhandlers.go:206] "Update event for scheduled pod" pod="default/kbench-deployment-oid-0-tid-1-778f5d498c-kg897"
2023-09-28T00:07:36.226101621+02:00 stderr F I0927 22:07:36.225996       1 schedule_one.go:80] "Attempting to schedule pod" pod="default/kbench-deployment-oid-0-tid-0-bdb979454-ztd7s"
2023-09-28T00:07:17.742284378+02:00 stderr F I0927 22:07:17.740900       1 eventhandlers.go:161] "Delete event for unscheduled pod" pod="default/kbench-deployment-oid-0-tid-2-cc4784d96-82csv"
2023-09-03T06:43:56.619180611+02:00 stderr F I0903 04:43:56.618926       1 cache.go:758] "Could not expire cache for pod as binding is still in progress" podKey="4f1e3ca5-7fee-4797-ae8c-f2451b50bc72" pod="default/kbench-deployment-oid-0-tid-1-db946cf6f-7p9p5"
2023-09-03T06:43:24.788119385+02:00 stderr F I0903 04:43:24.787984       1 schedule_one.go:252] "Successfully bound pod to node" pod="default/kbench-deployment-oid-0-tid-1-778f5d498c-lprgw" node="w03" evaluatedNodes=5 feasibleNodes=3
2023-09-03T06:43:24.796916704+02:00 stderr F I0903 04:43:24.796737       1 eventhandlers.go:161] "Delete event for unscheduled pod" pod="default/kbench-deployment-oid-0-tid-1-778f5d498c-cccvv"
2023-09-03T06:43:38.43103626+02:00 stderr F I0903 04:43:38.430704       1 eventhandlers.go:118] "Add event for unscheduled pod" pod="default/kbench-deployment-oid-0-tid-1-db946cf6f-klg8p"
2023-09-03T06:44:12.084823333+02:00 stderr F I0903 04:44:12.084530       1 eventhandlers.go:231] "Delete event for scheduled pod" pod="default/kbench-deployment-oid-0-tid-1-778f5d498c-jlfsl"
2023-09-03T06:44:01.240984353+02:00 stderr F I0903 04:44:01.240803       1 httplog.go:132] "HTTP" verb="GET" URI="/metrics" latency="19.366898ms" userAgent="Prometheus/2.46.0" audit-ID="" srcIP="192.168.100.20:15612" resp=200
2023-09-03T06:43:56.62824809+02:00 stderr F I0903 04:43:56.627770       1 round_trippers.go:553] POST https://192.168.100.1:6443/api/v1/namespaces/default/pods/kbench-deployment-oid-0-tid-1-db946cf6f-7p9p5/binding 201 Created in 11 milliseconds
2023-09-03T06:43:36.51272908+02:00 stderr F I0903 04:43:36.512650       1 default_binder.go:53] "Attempting to bind pod to node" pod="default/kbench-deployment-oid-0-tid-1-778f5d498c-jlfsl" node="w02"
2023-09-03T06:43:44.745072181+02:00 stderr F I0903 04:43:44.744794       1 pathrecorder.go:241] kube-scheduler: "/healthz" satisfied by exact match
2023-09-03T06:43:24.791435167+02:00 stderr F I0903 04:43:24.791257       1 cache.go:401] "Finished binding for pod, can be expired" podKey="58366ad0-68e9-41eb-80a2-82baf88a2f4b" pod="default/kbench-deployment-oid-0-tid-0-bdb979454-fcvpd"
2023-09-03T06:43:34.28105641+02:00 stderr F I0903 04:43:34.280743       1 pathrecorder.go:241] kube-scheduler: "/metrics" satisfied by exact match
2023-09-03T06:43:24.7680741+02:00 stderr F I0903 04:43:24.766098       1 eventhandlers.go:118] "Add event for unscheduled pod" pod="default/kbench-deployment-oid-0-tid-0-bdb979454-fcvpd"
2023-09-03T06:43:24.76808304+02:00 stderr F I0903 04:43:24.768023       1 scheduling_queue.go:419] "Pod moved to an internal scheduling queue" pod="default/kbench-deployment-oid-0-tid-0-bdb979454-fcvpd" event="PodAdd" queue="Active"
2023-09-03T06:43:36.608849185+02:00 stderr F I0903 04:43:36.608658       1 eventhandlers.go:186] "Add event for scheduled pod" pod="default/kbench-deployment-oid-0-tid-1-db946cf6f-4dwk7"
2023-09-03T06:43:38.441731554+02:00 stderr F I0903 04:43:38.441524       1 cache.go:401] "Finished binding for pod, can be expired" podKey="ceb55a34-6bc3-4268-9dff-d6764ddbf59d" pod="default/kbench-deployment-oid-0-tid-1-db946cf6f-klg8p"
2023-09-03T06:43:36.54471515+02:00 stderr F I0903 04:43:36.544563       1 schedule_one.go:252] "Successfully bound pod to node" pod="default/kbench-deployment-oid-0-tid-0-bdb979454-7kgzf" node="w03" evaluatedNodes=5 feasibleNodes=3
2023-09-03T06:43:56.64839454+02:00 stderr F I0903 04:43:56.648305       1 eventhandlers.go:206] "Update event for scheduled pod" pod="default/kbench-deployment-oid-0-tid-1-db946cf6f-7p9p5"
2023-09-03T06:44:06.842449644+02:00 stderr F I0903 04:44:06.842333       1 eventhandlers.go:206] "Update event for scheduled pod" pod="default/kbench-deployment-oid-0-tid-0-bdb979454-drpz7"
2023-09-03T06:43:36.592137574+02:00 stderr F I0903 04:43:36.591989       1 scheduling_queue.go:419] "Pod moved to an internal scheduling queue" pod="default/kbench-deployment-oid-0-tid-1-db946cf6f-4dwk7" event="PodAdd" queue="Active"
2023-09-03T06:43:36.544850603+02:00 stderr F I0903 04:43:36.544499       1 eventhandlers.go:186] "Add event for scheduled pod" pod="default/kbench-deployment-oid-0-tid-0-bdb979454-7kgzf"
2023-09-03T06:43:24.788807927+02:00 stderr F I0903 04:43:24.788748       1 eventhandlers.go:186] "Add event for scheduled pod" pod="default/kbench-deployment-oid-0-tid-1-778f5d498c-lprgw"
2023-09-03T06:43:24.777507896+02:00 stderr F I0903 04:43:24.777374       1 schedule_one.go:80] "Attempting to schedule pod" pod="default/kbench-deployment-oid-0-tid-1-778f5d498c-cccvv"
2023-09-03T06:43:24.75533714+02:00 stderr F I0903 04:43:24.755256       1 schedule_one.go:80] "Attempting to schedule pod" pod="default/kbench-deployment-oid-0-tid-0-bdb979454-hn8v5"
2023-09-03T06:43:25.241992287+02:00 stderr F I0903 04:43:25.241571       1 httplog.go:132] "HTTP" verb="GET" URI="/metrics" latency="21.094471ms" userAgent="Prometheus/2.46.0" audit-ID="" srcIP="192.168.100.20:15612" resp=200
2023-09-03T06:43:30.957629741+02:00 stderr F I0903 04:43:30.957335       1 round_trippers.go:553] GET https://192.168.100.1:6443/apis/coordination.k8s.io/v1/namespaces/kube-system/leases/kube-scheduler?timeout=5s 200 OK in 9 milliseconds
2023-09-03T06:43:24.821482304+02:00 stderr F I0903 04:43:24.821165       1 round_trippers.go:553] POST https://192.168.100.1:6443/apis/events.k8s.io/v1/namespaces/default/events 201 Created in 23 milliseconds
2023-09-03T06:44:14.929386898+02:00 stderr F I0903 04:44:14.928066       1 eventhandlers.go:206] "Update event for scheduled pod" pod="default/kbench-deployment-oid-0-tid-1-db946cf6f-nln8n"
2023-09-03T06:43:36.528898889+02:00 stderr F I0903 04:43:36.528834       1 schedule_one.go:252] "Successfully bound pod to node" pod="default/kbench-deployment-oid-0-tid-1-778f5d498c-jlfsl" node="w02" evaluatedNodes=5 feasibleNodes=3
2023-09-03T06:43:46.586757244+02:00 stderr F I0903 04:43:46.586432       1 round_trippers.go:553] POST https://192.168.100.1:6443/apis/events.k8s.io/v1/namespaces/default/events 201 Created in 13 milliseconds
2023-09-03T06:43:46.220623563+02:00 stderr F I0903 04:43:46.220317       1 pathrecorder.go:241] kube-scheduler: "/metrics" satisfied by exact match
2023-09-03T06:43:36.598011198+02:00 stderr F I0903 04:43:36.597778       1 cache.go:758] "Could not expire cache for pod as binding is still in progress" podKey="f695f86b-64c6-46e4-8a66-4e2df1047afa" pod="default/kbench-deployment-oid-0-tid-1-db946cf6f-4dwk7"
2023-09-03T06:43:56.613901091+02:00 stderr F I0903 04:43:56.613760       1 schedule_one.go:80] "Attempting to schedule pod" pod="default/kbench-deployment-oid-0-tid-0-bdb979454-drpz7"
2023-09-03T06:43:58.222342963+02:00 stderr F I0903 04:43:58.222004       1 pathrecorder.go:241] kube-scheduler: "/metrics" satisfied by exact match
2023-09-03T06:43:24.769343851+02:00 stderr F I0903 04:43:24.769072       1 eventhandlers.go:161] "Delete event for unscheduled pod" pod="default/kbench-deployment-oid-0-tid-0-bdb979454-hn8v5"
2023-09-03T06:43:24.830081527+02:00 stderr F I0903 04:43:24.830005       1 eventhandlers.go:206] "Update event for scheduled pod" pod="default/kbench-deployment-oid-0-tid-1-778f5d498c-lprgw"
2023-09-03T06:43:46.556444713+02:00 stderr F I0903 04:43:46.556221       1 default_binder.go:53] "Attempting to bind pod to node" pod="default/kbench-deployment-oid-0-tid-0-bdb979454-pgxqv" node="w01"
2023-09-03T06:44:14.90592657+02:00 stderr F I0903 04:44:14.905755       1 eventhandlers.go:231] "Delete event for scheduled pod" pod="default/kbench-deployment-oid-0-tid-0-bdb979454-hn8v5"
2023-09-03T06:43:58.2363317+02:00 stderr F I0903 04:43:58.236042       1 httplog.go:132] "HTTP" verb="GET" URI="/metrics" latency="14.191825ms" userAgent="Prometheus/2.46.0" audit-ID="" srcIP="192.168.100.20:15612" resp=200
2023-09-03T06:43:55.175562744+02:00 stderr F I0903 04:43:55.175137       1 round_trippers.go:553] GET https://192.168.100.1:6443/apis/coordination.k8s.io/v1/namespaces/kube-system/leases/kube-scheduler?timeout=5s 200 OK in 5 milliseconds
2023-09-03T06:43:46.56964989+02:00 stderr F I0903 04:43:46.569492       1 eventhandlers.go:161] "Delete event for unscheduled pod" pod="default/kbench-deployment-oid-0-tid-1-db946cf6f-nln8n"
2023-09-03T06:44:14.915082849+02:00 stderr F I0903 04:44:14.914908       1 eventhandlers.go:206] "Update event for scheduled pod" pod="default/kbench-deployment-oid-0-tid-1-db946cf6f-klg8p"
2023-09-03T06:43:36.608036516+02:00 stderr F I0903 04:43:36.607897       1 round_trippers.go:553] POST https://192.168.100.1:6443/api/v1/namespaces/default/pods/kbench-deployment-oid-0-tid-1-db946cf6f-4dwk7/binding 201 Created in 13 milliseconds
2023-09-03T06:43:24.75656956+02:00 stderr F I0903 04:43:24.756327       1 default_binder.go:53] "Attempting to bind pod to node" pod="default/kbench-deployment-oid-0-tid-0-bdb979454-hn8v5" node="w01"
2023-09-03T06:43:47.099695591+02:00 stderr F I0903 04:43:47.099360       1 round_trippers.go:553] GET https://192.168.100.1:6443/apis/coordination.k8s.io/v1/namespaces/kube-system/leases/kube-scheduler?timeout=5s 200 OK in 5 milliseconds
2023-09-03T06:44:06.830746678+02:00 stderr F I0903 04:44:06.830641       1 eventhandlers.go:206] "Update event for scheduled pod" pod="default/kbench-deployment-oid-0-tid-0-bdb979454-7kgzf"
2023-09-03T06:44:14.898361807+02:00 stderr F I0903 04:44:14.898032       1 eventhandlers.go:231] "Delete event for scheduled pod" pod="default/kbench-deployment-oid-0-tid-0-bdb979454-fcvpd"
2023-09-03T06:43:43.063698667+02:00 stderr F I0903 04:43:43.063382       1 round_trippers.go:553] GET https://192.168.100.1:6443/apis/coordination.k8s.io/v1/namespaces/kube-system/leases/kube-scheduler?timeout=5s 200 OK in 5 milliseconds
2023-09-03T06:44:05.266788532+02:00 stderr F I0903 04:44:05.266330       1 round_trippers.go:553] PUT https://192.168.100.1:6443/apis/coordination.k8s.io/v1/namespaces/kube-system/leases/kube-scheduler?timeout=5s 200 OK in 8 milliseconds
2023-09-03T06:43:36.527043135+02:00 stderr F I0903 04:43:36.526854       1 eventhandlers.go:161] "Delete event for unscheduled pod" pod="default/kbench-deployment-oid-0-tid-1-778f5d498c-jlfsl"
2023-09-03T06:44:14.745714256+02:00 stderr F I0903 04:44:14.745336       1 pathrecorder.go:241] kube-scheduler: "/healthz" satisfied by exact match
2023-09-03T06:43:34.744526166+02:00 stderr F I0903 04:43:34.744322       1 httplog.go:132] "HTTP" verb="GET" URI="/healthz" latency="148.765µs" userAgent="kube-probe/1.27" audit-ID="" srcIP="127.0.0.1:48660" resp=200
2023-09-03T06:43:46.573630898+02:00 stderr F I0903 04:43:46.573106       1 schedule_one.go:252] "Successfully bound pod to node" pod="default/kbench-deployment-oid-0-tid-0-bdb979454-pgxqv" node="w01" evaluatedNodes=5 feasibleNodes=3
2023-09-03T06:43:41.056467697+02:00 stderr F I0903 04:43:41.056304       1 leaderelection.go:276] successfully renewed lease kube-system/kube-scheduler
2023-09-03T06:43:24.792171051+02:00 stderr F I0903 04:43:24.792031       1 schedule_one.go:252] "Successfully bound pod to node" pod="default/kbench-deployment-oid-0-tid-0-bdb979454-fcvpd" node="w02" evaluatedNodes=5 feasibleNodes=3
2023-09-03T06:43:41.650301274+02:00 stderr F I0903 04:43:41.650019       1 eventhandlers.go:206] "Update event for scheduled pod" pod="default/kbench-deployment-oid-0-tid-1-db946cf6f-p52sk"
2023-09-03T06:43:36.621379203+02:00 stderr F I0903 04:43:36.621153       1 round_trippers.go:553] POST https://192.168.100.1:6443/apis/events.k8s.io/v1/namespaces/default/events 201 Created in 12 milliseconds
2023-09-03T06:43:36.511902633+02:00 stderr F I0903 04:43:36.511806       1 schedule_one.go:80] "Attempting to schedule pod" pod="default/kbench-deployment-oid-0-tid-1-778f5d498c-jlfsl"
2023-09-03T06:43:56.613874777+02:00 stderr F I0903 04:43:56.613688       1 eventhandlers.go:118] "Add event for unscheduled pod" pod="default/kbench-deployment-oid-0-tid-0-bdb979454-drpz7"
2023-09-03T06:43:43.07268611+02:00 stderr F I0903 04:43:43.072470       1 leaderelection.go:276] successfully renewed lease kube-system/kube-scheduler
2023-09-03T06:44:01.22886648+02:00 stderr F I0903 04:44:01.228664       1 round_trippers.go:553] PUT https://192.168.100.1:6443/apis/coordination.k8s.io/v1/namespaces/kube-system/leases/kube-scheduler?timeout=5s 200 OK in 7 milliseconds
2023-09-03T06:43:40.075540529+02:00 stderr F I0903 04:43:40.073897       1 eventhandlers.go:118] "Add event for unscheduled pod" pod="default/kbench-deployment-oid-0-tid-1-db946cf6f-p52sk"
2023-09-03T06:44:09.310430816+02:00 stderr F I0903 04:44:09.310258       1 leaderelection.go:276] successfully renewed lease kube-system/kube-scheduler
2023-09-03T06:43:56.613896685+02:00 stderr F I0903 04:43:56.613750       1 scheduling_queue.go:1133] "About to try and schedule pod" pod="default/kbench-deployment-oid-0-tid-0-bdb979454-drpz7"
2023-09-03T06:43:36.594401956+02:00 stderr F I0903 04:43:36.591916       1 eventhandlers.go:206] "Update event for scheduled pod" pod="default/kbench-deployment-oid-0-tid-0-bdb979454-7kgzf"
2023-09-03T06:43:44.745097028+02:00 stderr F I0903 04:43:44.744918       1 httplog.go:132] "HTTP" verb="GET" URI="/healthz" latency="144.461µs" userAgent="kube-probe/1.27" audit-ID="" srcIP="127.0.0.1:40754" resp=200
2023-09-03T06:43:31.233430061+02:00 stderr F I0903 04:43:31.233075       1 httplog.go:132] "HTTP" verb="GET" URI="/metrics" latency="11.946423ms" userAgent="Prometheus/2.46.0" audit-ID="" srcIP="192.168.100.20:15612" resp=200
2023-09-03T06:43:24.741985322+02:00 stderr F I0903 04:43:24.741852       1 pathrecorder.go:241] kube-scheduler: "/healthz" satisfied by exact match
2023-09-03T06:43:24.762100228+02:00 stderr F I0903 04:43:24.760481       1 eventhandlers.go:118] "Add event for unscheduled pod" pod="default/kbench-deployment-oid-0-tid-1-778f5d498c-lprgw"
2023-09-03T06:43:24.762215537+02:00 stderr F I0903 04:43:24.760613       1 schedule_one.go:80] "Attempting to schedule pod" pod="default/kbench-deployment-oid-0-tid-1-778f5d498c-lprgw"
2023-09-03T06:43:36.544187447+02:00 stderr F I0903 04:43:36.543950       1 round_trippers.go:553] POST https://192.168.100.1:6443/apis/events.k8s.io/v1/namespaces/default/events 201 Created in 14 milliseconds
2023-09-03T06:43:24.779710347+02:00 stderr F I0903 04:43:24.779449       1 default_binder.go:53] "Attempting to bind pod to node" pod="default/kbench-deployment-oid-0-tid-1-778f5d498c-cccvv" node="w01"
2023-09-03T06:43:24.78490456+02:00 stderr F I0903 04:43:24.784761       1 round_trippers.go:553] POST https://192.168.100.1:6443/apis/events.k8s.io/v1/namespaces/default/events 201 Created in 15 milliseconds
2023-09-03T06:43:24.788109737+02:00 stderr F I0903 04:43:24.787951       1 cache.go:401] "Finished binding for pod, can be expired" podKey="14f5e4e1-9d57-467d-adf3-1517d938f7eb" pod="default/kbench-deployment-oid-0-tid-1-778f5d498c-lprgw"
2023-09-03T06:43:46.559132102+02:00 stderr F I0903 04:43:46.558039       1 schedule_one.go:80] "Attempting to schedule pod" pod="default/kbench-deployment-oid-0-tid-1-db946cf6f-nln8n"
2023-09-03T06:44:01.231085319+02:00 stderr F I0903 04:44:01.230905       1 pathrecorder.go:241] kube-scheduler: "/metrics" satisfied by exact match
2023-09-03T06:43:52.226477298+02:00 stderr F I0903 04:43:52.226014       1 pathrecorder.go:241] kube-scheduler: "/metrics" satisfied by exact match
2023-09-03T06:44:13.351440615+02:00 stderr F I0903 04:44:13.351210       1 round_trippers.go:553] PUT https://192.168.100.1:6443/apis/coordination.k8s.io/v1/namespaces/kube-system/leases/kube-scheduler?timeout=5s 200 OK in 12 milliseconds
2023-09-03T06:43:47.389947274+02:00 stderr F I0903 04:43:47.389730       1 eventhandlers.go:206] "Update event for scheduled pod" pod="default/kbench-deployment-oid-0-tid-0-bdb979454-pgxqv"
2023-09-03T06:43:24.767040614+02:00 stderr F I0903 04:43:24.765170       1 default_binder.go:53] "Attempting to bind pod to node" pod="default/kbench-deployment-oid-0-tid-1-778f5d498c-lprgw" node="w03"
2023-09-03T06:44:05.266816438+02:00 stderr F I0903 04:44:05.266490       1 leaderelection.go:276] successfully renewed lease kube-system/kube-scheduler
2023-09-03T06:44:01.219989189+02:00 stderr F I0903 04:44:01.219652       1 round_trippers.go:553] GET https://192.168.100.1:6443/apis/coordination.k8s.io/v1/namespaces/kube-system/leases/kube-scheduler?timeout=5s 200 OK in 5 milliseconds
2023-09-03T06:43:46.56995257+02:00 stderr F I0903 04:43:46.569696       1 schedule_one.go:252] "Successfully bound pod to node" pod="default/kbench-deployment-oid-0-tid-1-db946cf6f-nln8n" node="w02" evaluatedNodes=5 feasibleNodes=3
2023-09-03T06:43:46.574258636+02:00 stderr F I0903 04:43:46.574154       1 eventhandlers.go:161] "Delete event for unscheduled pod" pod="default/kbench-deployment-oid-0-tid-0-bdb979454-pgxqv"
2023-09-03T06:43:35.000384572+02:00 stderr F I0903 04:43:35.000008       1 round_trippers.go:553] GET https://192.168.100.1:6443/apis/coordination.k8s.io/v1/namespaces/kube-system/leases/kube-scheduler?timeout=5s 200 OK in 5 milliseconds
2023-09-03T06:43:24.817553181+02:00 stderr F I0903 04:43:24.817380       1 round_trippers.go:553] POST https://192.168.100.1:6443/apis/events.k8s.io/v1/namespaces/default/events 201 Created in 29 milliseconds
2023-09-03T06:43:32.994669504+02:00 stderr F I0903 04:43:32.994279       1 round_trippers.go:553] PUT https://192.168.100.1:6443/apis/coordination.k8s.io/v1/namespaces/kube-system/leases/kube-scheduler?timeout=5s 200 OK in 12 milliseconds
2023-09-03T06:43:24.911000082+02:00 stderr F I0903 04:43:24.910921       1 leaderelection.go:276] successfully renewed lease kube-system/kube-scheduler
2023-09-03T06:43:56.607996602+02:00 stderr F I0903 04:43:56.607827       1 eventhandlers.go:118] "Add event for unscheduled pod" pod="default/kbench-deployment-oid-0-tid-1-db946cf6f-7p9p5"
2023-09-03T06:43:38.431816749+02:00 stderr F I0903 04:43:38.431654       1 scheduling_queue.go:1133] "About to try and schedule pod" pod="default/kbench-deployment-oid-0-tid-1-db946cf6f-klg8p"
2023-09-03T06:44:10.404377226+02:00 stderr F I0903 04:44:10.404179       1 eventhandlers.go:231] "Delete event for scheduled pod" pod="default/kbench-deployment-oid-0-tid-1-778f5d498c-lprgw"
2023-09-03T06:44:04.743510801+02:00 stderr F I0903 04:44:04.743387       1 httplog.go:132] "HTTP" verb="GET" URI="/healthz" latency="239.495µs" userAgent="kube-probe/1.27" audit-ID="" srcIP="127.0.0.1:57812" resp=200
2023-09-03T06:43:30.968405871+02:00 stderr F I0903 04:43:30.968105       1 round_trippers.go:553] PUT https://192.168.100.1:6443/apis/coordination.k8s.io/v1/namespaces/kube-system/leases/kube-scheduler?timeout=5s 200 OK in 10 milliseconds
2023-09-03T06:43:56.632012279+02:00 stderr F I0903 04:43:56.631798       1 eventhandlers.go:186] "Add event for scheduled pod" pod="default/kbench-deployment-oid-0-tid-0-bdb979454-drpz7"
2023-09-03T06:43:24.769350849+02:00 stderr F I0903 04:43:24.769112       1 eventhandlers.go:186] "Add event for scheduled pod" pod="default/kbench-deployment-oid-0-tid-0-bdb979454-hn8v5"
2023-09-03T06:43:51.149138577+02:00 stderr F I0903 04:43:51.149062       1 leaderelection.go:276] successfully renewed lease kube-system/kube-scheduler
2023-09-03T06:43:39.038031436+02:00 stderr F I0903 04:43:39.037753       1 round_trippers.go:553] PUT https://192.168.100.1:6443/apis/coordination.k8s.io/v1/namespaces/kube-system/leases/kube-scheduler?timeout=5s 200 OK in 8 milliseconds
2023-09-03T06:44:10.235272036+02:00 stderr F I0903 04:44:10.234999       1 httplog.go:132] "HTTP" verb="GET" URI="/metrics" latency="13.706745ms" userAgent="Prometheus/2.46.0" audit-ID="" srcIP="192.168.100.20:15612" resp=200
2023-09-03T06:44:04.2352164+02:00 stderr F I0903 04:44:04.234857       1 httplog.go:132] "HTTP" verb="GET" URI="/metrics" latency="14.925071ms" userAgent="Prometheus/2.46.0" audit-ID="" srcIP="192.168.100.20:15612" resp=200
2023-09-03T06:43:26.574156509+02:00 stderr F I0903 04:43:26.573826       1 eventhandlers.go:206] "Update event for scheduled pod" pod="default/kbench-deployment-oid-0-tid-0-bdb979454-fcvpd"
2023-09-03T06:43:46.57362588+02:00 stderr F I0903 04:43:46.573072       1 cache.go:401] "Finished binding for pod, can be expired" podKey="9b2ce02f-766d-4f8b-8e11-e04f4cd49fbb" pod="default/kbench-deployment-oid-0-tid-0-bdb979454-pgxqv"
2023-09-03T06:43:36.511897353+02:00 stderr F I0903 04:43:36.511785       1 scheduling_queue.go:1133] "About to try and schedule pod" pod="default/kbench-deployment-oid-0-tid-1-778f5d498c-jlfsl"
2023-09-03T06:43:40.232328698+02:00 stderr F I0903 04:43:40.231984       1 httplog.go:132] "HTTP" verb="GET" URI="/metrics" latency="10.818354ms" userAgent="Prometheus/2.46.0" audit-ID="" srcIP="192.168.100.20:15612" resp=200
2023-09-03T06:44:07.286292131+02:00 stderr F I0903 04:44:07.285682       1 round_trippers.go:553] PUT https://192.168.100.1:6443/apis/coordination.k8s.io/v1/namespaces/kube-system/leases/kube-scheduler?timeout=5s 200 OK in 11 milliseconds
2023-09-03T06:43:56.642142023+02:00 stderr F I0903 04:43:56.641987       1 round_trippers.go:553] POST https://192.168.100.1:6443/apis/events.k8s.io/v1/namespaces/default/events 201 Created in 13 milliseconds
2023-09-03T06:43:47.107339447+02:00 stderr F I0903 04:43:47.107121       1 round_trippers.go:553] PUT https://192.168.100.1:6443/apis/coordination.k8s.io/v1/namespaces/kube-system/leases/kube-scheduler?timeout=5s 200 OK in 7 milliseconds
2023-09-03T06:43:24.788925092+02:00 stderr F I0903 04:43:24.788789       1 eventhandlers.go:186] "Add event for scheduled pod" pod="default/kbench-deployment-oid-0-tid-0-bdb979454-fcvpd"
2023-09-03T06:44:10.221777211+02:00 stderr F I0903 04:44:10.221422       1 pathrecorder.go:241] kube-scheduler: "/metrics" satisfied by exact match
2023-09-03T06:43:46.574272176+02:00 stderr F I0903 04:43:46.574186       1 eventhandlers.go:186] "Add event for scheduled pod" pod="default/kbench-deployment-oid-0-tid-0-bdb979454-pgxqv"
2023-09-03T06:43:35.008025074+02:00 stderr F I0903 04:43:35.007890       1 leaderelection.go:276] successfully renewed lease kube-system/kube-scheduler
2023-09-03T06:43:46.233634999+02:00 stderr F I0903 04:43:46.233371       1 httplog.go:132] "HTTP" verb="GET" URI="/metrics" latency="13.206754ms" userAgent="Prometheus/2.46.0" audit-ID="" srcIP="192.168.100.20:15612" resp=200
2023-09-03T06:43:39.029305283+02:00 stderr F I0903 04:43:39.029013       1 round_trippers.go:553] GET https://192.168.100.1:6443/apis/coordination.k8s.io/v1/namespaces/kube-system/leases/kube-scheduler?timeout=5s 200 OK in 5 milliseconds
2023-09-03T06:43:38.431828031+02:00 stderr F I0903 04:43:38.431680       1 schedule_one.go:80] "Attempting to schedule pod" pod="default/kbench-deployment-oid-0-tid-1-db946cf6f-klg8p"
2023-09-03T06:43:36.608365932+02:00 stderr F I0903 04:43:36.608184       1 cache.go:401] "Finished binding for pod, can be expired" podKey="f695f86b-64c6-46e4-8a66-4e2df1047afa" pod="default/kbench-deployment-oid-0-tid-1-db946cf6f-4dwk7"
2023-09-03T06:43:46.596676673+02:00 stderr F I0903 04:43:46.596530       1 eventhandlers.go:206] "Update event for scheduled pod" pod="default/kbench-deployment-oid-0-tid-1-db946cf6f-nln8n"
2023-09-03T06:43:56.672188582+02:00 stderr F I0903 04:43:56.671961       1 eventhandlers.go:206] "Update event for scheduled pod" pod="default/kbench-deployment-oid-0-tid-0-bdb979454-drpz7"
2023-09-03T06:44:06.848736228+02:00 stderr F I0903 04:44:06.848245       1 eventhandlers.go:206] "Update event for scheduled pod" pod="default/kbench-deployment-oid-0-tid-0-bdb979454-hn8v5"
2023-09-03T06:43:40.221594146+02:00 stderr F I0903 04:43:40.221305       1 pathrecorder.go:241] kube-scheduler: "/metrics" satisfied by exact match
2023-09-03T06:43:34.289447796+02:00 stderr F I0903 04:43:34.288267       1 httplog.go:132] "HTTP" verb="GET" URI="/metrics" latency="7.680032ms" userAgent="Prometheus/2.46.0" audit-ID="" srcIP="192.168.100.20:15612" resp=200
2023-09-03T06:43:56.6325544+02:00 stderr F I0903 04:43:56.632446       1 round_trippers.go:553] POST https://192.168.100.1:6443/api/v1/namespaces/default/pods/kbench-deployment-oid-0-tid-0-bdb979454-drpz7/binding 201 Created in 14 milliseconds
2023-09-03T06:44:04.220523508+02:00 stderr F I0903 04:44:04.220133       1 pathrecorder.go:241] kube-scheduler: "/metrics" satisfied by exact match
2023-09-03T06:43:43.232152509+02:00 stderr F I0903 04:43:43.231706       1 httplog.go:132] "HTTP" verb="GET" URI="/metrics" latency="10.504484ms" userAgent="Prometheus/2.46.0" audit-ID="" srcIP="192.168.100.20:15612" resp=200
2023-09-03T06:43:24.770047574+02:00 stderr F I0903 04:43:24.769852       1 schedule_one.go:252] "Successfully bound pod to node" pod="default/kbench-deployment-oid-0-tid-0-bdb979454-hn8v5" node="w01" evaluatedNodes=5 feasibleNodes=3
2023-09-03T06:44:03.238547991+02:00 stderr F I0903 04:44:03.238165       1 round_trippers.go:553] GET https://192.168.100.1:6443/apis/coordination.k8s.io/v1/namespaces/kube-system/leases/kube-scheduler?timeout=5s 200 OK in 6 milliseconds
2023-09-03T06:43:38.348973507+02:00 stderr F I0903 04:43:38.348585       1 eventhandlers.go:206] "Update event for scheduled pod" pod="default/kbench-deployment-oid-0-tid-1-db946cf6f-4dwk7"
2023-09-03T06:44:06.825440161+02:00 stderr F I0903 04:44:06.825305       1 eventhandlers.go:206] "Update event for scheduled pod" pod="default/kbench-deployment-oid-0-tid-1-db946cf6f-klg8p"
2023-09-03T06:43:24.768097774+02:00 stderr F I0903 04:43:24.768068       1 scheduling_queue.go:1133] "About to try and schedule pod" pod="default/kbench-deployment-oid-0-tid-0-bdb979454-fcvpd"
2023-09-03T06:43:24.77748891+02:00 stderr F I0903 04:43:24.777284       1 eventhandlers.go:118] "Add event for unscheduled pod" pod="default/kbench-deployment-oid-0-tid-1-778f5d498c-cccvv"
2023-09-03T06:44:14.841327725+02:00 stderr F I0903 04:44:14.841202       1 eventhandlers.go:206] "Update event for scheduled pod" pod="default/kbench-deployment-oid-0-tid-0-bdb979454-drpz7"
2023-09-03T06:43:53.167209298+02:00 stderr F I0903 04:43:53.166934       1 round_trippers.go:553] PUT https://192.168.100.1:6443/apis/coordination.k8s.io/v1/namespaces/kube-system/leases/kube-scheduler?timeout=5s 200 OK in 11 milliseconds
2023-09-03T06:43:38.431131648+02:00 stderr F I0903 04:43:38.430917       1 scheduling_queue.go:419] "Pod moved to an internal scheduling queue" pod="default/kbench-deployment-oid-0-tid-1-db946cf6f-klg8p" event="PodAdd" queue="Active"
2023-09-03T06:43:52.235653132+02:00 stderr F I0903 04:43:52.235224       1 httplog.go:132] "HTTP" verb="GET" URI="/metrics" latency="9.365245ms" userAgent="Prometheus/2.46.0" audit-ID="" srcIP="192.168.100.20:15612" resp=200
2023-09-03T06:43:47.107354855+02:00 stderr F I0903 04:43:47.107271       1 leaderelection.go:276] successfully renewed lease kube-system/kube-scheduler
2023-09-03T06:43:40.08710026+02:00 stderr F I0903 04:43:40.086820       1 schedule_one.go:252] "Successfully bound pod to node" pod="default/kbench-deployment-oid-0-tid-1-db946cf6f-p52sk" node="w02" evaluatedNodes=5 feasibleNodes=3
2023-09-03T06:43:54.75181675+02:00 stderr F I0903 04:43:54.751389       1 pathrecorder.go:241] kube-scheduler: "/healthz" satisfied by exact match
2023-09-03T06:43:24.788789093+02:00 stderr F I0903 04:43:24.788625       1 eventhandlers.go:161] "Delete event for unscheduled pod" pod="default/kbench-deployment-oid-0-tid-1-778f5d498c-lprgw"
2023-09-03T06:43:46.559112585+02:00 stderr F I0903 04:43:46.558002       1 scheduling_queue.go:419] "Pod moved to an internal scheduling queue" pod="default/kbench-deployment-oid-0-tid-1-db946cf6f-nln8n" event="PodAdd" queue="Active"
2023-09-03T06:43:36.524150908+02:00 stderr F I0903 04:43:36.523814       1 eventhandlers.go:118] "Add event for unscheduled pod" pod="default/kbench-deployment-oid-0-tid-0-bdb979454-7kgzf"
2023-09-03T06:43:26.927736036+02:00 stderr F I0903 04:43:26.927461       1 leaderelection.go:276] successfully renewed lease kube-system/kube-scheduler
2023-09-03T06:43:31.221561855+02:00 stderr F I0903 04:43:31.221269       1 pathrecorder.go:241] kube-scheduler: "/metrics" satisfied by exact match
2023-09-03T06:43:24.910957225+02:00 stderr F I0903 04:43:24.910773       1 round_trippers.go:553] PUT https://192.168.100.1:6443/apis/coordination.k8s.io/v1/namespaces/kube-system/leases/kube-scheduler?timeout=5s 200 OK in 10 milliseconds
2023-09-03T06:43:36.543846099+02:00 stderr F I0903 04:43:36.543587       1 round_trippers.go:553] POST https://192.168.100.1:6443/api/v1/namespaces/default/pods/kbench-deployment-oid-0-tid-0-bdb979454-7kgzf/binding 201 Created in 18 milliseconds
2023-09-03T06:43:46.568552502+02:00 stderr F I0903 04:43:46.568251       1 round_trippers.go:553] POST https://192.168.100.1:6443/api/v1/namespaces/default/pods/kbench-deployment-oid-0-tid-1-db946cf6f-nln8n/binding 201 Created in 9 milliseconds
2023-09-03T06:43:57.190858126+02:00 stderr F I0903 04:43:57.190396       1 round_trippers.go:553] GET https://192.168.100.1:6443/apis/coordination.k8s.io/v1/namespaces/kube-system/leases/kube-scheduler?timeout=5s 200 OK in 5 milliseconds
2023-09-03T06:43:56.617332045+02:00 stderr F I0903 04:43:56.617128       1 default_binder.go:53] "Attempting to bind pod to node" pod="default/kbench-deployment-oid-0-tid-0-bdb979454-drpz7" node="w03"
2023-09-03T06:44:14.978109211+02:00 stderr F I0903 04:44:14.978022       1 eventhandlers.go:231] "Delete event for scheduled pod" pod="default/kbench-deployment-oid-0-tid-1-db946cf6f-p52sk"
2023-09-03T06:43:36.592181772+02:00 stderr F I0903 04:43:36.592028       1 scheduling_queue.go:1133] "About to try and schedule pod" pod="default/kbench-deployment-oid-0-tid-1-db946cf6f-4dwk7"
2023-09-03T06:43:58.090201462+02:00 stderr F I0903 04:43:58.090015       1 eventhandlers.go:206] "Update event for scheduled pod" pod="default/kbench-deployment-oid-0-tid-1-db946cf6f-7p9p5"
2023-09-03T06:44:06.830866061+02:00 stderr F I0903 04:44:06.830785       1 eventhandlers.go:206] "Update event for scheduled pod" pod="default/kbench-deployment-oid-0-tid-0-bdb979454-pgxqv"
2023-09-03T06:44:06.817089476+02:00 stderr F I0903 04:44:06.816536       1 eventhandlers.go:206] "Update event for scheduled pod" pod="default/kbench-deployment-oid-0-tid-0-bdb979454-fcvpd"
2023-09-03T06:44:07.222040864+02:00 stderr F I0903 04:44:07.221549       1 pathrecorder.go:241] kube-scheduler: "/metrics" satisfied by exact match
2023-09-03T06:43:43.072466968+02:00 stderr F I0903 04:43:43.072319       1 round_trippers.go:553] PUT https://192.168.100.1:6443/apis/coordination.k8s.io/v1/namespaces/kube-system/leases/kube-scheduler?timeout=5s 200 OK in 8 milliseconds
2023-09-03T06:43:36.524180368+02:00 stderr F I0903 04:43:36.523946       1 schedule_one.go:80] "Attempting to schedule pod" pod="default/kbench-deployment-oid-0-tid-0-bdb979454-7kgzf"
2023-09-03T06:43:38.44082474+02:00 stderr F I0903 04:43:38.440650       1 eventhandlers.go:161] "Delete event for unscheduled pod" pod="default/kbench-deployment-oid-0-tid-1-db946cf6f-klg8p"
2023-09-03T06:43:24.762122248+02:00 stderr F I0903 04:43:24.760602       1 scheduling_queue.go:1133] "About to try and schedule pod" pod="default/kbench-deployment-oid-0-tid-1-778f5d498c-lprgw"
2023-09-03T06:43:24.788084323+02:00 stderr F I0903 04:43:24.787878       1 round_trippers.go:553] POST https://192.168.100.1:6443/api/v1/namespaces/default/pods/kbench-deployment-oid-0-tid-1-778f5d498c-lprgw/binding 201 Created in 20 milliseconds
2023-09-03T06:43:49.131472741+02:00 stderr F I0903 04:43:49.131130       1 round_trippers.go:553] PUT https://192.168.100.1:6443/apis/coordination.k8s.io/v1/namespaces/kube-system/leases/kube-scheduler?timeout=5s 200 OK in 8 milliseconds
2023-09-03T06:43:55.231996506+02:00 stderr F I0903 04:43:55.231608       1 httplog.go:132] "HTTP" verb="GET" URI="/metrics" latency="10.212946ms" userAgent="Prometheus/2.46.0" audit-ID="" srcIP="192.168.100.20:15612" resp=200
2023-09-03T06:43:37.022726892+02:00 stderr F I0903 04:43:37.022528       1 round_trippers.go:553] PUT https://192.168.100.1:6443/apis/coordination.k8s.io/v1/namespaces/kube-system/leases/kube-scheduler?timeout=5s 200 OK in 8 milliseconds
2023-09-03T06:43:38.433890973+02:00 stderr F I0903 04:43:38.433712       1 default_binder.go:53] "Attempting to bind pod to node" pod="default/kbench-deployment-oid-0-tid-1-db946cf6f-klg8p" node="w03"
2023-09-03T06:43:36.524832148+02:00 stderr F I0903 04:43:36.524699       1 default_binder.go:53] "Attempting to bind pod to node" pod="default/kbench-deployment-oid-0-tid-0-bdb979454-7kgzf" node="w03"
2023-09-03T06:43:36.561903001+02:00 stderr F I0903 04:43:36.561499       1 eventhandlers.go:206] "Update event for scheduled pod" pod="default/kbench-deployment-oid-0-tid-1-778f5d498c-jlfsl"
2023-09-03T06:43:40.075583501+02:00 stderr F I0903 04:43:40.074074       1 schedule_one.go:80] "Attempting to schedule pod" pod="default/kbench-deployment-oid-0-tid-1-db946cf6f-p52sk"
2023-09-03T06:43:37.623272186+02:00 stderr F I0903 04:43:37.623041       1 eventhandlers.go:206] "Update event for scheduled pod" pod="default/kbench-deployment-oid-0-tid-1-778f5d498c-jlfsl"
2023-09-03T06:43:46.556409871+02:00 stderr F I0903 04:43:46.555544       1 eventhandlers.go:118] "Add event for unscheduled pod" pod="default/kbench-deployment-oid-0-tid-0-bdb979454-pgxqv"
2023-09-03T06:44:08.806011498+02:00 stderr F I0903 04:44:08.805469       1 eventhandlers.go:231] "Delete event for scheduled pod" pod="default/kbench-deployment-oid-0-tid-1-778f5d498c-cccvv"
2023-09-03T06:43:40.075557914+02:00 stderr F I0903 04:43:40.074055       1 scheduling_queue.go:1133] "About to try and schedule pod" pod="default/kbench-deployment-oid-0-tid-1-db946cf6f-p52sk"
2023-09-03T06:43:24.742528128+02:00 stderr F I0903 04:43:24.742329       1 httplog.go:132] "HTTP" verb="GET" URI="/healthz" latency="170.239µs" userAgent="kube-probe/1.27" audit-ID="" srcIP="127.0.0.1:42586" resp=200
2023-08-25T21:06:29.126759582+02:00 stderr F I0825 19:06:29.126606       1 default_binder.go:53] "Attempting to bind pod to node" pod="default/kbench-deployment-oid-0-tid-1-778f5d498c-m84zn" node="w02"
2023-08-25T21:06:44.509582851+02:00 stderr F I0825 19:06:44.509366       1 leaderelection.go:276] successfully renewed lease kube-system/kube-scheduler
2023-08-25T21:06:22.416428852+02:00 stderr F I0825 19:06:22.415806       1 eventhandlers.go:206] "Update event for scheduled pod" pod="kube-system/coredns-5d78c9869d-rtbl9"
2023-08-25T21:06:29.144194452+02:00 stderr F I0825 19:06:29.144031       1 round_trippers.go:553] POST https://192.168.100.1:6443/apis/events.k8s.io/v1/namespaces/default/events 201 Created in 19 milliseconds
2023-08-25T21:06:44.498873815+02:00 stderr F I0825 19:06:44.498627       1 round_trippers.go:553] GET https://192.168.100.1:6443/apis/coordination.k8s.io/v1/namespaces/kube-system/leases/kube-scheduler?timeout=5s 200 OK in 5 milliseconds
2023-08-25T21:06:29.146011382+02:00 stderr F I0825 19:06:29.145853       1 schedule_one.go:252] "Successfully bound pod to node" pod="default/kbench-deployment-oid-0-tid-1-778f5d498c-m84zn" node="w02" evaluatedNodes=5 feasibleNodes=3
2023-08-25T21:06:58.62548622+02:00 stderr F I0825 19:06:58.625298       1 leaderelection.go:276] successfully renewed lease kube-system/kube-scheduler
2023-08-25T21:06:52.565954831+02:00 stderr F I0825 19:06:52.565739       1 round_trippers.go:553] GET https://192.168.100.1:6443/apis/coordination.k8s.io/v1/namespaces/kube-system/leases/kube-scheduler?timeout=5s 200 OK in 5 milliseconds
2023-08-25T21:06:29.173888318+02:00 stderr F I0825 19:06:29.173775       1 eventhandlers.go:206] "Update event for scheduled pod" pod="default/kbench-deployment-oid-0-tid-1-778f5d498c-m84zn"
2023-08-25T21:06:29.073408462+02:00 stderr F I0825 19:06:29.073319       1 default_binder.go:53] "Attempting to bind pod to node" pod="default/kbench-deployment-oid-0-tid-0-bdb979454-2twx7" node="w01"
2023-08-25T21:06:29.1579161+02:00 stderr F I0825 19:06:29.157812       1 round_trippers.go:553] POST https://192.168.100.1:6443/apis/events.k8s.io/v1/namespaces/default/events 201 Created in 11 milliseconds
2023-08-25T21:06:30.381159695+02:00 stderr F I0825 19:06:30.381023       1 pathrecorder.go:241] kube-scheduler: "/metrics" satisfied by exact match
2023-08-25T21:06:30.158191675+02:00 stderr F I0825 19:06:30.158043       1 eventhandlers.go:206] "Update event for scheduled pod" pod="default/kbench-deployment-oid-0-tid-2-cc4784d96-fwmr8"
2023-08-25T21:06:54.388015725+02:00 stderr F I0825 19:06:54.387580       1 pathrecorder.go:241] kube-scheduler: "/metrics" satisfied by exact match
2023-08-25T21:06:24.378038565+02:00 stderr F I0825 19:06:24.377791       1 httplog.go:132] "HTTP" verb="GET" URI="/metrics" latency="7.894801ms" userAgent="Prometheus/2.46.0" audit-ID="" srcIP="192.168.100.20:38595" resp=200
2023-08-25T21:06:29.121650234+02:00 stderr F I0825 19:06:29.121490       1 cache.go:401] "Finished binding for pod, can be expired" podKey="a296a173-dd63-463c-ba00-f8578ac3de56" pod="default/kbench-deployment-oid-0-tid-2-cc4784d96-ls29s"
2023-08-25T21:06:29.124458653+02:00 stderr F I0825 19:06:29.124254       1 scheduling_queue.go:1133] "About to try and schedule pod" pod="default/kbench-deployment-oid-0-tid-1-778f5d498c-m84zn"
2023-08-25T21:06:24.327002942+02:00 stderr F I0825 19:06:24.326608       1 round_trippers.go:553] GET https://192.168.100.1:6443/apis/coordination.k8s.io/v1/namespaces/kube-system/leases/kube-scheduler?timeout=5s 200 OK in 5 milliseconds
2023-08-25T21:06:30.39765167+02:00 stderr F I0825 19:06:30.397370       1 httplog.go:132] "HTTP" verb="GET" URI="/metrics" latency="27.993506ms" userAgent="Prometheus/2.46.0" audit-ID="" srcIP="192.168.100.20:38595" resp=200
2023-08-25T21:07:07.135982779+02:00 stderr F I0825 19:07:07.135600       1 eventhandlers.go:206] "Update event for scheduled pod" pod="default/kbench-deployment-oid-0-tid-0-bdb979454-692lh"
2023-08-25T21:06:42.492258248+02:00 stderr F I0825 19:06:42.492105       1 leaderelection.go:276] successfully renewed lease kube-system/kube-scheduler
2023-08-25T21:06:57.371219765+02:00 stderr F I0825 19:06:57.370957       1 pathrecorder.go:241] kube-scheduler: "/metrics" satisfied by exact match
2023-08-25T21:06:29.122141334+02:00 stderr F I0825 19:06:29.122006       1 schedule_one.go:252] "Successfully bound pod to node" pod="default/kbench-deployment-oid-0-tid-2-cc4784d96-ls29s" node="w02" evaluatedNodes=5 feasibleNodes=3
2023-08-25T21:06:30.701307591+02:00 stderr F I0825 19:06:30.700698       1 eventhandlers.go:206] "Update event for scheduled pod" pod="default/kbench-deployment-oid-0-tid-2-cc4784d96-ls29s"
2023-08-25T21:06:27.3795792+02:00 stderr F I0825 19:06:27.379355       1 httplog.go:132] "HTTP" verb="GET" URI="/metrics" latency="10.979037ms" userAgent="Prometheus/2.46.0" audit-ID="" srcIP="192.168.100.20:38595" resp=200
2023-08-25T21:06:54.378737135+02:00 stderr F I0825 19:06:54.378434       1 round_trippers.go:553] POST https://192.168.100.1:6443/apis/authentication.k8s.io/v1/tokenreviews 201 Created in 7 milliseconds
2023-08-25T21:06:29.096847289+02:00 stderr F I0825 19:06:29.096809       1 scheduling_queue.go:419] "Pod moved to an internal scheduling queue" pod="default/kbench-deployment-oid-0-tid-2-cc4784d96-fwmr8" event="PodAdd" queue="Active"
2023-08-25T21:07:00.645034783+02:00 stderr F I0825 19:07:00.644867       1 round_trippers.go:553] PUT https://192.168.100.1:6443/apis/coordination.k8s.io/v1/namespaces/kube-system/leases/kube-scheduler?timeout=5s 200 OK in 9 milliseconds
2023-08-25T21:06:34.409360152+02:00 stderr F I0825 19:06:34.409062       1 round_trippers.go:553] GET https://192.168.100.1:6443/apis/coordination.k8s.io/v1/namespaces/kube-system/leases/kube-scheduler?timeout=5s 200 OK in 4 milliseconds
2023-08-25T21:06:58.624971616+02:00 stderr F I0825 19:06:58.624787       1 round_trippers.go:553] PUT https://192.168.100.1:6443/apis/coordination.k8s.io/v1/namespaces/kube-system/leases/kube-scheduler?timeout=5s 200 OK in 8 milliseconds
2023-08-25T21:06:50.559388895+02:00 stderr F I0825 19:06:50.559114       1 round_trippers.go:553] PUT https://192.168.100.1:6443/apis/coordination.k8s.io/v1/namespaces/kube-system/leases/kube-scheduler?timeout=5s 200 OK in 7 milliseconds
2023-08-25T21:06:39.381545569+02:00 stderr F I0825 19:06:39.381082       1 httplog.go:132] "HTTP" verb="GET" URI="/metrics" latency="11.50479ms" userAgent="Prometheus/2.46.0" audit-ID="" srcIP="192.168.100.20:38595" resp=200
2023-08-25T21:06:29.113634671+02:00 stderr F I0825 19:06:29.113496       1 round_trippers.go:553] POST https://192.168.100.1:6443/apis/events.k8s.io/v1/namespaces/default/events 201 Created in 22 milliseconds
2023-08-25T21:06:29.100398901+02:00 stderr F I0825 19:06:29.099674       1 schedule_one.go:252] "Successfully bound pod to node" pod="default/kbench-deployment-oid-0-tid-1-778f5d498c-cj26m" node="w03" evaluatedNodes=5 feasibleNodes=3
2023-08-25T21:06:30.386816523+02:00 stderr F I0825 19:06:30.386610       1 round_trippers.go:553] PUT https://192.168.100.1:6443/apis/coordination.k8s.io/v1/namespaces/kube-system/leases/kube-scheduler?timeout=5s 200 OK in 7 milliseconds
2023-08-25T21:06:30.300157119+02:00 stderr F I0825 19:06:30.300023       1 eventhandlers.go:206] "Update event for scheduled pod" pod="default/kbench-deployment-oid-0-tid-1-778f5d498c-cj26m"
2023-08-25T21:07:06.691162253+02:00 stderr F I0825 19:07:06.690763       1 round_trippers.go:553] GET https://192.168.100.1:6443/apis/coordination.k8s.io/v1/namespaces/kube-system/leases/kube-scheduler?timeout=5s 200 OK in 5 milliseconds
2023-08-25T21:06:29.124115183+02:00 stderr F I0825 19:06:29.123406       1 eventhandlers.go:118] "Add event for unscheduled pod" pod="default/kbench-deployment-oid-0-tid-1-778f5d498c-m84zn"
2023-08-25T21:06:29.100394333+02:00 stderr F I0825 19:06:29.099645       1 cache.go:401] "Finished binding for pod, can be expired" podKey="02388b3a-f6a4-45a9-8374-6374cdb8d30f" pod="default/kbench-deployment-oid-0-tid-1-778f5d498c-cj26m"
2023-08-25T21:06:29.080001822+02:00 stderr F I0825 19:06:29.079712       1 default_binder.go:53] "Attempting to bind pod to node" pod="default/kbench-deployment-oid-0-tid-1-778f5d498c-cj26m" node="w03"
2023-08-25T21:06:40.465325687+02:00 stderr F I0825 19:06:40.465083       1 round_trippers.go:553] GET https://192.168.100.1:6443/apis/coordination.k8s.io/v1/namespaces/kube-system/leases/kube-scheduler?timeout=5s 200 OK in 5 milliseconds
2023-08-25T21:06:29.146515295+02:00 stderr F I0825 19:06:29.146416       1 eventhandlers.go:161] "Delete event for unscheduled pod" pod="default/kbench-deployment-oid-0-tid-0-bdb979454-692lh"
2023-08-25T21:06:38.61749044+02:00 stderr F I0825 19:06:38.617155       1 pathrecorder.go:241] kube-scheduler: "/healthz" satisfied by exact match
2023-08-25T21:06:36.423885168+02:00 stderr F I0825 19:06:36.423539       1 round_trippers.go:553] GET https://192.168.100.1:6443/apis/coordination.k8s.io/v1/namespaces/kube-system/leases/kube-scheduler?timeout=5s 200 OK in 4 milliseconds
2023-08-25T21:06:36.432851817+02:00 stderr F I0825 19:06:36.432745       1 round_trippers.go:553] PUT https://192.168.100.1:6443/apis/coordination.k8s.io/v1/namespaces/kube-system/leases/kube-scheduler?timeout=5s 200 OK in 8 milliseconds
2023-08-25T21:06:38.440173668+02:00 stderr F I0825 19:06:38.439843       1 round_trippers.go:553] GET https://192.168.100.1:6443/apis/coordination.k8s.io/v1/namespaces/kube-system/leases/kube-scheduler?timeout=5s 200 OK in 3 milliseconds
2023-08-25T21:06:29.129327107+02:00 stderr F I0825 19:06:29.129181       1 default_binder.go:53] "Attempting to bind pod to node" pod="default/kbench-deployment-oid-0-tid-0-bdb979454-692lh" node="w03"
2023-08-25T21:06:29.078289937+02:00 stderr F I0825 19:06:29.078234       1 scheduling_queue.go:419] "Pod moved to an internal scheduling queue" pod="default/kbench-deployment-oid-0-tid-1-778f5d498c-cj26m" event="PodAdd" queue="Active"
2023-08-25T21:06:29.090709559+02:00 stderr F I0825 19:06:29.090470       1 schedule_one.go:252] "Successfully bound pod to node" pod="default/kbench-deployment-oid-0-tid-0-bdb979454-2twx7" node="w01" evaluatedNodes=5 feasibleNodes=3
2023-08-25T21:06:29.143729286+02:00 stderr F I0825 19:06:29.143564       1 round_trippers.go:553] POST https://192.168.100.1:6443/api/v1/namespaces/default/pods/kbench-deployment-oid-0-tid-1-778f5d498c-m84zn/binding 201 Created in 16 milliseconds
2023-08-25T21:06:28.61072665+02:00 stderr F I0825 19:06:28.610274       1 httplog.go:132] "HTTP" verb="GET" URI="/healthz" latency="453.806µs" userAgent="kube-probe/1.27" audit-ID="" srcIP="127.0.0.1:43814" resp=200
2023-08-25T21:06:30.386902132+02:00 stderr F I0825 19:06:30.386793       1 leaderelection.go:276] successfully renewed lease kube-system/kube-scheduler
2023-08-25T21:06:32.393455127+02:00 stderr F I0825 19:06:32.393159       1 round_trippers.go:553] GET https://192.168.100.1:6443/apis/coordination.k8s.io/v1/namespaces/kube-system/leases/kube-scheduler?timeout=5s 200 OK in 4 milliseconds
2023-08-25T21:06:24.37063561+02:00 stderr F I0825 19:06:24.370364       1 pathrecorder.go:241] kube-scheduler: "/metrics" satisfied by exact match
2023-08-25T21:06:28.361138492+02:00 stderr F I0825 19:06:28.360849       1 round_trippers.go:553] GET https://192.168.100.1:6443/apis/coordination.k8s.io/v1/namespaces/kube-system/leases/kube-scheduler?timeout=5s 200 OK in 5 milliseconds
2023-08-25T21:06:29.078281287+02:00 stderr F I0825 19:06:29.078188       1 eventhandlers.go:118] "Add event for unscheduled pod" pod="default/kbench-deployment-oid-0-tid-1-778f5d498c-cj26m"
2023-08-25T21:06:48.610783673+02:00 stderr F I0825 19:06:48.610544       1 httplog.go:132] "HTTP" verb="GET" URI="/healthz" latency="138.962µs" userAgent="kube-probe/1.27" audit-ID="" srcIP="127.0.0.1:60074" resp=200
2023-08-25T21:06:54.582344029+02:00 stderr F I0825 19:06:54.582104       1 round_trippers.go:553] GET https://192.168.100.1:6443/apis/coordination.k8s.io/v1/namespaces/kube-system/leases/kube-scheduler?timeout=5s 200 OK in 6 milliseconds
2023-08-25T21:06:45.385658831+02:00 stderr F I0825 19:06:45.385407       1 httplog.go:132] "HTTP" verb="GET" URI="/metrics" latency="16.584932ms" userAgent="Prometheus/2.46.0" audit-ID="" srcIP="192.168.100.20:38595" resp=200
2023-08-25T21:06:29.110019404+02:00 stderr F I0825 19:06:29.109896       1 eventhandlers.go:186] "Add event for scheduled pod" pod="default/kbench-deployment-oid-0-tid-1-778f5d498c-cj26m"
2023-08-25T21:06:29.096858565+02:00 stderr F I0825 19:06:29.096834       1 scheduling_queue.go:1133] "About to try and schedule pod" pod="default/kbench-deployment-oid-0-tid-2-cc4784d96-fwmr8"
2023-08-25T21:06:22.653701901+02:00 stderr F I0825 19:06:22.653496       1 eventhandlers.go:206] "Update event for scheduled pod" pod="kube-system/coredns-7db47766f6-6726c"
2023-08-25T21:06:24.339259948+02:00 stderr F I0825 19:06:24.339134       1 leaderelection.go:276] successfully renewed lease kube-system/kube-scheduler
2023-08-25T21:06:54.387021861+02:00 stderr F I0825 19:06:54.386802       1 round_trippers.go:553] POST https://192.168.100.1:6443/apis/authorization.k8s.io/v1/subjectaccessreviews?timeout=10s 201 Created in 7 milliseconds
2023-08-25T21:06:30.680075287+02:00 stderr F I0825 19:06:30.679745       1 eventhandlers.go:206] "Update event for scheduled pod" pod="default/kbench-deployment-oid-0-tid-1-778f5d498c-m84zn"
2023-08-25T21:06:45.369328621+02:00 stderr F I0825 19:06:45.369029       1 pathrecorder.go:241] kube-scheduler: "/metrics" satisfied by exact match
2023-08-25T21:07:00.634762445+02:00 stderr F I0825 19:07:00.634483       1 round_trippers.go:553] GET https://192.168.100.1:6443/apis/coordination.k8s.io/v1/namespaces/kube-system/leases/kube-scheduler?timeout=5s 200 OK in 7 milliseconds
2023-08-25T21:06:26.354108339+02:00 stderr F I0825 19:06:26.353874       1 round_trippers.go:553] PUT https://192.168.100.1:6443/apis/coordination.k8s.io/v1/namespaces/kube-system/leases/kube-scheduler?timeout=5s 200 OK in 7 milliseconds
2023-08-25T21:06:22.319673998+02:00 stderr F I0825 19:06:22.319533       1 round_trippers.go:553] PUT https://192.168.100.1:6443/apis/coordination.k8s.io/v1/namespaces/kube-system/leases/kube-scheduler?timeout=5s 200 OK in 8 milliseconds
2023-08-25T21:06:42.380432708+02:00 stderr F I0825 19:06:42.380283       1 pathrecorder.go:241] kube-scheduler: "/metrics" satisfied by exact match
2023-08-25T21:06:29.077653843+02:00 stderr F I0825 19:06:29.077559       1 scheduling_queue.go:419] "Pod moved to an internal scheduling queue" pod="default/kbench-deployment-oid-0-tid-2-cc4784d96-ls29s" event="PodAdd" queue="Active"
2023-08-25T21:06:28.610456373+02:00 stderr F I0825 19:06:28.609863       1 pathrecorder.go:241] kube-scheduler: "/healthz" satisfied by exact match
2023-08-25T21:06:50.551667898+02:00 stderr F I0825 19:06:50.551460       1 round_trippers.go:553] GET https://192.168.100.1:6443/apis/coordination.k8s.io/v1/namespaces/kube-system/leases/kube-scheduler?timeout=5s 200 OK in 4 milliseconds
2023-08-25T21:07:03.382600351+02:00 stderr F I0825 19:07:03.382212       1 httplog.go:132] "HTTP" verb="GET" URI="/metrics" latency="12.511891ms" userAgent="Prometheus/2.46.0" audit-ID="" srcIP="192.168.100.20:38595" resp=200
2023-08-25T21:06:26.346200529+02:00 stderr F I0825 19:06:26.345590       1 round_trippers.go:553] GET https://192.168.100.1:6443/apis/coordination.k8s.io/v1/namespaces/kube-system/leases/kube-scheduler?timeout=5s 200 OK in 5 milliseconds
2023-08-25T21:06:32.402222167+02:00 stderr F I0825 19:06:32.402058       1 leaderelection.go:276] successfully renewed lease kube-system/kube-scheduler
2023-08-25T21:06:27.368905564+02:00 stderr F I0825 19:06:27.368501       1 pathrecorder.go:241] kube-scheduler: "/metrics" satisfied by exact match
2023-08-25T21:06:29.126753494+02:00 stderr F I0825 19:06:29.126520       1 schedule_one.go:80] "Attempting to schedule pod" pod="default/kbench-deployment-oid-0-tid-0-bdb979454-692lh"
2023-08-25T21:06:59.111027155+02:00 stderr F I0825 19:06:59.110761       1 eventhandlers.go:206] "Update event for scheduled pod" pod="default/kbench-deployment-oid-0-tid-1-778f5d498c-m84zn"
2023-08-25T21:06:57.38459041+02:00 stderr F I0825 19:06:57.384278       1 httplog.go:132] "HTTP" verb="GET" URI="/metrics" latency="13.465305ms" userAgent="Prometheus/2.46.0" audit-ID="" srcIP="192.168.100.20:38595" resp=200
2023-08-25T21:06:38.61781308+02:00 stderr F I0825 19:06:38.617593       1 httplog.go:132] "HTTP" verb="GET" URI="/healthz" latency="471.616µs" userAgent="kube-probe/1.27" audit-ID="" srcIP="127.0.0.1:33814" resp=200
2023-08-25T21:06:52.574147819+02:00 stderr F I0825 19:06:52.573868       1 round_trippers.go:553] PUT https://192.168.100.1:6443/apis/coordination.k8s.io/v1/namespaces/kube-system/leases/kube-scheduler?timeout=5s 200 OK in 7 milliseconds
2023-08-25T21:06:30.281302743+02:00 stderr F I0825 19:06:30.281059       1 eventhandlers.go:206] "Update event for scheduled pod" pod="default/kbench-deployment-oid-0-tid-0-bdb979454-692lh"
2023-08-25T21:06:56.609782245+02:00 stderr F I0825 19:06:56.609516       1 round_trippers.go:553] PUT https://192.168.100.1:6443/apis/coordination.k8s.io/v1/namespaces/kube-system/leases/kube-scheduler?timeout=5s 200 OK in 10 milliseconds
2023-08-25T21:06:48.545915133+02:00 stderr F I0825 19:06:48.545678       1 leaderelection.go:276] successfully renewed lease kube-system/kube-scheduler
2023-08-25T21:07:07.153459216+02:00 stderr F I0825 19:07:07.153087       1 eventhandlers.go:206] "Update event for scheduled pod" pod="default/kbench-deployment-oid-0-tid-1-778f5d498c-m84zn"
2023-08-25T21:06:48.545570471+02:00 stderr F I0825 19:06:48.545454       1 round_trippers.go:553] PUT https://192.168.100.1:6443/apis/coordination.k8s.io/v1/namespaces/kube-system/leases/kube-scheduler?timeout=5s 200 OK in 8 milliseconds
2023-08-25T21:06:46.521586488+02:00 stderr F I0825 19:06:46.521388       1 round_trippers.go:553] GET https://192.168.100.1:6443/apis/coordination.k8s.io/v1/namespaces/kube-system/leases/kube-scheduler?timeout=5s 200 OK in 5 milliseconds
2023-08-25T21:06:48.53668917+02:00 stderr F I0825 19:06:48.536283       1 round_trippers.go:553] GET https://192.168.100.1:6443/apis/coordination.k8s.io/v1/namespaces/kube-system/leases/kube-scheduler?timeout=5s 200 OK in 4 milliseconds
2023-08-25T21:06:29.124130237+02:00 stderr F I0825 19:06:29.124004       1 scheduling_queue.go:419] "Pod moved to an internal scheduling queue" pod="default/kbench-deployment-oid-0-tid-1-778f5d498c-m84zn" event="PodAdd" queue="Active"
2023-08-25T21:06:29.118941301+02:00 stderr F I0825 19:06:29.117007       1 eventhandlers.go:161] "Delete event for unscheduled pod" pod="default/kbench-deployment-oid-0-tid-2-cc4784d96-ls29s"
2023-08-25T21:06:28.372975207+02:00 stderr F I0825 19:06:28.372504       1 round_trippers.go:553] PUT https://192.168.100.1:6443/apis/coordination.k8s.io/v1/namespaces/kube-system/leases/kube-scheduler?timeout=5s 200 OK in 11 milliseconds
2023-08-25T21:06:58.61139095+02:00 stderr F I0825 19:06:58.611018       1 pathrecorder.go:241] kube-scheduler: "/healthz" satisfied by exact match
2023-08-25T21:06:29.096866603+02:00 stderr F I0825 19:06:29.096843       1 schedule_one.go:80] "Attempting to schedule pod" pod="default/kbench-deployment-oid-0-tid-2-cc4784d96-fwmr8"
2023-08-25T21:06:30.374303388+02:00 stderr F I0825 19:06:30.374115       1 round_trippers.go:553] POST https://192.168.100.1:6443/apis/authentication.k8s.io/v1/tokenreviews 201 Created in 4 milliseconds
2023-08-25T21:06:58.616480483+02:00 stderr F I0825 19:06:58.616046       1 round_trippers.go:553] GET https://192.168.100.1:6443/apis/coordination.k8s.io/v1/namespaces/kube-system/leases/kube-scheduler?timeout=5s 200 OK in 5 milliseconds
2023-08-25T21:06:29.079043436+02:00 stderr F I0825 19:06:29.078792       1 scheduling_queue.go:1133] "About to try and schedule pod" pod="default/kbench-deployment-oid-0-tid-1-778f5d498c-cj26m"
2023-08-25T21:06:34.417795397+02:00 stderr F I0825 19:06:34.417697       1 leaderelection.go:276] successfully renewed lease kube-system/kube-scheduler
2023-08-25T21:06:29.153183719+02:00 stderr F I0825 19:06:29.152920       1 eventhandlers.go:206] "Update event for scheduled pod" pod="default/kbench-deployment-oid-0-tid-2-cc4784d96-ls29s"
2023-08-25T21:07:07.191844486+02:00 stderr F I0825 19:07:07.191607       1 eventhandlers.go:231] "Delete event for scheduled pod" pod="default/kbench-deployment-oid-0-tid-1-778f5d498c-cj26m"
2023-08-25T21:07:06.396250794+02:00 stderr F I0825 19:07:06.395623       1 httplog.go:132] "HTTP" verb="GET" URI="/metrics" latency="25.336769ms" userAgent="Prometheus/2.46.0" audit-ID="" srcIP="192.168.100.20:38595" resp=200
2023-08-25T21:06:29.145993526+02:00 stderr F I0825 19:06:29.145811       1 cache.go:401] "Finished binding for pod, can be expired" podKey="0ae963d5-3019-4b3a-904b-e1ec789e416d" pod="default/kbench-deployment-oid-0-tid-1-778f5d498c-m84zn"
2023-08-25T21:06:42.483317757+02:00 stderr F I0825 19:06:42.483042       1 round_trippers.go:553] GET https://192.168.100.1:6443/apis/coordination.k8s.io/v1/namespaces/kube-system/leases/kube-scheduler?timeout=5s 200 OK in 4 milliseconds
2023-08-25T21:06:29.100381619+02:00 stderr F I0825 19:06:29.099577       1 round_trippers.go:553] POST https://192.168.100.1:6443/api/v1/namespaces/default/pods/kbench-deployment-oid-0-tid-1-778f5d498c-cj26m/binding 201 Created in 19 milliseconds
2023-08-25T21:06:30.379158806+02:00 stderr F I0825 19:06:30.378960       1 round_trippers.go:553] GET https://192.168.100.1:6443/apis/coordination.k8s.io/v1/namespaces/kube-system/leases/kube-scheduler?timeout=5s 200 OK in 5 milliseconds
2023-08-25T21:07:07.178059015+02:00 stderr F I0825 19:07:07.177798       1 eventhandlers.go:231] "Delete event for scheduled pod" pod="default/kbench-deployment-oid-0-tid-0-bdb979454-692lh"
2023-08-25T21:06:29.144127759+02:00 stderr F I0825 19:06:29.143749       1 round_trippers.go:553] POST https://192.168.100.1:6443/api/v1/namespaces/default/pods/kbench-deployment-oid-0-tid-0-bdb979454-692lh/binding 201 Created in 14 milliseconds
2023-08-25T21:06:29.072879746+02:00 stderr F I0825 19:06:29.072593       1 eventhandlers.go:118] "Add event for unscheduled pod" pod="default/kbench-deployment-oid-0-tid-0-bdb979454-2twx7"
2023-08-25T21:06:52.574453946+02:00 stderr F I0825 19:06:52.574231       1 leaderelection.go:276] successfully renewed lease kube-system/kube-scheduler
2023-08-25T21:06:29.077865291+02:00 stderr F I0825 19:06:29.077628       1 scheduling_queue.go:1133] "About to try and schedule pod" pod="default/kbench-deployment-oid-0-tid-2-cc4784d96-ls29s"
2023-08-25T21:06:44.50951994+02:00 stderr F I0825 19:06:44.509199       1 round_trippers.go:553] PUT https://192.168.100.1:6443/apis/coordination.k8s.io/v1/namespaces/kube-system/leases/kube-scheduler?timeout=5s 200 OK in 10 milliseconds
2023-08-25T21:06:29.096839129+02:00 stderr F I0825 19:06:29.096766       1 eventhandlers.go:118] "Add event for unscheduled pod" pod="default/kbench-deployment-oid-0-tid-2-cc4784d96-fwmr8"
2023-08-25T21:06:24.339240358+02:00 stderr F I0825 19:06:24.338993       1 round_trippers.go:553] PUT https://192.168.100.1:6443/apis/coordination.k8s.io/v1/namespaces/kube-system/leases/kube-scheduler?timeout=5s 200 OK in 11 milliseconds
2023-08-25T21:07:04.669189289+02:00 stderr F I0825 19:07:04.668899       1 round_trippers.go:553] GET https://192.168.100.1:6443/apis/coordination.k8s.io/v1/namespaces/kube-system/leases/kube-scheduler?timeout=5s 200 OK in 5 milliseconds
2023-08-25T21:06:36.385240602+02:00 stderr F I0825 19:06:36.384986       1 httplog.go:132] "HTTP" verb="GET" URI="/metrics" latency="16.044677ms" userAgent="Prometheus/2.46.0" audit-ID="" srcIP="192.168.100.20:38595" resp=200
2023-08-25T21:06:29.090591101+02:00 stderr F I0825 19:06:29.090369       1 cache.go:401] "Finished binding for pod, can be expired" podKey="8ca9ec6e-1785-468d-8087-54a1f656a284" pod="default/kbench-deployment-oid-0-tid-0-bdb979454-2twx7"
2023-08-25T21:06:29.138219434+02:00 stderr F I0825 19:06:29.138070       1 round_trippers.go:553] POST https://192.168.100.1:6443/apis/events.k8s.io/v1/namespaces/default/events 201 Created in 15 milliseconds
2023-08-25T21:06:40.477168106+02:00 stderr F I0825 19:06:40.476995       1 leaderelection.go:276] successfully renewed lease kube-system/kube-scheduler
2023-08-25T21:07:00.369834823+02:00 stderr F I0825 19:07:00.369463       1 pathrecorder.go:241] kube-scheduler: "/metrics" satisfied by exact match
2023-08-25T21:06:29.072915588+02:00 stderr F I0825 19:06:29.072726       1 scheduling_queue.go:1133] "About to try and schedule pod" pod="default/kbench-deployment-oid-0-tid-0-bdb979454-2twx7"
2023-08-25T21:06:59.104044348+02:00 stderr F I0825 19:06:59.103912       1 eventhandlers.go:206] "Update event for scheduled pod" pod="default/kbench-deployment-oid-0-tid-0-bdb979454-692lh"
2023-08-25T21:06:39.371517222+02:00 stderr F I0825 19:06:39.369735       1 pathrecorder.go:241] kube-scheduler: "/metrics" satisfied by exact match
2023-08-25T21:06:30.380870526+02:00 stderr F I0825 19:06:30.380672       1 round_trippers.go:553] POST https://192.168.100.1:6443/apis/authorization.k8s.io/v1/subjectaccessreviews?timeout=10s 201 Created in 5 milliseconds
2023-08-25T21:06:22.308838382+02:00 stderr F I0825 19:06:22.308465       1 round_trippers.go:553] GET https://192.168.100.1:6443/apis/coordination.k8s.io/v1/namespaces/kube-system/leases/kube-scheduler?timeout=5s 200 OK in 24 milliseconds
2023-08-25T21:07:00.382468314+02:00 stderr F I0825 19:07:00.382110       1 httplog.go:132] "HTTP" verb="GET" URI="/metrics" latency="12.827838ms" userAgent="Prometheus/2.46.0" audit-ID="" srcIP="192.168.100.20:38595" resp=200
2023-08-25T21:06:29.085801304+02:00 stderr F I0825 19:06:29.085649       1 eventhandlers.go:186] "Add event for scheduled pod" pod="default/kbench-deployment-oid-0-tid-0-bdb979454-2twx7"
2023-08-25T21:07:06.37624856+02:00 stderr F I0825 19:07:06.376025       1 round_trippers.go:553] POST https://192.168.100.1:6443/apis/authentication.k8s.io/v1/tokenreviews 201 Created in 5 milliseconds
2023-08-25T21:06:29.169497042+02:00 stderr F I0825 19:06:29.169146       1 eventhandlers.go:206] "Update event for scheduled pod" pod="default/kbench-deployment-oid-0-tid-2-cc4784d96-fwmr8"
2023-08-25T21:06:58.6114351+02:00 stderr F I0825 19:06:58.611152       1 httplog.go:132] "HTTP" verb="GET" URI="/healthz" latency="184.422µs" userAgent="kube-probe/1.27" audit-ID="" srcIP="127.0.0.1:60758" resp=200
2023-08-25T21:06:29.146681525+02:00 stderr F I0825 19:06:29.146571       1 eventhandlers.go:186] "Add event for scheduled pod" pod="default/kbench-deployment-oid-0-tid-0-bdb979454-692lh"
2023-08-25T21:06:28.372990205+02:00 stderr F I0825 19:06:28.372795       1 leaderelection.go:276] successfully renewed lease kube-system/kube-scheduler
2023-08-25T21:07:04.678637837+02:00 stderr F I0825 19:07:04.678431       1 round_trippers.go:553] PUT https://192.168.100.1:6443/apis/coordination.k8s.io/v1/namespaces/kube-system/leases/kube-scheduler?timeout=5s 200 OK in 9 milliseconds
2023-08-25T21:07:07.16024802+02:00 stderr F I0825 19:07:07.159723       1 eventhandlers.go:231] "Delete event for scheduled pod" pod="default/kbench-deployment-oid-0-tid-0-bdb979454-2twx7"
2023-08-25T21:06:22.306628147+02:00 stderr F I0825 19:06:22.306379       1 eventhandlers.go:206] "Update event for scheduled pod" pod="kube-system/coredns-7db47766f6-pwxls"
2023-08-25T21:06:29.124918949+02:00 stderr F I0825 19:06:29.124343       1 eventhandlers.go:161] "Delete event for unscheduled pod" pod="default/kbench-deployment-oid-0-tid-2-cc4784d96-fwmr8"
2023-08-25T21:07:07.212078337+02:00 stderr F I0825 19:07:07.211637       1 eventhandlers.go:231] "Delete event for scheduled pod" pod="default/kbench-deployment-oid-0-tid-2-cc4784d96-fwmr8"
2023-08-25T21:06:29.119822422+02:00 stderr F I0825 19:06:29.119709       1 round_trippers.go:553] POST https://192.168.100.1:6443/api/v1/namespaces/default/pods/kbench-deployment-oid-0-tid-2-cc4784d96-ls29s/binding 201 Created in 40 milliseconds
2023-08-25T21:06:30.177039697+02:00 stderr F I0825 19:06:30.176861       1 eventhandlers.go:206] "Update event for scheduled pod" pod="default/kbench-deployment-oid-0-tid-0-bdb979454-2twx7"
2023-08-25T21:07:07.193961894+02:00 stderr F I0825 19:07:07.193672       1 eventhandlers.go:231] "Delete event for scheduled pod" pod="default/kbench-deployment-oid-0-tid-1-778f5d498c-m84zn"
2023-08-25T21:06:23.052591302+02:00 stderr F I0825 19:06:23.052220       1 eventhandlers.go:206] "Update event for scheduled pod" pod="kube-system/coredns-5d78c9869d-h7grl"
2023-08-25T21:07:07.184293812+02:00 stderr F I0825 19:07:07.184163       1 eventhandlers.go:206] "Update event for scheduled pod" pod="default/kbench-deployment-oid-0-tid-2-cc4784d96-ls29s"
2023-08-25T21:06:29.12321261+02:00 stderr F I0825 19:06:29.123120       1 schedule_one.go:252] "Successfully bound pod to node" pod="default/kbench-deployment-oid-0-tid-2-cc4784d96-fwmr8" node="w01" evaluatedNodes=5 feasibleNodes=3
2023-08-25T21:07:06.700696878+02:00 stderr F I0825 19:07:06.700521       1 leaderelection.go:276] successfully renewed lease kube-system/kube-scheduler
2023-08-25T21:06:29.098086328+02:00 stderr F I0825 19:06:29.097885       1 default_binder.go:53] "Attempting to bind pod to node" pod="default/kbench-deployment-oid-0-tid-2-cc4784d96-fwmr8" node="w01"
2023-08-25T21:06:29.11907735+02:00 stderr F I0825 19:06:29.118963       1 eventhandlers.go:186] "Add event for scheduled pod" pod="default/kbench-deployment-oid-0-tid-2-cc4784d96-ls29s"
2023-08-25T21:06:23.273799853+02:00 stderr F I0825 19:06:23.273599       1 eventhandlers.go:231] "Delete event for scheduled pod" pod="kube-system/coredns-5d78c9869d-h7grl"
2023-08-25T21:07:07.213851667+02:00 stderr F I0825 19:07:07.213699       1 eventhandlers.go:231] "Delete event for scheduled pod" pod="default/kbench-deployment-oid-0-tid-2-cc4784d96-ls29s"
2023-08-25T21:06:38.459184337+02:00 stderr F I0825 19:06:38.459081       1 leaderelection.go:276] successfully renewed lease kube-system/kube-scheduler
2023-08-25T21:06:29.072920102+02:00 stderr F I0825 19:06:29.072737       1 schedule_one.go:80] "Attempting to schedule pod" pod="default/kbench-deployment-oid-0-tid-0-bdb979454-2twx7"
2023-08-25T21:07:06.700671067+02:00 stderr F I0825 19:07:06.700375       1 round_trippers.go:553] PUT https://192.168.100.1:6443/apis/coordination.k8s.io/v1/namespaces/kube-system/leases/kube-scheduler?timeout=5s 200 OK in 9 milliseconds
2023-08-25T21:06:32.401839602+02:00 stderr F I0825 19:06:32.401688       1 round_trippers.go:553] PUT https://192.168.100.1:6443/apis/coordination.k8s.io/v1/namespaces/kube-system/leases/kube-scheduler?timeout=5s 200 OK in 8 milliseconds
2023-08-25T21:07:07.168252439+02:00 stderr F I0825 19:07:07.168097       1 eventhandlers.go:206] "Update event for scheduled pod" pod="default/kbench-deployment-oid-0-tid-2-cc4784d96-fwmr8"
2023-08-25T21:06:22.65134232+02:00 stderr F I0825 19:06:22.651080       1 eventhandlers.go:231] "Delete event for scheduled pod" pod="kube-system/coredns-5d78c9869d-rtbl9"
2023-08-25T21:06:29.123099318+02:00 stderr F I0825 19:06:29.122939       1 round_trippers.go:553] POST https://192.168.100.1:6443/api/v1/namespaces/default/pods/kbench-deployment-oid-0-tid-2-cc4784d96-fwmr8/binding 201 Created in 24 milliseconds
2023-08-25T21:06:29.077880898+02:00 stderr F I0825 19:06:29.077667       1 schedule_one.go:80] "Attempting to schedule pod" pod="default/kbench-deployment-oid-0-tid-2-cc4784d96-ls29s"
2023-08-25T21:06:29.124437591+02:00 stderr F I0825 19:06:29.124294       1 scheduling_queue.go:419] "Pod moved to an internal scheduling queue" pod="default/kbench-deployment-oid-0-tid-0-bdb979454-692lh" event="PodAdd" queue="Active"
2023-08-25T21:06:29.124479439+02:00 stderr F I0825 19:06:29.124423       1 schedule_one.go:80] "Attempting to schedule pod" pod="default/kbench-deployment-oid-0-tid-1-778f5d498c-m84zn"
2023-08-25T21:06:40.476808059+02:00 stderr F I0825 19:06:40.476717       1 round_trippers.go:553] PUT https://192.168.100.1:6443/apis/coordination.k8s.io/v1/namespaces/kube-system/leases/kube-scheduler?timeout=5s 200 OK in 11 milliseconds
2023-08-25T21:06:29.085779456+02:00 stderr F I0825 19:06:29.085607       1 eventhandlers.go:161] "Delete event for unscheduled pod" pod="default/kbench-deployment-oid-0-tid-0-bdb979454-2twx7"
2023-08-25T21:06:42.491747494+02:00 stderr F I0825 19:06:42.491597       1 round_trippers.go:553] PUT https://192.168.100.1:6443/apis/coordination.k8s.io/v1/namespaces/kube-system/leases/kube-scheduler?timeout=5s 200 OK in 8 milliseconds
2023-08-25T21:06:29.079257101+02:00 stderr F I0825 19:06:29.079061       1 default_binder.go:53] "Attempting to bind pod to node" pod="default/kbench-deployment-oid-0-tid-2-cc4784d96-ls29s" node="w02"
2023-08-25T21:06:34.417762933+02:00 stderr F I0825 19:06:34.417525       1 round_trippers.go:553] PUT https://192.168.100.1:6443/apis/coordination.k8s.io/v1/namespaces/kube-system/leases/kube-scheduler?timeout=5s 200 OK in 8 milliseconds
2023-08-25T21:06:48.610757696+02:00 stderr F I0825 19:06:48.610435       1 pathrecorder.go:241] kube-scheduler: "/healthz" satisfied by exact match
2023-08-25T21:06:46.530678241+02:00 stderr F I0825 19:06:46.530473       1 round_trippers.go:553] PUT https://192.168.100.1:6443/apis/coordination.k8s.io/v1/namespaces/kube-system/leases/kube-scheduler?timeout=5s 200 OK in 8 milliseconds
2023-08-25T21:06:42.37445194+02:00 stderr F I0825 19:06:42.374228       1 round_trippers.go:553] POST https://192.168.100.1:6443/apis/authentication.k8s.io/v1/tokenreviews 201 Created in 3 milliseconds
2023-08-25T21:06:22.237838787+02:00 stderr F I0825 19:06:22.237609       1 eventhandlers.go:206] "Update event for scheduled pod" pod="kube-system/coredns-7db47766f6-pwxls"
2023-08-25T21:06:29.149435361+02:00 stderr F I0825 19:06:29.149301       1 eventhandlers.go:206] "Update event for scheduled pod" pod="default/kbench-deployment-oid-0-tid-1-778f5d498c-cj26m"
2023-09-03T06:40:18.884978977+02:00 stderr F I0903 04:40:18.883397       1 eventhandlers.go:206] "Update event for scheduled pod" pod="default/kbench-deployment-oid-0-tid-0-bdb979454-p2w87"
2023-09-03T06:40:40.84414543+02:00 stderr F I0903 04:40:40.843871       1 httplog.go:132] "HTTP" verb="GET" URI="/metrics" latency="13.006692ms" userAgent="Prometheus/2.46.0" audit-ID="" srcIP="192.168.100.20:44855" resp=200
2023-09-03T06:40:18.695623097+02:00 stderr F I0903 04:40:18.695470       1 default_binder.go:53] "Attempting to bind pod to node" pod="default/kbench-deployment-oid-0-tid-1-db946cf6f-v8q66" node="w02"
2023-09-03T06:40:33.928779446+02:00 stderr F I0903 04:40:33.928611       1 round_trippers.go:553] PUT https://192.168.100.1:6443/apis/coordination.k8s.io/v1/namespaces/kube-system/leases/kube-scheduler?timeout=5s 200 OK in 9 milliseconds
2023-09-03T06:40:44.016423118+02:00 stderr F I0903 04:40:44.016194       1 leaderelection.go:276] successfully renewed lease kube-system/kube-scheduler
2023-09-03T06:40:17.335481526+02:00 stderr F I0903 04:40:17.333699       1 cache.go:401] "Finished binding for pod, can be expired" podKey="02520aec-e701-41e3-a9d0-c1614a5db790" pod="default/kbench-deployment-oid-0-tid-1-db946cf6f-gq6lk"
2023-09-03T06:40:46.830774626+02:00 stderr F I0903 04:40:46.830399       1 pathrecorder.go:241] kube-scheduler: "/metrics" satisfied by exact match
2023-09-03T06:40:18.692678997+02:00 stderr F I0903 04:40:18.692599       1 scheduling_queue.go:1133] "About to try and schedule pod" pod="default/kbench-deployment-oid-0-tid-1-db946cf6f-v8q66"
2023-09-03T06:40:17.265716966+02:00 stderr F I0903 04:40:17.265654       1 scheduling_queue.go:419] "Pod moved to an internal scheduling queue" pod="default/kbench-deployment-oid-0-tid-1-778f5d498c-vnwk8" event="PodAdd" queue="Active"
2023-09-03T06:40:55.377011+02:00 stderr F I0903 04:40:55.376734       1 eventhandlers.go:231] "Delete event for scheduled pod" pod="default/kbench-deployment-oid-0-tid-1-db946cf6f-v8q66"
2023-09-03T06:40:17.337691379+02:00 stderr F I0903 04:40:17.337531       1 eventhandlers.go:206] "Update event for scheduled pod" pod="default/kbench-deployment-oid-0-tid-0-bdb979454-xw4m6"
2023-09-03T06:40:17.336781498+02:00 stderr F I0903 04:40:17.333799       1 eventhandlers.go:186] "Add event for scheduled pod" pod="default/kbench-deployment-oid-0-tid-2-cc4784d96-w26gm"
2023-09-03T06:40:17.284252342+02:00 stderr F I0903 04:40:17.282613       1 schedule_one.go:80] "Attempting to schedule pod" pod="default/kbench-deployment-oid-0-tid-0-bdb979454-p2w87"
2023-09-03T06:40:17.298494637+02:00 stderr F I0903 04:40:17.298375       1 default_binder.go:53] "Attempting to bind pod to node" pod="default/kbench-deployment-oid-0-tid-0-bdb979454-p2w87" node="w03"
2023-09-03T06:40:29.890772127+02:00 stderr F I0903 04:40:29.890368       1 leaderelection.go:276] successfully renewed lease kube-system/kube-scheduler
2023-09-03T06:40:17.363889511+02:00 stderr F I0903 04:40:17.362680       1 round_trippers.go:553] POST https://192.168.100.1:6443/apis/events.k8s.io/v1/namespaces/default/events 201 Created in 25 milliseconds
2023-09-03T06:40:35.93454251+02:00 stderr F I0903 04:40:35.934149       1 round_trippers.go:553] GET https://192.168.100.1:6443/apis/coordination.k8s.io/v1/namespaces/kube-system/leases/kube-scheduler?timeout=5s 200 OK in 4 milliseconds
2023-09-03T06:40:17.283030827+02:00 stderr F I0903 04:40:17.281996       1 round_trippers.go:553] POST https://192.168.100.1:6443/api/v1/namespaces/default/pods/kbench-deployment-oid-0-tid-1-778f5d498c-pxt8b/binding 201 Created in 41 milliseconds
2023-09-03T06:40:17.379172942+02:00 stderr F I0903 04:40:17.378371       1 eventhandlers.go:206] "Update event for scheduled pod" pod="default/kbench-deployment-oid-0-tid-1-778f5d498c-vnwk8"
2023-09-03T06:40:40.831431446+02:00 stderr F I0903 04:40:40.831019       1 pathrecorder.go:241] kube-scheduler: "/metrics" satisfied by exact match
2023-09-03T06:40:52.074863192+02:00 stderr F I0903 04:40:52.074484       1 round_trippers.go:553] GET https://192.168.100.1:6443/apis/coordination.k8s.io/v1/namespaces/kube-system/leases/kube-scheduler?timeout=5s 200 OK in 5 milliseconds
2023-09-03T06:40:46.199012839+02:00 stderr F I0903 04:40:46.198818       1 pathrecorder.go:241] kube-scheduler: "/healthz" satisfied by exact match
2023-09-03T06:40:17.291128393+02:00 stderr F I0903 04:40:17.290993       1 eventhandlers.go:118] "Add event for unscheduled pod" pod="default/kbench-deployment-oid-0-tid-1-db946cf6f-gq6lk"
2023-09-03T06:40:50.056541699+02:00 stderr F I0903 04:40:50.056332       1 round_trippers.go:553] GET https://192.168.100.1:6443/apis/coordination.k8s.io/v1/namespaces/kube-system/leases/kube-scheduler?timeout=5s 200 OK in 7 milliseconds
2023-09-03T06:40:17.239501046+02:00 stderr F I0903 04:40:17.239413       1 schedule_one.go:80] "Attempting to schedule pod" pod="default/kbench-deployment-oid-0-tid-2-cc4784d96-5bzns"
2023-09-03T06:40:46.84318259+02:00 stderr F I0903 04:40:46.842996       1 httplog.go:132] "HTTP" verb="GET" URI="/metrics" latency="12.781657ms" userAgent="Prometheus/2.46.0" audit-ID="" srcIP="192.168.100.20:44855" resp=200
2023-09-03T06:40:17.272177009+02:00 stderr F I0903 04:40:17.271123       1 eventhandlers.go:161] "Delete event for unscheduled pod" pod="default/kbench-deployment-oid-0-tid-1-778f5d498c-pxt8b"
2023-09-03T06:40:18.720838561+02:00 stderr F I0903 04:40:18.720654       1 round_trippers.go:553] POST https://192.168.100.1:6443/api/v1/namespaces/default/pods/kbench-deployment-oid-0-tid-1-db946cf6f-v8q66/binding 201 Created in 21 milliseconds
2023-09-03T06:40:31.90977445+02:00 stderr F I0903 04:40:31.909599       1 round_trippers.go:553] PUT https://192.168.100.1:6443/apis/coordination.k8s.io/v1/namespaces/kube-system/leases/kube-scheduler?timeout=5s 200 OK in 10 milliseconds
2023-09-03T06:40:17.336914078+02:00 stderr F I0903 04:40:17.336617       1 schedule_one.go:252] "Successfully bound pod to node" pod="default/kbench-deployment-oid-0-tid-0-bdb979454-p2w87" node="w03" evaluatedNodes=5 feasibleNodes=3
2023-09-03T06:40:17.235448756+02:00 stderr F I0903 04:40:17.235355       1 eventhandlers.go:118] "Add event for unscheduled pod" pod="default/kbench-deployment-oid-0-tid-2-cc4784d96-5bzns"
2023-09-03T06:40:18.587979141+02:00 stderr F I0903 04:40:18.587804       1 eventhandlers.go:206] "Update event for scheduled pod" pod="default/kbench-deployment-oid-0-tid-2-cc4784d96-w26gm"
2023-09-03T06:40:17.235405131+02:00 stderr F I0903 04:40:17.234476       1 scheduling_queue.go:419] "Pod moved to an internal scheduling queue" pod="default/kbench-deployment-oid-0-tid-0-bdb979454-xw4m6" event="PodAdd" queue="Active"
2023-09-03T06:40:15.766761527+02:00 stderr F I0903 04:40:15.766385       1 round_trippers.go:553] GET https://192.168.100.1:6443/apis/coordination.k8s.io/v1/namespaces/kube-system/leases/kube-scheduler?timeout=5s 200 OK in 7 milliseconds
2023-09-03T06:40:17.239488166+02:00 stderr F I0903 04:40:17.239388       1 scheduling_queue.go:1133] "About to try and schedule pod" pod="default/kbench-deployment-oid-0-tid-2-cc4784d96-5bzns"
2023-09-03T06:40:44.016157458+02:00 stderr F I0903 04:40:44.015868       1 round_trippers.go:553] PUT https://192.168.100.1:6443/apis/coordination.k8s.io/v1/namespaces/kube-system/leases/kube-scheduler?timeout=5s 200 OK in 9 milliseconds
2023-09-03T06:40:17.297798241+02:00 stderr F I0903 04:40:17.297527       1 scheduling_queue.go:419] "Pod moved to an internal scheduling queue" pod="default/kbench-deployment-oid-0-tid-1-db946cf6f-gq6lk" event="PodAdd" queue="Active"
2023-09-03T06:40:18.692661747+02:00 stderr F I0903 04:40:18.692510       1 eventhandlers.go:118] "Add event for unscheduled pod" pod="default/kbench-deployment-oid-0-tid-1-db946cf6f-v8q66"
2023-09-03T06:40:17.289096029+02:00 stderr F I0903 04:40:17.288925       1 round_trippers.go:553] POST https://192.168.100.1:6443/api/v1/namespaces/default/pods/kbench-deployment-oid-0-tid-1-778f5d498c-vnwk8/binding 201 Created in 22 milliseconds
2023-09-03T06:40:17.33184224+02:00 stderr F I0903 04:40:17.331589       1 round_trippers.go:553] POST https://192.168.100.1:6443/api/v1/namespaces/default/pods/kbench-deployment-oid-0-tid-1-db946cf6f-gq6lk/binding 201 Created in 32 milliseconds
2023-09-03T06:40:50.068027239+02:00 stderr F I0903 04:40:50.067831       1 leaderelection.go:276] successfully renewed lease kube-system/kube-scheduler
2023-09-03T06:40:17.283691271+02:00 stderr F I0903 04:40:17.283482       1 schedule_one.go:252] "Successfully bound pod to node" pod="default/kbench-deployment-oid-0-tid-1-778f5d498c-pxt8b" node="w03" evaluatedNodes=5 feasibleNodes=3
2023-09-03T06:40:43.851802111+02:00 stderr F I0903 04:40:43.851444       1 httplog.go:132] "HTTP" verb="GET" URI="/metrics" latency="17.750924ms" userAgent="Prometheus/2.46.0" audit-ID="" srcIP="192.168.100.20:44855" resp=200
2023-09-03T06:40:25.848986895+02:00 stderr F I0903 04:40:25.848755       1 round_trippers.go:553] GET https://192.168.100.1:6443/apis/coordination.k8s.io/v1/namespaces/kube-system/leases/kube-scheduler?timeout=5s 200 OK in 7 milliseconds
2023-09-03T06:40:17.336761476+02:00 stderr F I0903 04:40:17.333764       1 eventhandlers.go:161] "Delete event for unscheduled pod" pod="default/kbench-deployment-oid-0-tid-2-cc4784d96-w26gm"
2023-09-03T06:40:17.336789013+02:00 stderr F I0903 04:40:17.333902       1 cache.go:401] "Finished binding for pod, can be expired" podKey="f62eb19c-528c-4ddb-af9a-2563edd7fa91" pod="default/kbench-deployment-oid-0-tid-0-bdb979454-p2w87"
2023-09-03T06:40:55.304566777+02:00 stderr F I0903 04:40:55.304331       1 eventhandlers.go:206] "Update event for scheduled pod" pod="default/kbench-deployment-oid-0-tid-0-bdb979454-p2w87"
2023-09-03T06:40:49.841578011+02:00 stderr F I0903 04:40:49.841245       1 round_trippers.go:553] POST https://192.168.100.1:6443/apis/authorization.k8s.io/v1/subjectaccessreviews?timeout=10s 201 Created in 3 milliseconds
2023-09-03T06:40:17.337670819+02:00 stderr F I0903 04:40:17.337327       1 eventhandlers.go:161] "Delete event for unscheduled pod" pod="default/kbench-deployment-oid-0-tid-0-bdb979454-p2w87"
2023-09-03T06:40:37.951296126+02:00 stderr F I0903 04:40:37.950985       1 round_trippers.go:553] GET https://192.168.100.1:6443/apis/coordination.k8s.io/v1/namespaces/kube-system/leases/kube-scheduler?timeout=5s 200 OK in 5 milliseconds
2023-09-03T06:40:17.333487606+02:00 stderr F I0903 04:40:17.333369       1 cache.go:401] "Finished binding for pod, can be expired" podKey="df13a685-1dc8-42c2-81e3-8b1285ae4d71" pod="default/kbench-deployment-oid-0-tid-2-cc4784d96-w26gm"
2023-09-03T06:40:17.333511868+02:00 stderr F I0903 04:40:17.333424       1 round_trippers.go:553] POST https://192.168.100.1:6443/apis/events.k8s.io/v1/namespaces/default/events 201 Created in 42 milliseconds
2023-09-03T06:40:17.240040017+02:00 stderr F I0903 04:40:17.239901       1 default_binder.go:53] "Attempting to bind pod to node" pod="default/kbench-deployment-oid-0-tid-1-778f5d498c-pxt8b" node="w03"
2023-09-03T06:40:28.832344093+02:00 stderr F I0903 04:40:28.832126       1 pathrecorder.go:241] kube-scheduler: "/metrics" satisfied by exact match
2023-09-03T06:40:16.835289794+02:00 stderr F I0903 04:40:16.834946       1 pathrecorder.go:241] kube-scheduler: "/metrics" satisfied by exact match
2023-09-03T06:40:18.729315696+02:00 stderr F I0903 04:40:18.729162       1 round_trippers.go:553] POST https://192.168.100.1:6443/apis/events.k8s.io/v1/namespaces/default/events 201 Created in 7 milliseconds
2023-09-03T06:40:18.719824355+02:00 stderr F I0903 04:40:18.718495       1 eventhandlers.go:161] "Delete event for unscheduled pod" pod="default/kbench-deployment-oid-0-tid-1-db946cf6f-v8q66"
2023-09-03T06:40:39.983464343+02:00 stderr F I0903 04:40:39.983351       1 leaderelection.go:276] successfully renewed lease kube-system/kube-scheduler
2023-09-03T06:40:18.739281139+02:00 stderr F I0903 04:40:18.738764       1 eventhandlers.go:206] "Update event for scheduled pod" pod="default/kbench-deployment-oid-0-tid-1-db946cf6f-v8q66"
2023-09-03T06:40:13.757609425+02:00 stderr F I0903 04:40:13.757414       1 round_trippers.go:553] PUT https://192.168.100.1:6443/apis/coordination.k8s.io/v1/namespaces/kube-system/leases/kube-scheduler?timeout=5s 200 OK in 9 milliseconds
2023-09-03T06:40:17.298070065+02:00 stderr F I0903 04:40:17.291019       1 eventhandlers.go:186] "Add event for scheduled pod" pod="default/kbench-deployment-oid-0-tid-1-778f5d498c-vnwk8"
2023-09-03T06:40:37.841766612+02:00 stderr F I0903 04:40:37.841608       1 round_trippers.go:553] POST https://192.168.100.1:6443/apis/authorization.k8s.io/v1/subjectaccessreviews?timeout=10s 201 Created in 3 milliseconds
2023-09-03T06:40:18.692673975+02:00 stderr F I0903 04:40:18.692571       1 scheduling_queue.go:419] "Pod moved to an internal scheduling queue" pod="default/kbench-deployment-oid-0-tid-1-db946cf6f-v8q66" event="PodAdd" queue="Active"
2023-09-03T06:40:49.841663973+02:00 stderr F I0903 04:40:49.841542       1 pathrecorder.go:241] kube-scheduler: "/metrics" satisfied by exact match
2023-09-03T06:40:27.863298358+02:00 stderr F I0903 04:40:27.863022       1 round_trippers.go:553] GET https://192.168.100.1:6443/apis/coordination.k8s.io/v1/namespaces/kube-system/leases/kube-scheduler?timeout=5s 200 OK in 5 milliseconds
2023-09-03T06:40:25.856502201+02:00 stderr F I0903 04:40:25.856238       1 round_trippers.go:553] PUT https://192.168.100.1:6443/apis/coordination.k8s.io/v1/namespaces/kube-system/leases/kube-scheduler?timeout=5s 200 OK in 6 milliseconds
2023-09-03T06:40:29.881143032+02:00 stderr F I0903 04:40:29.880797       1 round_trippers.go:553] GET https://192.168.100.1:6443/apis/coordination.k8s.io/v1/namespaces/kube-system/leases/kube-scheduler?timeout=5s 200 OK in 4 milliseconds
2023-09-03T06:40:55.322963224+02:00 stderr F I0903 04:40:55.322359       1 eventhandlers.go:206] "Update event for scheduled pod" pod="default/kbench-deployment-oid-0-tid-1-db946cf6f-gq6lk"
2023-09-03T06:40:54.105882763+02:00 stderr F I0903 04:40:54.105564       1 round_trippers.go:553] PUT https://192.168.100.1:6443/apis/coordination.k8s.io/v1/namespaces/kube-system/leases/kube-scheduler?timeout=5s 200 OK in 7 milliseconds
2023-09-03T06:40:17.27113972+02:00 stderr F I0903 04:40:17.271062       1 round_trippers.go:553] POST https://192.168.100.1:6443/api/v1/namespaces/default/pods/kbench-deployment-oid-0-tid-0-bdb979454-xw4m6/binding 201 Created in 31 milliseconds
2023-09-03T06:40:20.216720997+02:00 stderr F I0903 04:40:20.216179       1 eventhandlers.go:206] "Update event for scheduled pod" pod="default/kbench-deployment-oid-0-tid-1-778f5d498c-vnwk8"
2023-09-03T06:40:54.097392782+02:00 stderr F I0903 04:40:54.097101       1 round_trippers.go:553] GET https://192.168.100.1:6443/apis/coordination.k8s.io/v1/namespaces/kube-system/leases/kube-scheduler?timeout=5s 200 OK in 5 milliseconds
2023-09-03T06:40:17.364520698+02:00 stderr F I0903 04:40:17.362728       1 round_trippers.go:553] POST https://192.168.100.1:6443/apis/events.k8s.io/v1/namespaces/default/events 201 Created in 26 milliseconds
2023-09-03T06:40:47.254871924+02:00 stderr F I0903 04:40:47.254586       1 eventhandlers.go:206] "Update event for scheduled pod" pod="default/kbench-deployment-oid-0-tid-0-bdb979454-p2w87"
2023-09-03T06:40:17.235444318+02:00 stderr F I0903 04:40:17.235317       1 scheduling_queue.go:419] "Pod moved to an internal scheduling queue" pod="default/kbench-deployment-oid-0-tid-1-778f5d498c-pxt8b" event="PodAdd" queue="Active"
2023-09-03T06:40:17.249797259+02:00 stderr F I0903 04:40:17.247449       1 eventhandlers.go:118] "Add event for unscheduled pod" pod="default/kbench-deployment-oid-0-tid-2-cc4784d96-w26gm"
2023-09-03T06:40:21.813149897+02:00 stderr F I0903 04:40:21.812788       1 round_trippers.go:553] GET https://192.168.100.1:6443/apis/coordination.k8s.io/v1/namespaces/kube-system/leases/kube-scheduler?timeout=5s 200 OK in 4 milliseconds
2023-09-03T06:40:23.840308694+02:00 stderr F I0903 04:40:23.839599       1 round_trippers.go:553] PUT https://192.168.100.1:6443/apis/coordination.k8s.io/v1/namespaces/kube-system/leases/kube-scheduler?timeout=5s 200 OK in 10 milliseconds
2023-09-03T06:40:34.844325332+02:00 stderr F I0903 04:40:34.843660       1 httplog.go:132] "HTTP" verb="GET" URI="/metrics" latency="12.390959ms" userAgent="Prometheus/2.46.0" audit-ID="" srcIP="192.168.100.20:44855" resp=200
2023-09-03T06:40:17.336900368+02:00 stderr F I0903 04:40:17.332171       1 round_trippers.go:553] POST https://192.168.100.1:6443/apis/events.k8s.io/v1/namespaces/default/events 201 Created in 52 milliseconds
2023-09-03T06:40:17.24987169+02:00 stderr F I0903 04:40:17.249708       1 schedule_one.go:80] "Attempting to schedule pod" pod="default/kbench-deployment-oid-0-tid-2-cc4784d96-w26gm"
2023-09-03T06:40:33.92905865+02:00 stderr F I0903 04:40:33.928942       1 leaderelection.go:276] successfully renewed lease kube-system/kube-scheduler
2023-09-03T06:40:18.720955644+02:00 stderr F I0903 04:40:18.720781       1 cache.go:401] "Finished binding for pod, can be expired" podKey="767e1256-0b26-4cbe-926e-e123a1d44633" pod="default/kbench-deployment-oid-0-tid-1-db946cf6f-v8q66"
2023-09-03T06:40:18.692685945+02:00 stderr F I0903 04:40:18.692610       1 schedule_one.go:80] "Attempting to schedule pod" pod="default/kbench-deployment-oid-0-tid-1-db946cf6f-v8q66"
2023-09-03T06:40:46.199183112+02:00 stderr F I0903 04:40:46.199059       1 httplog.go:132] "HTTP" verb="GET" URI="/healthz" latency="173.125µs" userAgent="kube-probe/1.27" audit-ID="" srcIP="127.0.0.1:60410" resp=200
2023-09-03T06:40:17.26570767+02:00 stderr F I0903 04:40:17.265618       1 eventhandlers.go:118] "Add event for unscheduled pod" pod="default/kbench-deployment-oid-0-tid-1-778f5d498c-vnwk8"
2023-09-03T06:40:18.617372941+02:00 stderr F I0903 04:40:18.616699       1 eventhandlers.go:206] "Update event for scheduled pod" pod="default/kbench-deployment-oid-0-tid-1-db946cf6f-gq6lk"
2023-09-03T06:40:49.238536351+02:00 stderr F I0903 04:40:49.238165       1 eventhandlers.go:231] "Delete event for scheduled pod" pod="default/kbench-deployment-oid-0-tid-1-778f5d498c-pxt8b"
2023-09-03T06:40:17.266255637+02:00 stderr F I0903 04:40:17.266121       1 eventhandlers.go:161] "Delete event for unscheduled pod" pod="default/kbench-deployment-oid-0-tid-0-bdb979454-xw4m6"
2023-09-03T06:40:21.82144251+02:00 stderr F I0903 04:40:21.821119       1 round_trippers.go:553] PUT https://192.168.100.1:6443/apis/coordination.k8s.io/v1/namespaces/kube-system/leases/kube-scheduler?timeout=5s 200 OK in 8 milliseconds
2023-09-03T06:40:18.643582743+02:00 stderr F I0903 04:40:18.643182       1 eventhandlers.go:206] "Update event for scheduled pod" pod="default/kbench-deployment-oid-0-tid-0-bdb979454-xw4m6"
2023-09-03T06:40:46.023073504+02:00 stderr F I0903 04:40:46.022778       1 round_trippers.go:553] GET https://192.168.100.1:6443/apis/coordination.k8s.io/v1/namespaces/kube-system/leases/kube-scheduler?timeout=5s 200 OK in 5 milliseconds
2023-09-03T06:40:31.898425234+02:00 stderr F I0903 04:40:31.898052       1 round_trippers.go:553] GET https://192.168.100.1:6443/apis/coordination.k8s.io/v1/namespaces/kube-system/leases/kube-scheduler?timeout=5s 200 OK in 5 milliseconds
2023-09-03T06:40:28.844030885+02:00 stderr F I0903 04:40:28.843674       1 httplog.go:132] "HTTP" verb="GET" URI="/metrics" latency="11.651396ms" userAgent="Prometheus/2.46.0" audit-ID="" srcIP="192.168.100.20:44855" resp=200
2023-09-03T06:40:17.290355481+02:00 stderr F I0903 04:40:17.290187       1 eventhandlers.go:186] "Add event for scheduled pod" pod="default/kbench-deployment-oid-0-tid-2-cc4784d96-5bzns"
2023-09-03T06:40:35.944615996+02:00 stderr F I0903 04:40:35.944510       1 leaderelection.go:276] successfully renewed lease kube-system/kube-scheduler
2023-09-03T06:40:46.031994415+02:00 stderr F I0903 04:40:46.031745       1 leaderelection.go:276] successfully renewed lease kube-system/kube-scheduler
2023-09-03T06:40:25.855222422+02:00 stderr F I0903 04:40:25.855050       1 httplog.go:132] "HTTP" verb="GET" URI="/metrics" latency="22.007135ms" userAgent="Prometheus/2.46.0" audit-ID="" srcIP="192.168.100.20:44855" resp=200
2023-09-03T06:40:17.379181042+02:00 stderr F I0903 04:40:17.378745       1 eventhandlers.go:206] "Update event for scheduled pod" pod="default/kbench-deployment-oid-0-tid-0-bdb979454-p2w87"
2023-09-03T06:40:17.341138152+02:00 stderr F I0903 04:40:17.340947       1 eventhandlers.go:161] "Delete event for unscheduled pod" pod="default/kbench-deployment-oid-0-tid-1-db946cf6f-gq6lk"
2023-09-03T06:40:21.821649621+02:00 stderr F I0903 04:40:21.821475       1 leaderelection.go:276] successfully renewed lease kube-system/kube-scheduler
2023-09-03T06:40:17.283015639+02:00 stderr F I0903 04:40:17.278258       1 round_trippers.go:553] POST https://192.168.100.1:6443/api/v1/namespaces/default/pods/kbench-deployment-oid-0-tid-2-cc4784d96-5bzns/binding 201 Created in 29 milliseconds
2023-09-03T06:40:25.843306069+02:00 stderr F I0903 04:40:25.843038       1 round_trippers.go:553] POST https://192.168.100.1:6443/apis/authorization.k8s.io/v1/subjectaccessreviews?timeout=10s 201 Created in 3 milliseconds
2023-09-03T06:40:18.72166381+02:00 stderr F I0903 04:40:18.721164       1 schedule_one.go:252] "Successfully bound pod to node" pod="default/kbench-deployment-oid-0-tid-1-db946cf6f-v8q66" node="w02" evaluatedNodes=5 feasibleNodes=3
2023-09-03T06:40:36.197160075+02:00 stderr F I0903 04:40:36.196823       1 httplog.go:132] "HTTP" verb="GET" URI="/healthz" latency="168.656µs" userAgent="kube-probe/1.27" audit-ID="" srcIP="127.0.0.1:38738" resp=200
2023-09-03T06:40:17.299587508+02:00 stderr F I0903 04:40:17.299430       1 default_binder.go:53] "Attempting to bind pod to node" pod="default/kbench-deployment-oid-0-tid-1-db946cf6f-gq6lk" node="w01"
2023-09-03T06:40:50.067513934+02:00 stderr F I0903 04:40:50.067264       1 round_trippers.go:553] PUT https://192.168.100.1:6443/apis/coordination.k8s.io/v1/namespaces/kube-system/leases/kube-scheduler?timeout=5s 200 OK in 10 milliseconds
2023-09-03T06:40:17.362942757+02:00 stderr F I0903 04:40:17.362502       1 round_trippers.go:553] POST https://192.168.100.1:6443/apis/events.k8s.io/v1/namespaces/default/events 201 Created in 26 milliseconds
2023-09-03T06:40:25.856515309+02:00 stderr F I0903 04:40:25.856322       1 leaderelection.go:276] successfully renewed lease kube-system/kube-scheduler
2023-09-03T06:40:43.834549182+02:00 stderr F I0903 04:40:43.833861       1 pathrecorder.go:241] kube-scheduler: "/metrics" satisfied by exact match
2023-09-03T06:40:48.047981139+02:00 stderr F I0903 04:40:48.047793       1 leaderelection.go:276] successfully renewed lease kube-system/kube-scheduler
2023-09-03T06:40:52.091054556+02:00 stderr F I0903 04:40:52.090780       1 round_trippers.go:553] PUT https://192.168.100.1:6443/apis/coordination.k8s.io/v1/namespaces/kube-system/leases/kube-scheduler?timeout=5s 200 OK in 15 milliseconds
2023-09-03T06:40:17.271850545+02:00 stderr F I0903 04:40:17.271738       1 cache.go:401] "Finished binding for pod, can be expired" podKey="d85ffd27-758f-4f50-8769-e29fa6eac67c" pod="default/kbench-deployment-oid-0-tid-0-bdb979454-xw4m6"
2023-09-03T06:40:13.843508277+02:00 stderr F I0903 04:40:13.843330       1 round_trippers.go:553] POST https://192.168.100.1:6443/apis/authorization.k8s.io/v1/subjectaccessreviews?timeout=10s 201 Created in 4 milliseconds
2023-09-03T06:40:37.837396335+02:00 stderr F I0903 04:40:37.837086       1 round_trippers.go:553] POST https://192.168.100.1:6443/apis/authentication.k8s.io/v1/tokenreviews 201 Created in 5 milliseconds
2023-09-03T06:40:31.844573403+02:00 stderr F I0903 04:40:31.844383       1 httplog.go:132] "HTTP" verb="GET" URI="/metrics" latency="14.131138ms" userAgent="Prometheus/2.46.0" audit-ID="" srcIP="192.168.100.20:44855" resp=200
2023-09-03T06:40:17.238123058+02:00 stderr F I0903 04:40:17.237977       1 scheduling_queue.go:1133] "About to try and schedule pod" pod="default/kbench-deployment-oid-0-tid-1-778f5d498c-pxt8b"
2023-09-03T06:40:17.277472592+02:00 stderr F I0903 04:40:17.277147       1 schedule_one.go:252] "Successfully bound pod to node" pod="default/kbench-deployment-oid-0-tid-0-bdb979454-xw4m6" node="w01" evaluatedNodes=5 feasibleNodes=3
2023-09-03T06:40:18.150277624+02:00 stderr F I0903 04:40:18.149990       1 eventhandlers.go:206] "Update event for scheduled pod" pod="default/kbench-deployment-oid-0-tid-1-778f5d498c-vnwk8"
2023-09-03T06:40:18.171024804+02:00 stderr F I0903 04:40:18.170515       1 eventhandlers.go:206] "Update event for scheduled pod" pod="default/kbench-deployment-oid-0-tid-2-cc4784d96-5bzns"
2023-09-03T06:40:39.969136764+02:00 stderr F I0903 04:40:39.968993       1 round_trippers.go:553] GET https://192.168.100.1:6443/apis/coordination.k8s.io/v1/namespaces/kube-system/leases/kube-scheduler?timeout=5s 200 OK in 7 milliseconds
2023-09-03T06:40:17.341151428+02:00 stderr F I0903 04:40:17.340984       1 eventhandlers.go:186] "Add event for scheduled pod" pod="default/kbench-deployment-oid-0-tid-1-db946cf6f-gq6lk"
2023-09-03T06:40:17.264562585+02:00 stderr F I0903 04:40:17.264377       1 default_binder.go:53] "Attempting to bind pod to node" pod="default/kbench-deployment-oid-0-tid-2-cc4784d96-w26gm" node="w01"
2023-09-03T06:40:17.783963813+02:00 stderr F I0903 04:40:17.783697       1 round_trippers.go:553] GET https://192.168.100.1:6443/apis/coordination.k8s.io/v1/namespaces/kube-system/leases/kube-scheduler?timeout=5s 200 OK in 5 milliseconds
2023-09-03T06:40:13.747953247+02:00 stderr F I0903 04:40:13.747648       1 round_trippers.go:553] GET https://192.168.100.1:6443/apis/coordination.k8s.io/v1/namespaces/kube-system/leases/kube-scheduler?timeout=5s 200 OK in 5 milliseconds
2023-09-03T06:40:17.266243397+02:00 stderr F I0903 04:40:17.265881       1 eventhandlers.go:186] "Add event for scheduled pod" pod="default/kbench-deployment-oid-0-tid-0-bdb979454-xw4m6"
2023-09-03T06:40:17.249867276+02:00 stderr F I0903 04:40:17.249695       1 scheduling_queue.go:1133] "About to try and schedule pod" pod="default/kbench-deployment-oid-0-tid-2-cc4784d96-w26gm"
2023-09-03T06:40:17.332458392+02:00 stderr F I0903 04:40:17.332170       1 round_trippers.go:553] POST https://192.168.100.1:6443/apis/events.k8s.io/v1/namespaces/default/events 201 Created in 46 milliseconds
2023-09-03T06:40:47.287300454+02:00 stderr F I0903 04:40:47.287023       1 eventhandlers.go:206] "Update event for scheduled pod" pod="default/kbench-deployment-oid-0-tid-1-db946cf6f-v8q66"
2023-09-03T06:40:19.83123362+02:00 stderr F I0903 04:40:19.831021       1 pathrecorder.go:241] kube-scheduler: "/metrics" satisfied by exact match
2023-09-03T06:40:10.846705333+02:00 stderr F I0903 04:40:10.846411       1 httplog.go:132] "HTTP" verb="GET" URI="/metrics" latency="15.014669ms" userAgent="Prometheus/2.46.0" audit-ID="" srcIP="192.168.100.20:44855" resp=200
2023-09-03T06:40:19.807356828+02:00 stderr F I0903 04:40:19.807277       1 leaderelection.go:276] successfully renewed lease kube-system/kube-scheduler
2023-09-03T06:40:17.332826537+02:00 stderr F I0903 04:40:17.332479       1 round_trippers.go:553] POST https://192.168.100.1:6443/api/v1/namespaces/default/pods/kbench-deployment-oid-0-tid-2-cc4784d96-w26gm/binding 201 Created in 67 milliseconds
2023-09-03T06:40:17.338389763+02:00 stderr F I0903 04:40:17.337814       1 eventhandlers.go:206] "Update event for scheduled pod" pod="default/kbench-deployment-oid-0-tid-1-778f5d498c-pxt8b"
2023-09-03T06:40:17.298024457+02:00 stderr F I0903 04:40:17.297730       1 eventhandlers.go:161] "Delete event for unscheduled pod" pod="default/kbench-deployment-oid-0-tid-1-778f5d498c-vnwk8"
2023-09-03T06:40:17.280812044+02:00 stderr F I0903 04:40:17.277019       1 scheduling_queue.go:419] "Pod moved to an internal scheduling queue" pod="default/kbench-deployment-oid-0-tid-0-bdb979454-p2w87" event="PodAdd" queue="Active"
2023-09-03T06:40:36.197117898+02:00 stderr F I0903 04:40:36.196693       1 pathrecorder.go:241] kube-scheduler: "/healthz" satisfied by exact match
2023-09-03T06:40:50.593306333+02:00 stderr F I0903 04:40:50.593129       1 eventhandlers.go:231] "Delete event for scheduled pod" pod="default/kbench-deployment-oid-0-tid-1-778f5d498c-vnwk8"
2023-09-03T06:40:29.890107771+02:00 stderr F I0903 04:40:29.889819       1 round_trippers.go:553] PUT https://192.168.100.1:6443/apis/coordination.k8s.io/v1/namespaces/kube-system/leases/kube-scheduler?timeout=5s 200 OK in 8 milliseconds
2023-09-03T06:40:17.298259968+02:00 stderr F I0903 04:40:17.298139       1 scheduling_queue.go:1133] "About to try and schedule pod" pod="default/kbench-deployment-oid-0-tid-1-db946cf6f-gq6lk"
2023-09-03T06:40:17.335499538+02:00 stderr F I0903 04:40:17.335215       1 schedule_one.go:252] "Successfully bound pod to node" pod="default/kbench-deployment-oid-0-tid-1-db946cf6f-gq6lk" node="w01" evaluatedNodes=5 feasibleNodes=3
2023-09-03T06:40:17.265884095+02:00 stderr F I0903 04:40:17.265685       1 scheduling_queue.go:1133] "About to try and schedule pod" pod="default/kbench-deployment-oid-0-tid-1-778f5d498c-vnwk8"
2023-09-03T06:40:37.960742835+02:00 stderr F I0903 04:40:37.960648       1 leaderelection.go:276] successfully renewed lease kube-system/kube-scheduler
2023-09-03T06:40:33.916459802+02:00 stderr F I0903 04:40:33.916159       1 round_trippers.go:553] GET https://192.168.100.1:6443/apis/coordination.k8s.io/v1/namespaces/kube-system/leases/kube-scheduler?timeout=5s 200 OK in 4 milliseconds
2023-09-03T06:40:17.233228668+02:00 stderr F I0903 04:40:17.233077       1 eventhandlers.go:118] "Add event for unscheduled pod" pod="default/kbench-deployment-oid-0-tid-0-bdb979454-xw4m6"
2023-09-03T06:40:17.282391999+02:00 stderr F I0903 04:40:17.281894       1 scheduling_queue.go:1133] "About to try and schedule pod" pod="default/kbench-deployment-oid-0-tid-0-bdb979454-p2w87"
2023-09-03T06:40:17.23857377+02:00 stderr F I0903 04:40:17.238464       1 default_binder.go:53] "Attempting to bind pod to node" pod="default/kbench-deployment-oid-0-tid-0-bdb979454-xw4m6" node="w01"
2023-09-03T06:40:17.284736201+02:00 stderr F I0903 04:40:17.284595       1 schedule_one.go:252] "Successfully bound pod to node" pod="default/kbench-deployment-oid-0-tid-2-cc4784d96-5bzns" node="w02" evaluatedNodes=5 feasibleNodes=3
2023-09-03T06:40:18.674243486+02:00 stderr F I0903 04:40:18.673648       1 eventhandlers.go:206] "Update event for scheduled pod" pod="default/kbench-deployment-oid-0-tid-1-778f5d498c-pxt8b"
2023-09-03T06:40:17.379148482+02:00 stderr F I0903 04:40:17.378072       1 eventhandlers.go:206] "Update event for scheduled pod" pod="default/kbench-deployment-oid-0-tid-2-cc4784d96-w26gm"
2023-09-03T06:40:13.758047427+02:00 stderr F I0903 04:40:13.757832       1 leaderelection.go:276] successfully renewed lease kube-system/kube-scheduler
2023-09-03T06:40:17.235555312+02:00 stderr F I0903 04:40:17.235377       1 scheduling_queue.go:419] "Pod moved to an internal scheduling queue" pod="default/kbench-deployment-oid-0-tid-2-cc4784d96-5bzns" event="PodAdd" queue="Active"
2023-09-03T06:40:17.284475154+02:00 stderr F I0903 04:40:17.284052       1 cache.go:401] "Finished binding for pod, can be expired" podKey="0e491a06-e2fb-4a18-9655-524c04e25555" pod="default/kbench-deployment-oid-0-tid-2-cc4784d96-5bzns"
2023-09-03T06:40:13.855606762+02:00 stderr F I0903 04:40:13.854903       1 httplog.go:132] "HTTP" verb="GET" URI="/metrics" latency="24.392254ms" userAgent="Prometheus/2.46.0" audit-ID="" srcIP="192.168.100.20:44855" resp=200
2023-09-03T06:40:26.193551878+02:00 stderr F I0903 04:40:26.193379       1 httplog.go:132] "HTTP" verb="GET" URI="/healthz" latency="706.689µs" userAgent="kube-probe/1.27" audit-ID="" srcIP="127.0.0.1:50654" resp=200
2023-09-03T06:40:34.831681154+02:00 stderr F I0903 04:40:34.831375       1 pathrecorder.go:241] kube-scheduler: "/metrics" satisfied by exact match
2023-09-03T06:40:55.401513844+02:00 stderr F I0903 04:40:55.401312       1 eventhandlers.go:231] "Delete event for scheduled pod" pod="default/kbench-deployment-oid-0-tid-2-cc4784d96-w26gm"
2023-09-03T06:40:17.291111961+02:00 stderr F I0903 04:40:17.290930       1 eventhandlers.go:161] "Delete event for unscheduled pod" pod="default/kbench-deployment-oid-0-tid-2-cc4784d96-5bzns"
2023-09-03T06:40:31.910164174+02:00 stderr F I0903 04:40:31.909977       1 leaderelection.go:276] successfully renewed lease kube-system/kube-scheduler
2023-09-03T06:40:11.741678038+02:00 stderr F I0903 04:40:11.741404       1 leaderelection.go:276] successfully renewed lease kube-system/kube-scheduler
2023-09-03T06:40:17.266582039+02:00 stderr F I0903 04:40:17.266448       1 default_binder.go:53] "Attempting to bind pod to node" pod="default/kbench-deployment-oid-0-tid-1-778f5d498c-vnwk8" node="w02"
2023-09-03T06:40:48.037961496+02:00 stderr F I0903 04:40:48.037675       1 round_trippers.go:553] GET https://192.168.100.1:6443/apis/coordination.k8s.io/v1/namespaces/kube-system/leases/kube-scheduler?timeout=5s 200 OK in 5 milliseconds
2023-09-03T06:40:26.193106188+02:00 stderr F I0903 04:40:26.192714       1 pathrecorder.go:241] kube-scheduler: "/healthz" satisfied by exact match
2023-09-03T06:40:52.835171202+02:00 stderr F I0903 04:40:52.834906       1 pathrecorder.go:241] kube-scheduler: "/metrics" satisfied by exact match
2023-09-03T06:40:52.847783763+02:00 stderr F I0903 04:40:52.847503       1 httplog.go:132] "HTTP" verb="GET" URI="/metrics" latency="12.683748ms" userAgent="Prometheus/2.46.0" audit-ID="" srcIP="192.168.100.20:44855" resp=200
2023-09-03T06:40:13.843887865+02:00 stderr F I0903 04:40:13.843697       1 pathrecorder.go:241] kube-scheduler: "/metrics" satisfied by exact match
2023-09-03T06:40:17.241160964+02:00 stderr F I0903 04:40:17.240937       1 default_binder.go:53] "Attempting to bind pod to node" pod="default/kbench-deployment-oid-0-tid-2-cc4784d96-5bzns" node="w02"
2023-08-25T20:41:09.255312617+02:00 stderr F I0825 18:41:09.255129       1 round_trippers.go:553] PUT https://192.168.100.1:6443/apis/coordination.k8s.io/v1/namespaces/kube-system/leases/kube-scheduler?timeout=5s 200 OK in 8 milliseconds
2023-08-25T20:41:14.351109064+02:00 stderr F I0825 18:41:14.351056       1 scheduling_queue.go:1133] "About to try and schedule pod" pod="default/kbench-deployment-oid-0-tid-1-778f5d498c-xhwqk"
2023-08-25T20:41:17.311525004+02:00 stderr F I0825 18:41:17.311256       1 round_trippers.go:553] GET https://192.168.100.1:6443/apis/coordination.k8s.io/v1/namespaces/kube-system/leases/kube-scheduler?timeout=5s 200 OK in 4 milliseconds
2023-08-25T20:40:54.326650313+02:00 stderr F I0825 18:40:54.326473       1 eventhandlers.go:206] "Update event for scheduled pod" pod="default/kbench-deployment-oid-0-tid-1-778f5d498c-79tcr"
2023-08-25T20:40:55.142029383+02:00 stderr F I0825 18:40:55.141899       1 leaderelection.go:276] successfully renewed lease kube-system/kube-scheduler
2023-08-25T20:41:14.358008408+02:00 stderr F I0825 18:41:14.357894       1 schedule_one.go:80] "Attempting to schedule pod" pod="default/kbench-deployment-oid-0-tid-0-bdb979454-z6bz7"
2023-08-25T20:40:54.303974152+02:00 stderr F I0825 18:40:54.303553       1 round_trippers.go:553] POST https://192.168.100.1:6443/api/v1/namespaces/default/pods/kbench-deployment-oid-0-tid-1-778f5d498c-79tcr/binding 201 Created in 13 milliseconds
2023-08-25T20:40:54.285721955+02:00 stderr F I0825 18:40:54.285556       1 default_binder.go:53] "Attempting to bind pod to node" pod="default/kbench-deployment-oid-0-tid-0-bdb979454-c8gwq" node="w02"
2023-08-25T20:41:28.616657041+02:00 stderr F I0825 18:41:28.616186       1 pathrecorder.go:241] kube-scheduler: "/metrics" satisfied by exact match
2023-08-25T20:40:43.029668058+02:00 stderr F I0825 18:40:43.029486       1 round_trippers.go:553] GET https://192.168.100.1:6443/apis/coordination.k8s.io/v1/namespaces/kube-system/leases/kube-scheduler?timeout=5s 200 OK in 5 milliseconds
2023-08-25T20:40:53.115963054+02:00 stderr F I0825 18:40:53.115549       1 round_trippers.go:553] GET https://192.168.100.1:6443/apis/coordination.k8s.io/v1/namespaces/kube-system/leases/kube-scheduler?timeout=5s 200 OK in 5 milliseconds
2023-08-25T20:40:43.616592472+02:00 stderr F I0825 18:40:43.616174       1 pathrecorder.go:241] kube-scheduler: "/metrics" satisfied by exact match
2023-08-25T20:40:54.273671712+02:00 stderr F I0825 18:40:54.271612       1 scheduling_queue.go:419] "Pod moved to an internal scheduling queue" pod="default/kbench-deployment-oid-0-tid-0-bdb979454-c8gwq" event="PodAdd" queue="Active"
2023-08-25T20:40:42.497385908+02:00 stderr F I0825 18:40:42.497310       1 round_trippers.go:553] POST https://192.168.100.1:6443/api/v1/namespaces/default/pods/kbench-deployment-oid-0-tid-1-778f5d498c-qlt6g/binding 201 Created in 27 milliseconds
2023-08-25T20:41:32.662887135+02:00 stderr F I0825 18:41:32.662667       1 eventhandlers.go:231] "Delete event for scheduled pod" pod="default/kbench-deployment-oid-0-tid-0-bdb979454-z6bz7"
2023-08-25T20:40:59.164695407+02:00 stderr F I0825 18:40:59.164328       1 round_trippers.go:553] GET https://192.168.100.1:6443/apis/coordination.k8s.io/v1/namespaces/kube-system/leases/kube-scheduler?timeout=5s 200 OK in 4 milliseconds
2023-08-25T20:41:07.627950073+02:00 stderr F I0825 18:41:07.627830       1 httplog.go:132] "HTTP" verb="GET" URI="/metrics" latency="11.735764ms" userAgent="Prometheus/2.46.0" audit-ID="" srcIP="192.168.100.20:31814" resp=200
2023-08-25T20:40:49.084675973+02:00 stderr F I0825 18:40:49.084374       1 round_trippers.go:553] GET https://192.168.100.1:6443/apis/coordination.k8s.io/v1/namespaces/kube-system/leases/kube-scheduler?timeout=5s 200 OK in 5 milliseconds
2023-08-25T20:40:42.522953239+02:00 stderr F I0825 18:40:42.522800       1 eventhandlers.go:206] "Update event for scheduled pod" pod="default/kbench-deployment-oid-0-tid-1-778f5d498c-qlt6g"
2023-08-25T20:40:46.626708148+02:00 stderr F I0825 18:40:46.626504       1 httplog.go:132] "HTTP" verb="GET" URI="/metrics" latency="10.312716ms" userAgent="Prometheus/2.46.0" audit-ID="" srcIP="192.168.100.20:31814" resp=200
2023-08-25T20:41:14.378681122+02:00 stderr F I0825 18:41:14.378660       1 schedule_one.go:252] "Successfully bound pod to node" pod="default/kbench-deployment-oid-0-tid-0-bdb979454-z6bz7" node="w03" evaluatedNodes=5 feasibleNodes=3
2023-08-25T20:41:04.317469165+02:00 stderr F I0825 18:41:04.317396       1 default_binder.go:53] "Attempting to bind pod to node" pod="default/kbench-deployment-oid-0-tid-1-778f5d498c-jbs5f" node="w03"
2023-08-25T20:41:01.625648464+02:00 stderr F I0825 18:41:01.625502       1 pathrecorder.go:241] kube-scheduler: "/metrics" satisfied by exact match
2023-08-25T20:41:04.32644747+02:00 stderr F I0825 18:41:04.326261       1 eventhandlers.go:186] "Add event for scheduled pod" pod="default/kbench-deployment-oid-0-tid-0-bdb979454-7qkgt"
2023-08-25T20:40:42.479751528+02:00 stderr F I0825 18:40:42.479473       1 scheduling_queue.go:1133] "About to try and schedule pod" pod="default/kbench-deployment-oid-0-tid-1-778f5d498c-5tgnz"
2023-08-25T20:41:05.893303249+02:00 stderr F I0825 18:41:05.893025       1 pathrecorder.go:241] kube-scheduler: "/healthz" satisfied by exact match
2023-08-25T20:41:32.601841556+02:00 stderr F I0825 18:41:32.601690       1 eventhandlers.go:206] "Update event for scheduled pod" pod="default/kbench-deployment-oid-0-tid-0-bdb979454-z6bz7"
2023-08-25T20:41:29.424261585+02:00 stderr F I0825 18:41:29.424143       1 leaderelection.go:276] successfully renewed lease kube-system/kube-scheduler
2023-08-25T20:41:14.375615639+02:00 stderr F I0825 18:41:14.375523       1 round_trippers.go:553] POST https://192.168.100.1:6443/apis/events.k8s.io/v1/namespaces/default/events 201 Created in 13 milliseconds
2023-08-25T20:41:04.326075008+02:00 stderr F I0825 18:41:04.325982       1 round_trippers.go:553] POST https://192.168.100.1:6443/api/v1/namespaces/default/pods/kbench-deployment-oid-0-tid-0-bdb979454-7qkgt/binding 201 Created in 15 milliseconds
2023-08-25T20:40:55.141893584+02:00 stderr F I0825 18:40:55.141596       1 round_trippers.go:553] PUT https://192.168.100.1:6443/apis/coordination.k8s.io/v1/namespaces/kube-system/leases/kube-scheduler?timeout=5s 200 OK in 8 milliseconds
2023-08-25T20:41:32.702100401+02:00 stderr F I0825 18:41:32.701961       1 eventhandlers.go:231] "Delete event for scheduled pod" pod="default/kbench-deployment-oid-0-tid-1-778f5d498c-qlt6g"
2023-08-25T20:41:32.635690271+02:00 stderr F I0825 18:41:32.635529       1 eventhandlers.go:231] "Delete event for scheduled pod" pod="default/kbench-deployment-oid-0-tid-0-bdb979454-g9v5h"
2023-08-25T20:41:24.568057404+02:00 stderr F I0825 18:41:24.567912       1 eventhandlers.go:206] "Update event for scheduled pod" pod="default/kbench-deployment-oid-0-tid-0-bdb979454-c8gwq"
2023-08-25T20:41:10.61550132+02:00 stderr F I0825 18:41:10.615254       1 pathrecorder.go:241] kube-scheduler: "/metrics" satisfied by exact match
2023-08-25T20:40:46.616608691+02:00 stderr F I0825 18:40:46.616360       1 pathrecorder.go:241] kube-scheduler: "/metrics" satisfied by exact match
2023-08-25T20:40:42.508257337+02:00 stderr F I0825 18:40:42.507456       1 cache.go:401] "Finished binding for pod, can be expired" podKey="7d3c66f4-5eb3-4f75-8b6f-7c187b63c655" pod="default/kbench-deployment-oid-0-tid-0-bdb979454-g9v5h"
2023-08-25T20:40:51.100868629+02:00 stderr F I0825 18:40:51.100465       1 round_trippers.go:553] GET https://192.168.100.1:6443/apis/coordination.k8s.io/v1/namespaces/kube-system/leases/kube-scheduler?timeout=5s 200 OK in 5 milliseconds
2023-08-25T20:41:15.890812401+02:00 stderr F I0825 18:41:15.890556       1 pathrecorder.go:241] kube-scheduler: "/healthz" satisfied by exact match
2023-08-25T20:41:14.378863174+02:00 stderr F I0825 18:41:14.378819       1 eventhandlers.go:186] "Add event for scheduled pod" pod="default/kbench-deployment-oid-0-tid-0-bdb979454-z6bz7"
2023-08-25T20:40:54.297537476+02:00 stderr F I0825 18:40:54.297287       1 eventhandlers.go:186] "Add event for scheduled pod" pod="default/kbench-deployment-oid-0-tid-0-bdb979454-c8gwq"
2023-08-25T20:41:04.627873671+02:00 stderr F I0825 18:41:04.627513       1 httplog.go:132] "HTTP" verb="GET" URI="/metrics" latency="11.938694ms" userAgent="Prometheus/2.46.0" audit-ID="" srcIP="192.168.100.20:31814" resp=200
2023-08-25T20:40:42.527221358+02:00 stderr F I0825 18:40:42.526978       1 eventhandlers.go:206] "Update event for scheduled pod" pod="default/kbench-deployment-oid-0-tid-0-bdb979454-z7gsq"
2023-08-25T20:41:32.676659459+02:00 stderr F I0825 18:41:32.676500       1 eventhandlers.go:206] "Update event for scheduled pod" pod="default/kbench-deployment-oid-0-tid-1-778f5d498c-xhwqk"
2023-08-25T20:41:16.626171014+02:00 stderr F I0825 18:41:16.625958       1 httplog.go:132] "HTTP" verb="GET" URI="/metrics" latency="10.63148ms" userAgent="Prometheus/2.46.0" audit-ID="" srcIP="192.168.100.20:31814" resp=200
2023-08-25T20:40:42.495239224+02:00 stderr F I0825 18:40:42.493077       1 eventhandlers.go:186] "Add event for scheduled pod" pod="default/kbench-deployment-oid-0-tid-1-778f5d498c-qlt6g"
2023-08-25T20:41:16.615752726+02:00 stderr F I0825 18:41:16.615521       1 pathrecorder.go:241] kube-scheduler: "/metrics" satisfied by exact match
2023-08-25T20:40:42.497428391+02:00 stderr F I0825 18:40:42.497387       1 round_trippers.go:553] POST https://192.168.100.1:6443/api/v1/namespaces/default/pods/kbench-deployment-oid-0-tid-0-bdb979454-z7gsq/binding 201 Created in 20 milliseconds
2023-08-25T20:40:54.283157554+02:00 stderr F I0825 18:40:54.282931       1 scheduling_queue.go:419] "Pod moved to an internal scheduling queue" pod="default/kbench-deployment-oid-0-tid-1-778f5d498c-79tcr" event="PodAdd" queue="Active"
2023-08-25T20:41:32.705033261+02:00 stderr F I0825 18:41:32.704830       1 eventhandlers.go:231] "Delete event for scheduled pod" pod="default/kbench-deployment-oid-0-tid-1-778f5d498c-xhwqk"
2023-08-25T20:40:42.497500586+02:00 stderr F I0825 18:40:42.497441       1 cache.go:401] "Finished binding for pod, can be expired" podKey="ea3636cd-6a3b-431f-b021-b91b14556a90" pod="default/kbench-deployment-oid-0-tid-0-bdb979454-z7gsq"
2023-08-25T20:41:15.890842315+02:00 stderr F I0825 18:41:15.890661       1 httplog.go:132] "HTTP" verb="GET" URI="/healthz" latency="268.541µs" userAgent="kube-probe/1.27" audit-ID="" srcIP="127.0.0.1:46162" resp=200
2023-08-25T20:40:42.485903932+02:00 stderr F I0825 18:40:42.485709       1 eventhandlers.go:118] "Add event for unscheduled pod" pod="default/kbench-deployment-oid-0-tid-0-bdb979454-g9v5h"
2023-08-25T20:41:13.279114819+02:00 stderr F I0825 18:41:13.278888       1 round_trippers.go:553] GET https://192.168.100.1:6443/apis/coordination.k8s.io/v1/namespaces/kube-system/leases/kube-scheduler?timeout=5s 200 OK in 4 milliseconds
2023-08-25T20:40:42.497607893+02:00 stderr F I0825 18:40:42.497477       1 schedule_one.go:252] "Successfully bound pod to node" pod="default/kbench-deployment-oid-0-tid-0-bdb979454-z7gsq" node="w03" evaluatedNodes=5 feasibleNodes=3
2023-08-25T20:41:19.626061266+02:00 stderr F I0825 18:41:19.625774       1 httplog.go:132] "HTTP" verb="GET" URI="/metrics" latency="10.353304ms" userAgent="Prometheus/2.46.0" audit-ID="" srcIP="192.168.100.20:31814" resp=200
2023-08-25T20:41:31.628089223+02:00 stderr F I0825 18:41:31.627633       1 httplog.go:132] "HTTP" verb="GET" URI="/metrics" latency="12.219025ms" userAgent="Prometheus/2.46.0" audit-ID="" srcIP="192.168.100.20:31814" resp=200
2023-08-25T20:40:49.627459178+02:00 stderr F I0825 18:40:49.627231       1 pathrecorder.go:241] kube-scheduler: "/metrics" satisfied by exact match
2023-08-25T20:40:55.894022925+02:00 stderr F I0825 18:40:55.893874       1 httplog.go:132] "HTTP" verb="GET" URI="/healthz" latency="188.389µs" userAgent="kube-probe/1.27" audit-ID="" srcIP="127.0.0.1:35344" resp=200
2023-08-25T20:40:54.297543506+02:00 stderr F I0825 18:40:54.297198       1 eventhandlers.go:161] "Delete event for unscheduled pod" pod="default/kbench-deployment-oid-0-tid-0-bdb979454-c8gwq"
2023-08-25T20:40:42.492944267+02:00 stderr F I0825 18:40:42.492788       1 eventhandlers.go:161] "Delete event for unscheduled pod" pod="default/kbench-deployment-oid-0-tid-1-778f5d498c-qlt6g"
2023-08-25T20:41:14.389961172+02:00 stderr F I0825 18:41:14.389808       1 round_trippers.go:553] POST https://192.168.100.1:6443/apis/events.k8s.io/v1/namespaces/default/events 201 Created in 10 milliseconds
2023-08-25T20:41:15.305571333+02:00 stderr F I0825 18:41:15.305503       1 leaderelection.go:276] successfully renewed lease kube-system/kube-scheduler
2023-08-25T20:41:31.440686642+02:00 stderr F I0825 18:41:31.440477       1 round_trippers.go:553] PUT https://192.168.100.1:6443/apis/coordination.k8s.io/v1/namespaces/kube-system/leases/kube-scheduler?timeout=5s 200 OK in 8 milliseconds
2023-08-25T20:41:04.326095964+02:00 stderr F I0825 18:41:04.326064       1 cache.go:401] "Finished binding for pod, can be expired" podKey="def57a1a-53c1-449d-8408-0ea17458a1ec" pod="default/kbench-deployment-oid-0-tid-0-bdb979454-7qkgt"
2023-08-25T20:41:07.22965935+02:00 stderr F I0825 18:41:07.229407       1 round_trippers.go:553] GET https://192.168.100.1:6443/apis/coordination.k8s.io/v1/namespaces/kube-system/leases/kube-scheduler?timeout=5s 200 OK in 6 milliseconds
2023-08-25T20:40:57.148491008+02:00 stderr F I0825 18:40:57.148245       1 round_trippers.go:553] GET https://192.168.100.1:6443/apis/coordination.k8s.io/v1/namespaces/kube-system/leases/kube-scheduler?timeout=5s 200 OK in 5 milliseconds
2023-08-25T20:41:27.403134718+02:00 stderr F I0825 18:41:27.402968       1 leaderelection.go:276] successfully renewed lease kube-system/kube-scheduler
2023-08-25T20:41:27.393121559+02:00 stderr F I0825 18:41:27.392680       1 round_trippers.go:553] GET https://192.168.100.1:6443/apis/coordination.k8s.io/v1/namespaces/kube-system/leases/kube-scheduler?timeout=5s 200 OK in 5 milliseconds
2023-08-25T20:41:04.616037708+02:00 stderr F I0825 18:41:04.615688       1 pathrecorder.go:241] kube-scheduler: "/metrics" satisfied by exact match
2023-08-25T20:41:14.378842319+02:00 stderr F I0825 18:41:14.378701       1 eventhandlers.go:161] "Delete event for unscheduled pod" pod="default/kbench-deployment-oid-0-tid-0-bdb979454-z6bz7"
2023-08-25T20:40:54.323811122+02:00 stderr F I0825 18:40:54.323655       1 eventhandlers.go:206] "Update event for scheduled pod" pod="default/kbench-deployment-oid-0-tid-0-bdb979454-c8gwq"
2023-08-25T20:41:31.431628417+02:00 stderr F I0825 18:41:31.431409       1 round_trippers.go:553] GET https://192.168.100.1:6443/apis/coordination.k8s.io/v1/namespaces/kube-system/leases/kube-scheduler?timeout=5s 200 OK in 6 milliseconds
2023-08-25T20:41:01.620285544+02:00 stderr F I0825 18:41:01.620028       1 round_trippers.go:553] POST https://192.168.100.1:6443/apis/authentication.k8s.io/v1/tokenreviews 201 Created in 3 milliseconds
2023-08-25T20:41:32.590212846+02:00 stderr F I0825 18:41:32.590063       1 eventhandlers.go:206] "Update event for scheduled pod" pod="default/kbench-deployment-oid-0-tid-0-bdb979454-g9v5h"
2023-08-25T20:41:14.378652844+02:00 stderr F I0825 18:41:14.378520       1 round_trippers.go:553] POST https://192.168.100.1:6443/api/v1/namespaces/default/pods/kbench-deployment-oid-0-tid-0-bdb979454-z6bz7/binding 201 Created in 17 milliseconds
2023-08-25T20:40:55.982644334+02:00 stderr F I0825 18:40:55.982385       1 eventhandlers.go:206] "Update event for scheduled pod" pod="default/kbench-deployment-oid-0-tid-1-778f5d498c-79tcr"
2023-08-25T20:41:32.565614669+02:00 stderr F I0825 18:41:32.565372       1 eventhandlers.go:206] "Update event for scheduled pod" pod="default/kbench-deployment-oid-0-tid-0-bdb979454-7qkgt"
2023-08-25T20:41:24.570679959+02:00 stderr F I0825 18:41:24.569147       1 eventhandlers.go:206] "Update event for scheduled pod" pod="default/kbench-deployment-oid-0-tid-1-778f5d498c-5tgnz"
2023-08-25T20:41:22.629826263+02:00 stderr F I0825 18:41:22.629625       1 httplog.go:132] "HTTP" verb="GET" URI="/metrics" latency="14.55594ms" userAgent="Prometheus/2.46.0" audit-ID="" srcIP="192.168.100.20:31814" resp=200
2023-08-25T20:40:43.041257052+02:00 stderr F I0825 18:40:43.041062       1 round_trippers.go:553] PUT https://192.168.100.1:6443/apis/coordination.k8s.io/v1/namespaces/kube-system/leases/kube-scheduler?timeout=5s 200 OK in 11 milliseconds
2023-08-25T20:40:42.518638592+02:00 stderr F I0825 18:40:42.518526       1 round_trippers.go:553] POST https://192.168.100.1:6443/apis/events.k8s.io/v1/namespaces/default/events 201 Created in 20 milliseconds
2023-08-25T20:41:14.36173177+02:00 stderr F I0825 18:41:14.361589       1 cache.go:401] "Finished binding for pod, can be expired" podKey="6f610eca-042a-4130-8a1f-a4566179605c" pod="default/kbench-deployment-oid-0-tid-1-778f5d498c-xhwqk"
2023-08-25T20:41:32.580473843+02:00 stderr F I0825 18:41:32.577769       1 eventhandlers.go:206] "Update event for scheduled pod" pod="default/kbench-deployment-oid-0-tid-0-bdb979454-c8gwq"
2023-08-25T20:41:25.376757874+02:00 stderr F I0825 18:41:25.376436       1 round_trippers.go:553] GET https://192.168.100.1:6443/apis/coordination.k8s.io/v1/namespaces/kube-system/leases/kube-scheduler?timeout=5s 200 OK in 6 milliseconds
2023-08-25T20:41:04.357432421+02:00 stderr F I0825 18:41:04.357210       1 eventhandlers.go:206] "Update event for scheduled pod" pod="default/kbench-deployment-oid-0-tid-1-778f5d498c-jbs5f"
2023-08-25T20:41:14.35797011+02:00 stderr F I0825 18:41:14.357799       1 eventhandlers.go:118] "Add event for unscheduled pod" pod="default/kbench-deployment-oid-0-tid-0-bdb979454-z6bz7"
2023-08-25T20:40:42.479730903+02:00 stderr F I0825 18:40:42.479407       1 eventhandlers.go:118] "Add event for unscheduled pod" pod="default/kbench-deployment-oid-0-tid-1-778f5d498c-5tgnz"
2023-08-25T20:40:53.126672862+02:00 stderr F I0825 18:40:53.126365       1 round_trippers.go:553] PUT https://192.168.100.1:6443/apis/coordination.k8s.io/v1/namespaces/kube-system/leases/kube-scheduler?timeout=5s 200 OK in 10 milliseconds
2023-08-25T20:41:24.559238209+02:00 stderr F I0825 18:41:24.558983       1 eventhandlers.go:206] "Update event for scheduled pod" pod="default/kbench-deployment-oid-0-tid-1-778f5d498c-jbs5f"
2023-08-25T20:40:54.282743054+02:00 stderr F I0825 18:40:54.282548       1 eventhandlers.go:118] "Add event for unscheduled pod" pod="default/kbench-deployment-oid-0-tid-1-778f5d498c-79tcr"
2023-08-25T20:40:54.275218651+02:00 stderr F I0825 18:40:54.274916       1 schedule_one.go:80] "Attempting to schedule pod" pod="default/kbench-deployment-oid-0-tid-0-bdb979454-c8gwq"
2023-08-25T20:41:13.28945739+02:00 stderr F I0825 18:41:13.289173       1 round_trippers.go:553] PUT https://192.168.100.1:6443/apis/coordination.k8s.io/v1/namespaces/kube-system/leases/kube-scheduler?timeout=5s 200 OK in 9 milliseconds
2023-08-25T20:41:32.630931436+02:00 stderr F I0825 18:41:32.630738       1 eventhandlers.go:231] "Delete event for scheduled pod" pod="default/kbench-deployment-oid-0-tid-0-bdb979454-c8gwq"
2023-08-25T20:41:25.893482837+02:00 stderr F I0825 18:41:25.893351       1 httplog.go:132] "HTTP" verb="GET" URI="/healthz" latency="177.999µs" userAgent="kube-probe/1.27" audit-ID="" srcIP="127.0.0.1:47536" resp=200
2023-08-25T20:41:23.369272946+02:00 stderr F I0825 18:41:23.368871       1 round_trippers.go:553] PUT https://192.168.100.1:6443/apis/coordination.k8s.io/v1/namespaces/kube-system/leases/kube-scheduler?timeout=5s 200 OK in 8 milliseconds
2023-08-25T20:41:04.331206704+02:00 stderr F I0825 18:41:04.331024       1 cache.go:401] "Finished binding for pod, can be expired" podKey="64ee3163-6c3a-4883-a882-ba5550aa2707" pod="default/kbench-deployment-oid-0-tid-1-778f5d498c-jbs5f"
2023-08-25T20:40:42.474171024+02:00 stderr F I0825 18:40:42.474030       1 eventhandlers.go:118] "Add event for unscheduled pod" pod="default/kbench-deployment-oid-0-tid-0-bdb979454-z7gsq"
2023-08-25T20:41:01.182703005+02:00 stderr F I0825 18:41:01.182495       1 round_trippers.go:553] GET https://192.168.100.1:6443/apis/coordination.k8s.io/v1/namespaces/kube-system/leases/kube-scheduler?timeout=5s 200 OK in 6 milliseconds
2023-08-25T20:40:42.543012992+02:00 stderr F I0825 18:40:42.542551       1 eventhandlers.go:206] "Update event for scheduled pod" pod="default/kbench-deployment-oid-0-tid-1-778f5d498c-5tgnz"
2023-08-25T20:41:28.628852326+02:00 stderr F I0825 18:41:28.628424       1 httplog.go:132] "HTTP" verb="GET" URI="/metrics" latency="12.39137ms" userAgent="Prometheus/2.46.0" audit-ID="" srcIP="192.168.100.20:31814" resp=200
2023-08-25T20:41:25.625649854+02:00 stderr F I0825 18:41:25.625306       1 round_trippers.go:553] POST https://192.168.100.1:6443/apis/authorization.k8s.io/v1/subjectaccessreviews?timeout=10s 201 Created in 4 milliseconds
2023-08-25T20:40:45.051248998+02:00 stderr F I0825 18:40:45.051001       1 round_trippers.go:553] GET https://192.168.100.1:6443/apis/coordination.k8s.io/v1/namespaces/kube-system/leases/kube-scheduler?timeout=5s 200 OK in 8 milliseconds
2023-08-25T20:41:14.351103366+02:00 stderr F I0825 18:41:14.350994       1 scheduling_queue.go:419] "Pod moved to an internal scheduling queue" pod="default/kbench-deployment-oid-0-tid-1-778f5d498c-xhwqk" event="PodAdd" queue="Active"
2023-08-25T20:40:54.273676918+02:00 stderr F I0825 18:40:54.271659       1 scheduling_queue.go:1133] "About to try and schedule pod" pod="default/kbench-deployment-oid-0-tid-0-bdb979454-c8gwq"
2023-08-25T20:41:01.191161846+02:00 stderr F I0825 18:41:01.191021       1 leaderelection.go:276] successfully renewed lease kube-system/kube-scheduler
2023-08-25T20:40:54.307801639+02:00 stderr F I0825 18:40:54.307581       1 round_trippers.go:553] POST https://192.168.100.1:6443/apis/events.k8s.io/v1/namespaces/default/events 201 Created in 9 milliseconds
2023-08-25T20:40:49.621686083+02:00 stderr F I0825 18:40:49.621182       1 round_trippers.go:553] POST https://192.168.100.1:6443/apis/authentication.k8s.io/v1/tokenreviews 201 Created in 5 milliseconds
2023-08-25T20:41:14.360558149+02:00 stderr F I0825 18:41:14.360317       1 eventhandlers.go:186] "Add event for scheduled pod" pod="default/kbench-deployment-oid-0-tid-1-778f5d498c-xhwqk"
2023-08-25T20:41:32.654668309+02:00 stderr F I0825 18:41:32.654457       1 eventhandlers.go:206] "Update event for scheduled pod" pod="default/kbench-deployment-oid-0-tid-1-778f5d498c-jbs5f"
2023-08-25T20:40:42.485929336+02:00 stderr F I0825 18:40:42.485790       1 schedule_one.go:80] "Attempting to schedule pod" pod="default/kbench-deployment-oid-0-tid-0-bdb979454-g9v5h"
2023-08-25T20:40:49.094747744+02:00 stderr F I0825 18:40:49.094627       1 leaderelection.go:276] successfully renewed lease kube-system/kube-scheduler
2023-08-25T20:41:15.305443342+02:00 stderr F I0825 18:41:15.305264       1 round_trippers.go:553] PUT https://192.168.100.1:6443/apis/coordination.k8s.io/v1/namespaces/kube-system/leases/kube-scheduler?timeout=5s 200 OK in 7 milliseconds
2023-08-25T20:41:03.205376629+02:00 stderr F I0825 18:41:03.205185       1 round_trippers.go:553] PUT https://192.168.100.1:6443/apis/coordination.k8s.io/v1/namespaces/kube-system/leases/kube-scheduler?timeout=5s 200 OK in 7 milliseconds
2023-08-25T20:41:07.241212931+02:00 stderr F I0825 18:41:07.241003       1 leaderelection.go:276] successfully renewed lease kube-system/kube-scheduler
2023-08-25T20:41:19.336990565+02:00 stderr F I0825 18:41:19.336615       1 leaderelection.go:276] successfully renewed lease kube-system/kube-scheduler
2023-08-25T20:40:54.298274539+02:00 stderr F I0825 18:40:54.298104       1 schedule_one.go:252] "Successfully bound pod to node" pod="default/kbench-deployment-oid-0-tid-0-bdb979454-c8gwq" node="w02" evaluatedNodes=5 feasibleNodes=3
2023-08-25T20:41:04.316905494+02:00 stderr F I0825 18:41:04.316808       1 schedule_one.go:80] "Attempting to schedule pod" pod="default/kbench-deployment-oid-0-tid-1-778f5d498c-jbs5f"
2023-08-25T20:40:54.297516496+02:00 stderr F I0825 18:40:54.297141       1 round_trippers.go:553] POST https://192.168.100.1:6443/api/v1/namespaces/default/pods/kbench-deployment-oid-0-tid-0-bdb979454-c8gwq/binding 201 Created in 11 milliseconds
2023-08-25T20:41:05.213292467+02:00 stderr F I0825 18:41:05.213095       1 round_trippers.go:553] GET https://192.168.100.1:6443/apis/coordination.k8s.io/v1/namespaces/kube-system/leases/kube-scheduler?timeout=5s 200 OK in 6 milliseconds
2023-08-25T20:41:04.316747852+02:00 stderr F I0825 18:41:04.316670       1 scheduling_queue.go:1133] "About to try and schedule pod" pod="default/kbench-deployment-oid-0-tid-1-778f5d498c-jbs5f"
2023-08-25T20:40:52.625235479+02:00 stderr F I0825 18:40:52.625093       1 httplog.go:132] "HTTP" verb="GET" URI="/metrics" latency="10.370553ms" userAgent="Prometheus/2.46.0" audit-ID="" srcIP="192.168.100.20:31814" resp=200
2023-08-25T20:40:42.497102659+02:00 stderr F I0825 18:40:42.496993       1 eventhandlers.go:186] "Add event for scheduled pod" pod="default/kbench-deployment-oid-0-tid-0-bdb979454-z7gsq"
2023-08-25T20:41:05.221782104+02:00 stderr F I0825 18:41:05.221638       1 round_trippers.go:553] PUT https://192.168.100.1:6443/apis/coordination.k8s.io/v1/namespaces/kube-system/leases/kube-scheduler?timeout=5s 200 OK in 8 milliseconds
2023-08-25T20:41:16.060609337+02:00 stderr F I0825 18:41:16.060308       1 eventhandlers.go:206] "Update event for scheduled pod" pod="default/kbench-deployment-oid-0-tid-0-bdb979454-z6bz7"
2023-08-25T20:41:04.307468733+02:00 stderr F I0825 18:41:04.307330       1 eventhandlers.go:118] "Add event for unscheduled pod" pod="default/kbench-deployment-oid-0-tid-0-bdb979454-7qkgt"
2023-08-25T20:40:42.466442975+02:00 stderr F I0825 18:40:42.466415       1 schedule_one.go:80] "Attempting to schedule pod" pod="default/kbench-deployment-oid-0-tid-1-778f5d498c-qlt6g"
2023-08-25T20:41:19.32795404+02:00 stderr F I0825 18:41:19.327413       1 round_trippers.go:553] GET https://192.168.100.1:6443/apis/coordination.k8s.io/v1/namespaces/kube-system/leases/kube-scheduler?timeout=5s 200 OK in 5 milliseconds
2023-08-25T20:41:03.205871248+02:00 stderr F I0825 18:41:03.205572       1 leaderelection.go:276] successfully renewed lease kube-system/kube-scheduler
2023-08-25T20:40:42.479745921+02:00 stderr F I0825 18:40:42.479445       1 scheduling_queue.go:419] "Pod moved to an internal scheduling queue" pod="default/kbench-deployment-oid-0-tid-1-778f5d498c-5tgnz" event="PodAdd" queue="Active"
2023-08-25T20:41:29.411675617+02:00 stderr F I0825 18:41:29.411318       1 round_trippers.go:553] GET https://192.168.100.1:6443/apis/coordination.k8s.io/v1/namespaces/kube-system/leases/kube-scheduler?timeout=5s 200 OK in 5 milliseconds
2023-08-25T20:40:42.485919492+02:00 stderr F I0825 18:40:42.485761       1 scheduling_queue.go:419] "Pod moved to an internal scheduling queue" pod="default/kbench-deployment-oid-0-tid-0-bdb979454-g9v5h" event="PodAdd" queue="Active"
2023-08-25T20:41:04.337664719+02:00 stderr F I0825 18:41:04.337491       1 round_trippers.go:553] POST https://192.168.100.1:6443/apis/events.k8s.io/v1/namespaces/default/events 201 Created in 11 milliseconds
2023-08-25T20:40:43.375663065+02:00 stderr F I0825 18:40:43.375132       1 eventhandlers.go:206] "Update event for scheduled pod" pod="default/kbench-deployment-oid-0-tid-0-bdb979454-g9v5h"
2023-08-25T20:40:47.078115188+02:00 stderr F I0825 18:40:47.077773       1 round_trippers.go:553] PUT https://192.168.100.1:6443/apis/coordination.k8s.io/v1/namespaces/kube-system/leases/kube-scheduler?timeout=5s 200 OK in 8 milliseconds
2023-08-25T20:41:24.564585821+02:00 stderr F I0825 18:41:24.564337       1 eventhandlers.go:206] "Update event for scheduled pod" pod="default/kbench-deployment-oid-0-tid-1-778f5d498c-79tcr"
2023-08-25T20:41:27.40291852+02:00 stderr F I0825 18:41:27.402759       1 round_trippers.go:553] PUT https://192.168.100.1:6443/apis/coordination.k8s.io/v1/namespaces/kube-system/leases/kube-scheduler?timeout=5s 200 OK in 9 milliseconds
2023-08-25T20:40:42.513247689+02:00 stderr F I0825 18:40:42.513111       1 schedule_one.go:252] "Successfully bound pod to node" pod="default/kbench-deployment-oid-0-tid-1-778f5d498c-5tgnz" node="w02" evaluatedNodes=5 feasibleNodes=3
2023-08-25T20:40:57.156794611+02:00 stderr F I0825 18:40:57.156554       1 leaderelection.go:276] successfully renewed lease kube-system/kube-scheduler
2023-08-25T20:40:45.895323581+02:00 stderr F I0825 18:40:45.895089       1 pathrecorder.go:241] kube-scheduler: "/healthz" satisfied by exact match
2023-08-25T20:41:32.697727557+02:00 stderr F I0825 18:41:32.697618       1 eventhandlers.go:231] "Delete event for scheduled pod" pod="default/kbench-deployment-oid-0-tid-1-778f5d498c-jbs5f"
2023-08-25T20:41:04.326195875+02:00 stderr F I0825 18:41:04.326099       1 schedule_one.go:252] "Successfully bound pod to node" pod="default/kbench-deployment-oid-0-tid-0-bdb979454-7qkgt" node="w01" evaluatedNodes=5 feasibleNodes=3
2023-08-25T20:40:54.311115832+02:00 stderr F I0825 18:40:54.310939       1 round_trippers.go:553] POST https://192.168.100.1:6443/apis/events.k8s.io/v1/namespaces/default/events 201 Created in 6 milliseconds
2023-08-25T20:41:24.578627781+02:00 stderr F I0825 18:41:24.578417       1 eventhandlers.go:206] "Update event for scheduled pod" pod="default/kbench-deployment-oid-0-tid-1-778f5d498c-xhwqk"
2023-08-25T20:41:17.320901623+02:00 stderr F I0825 18:41:17.320694       1 leaderelection.go:276] successfully renewed lease kube-system/kube-scheduler
2023-08-25T20:41:14.378675024+02:00 stderr F I0825 18:41:14.378620       1 cache.go:401] "Finished binding for pod, can be expired" podKey="3505a5c6-b0d9-451b-8ef7-b9b6e0070049" pod="default/kbench-deployment-oid-0-tid-0-bdb979454-z6bz7"
2023-08-25T20:40:42.507046438+02:00 stderr F I0825 18:40:42.506649       1 eventhandlers.go:186] "Add event for scheduled pod" pod="default/kbench-deployment-oid-0-tid-0-bdb979454-g9v5h"
2023-08-25T20:41:23.360511651+02:00 stderr F I0825 18:41:23.360119       1 round_trippers.go:553] GET https://192.168.100.1:6443/apis/coordination.k8s.io/v1/namespaces/kube-system/leases/kube-scheduler?timeout=5s 200 OK in 5 milliseconds
2023-08-25T20:40:58.629799966+02:00 stderr F I0825 18:40:58.629515       1 httplog.go:132] "HTTP" verb="GET" URI="/metrics" latency="13.015011ms" userAgent="Prometheus/2.46.0" audit-ID="" srcIP="192.168.100.20:31814" resp=200
2023-08-25T20:41:25.386746335+02:00 stderr F I0825 18:41:25.386478       1 leaderelection.go:276] successfully renewed lease kube-system/kube-scheduler
2023-08-25T20:41:13.63975987+02:00 stderr F I0825 18:41:13.639482       1 httplog.go:132] "HTTP" verb="GET" URI="/metrics" latency="21.384696ms" userAgent="Prometheus/2.46.0" audit-ID="" srcIP="192.168.100.20:31814" resp=200
2023-08-25T20:41:09.255334761+02:00 stderr F I0825 18:41:09.255226       1 leaderelection.go:276] successfully renewed lease kube-system/kube-scheduler
2023-08-25T20:40:55.629590445+02:00 stderr F I0825 18:40:55.629341       1 httplog.go:132] "HTTP" verb="GET" URI="/metrics" latency="14.482474ms" userAgent="Prometheus/2.46.0" audit-ID="" srcIP="192.168.100.20:31814" resp=200
2023-08-25T20:40:55.894005549+02:00 stderr F I0825 18:40:55.893754       1 pathrecorder.go:241] kube-scheduler: "/healthz" satisfied by exact match
2023-08-25T20:40:49.094584292+02:00 stderr F I0825 18:40:49.094422       1 round_trippers.go:553] PUT https://192.168.100.1:6443/apis/coordination.k8s.io/v1/namespaces/kube-system/leases/kube-scheduler?timeout=5s 200 OK in 9 milliseconds
2023-08-25T20:41:13.62863459+02:00 stderr F I0825 18:41:13.628380       1 round_trippers.go:553] POST https://192.168.100.1:6443/apis/authorization.k8s.io/v1/subjectaccessreviews?timeout=10s 201 Created in 4 milliseconds
2023-08-25T20:41:01.190868165+02:00 stderr F I0825 18:41:01.190726       1 round_trippers.go:553] PUT https://192.168.100.1:6443/apis/coordination.k8s.io/v1/namespaces/kube-system/leases/kube-scheduler?timeout=5s 200 OK in 7 milliseconds
2023-08-25T20:41:04.329956892+02:00 stderr F I0825 18:41:04.329842       1 eventhandlers.go:161] "Delete event for unscheduled pod" pod="default/kbench-deployment-oid-0-tid-1-778f5d498c-jbs5f"
2023-08-25T20:40:43.041329443+02:00 stderr F I0825 18:40:43.041270       1 leaderelection.go:276] successfully renewed lease kube-system/kube-scheduler
2023-08-25T20:41:07.241185176+02:00 stderr F I0825 18:41:07.240815       1 round_trippers.go:553] PUT https://192.168.100.1:6443/apis/coordination.k8s.io/v1/namespaces/kube-system/leases/kube-scheduler?timeout=5s 200 OK in 10 milliseconds
2023-08-25T20:41:32.667090647+02:00 stderr F I0825 18:41:32.666873       1 eventhandlers.go:206] "Update event for scheduled pod" pod="default/kbench-deployment-oid-0-tid-1-778f5d498c-qlt6g"
2023-08-25T20:41:22.615501637+02:00 stderr F I0825 18:41:22.615219       1 pathrecorder.go:241] kube-scheduler: "/metrics" satisfied by exact match
2023-08-25T20:40:43.923921168+02:00 stderr F I0825 18:40:43.923449       1 eventhandlers.go:206] "Update event for scheduled pod" pod="default/kbench-deployment-oid-0-tid-0-bdb979454-z7gsq"
2023-08-25T20:41:14.350774394+02:00 stderr F I0825 18:41:14.350651       1 eventhandlers.go:118] "Add event for unscheduled pod" pod="default/kbench-deployment-oid-0-tid-1-778f5d498c-xhwqk"
2023-08-25T20:41:04.330791078+02:00 stderr F I0825 18:41:04.330646       1 round_trippers.go:553] POST https://192.168.100.1:6443/api/v1/namespaces/default/pods/kbench-deployment-oid-0-tid-1-778f5d498c-jbs5f/binding 201 Created in 13 milliseconds
2023-08-25T20:40:54.289424095+02:00 stderr F I0825 18:40:54.289076       1 default_binder.go:53] "Attempting to bind pod to node" pod="default/kbench-deployment-oid-0-tid-1-778f5d498c-79tcr" node="w03"
2023-08-25T20:41:25.626206021+02:00 stderr F I0825 18:41:25.625930       1 pathrecorder.go:241] kube-scheduler: "/metrics" satisfied by exact match
2023-08-24T23:40:30.365323841+02:00 stderr F I0824 21:40:30.364814       1 eventhandlers.go:231] "Delete event for scheduled pod" pod="default/kbench-deployment-oid-0-tid-1-778f5d498c-lfqdr"
2023-08-24T23:40:01.99805029+02:00 stderr F I0824 21:40:01.997851       1 default_binder.go:53] "Attempting to bind pod to node" pod="default/kbench-deployment-oid-0-tid-1-778f5d498c-jmp8k" node="w02"
2023-08-24T23:39:52.970303781+02:00 stderr F I0824 21:39:52.970029       1 httplog.go:132] "HTTP" verb="GET" URI="/metrics" latency="22.581164ms" userAgent="Prometheus/2.46.0" audit-ID="" srcIP="192.168.100.20:1952" resp=200
2023-08-24T23:39:56.617357322+02:00 stderr F I0824 21:39:56.617179       1 leaderelection.go:276] successfully renewed lease kube-system/kube-scheduler
2023-08-24T23:40:08.717205271+02:00 stderr F I0824 21:40:08.717035       1 leaderelection.go:276] successfully renewed lease kube-system/kube-scheduler
2023-08-24T23:40:22.177459721+02:00 stderr F I0824 21:40:22.177282       1 eventhandlers.go:206] "Update event for scheduled pod" pod="default/kbench-deployment-oid-0-tid-1-778f5d498c-lfqdr"
2023-08-24T23:40:12.032562416+02:00 stderr F I0824 21:40:12.032197       1 default_binder.go:53] "Attempting to bind pod to node" pod="default/kbench-deployment-oid-0-tid-0-bdb979454-tzqrg" node="w03"
2023-08-24T23:40:04.967128518+02:00 stderr F I0824 21:40:04.966870       1 httplog.go:132] "HTTP" verb="GET" URI="/metrics" latency="21.424118ms" userAgent="Prometheus/2.46.0" audit-ID="" srcIP="192.168.100.20:1952" resp=200
2023-08-24T23:39:51.991293814+02:00 stderr F I0824 21:39:51.991205       1 eventhandlers.go:186] "Add event for scheduled pod" pod="default/kbench-deployment-oid-0-tid-1-778f5d498c-vn6dq"
2023-08-24T23:39:58.944521183+02:00 stderr F I0824 21:39:58.944304       1 pathrecorder.go:241] kube-scheduler: "/metrics" satisfied by exact match
2023-08-24T23:40:22.844245417+02:00 stderr F I0824 21:40:22.844023       1 round_trippers.go:553] PUT https://192.168.100.1:6443/apis/coordination.k8s.io/v1/namespaces/kube-system/leases/kube-scheduler?timeout=5s 200 OK in 10 milliseconds
2023-08-24T23:40:30.336897042+02:00 stderr F I0824 21:40:30.336541       1 eventhandlers.go:231] "Delete event for scheduled pod" pod="default/kbench-deployment-oid-0-tid-0-bdb979454-zgzqp"
2023-08-24T23:40:01.994406905+02:00 stderr F I0824 21:40:01.994217       1 scheduling_queue.go:1133] "About to try and schedule pod" pod="default/kbench-deployment-oid-0-tid-1-778f5d498c-jmp8k"
2023-08-24T23:40:12.04740882+02:00 stderr F I0824 21:40:12.047312       1 cache.go:401] "Finished binding for pod, can be expired" podKey="5ffe56cc-7beb-4fd4-bc61-2d10c300a4e8" pod="default/kbench-deployment-oid-0-tid-1-778f5d498c-f8qnc"
2023-08-24T23:40:12.045480146+02:00 stderr F I0824 21:40:12.045344       1 eventhandlers.go:161] "Delete event for unscheduled pod" pod="default/kbench-deployment-oid-0-tid-0-bdb979454-tzqrg"
2023-08-24T23:40:26.878605629+02:00 stderr F I0824 21:40:26.878433       1 leaderelection.go:276] successfully renewed lease kube-system/kube-scheduler
2023-08-24T23:40:30.273655462+02:00 stderr F I0824 21:40:30.273370       1 eventhandlers.go:206] "Update event for scheduled pod" pod="default/kbench-deployment-oid-0-tid-0-bdb979454-zgzqp"
2023-08-24T23:40:30.29329234+02:00 stderr F I0824 21:40:30.293179       1 eventhandlers.go:206] "Update event for scheduled pod" pod="default/kbench-deployment-oid-0-tid-1-778f5d498c-9xmgr"
2023-08-24T23:39:54.589095186+02:00 stderr F I0824 21:39:54.588889       1 round_trippers.go:553] PUT https://192.168.100.1:6443/apis/coordination.k8s.io/v1/namespaces/kube-system/leases/kube-scheduler?timeout=5s 200 OK in 9 milliseconds
2023-08-24T23:40:22.196975385+02:00 stderr F I0824 21:40:22.196837       1 eventhandlers.go:206] "Update event for scheduled pod" pod="default/kbench-deployment-oid-0-tid-1-778f5d498c-vn6dq"
2023-08-24T23:40:12.748267739+02:00 stderr F I0824 21:40:12.748157       1 leaderelection.go:276] successfully renewed lease kube-system/kube-scheduler
2023-08-24T23:40:16.955182662+02:00 stderr F I0824 21:40:16.954878       1 round_trippers.go:553] POST https://192.168.100.1:6443/apis/authorization.k8s.io/v1/subjectaccessreviews?timeout=10s 201 Created in 5 milliseconds
2023-08-24T23:39:50.207661697+02:00 stderr F I0824 21:39:50.207422       1 pathrecorder.go:241] kube-scheduler: "/healthz" satisfied by exact match
2023-08-24T23:40:12.045484456+02:00 stderr F I0824 21:40:12.045362       1 eventhandlers.go:186] "Add event for scheduled pod" pod="default/kbench-deployment-oid-0-tid-1-778f5d498c-f8qnc"
2023-08-24T23:40:30.309500307+02:00 stderr F I0824 21:40:30.309211       1 eventhandlers.go:206] "Update event for scheduled pod" pod="default/kbench-deployment-oid-0-tid-1-778f5d498c-f8qnc"
2023-08-24T23:40:26.878462867+02:00 stderr F I0824 21:40:26.878217       1 round_trippers.go:553] PUT https://192.168.100.1:6443/apis/coordination.k8s.io/v1/namespaces/kube-system/leases/kube-scheduler?timeout=5s 200 OK in 12 milliseconds
2023-08-24T23:40:19.945163501+02:00 stderr F I0824 21:40:19.944728       1 pathrecorder.go:241] kube-scheduler: "/metrics" satisfied by exact match
2023-08-24T23:40:12.028177126+02:00 stderr F I0824 21:40:12.028098       1 eventhandlers.go:118] "Add event for unscheduled pod" pod="default/kbench-deployment-oid-0-tid-1-778f5d498c-f8qnc"
2023-08-24T23:40:02.002688822+02:00 stderr F I0824 21:40:02.002575       1 round_trippers.go:553] POST https://192.168.100.1:6443/api/v1/namespaces/default/pods/kbench-deployment-oid-0-tid-0-bdb979454-nw8z7/binding 201 Created in 10 milliseconds
2023-08-24T23:40:00.641406927+02:00 stderr F I0824 21:40:00.641197       1 round_trippers.go:553] GET https://192.168.100.1:6443/apis/coordination.k8s.io/v1/namespaces/kube-system/leases/kube-scheduler?timeout=5s 200 OK in 5 milliseconds
2023-08-24T23:40:24.859416776+02:00 stderr F I0824 21:40:24.859152       1 leaderelection.go:276] successfully renewed lease kube-system/kube-scheduler
2023-08-24T23:39:52.003880754+02:00 stderr F I0824 21:39:52.003548       1 round_trippers.go:553] POST https://192.168.100.1:6443/apis/events.k8s.io/v1/namespaces/default/events 201 Created in 13 milliseconds
2023-08-24T23:39:51.988147951+02:00 stderr F I0824 21:39:51.988064       1 cache.go:401] "Finished binding for pod, can be expired" podKey="f341066c-68a3-45ae-851e-7150903c1388" pod="default/kbench-deployment-oid-0-tid-1-778f5d498c-vn6dq"
2023-08-24T23:39:48.544080712+02:00 stderr F I0824 21:39:48.543942       1 leaderelection.go:276] successfully renewed lease kube-system/kube-scheduler
2023-08-24T23:39:51.989850768+02:00 stderr F I0824 21:39:51.989404       1 eventhandlers.go:161] "Delete event for unscheduled pod" pod="default/kbench-deployment-oid-0-tid-0-bdb979454-zgzqp"
2023-08-24T23:40:30.241796011+02:00 stderr F I0824 21:40:30.241334       1 eventhandlers.go:206] "Update event for scheduled pod" pod="default/kbench-deployment-oid-0-tid-0-bdb979454-q6572"
2023-08-24T23:40:12.03338042+02:00 stderr F I0824 21:40:12.033243       1 default_binder.go:53] "Attempting to bind pod to node" pod="default/kbench-deployment-oid-0-tid-1-778f5d498c-f8qnc" node="w01"
2023-08-24T23:40:30.30477742+02:00 stderr F I0824 21:40:30.304457       1 eventhandlers.go:231] "Delete event for scheduled pod" pod="default/kbench-deployment-oid-0-tid-0-bdb979454-tzqrg"
2023-08-24T23:40:06.697786556+02:00 stderr F I0824 21:40:06.697503       1 round_trippers.go:553] PUT https://192.168.100.1:6443/apis/coordination.k8s.io/v1/namespaces/kube-system/leases/kube-scheduler?timeout=5s 200 OK in 8 milliseconds
2023-08-24T23:40:12.06156936+02:00 stderr F I0824 21:40:12.061448       1 round_trippers.go:553] POST https://192.168.100.1:6443/apis/events.k8s.io/v1/namespaces/default/events 201 Created in 12 milliseconds
2023-08-24T23:40:12.046434084+02:00 stderr F I0824 21:40:12.046334       1 cache.go:401] "Finished binding for pod, can be expired" podKey="c4292048-9b8f-44be-b982-903932cd070f" pod="default/kbench-deployment-oid-0-tid-0-bdb979454-tzqrg"
2023-08-24T23:40:12.047604655+02:00 stderr F I0824 21:40:12.047489       1 schedule_one.go:252] "Successfully bound pod to node" pod="default/kbench-deployment-oid-0-tid-1-778f5d498c-f8qnc" node="w01" evaluatedNodes=5 feasibleNodes=3
2023-08-24T23:40:30.351058994+02:00 stderr F I0824 21:40:30.350921       1 eventhandlers.go:231] "Delete event for scheduled pod" pod="default/kbench-deployment-oid-0-tid-1-778f5d498c-f8qnc"
2023-08-24T23:40:12.058405605+02:00 stderr F I0824 21:40:12.058250       1 round_trippers.go:553] POST https://192.168.100.1:6443/apis/events.k8s.io/v1/namespaces/default/events 201 Created in 11 milliseconds
2023-08-24T23:40:07.957477115+02:00 stderr F I0824 21:40:07.957194       1 httplog.go:132] "HTTP" verb="GET" URI="/metrics" latency="12.856627ms" userAgent="Prometheus/2.46.0" audit-ID="" srcIP="192.168.100.20:1952" resp=200
2023-08-24T23:39:50.550259211+02:00 stderr F I0824 21:39:50.550021       1 round_trippers.go:553] GET https://192.168.100.1:6443/apis/coordination.k8s.io/v1/namespaces/kube-system/leases/kube-scheduler?timeout=5s 200 OK in 5 milliseconds
2023-08-24T23:40:20.207976476+02:00 stderr F I0824 21:40:20.207498       1 pathrecorder.go:241] kube-scheduler: "/healthz" satisfied by exact match
2023-08-24T23:40:02.006829463+02:00 stderr F I0824 21:40:02.006606       1 eventhandlers.go:186] "Add event for scheduled pod" pod="default/kbench-deployment-oid-0-tid-1-778f5d498c-jmp8k"
2023-08-24T23:40:30.252986288+02:00 stderr F I0824 21:40:30.252886       1 eventhandlers.go:206] "Update event for scheduled pod" pod="default/kbench-deployment-oid-0-tid-0-bdb979454-rwlps"
2023-08-24T23:40:20.208012969+02:00 stderr F I0824 21:40:20.207616       1 httplog.go:132] "HTTP" verb="GET" URI="/healthz" latency="167.998µs" userAgent="kube-probe/1.27" audit-ID="" srcIP="127.0.0.1:53036" resp=200
2023-08-24T23:40:16.955225339+02:00 stderr F I0824 21:40:16.955127       1 pathrecorder.go:241] kube-scheduler: "/metrics" satisfied by exact match
2023-08-24T23:40:04.95621325+02:00 stderr F I0824 21:40:04.955901       1 round_trippers.go:553] POST https://192.168.100.1:6443/apis/authorization.k8s.io/v1/subjectaccessreviews?timeout=10s 201 Created in 5 milliseconds
2023-08-24T23:39:58.623837404+02:00 stderr F I0824 21:39:58.623569       1 round_trippers.go:553] GET https://192.168.100.1:6443/apis/coordination.k8s.io/v1/namespaces/kube-system/leases/kube-scheduler?timeout=5s 200 OK in 5 milliseconds
2023-08-24T23:40:02.015560427+02:00 stderr F I0824 21:40:02.015390       1 round_trippers.go:553] POST https://192.168.100.1:6443/apis/events.k8s.io/v1/namespaces/default/events 201 Created in 12 milliseconds
2023-08-24T23:39:51.97741087+02:00 stderr F I0824 21:39:51.976836       1 default_binder.go:53] "Attempting to bind pod to node" pod="default/kbench-deployment-oid-0-tid-0-bdb979454-zgzqp" node="w02"
2023-08-24T23:39:50.558714832+02:00 stderr F I0824 21:39:50.558624       1 leaderelection.go:276] successfully renewed lease kube-system/kube-scheduler
2023-08-24T23:40:12.046390308+02:00 stderr F I0824 21:40:12.046221       1 round_trippers.go:553] POST https://192.168.100.1:6443/api/v1/namespaces/default/pods/kbench-deployment-oid-0-tid-0-bdb979454-tzqrg/binding 201 Created in 13 milliseconds
2023-08-24T23:40:22.193276873+02:00 stderr F I0824 21:40:22.191784       1 eventhandlers.go:206] "Update event for scheduled pod" pod="default/kbench-deployment-oid-0-tid-1-778f5d498c-jmp8k"
2023-08-24T23:39:51.977062034+02:00 stderr F I0824 21:39:51.975285       1 eventhandlers.go:118] "Add event for unscheduled pod" pod="default/kbench-deployment-oid-0-tid-1-778f5d498c-vn6dq"
2023-08-24T23:40:01.994195248+02:00 stderr F I0824 21:40:01.994062       1 eventhandlers.go:118] "Add event for unscheduled pod" pod="default/kbench-deployment-oid-0-tid-1-778f5d498c-jmp8k"
2023-08-24T23:40:07.945068455+02:00 stderr F I0824 21:40:07.944556       1 pathrecorder.go:241] kube-scheduler: "/metrics" satisfied by exact match
2023-08-24T23:40:04.671185453+02:00 stderr F I0824 21:40:04.670911       1 round_trippers.go:553] GET https://192.168.100.1:6443/apis/coordination.k8s.io/v1/namespaces/kube-system/leases/kube-scheduler?timeout=5s 200 OK in 4 milliseconds
2023-08-24T23:40:02.003318416+02:00 stderr F I0824 21:40:02.003121       1 cache.go:401] "Finished binding for pod, can be expired" podKey="d03efc6e-e181-4c1b-a628-90ace00160b5" pod="default/kbench-deployment-oid-0-tid-0-bdb979454-nw8z7"
2023-08-24T23:40:20.810830856+02:00 stderr F I0824 21:40:20.810067       1 round_trippers.go:553] GET https://192.168.100.1:6443/apis/coordination.k8s.io/v1/namespaces/kube-system/leases/kube-scheduler?timeout=5s 200 OK in 4 milliseconds
2023-08-24T23:39:52.955599407+02:00 stderr F I0824 21:39:52.955417       1 round_trippers.go:553] POST https://192.168.100.1:6443/apis/authorization.k8s.io/v1/subjectaccessreviews?timeout=10s 201 Created in 3 milliseconds
2023-08-24T23:40:30.324001096+02:00 stderr F I0824 21:40:30.323703       1 eventhandlers.go:206] "Update event for scheduled pod" pod="default/kbench-deployment-oid-0-tid-1-778f5d498c-lfqdr"
2023-08-24T23:40:28.895140836+02:00 stderr F I0824 21:40:28.894727       1 round_trippers.go:553] PUT https://192.168.100.1:6443/apis/coordination.k8s.io/v1/namespaces/kube-system/leases/kube-scheduler?timeout=5s 200 OK in 9 milliseconds
2023-08-24T23:39:51.991180913+02:00 stderr F I0824 21:39:51.989439       1 eventhandlers.go:186] "Add event for scheduled pod" pod="default/kbench-deployment-oid-0-tid-0-bdb979454-zgzqp"
2023-08-24T23:40:13.242140552+02:00 stderr F I0824 21:40:13.241944       1 eventhandlers.go:206] "Update event for scheduled pod" pod="default/kbench-deployment-oid-0-tid-0-bdb979454-tzqrg"
2023-08-24T23:39:51.975244117+02:00 stderr F I0824 21:39:51.972086       1 scheduling_queue.go:419] "Pod moved to an internal scheduling queue" pod="default/kbench-deployment-oid-0-tid-0-bdb979454-zgzqp" event="PodAdd" queue="Active"
2023-08-24T23:40:04.680584389+02:00 stderr F I0824 21:40:04.680499       1 leaderelection.go:276] successfully renewed lease kube-system/kube-scheduler
2023-08-24T23:40:16.788586668+02:00 stderr F I0824 21:40:16.788497       1 leaderelection.go:276] successfully renewed lease kube-system/kube-scheduler
2023-08-24T23:39:46.961393874+02:00 stderr F I0824 21:39:46.960981       1 httplog.go:132] "HTTP" verb="GET" URI="/metrics" latency="16.922418ms" userAgent="Prometheus/2.46.0" audit-ID="" srcIP="192.168.100.20:1952" resp=200
2023-08-24T23:40:12.072195564+02:00 stderr F I0824 21:40:12.071580       1 eventhandlers.go:206] "Update event for scheduled pod" pod="default/kbench-deployment-oid-0-tid-0-bdb979454-tzqrg"
2023-08-24T23:40:02.020389733+02:00 stderr F I0824 21:40:02.020228       1 round_trippers.go:553] POST https://192.168.100.1:6443/apis/events.k8s.io/v1/namespaces/default/events 201 Created in 12 milliseconds
2023-08-24T23:39:54.579413786+02:00 stderr F I0824 21:39:54.579024       1 round_trippers.go:553] GET https://192.168.100.1:6443/apis/coordination.k8s.io/v1/namespaces/kube-system/leases/kube-scheduler?timeout=5s 200 OK in 5 milliseconds
2023-08-24T23:40:28.963001+02:00 stderr F I0824 21:40:28.962797       1 pathrecorder.go:241] kube-scheduler: "/metrics" satisfied by exact match
2023-08-24T23:40:12.029567717+02:00 stderr F I0824 21:40:12.029406       1 scheduling_queue.go:419] "Pod moved to an internal scheduling queue" pod="default/kbench-deployment-oid-0-tid-1-778f5d498c-f8qnc" event="PodAdd" queue="Active"
2023-08-24T23:40:04.68050709+02:00 stderr F I0824 21:40:04.680289       1 round_trippers.go:553] PUT https://192.168.100.1:6443/apis/coordination.k8s.io/v1/namespaces/kube-system/leases/kube-scheduler?timeout=5s 200 OK in 8 milliseconds
2023-08-24T23:39:51.991121424+02:00 stderr F I0824 21:39:51.991004       1 eventhandlers.go:161] "Delete event for unscheduled pod" pod="default/kbench-deployment-oid-0-tid-1-778f5d498c-vn6dq"
2023-08-24T23:39:58.957299354+02:00 stderr F I0824 21:39:58.956934       1 httplog.go:132] "HTTP" verb="GET" URI="/metrics" latency="12.757849ms" userAgent="Prometheus/2.46.0" audit-ID="" srcIP="192.168.100.20:1952" resp=200
2023-08-24T23:40:02.665938886+02:00 stderr F I0824 21:40:02.665717       1 leaderelection.go:276] successfully renewed lease kube-system/kube-scheduler
2023-08-24T23:39:56.595808427+02:00 stderr F I0824 21:39:56.595524       1 round_trippers.go:553] GET https://192.168.100.1:6443/apis/coordination.k8s.io/v1/namespaces/kube-system/leases/kube-scheduler?timeout=5s 200 OK in 5 milliseconds
2023-08-24T23:40:18.794288019+02:00 stderr F I0824 21:40:18.794084       1 round_trippers.go:553] GET https://192.168.100.1:6443/apis/coordination.k8s.io/v1/namespaces/kube-system/leases/kube-scheduler?timeout=5s 200 OK in 5 milliseconds
2023-08-24T23:40:13.945202105+02:00 stderr F I0824 21:40:13.944788       1 pathrecorder.go:241] kube-scheduler: "/metrics" satisfied by exact match
2023-08-24T23:40:30.276527464+02:00 stderr F I0824 21:40:30.276143       1 eventhandlers.go:231] "Delete event for scheduled pod" pod="default/kbench-deployment-oid-0-tid-0-bdb979454-nw8z7"
2023-08-24T23:40:12.026593427+02:00 stderr F I0824 21:40:12.026451       1 scheduling_queue.go:419] "Pod moved to an internal scheduling queue" pod="default/kbench-deployment-oid-0-tid-0-bdb979454-tzqrg" event="PodAdd" queue="Active"
2023-08-24T23:40:20.819155193+02:00 stderr F I0824 21:40:20.818954       1 round_trippers.go:553] PUT https://192.168.100.1:6443/apis/coordination.k8s.io/v1/namespaces/kube-system/leases/kube-scheduler?timeout=5s 200 OK in 8 milliseconds
2023-08-24T23:39:51.977086018+02:00 stderr F I0824 21:39:51.975367       1 scheduling_queue.go:1133] "About to try and schedule pod" pod="default/kbench-deployment-oid-0-tid-0-bdb979454-zgzqp"
2023-08-24T23:39:51.972164535+02:00 stderr F I0824 21:39:51.972015       1 eventhandlers.go:118] "Add event for unscheduled pod" pod="default/kbench-deployment-oid-0-tid-0-bdb979454-zgzqp"
2023-08-24T23:39:55.958620475+02:00 stderr F I0824 21:39:55.958346       1 httplog.go:132] "HTTP" verb="GET" URI="/metrics" latency="13.614664ms" userAgent="Prometheus/2.46.0" audit-ID="" srcIP="192.168.100.20:1952" resp=200
2023-08-24T23:40:30.262571437+02:00 stderr F I0824 21:40:30.262469       1 eventhandlers.go:206] "Update event for scheduled pod" pod="default/kbench-deployment-oid-0-tid-0-bdb979454-tzqrg"
2023-08-24T23:40:00.211224897+02:00 stderr F I0824 21:40:00.210931       1 httplog.go:132] "HTTP" verb="GET" URI="/healthz" latency="255.826µs" userAgent="kube-probe/1.27" audit-ID="" srcIP="127.0.0.1:55626" resp=200
2023-08-24T23:40:03.066792192+02:00 stderr F I0824 21:40:03.066657       1 eventhandlers.go:206] "Update event for scheduled pod" pod="default/kbench-deployment-oid-0-tid-1-778f5d498c-jmp8k"
2023-08-24T23:40:12.02661537+02:00 stderr F I0824 21:40:12.026519       1 scheduling_queue.go:1133] "About to try and schedule pod" pod="default/kbench-deployment-oid-0-tid-0-bdb979454-tzqrg"
2023-08-24T23:40:28.974492953+02:00 stderr F I0824 21:40:28.974129       1 httplog.go:132] "HTTP" verb="GET" URI="/metrics" latency="23.208324ms" userAgent="Prometheus/2.46.0" audit-ID="" srcIP="192.168.100.20:1952" resp=200
2023-08-24T23:40:01.991725798+02:00 stderr F I0824 21:40:01.991428       1 eventhandlers.go:118] "Add event for unscheduled pod" pod="default/kbench-deployment-oid-0-tid-0-bdb979454-nw8z7"
2023-08-24T23:40:20.819190993+02:00 stderr F I0824 21:40:20.819109       1 leaderelection.go:276] successfully renewed lease kube-system/kube-scheduler
2023-08-24T23:40:22.219143185+02:00 stderr F I0824 21:40:22.218869       1 eventhandlers.go:206] "Update event for scheduled pod" pod="default/kbench-deployment-oid-0-tid-0-bdb979454-zgzqp"
2023-08-24T23:40:10.208303414+02:00 stderr F I0824 21:40:10.207783       1 httplog.go:132] "HTTP" verb="GET" URI="/healthz" latency="164.785µs" userAgent="kube-probe/1.27" audit-ID="" srcIP="127.0.0.1:34026" resp=200
2023-08-24T23:40:30.209808468+02:00 stderr F I0824 21:40:30.209204       1 pathrecorder.go:241] kube-scheduler: "/healthz" satisfied by exact match
2023-08-24T23:40:22.193263863+02:00 stderr F I0824 21:40:22.191725       1 eventhandlers.go:206] "Update event for scheduled pod" pod="default/kbench-deployment-oid-0-tid-1-778f5d498c-9xmgr"
2023-08-24T23:40:12.026159575+02:00 stderr F I0824 21:40:12.025695       1 eventhandlers.go:118] "Add event for unscheduled pod" pod="default/kbench-deployment-oid-0-tid-0-bdb979454-tzqrg"
2023-08-24T23:40:04.949909882+02:00 stderr F I0824 21:40:04.949604       1 round_trippers.go:553] POST https://192.168.100.1:6443/apis/authentication.k8s.io/v1/tokenreviews 201 Created in 3 milliseconds
2023-08-24T23:40:10.208260166+02:00 stderr F I0824 21:40:10.207635       1 pathrecorder.go:241] kube-scheduler: "/healthz" satisfied by exact match
2023-08-24T23:40:01.944545963+02:00 stderr F I0824 21:40:01.944281       1 pathrecorder.go:241] kube-scheduler: "/metrics" satisfied by exact match
2023-08-24T23:39:51.97709492+02:00 stderr F I0824 21:39:51.976582       1 scheduling_queue.go:1133] "About to try and schedule pod" pod="default/kbench-deployment-oid-0-tid-1-778f5d498c-vn6dq"
2023-08-24T23:40:03.172684225+02:00 stderr F I0824 21:40:03.172511       1 eventhandlers.go:206] "Update event for scheduled pod" pod="default/kbench-deployment-oid-0-tid-0-bdb979454-nw8z7"
2023-08-24T23:40:00.210764494+02:00 stderr F I0824 21:40:00.210271       1 pathrecorder.go:241] kube-scheduler: "/healthz" satisfied by exact match
2023-08-24T23:40:08.706151757+02:00 stderr F I0824 21:40:08.705859       1 round_trippers.go:553] GET https://192.168.100.1:6443/apis/coordination.k8s.io/v1/namespaces/kube-system/leases/kube-scheduler?timeout=5s 200 OK in 6 milliseconds
2023-08-24T23:40:06.697809264+02:00 stderr F I0824 21:40:06.697658       1 leaderelection.go:276] successfully renewed lease kube-system/kube-scheduler
2023-08-24T23:39:51.987949401+02:00 stderr F I0824 21:39:51.987672       1 round_trippers.go:553] POST https://192.168.100.1:6443/api/v1/namespaces/default/pods/kbench-deployment-oid-0-tid-1-778f5d498c-vn6dq/binding 201 Created in 9 milliseconds
2023-08-24T23:40:16.966995441+02:00 stderr F I0824 21:40:16.966728       1 httplog.go:132] "HTTP" verb="GET" URI="/metrics" latency="22.439561ms" userAgent="Prometheus/2.46.0" audit-ID="" srcIP="192.168.100.20:1952" resp=200
2023-08-24T23:40:14.769177124+02:00 stderr F I0824 21:40:14.768999       1 round_trippers.go:553] PUT https://192.168.100.1:6443/apis/coordination.k8s.io/v1/namespaces/kube-system/leases/kube-scheduler?timeout=5s 200 OK in 9 milliseconds
2023-08-24T23:40:12.045488802+02:00 stderr F I0824 21:40:12.045388       1 eventhandlers.go:186] "Add event for scheduled pod" pod="default/kbench-deployment-oid-0-tid-0-bdb979454-tzqrg"
2023-08-24T23:39:52.003344918+02:00 stderr F I0824 21:39:52.003224       1 round_trippers.go:553] POST https://192.168.100.1:6443/apis/events.k8s.io/v1/namespaces/default/events 201 Created in 14 milliseconds
2023-08-24T23:40:10.945337031+02:00 stderr F I0824 21:40:10.944919       1 pathrecorder.go:241] kube-scheduler: "/metrics" satisfied by exact match
2023-08-24T23:40:01.991803509+02:00 stderr F I0824 21:40:01.991503       1 scheduling_queue.go:1133] "About to try and schedule pod" pod="default/kbench-deployment-oid-0-tid-0-bdb979454-nw8z7"
2023-08-24T23:40:10.959426952+02:00 stderr F I0824 21:40:10.958466       1 httplog.go:132] "HTTP" verb="GET" URI="/metrics" latency="13.69496ms" userAgent="Prometheus/2.46.0" audit-ID="" srcIP="192.168.100.20:1952" resp=200
2023-08-24T23:39:51.977080176+02:00 stderr F I0824 21:39:51.975434       1 scheduling_queue.go:419] "Pod moved to an internal scheduling queue" pod="default/kbench-deployment-oid-0-tid-1-778f5d498c-vn6dq" event="PodAdd" queue="Active"
2023-08-24T23:40:02.002448463+02:00 stderr F I0824 21:40:02.002027       1 eventhandlers.go:161] "Delete event for unscheduled pod" pod="default/kbench-deployment-oid-0-tid-0-bdb979454-nw8z7"
2023-08-24T23:40:24.859289304+02:00 stderr F I0824 21:40:24.858885       1 round_trippers.go:553] PUT https://192.168.100.1:6443/apis/coordination.k8s.io/v1/namespaces/kube-system/leases/kube-scheduler?timeout=5s 200 OK in 8 milliseconds
2023-08-24T23:40:10.732493824+02:00 stderr F I0824 21:40:10.732282       1 round_trippers.go:553] PUT https://192.168.100.1:6443/apis/coordination.k8s.io/v1/namespaces/kube-system/leases/kube-scheduler?timeout=5s 200 OK in 7 milliseconds
2023-08-24T23:40:12.076548352+02:00 stderr F I0824 21:40:12.076208       1 eventhandlers.go:206] "Update event for scheduled pod" pod="default/kbench-deployment-oid-0-tid-1-778f5d498c-f8qnc"
2023-08-24T23:40:22.957913317+02:00 stderr F I0824 21:40:22.957609       1 httplog.go:132] "HTTP" verb="GET" URI="/metrics" latency="12.117136ms" userAgent="Prometheus/2.46.0" audit-ID="" srcIP="192.168.100.20:1952" resp=200
2023-08-24T23:39:52.956238472+02:00 stderr F I0824 21:39:52.955935       1 pathrecorder.go:241] kube-scheduler: "/metrics" satisfied by exact match
2023-08-24T23:39:51.977099536+02:00 stderr F I0824 21:39:51.976889       1 schedule_one.go:80] "Attempting to schedule pod" pod="default/kbench-deployment-oid-0-tid-1-778f5d498c-vn6dq"
2023-08-24T23:40:24.850561516+02:00 stderr F I0824 21:40:24.850185       1 round_trippers.go:553] GET https://192.168.100.1:6443/apis/coordination.k8s.io/v1/namespaces/kube-system/leases/kube-scheduler?timeout=5s 200 OK in 5 milliseconds
2023-08-24T23:40:22.84431056+02:00 stderr F I0824 21:40:22.844247       1 leaderelection.go:276] successfully renewed lease kube-system/kube-scheduler
2023-08-24T23:39:55.94512623+02:00 stderr F I0824 21:39:55.944867       1 pathrecorder.go:241] kube-scheduler: "/metrics" satisfied by exact match
2023-08-24T23:40:02.00821617+02:00 stderr F I0824 21:40:02.007644       1 round_trippers.go:553] POST https://192.168.100.1:6443/api/v1/namespaces/default/pods/kbench-deployment-oid-0-tid-1-778f5d498c-jmp8k/binding 201 Created in 9 milliseconds
2023-08-24T23:39:56.617080571+02:00 stderr F I0824 21:39:56.616843       1 round_trippers.go:553] PUT https://192.168.100.1:6443/apis/coordination.k8s.io/v1/namespaces/kube-system/leases/kube-scheduler?timeout=5s 200 OK in 20 milliseconds
2023-08-24T23:40:30.304382205+02:00 stderr F I0824 21:40:30.303926       1 eventhandlers.go:231] "Delete event for scheduled pod" pod="default/kbench-deployment-oid-0-tid-0-bdb979454-rwlps"
2023-08-24T23:40:16.948656028+02:00 stderr F I0824 21:40:16.948330       1 round_trippers.go:553] POST https://192.168.100.1:6443/apis/authentication.k8s.io/v1/tokenreviews 201 Created in 3 milliseconds
2023-08-24T23:40:16.78849479+02:00 stderr F I0824 21:40:16.788313       1 round_trippers.go:553] PUT https://192.168.100.1:6443/apis/coordination.k8s.io/v1/namespaces/kube-system/leases/kube-scheduler?timeout=5s 200 OK in 10 milliseconds
2023-08-24T23:39:50.558419278+02:00 stderr F I0824 21:39:50.558293       1 round_trippers.go:553] PUT https://192.168.100.1:6443/apis/coordination.k8s.io/v1/namespaces/kube-system/leases/kube-scheduler?timeout=5s 200 OK in 7 milliseconds
2023-08-24T23:40:02.008267231+02:00 stderr F I0824 21:40:02.007810       1 schedule_one.go:252] "Successfully bound pod to node" pod="default/kbench-deployment-oid-0-tid-1-778f5d498c-jmp8k" node="w02" evaluatedNodes=5 feasibleNodes=3
2023-08-24T23:40:02.002631315+02:00 stderr F I0824 21:40:02.002067       1 eventhandlers.go:186] "Add event for scheduled pod" pod="default/kbench-deployment-oid-0-tid-0-bdb979454-nw8z7"
2023-08-24T23:39:49.96616588+02:00 stderr F I0824 21:39:49.965932       1 pathrecorder.go:241] kube-scheduler: "/metrics" satisfied by exact match
2023-08-24T23:40:12.046649113+02:00 stderr F I0824 21:40:12.046546       1 round_trippers.go:553] POST https://192.168.100.1:6443/api/v1/namespaces/default/pods/kbench-deployment-oid-0-tid-1-778f5d498c-f8qnc/binding 201 Created in 12 milliseconds
2023-08-24T23:40:28.885184688+02:00 stderr F I0824 21:40:28.884918       1 round_trippers.go:553] GET https://192.168.100.1:6443/apis/coordination.k8s.io/v1/namespaces/kube-system/leases/kube-scheduler?timeout=5s 200 OK in 6 milliseconds
2023-08-24T23:40:12.026659788+02:00 stderr F I0824 21:40:12.026540       1 schedule_one.go:80] "Attempting to schedule pod" pod="default/kbench-deployment-oid-0-tid-0-bdb979454-tzqrg"
2023-08-24T23:40:18.804882934+02:00 stderr F I0824 21:40:18.804772       1 leaderelection.go:276] successfully renewed lease kube-system/kube-scheduler
2023-08-24T23:39:58.634910424+02:00 stderr F I0824 21:39:58.634693       1 round_trippers.go:553] PUT https://192.168.100.1:6443/apis/coordination.k8s.io/v1/namespaces/kube-system/leases/kube-scheduler?timeout=5s 200 OK in 10 milliseconds
2023-08-24T23:39:48.53413666+02:00 stderr F I0824 21:39:48.533800       1 round_trippers.go:553] GET https://192.168.100.1:6443/apis/coordination.k8s.io/v1/namespaces/kube-system/leases/kube-scheduler?timeout=5s 200 OK in 5 milliseconds
2023-08-24T23:39:52.572745681+02:00 stderr F I0824 21:39:52.572633       1 leaderelection.go:276] successfully renewed lease kube-system/kube-scheduler
2023-08-24T23:40:12.739542604+02:00 stderr F I0824 21:40:12.739095       1 round_trippers.go:553] GET https://192.168.100.1:6443/apis/coordination.k8s.io/v1/namespaces/kube-system/leases/kube-scheduler?timeout=5s 200 OK in 5 milliseconds
2023-08-24T23:40:22.218899608+02:00 stderr F I0824 21:40:22.218529       1 eventhandlers.go:206] "Update event for scheduled pod" pod="default/kbench-deployment-oid-0-tid-0-bdb979454-tzqrg"
2023-08-24T23:40:30.360080558+02:00 stderr F I0824 21:40:30.359963       1 eventhandlers.go:231] "Delete event for scheduled pod" pod="default/kbench-deployment-oid-0-tid-1-778f5d498c-jmp8k"
2023-08-24T23:40:01.994210669+02:00 stderr F I0824 21:40:01.994110       1 scheduling_queue.go:419] "Pod moved to an internal scheduling queue" pod="default/kbench-deployment-oid-0-tid-1-778f5d498c-jmp8k" event="PodAdd" queue="Active"
2023-08-24T23:39:53.0393646+02:00 stderr F I0824 21:39:53.038900       1 eventhandlers.go:206] "Update event for scheduled pod" pod="default/kbench-deployment-oid-0-tid-0-bdb979454-zgzqp"
2023-08-24T23:40:14.759622235+02:00 stderr F I0824 21:40:14.759302       1 round_trippers.go:553] GET https://192.168.100.1:6443/apis/coordination.k8s.io/v1/namespaces/kube-system/leases/kube-scheduler?timeout=5s 200 OK in 4 milliseconds
2023-08-24T23:40:00.651550289+02:00 stderr F I0824 21:40:00.651285       1 round_trippers.go:553] PUT https://192.168.100.1:6443/apis/coordination.k8s.io/v1/namespaces/kube-system/leases/kube-scheduler?timeout=5s 200 OK in 9 milliseconds
2023-08-24T23:39:52.018848732+02:00 stderr F I0824 21:39:52.018566       1 eventhandlers.go:206] "Update event for scheduled pod" pod="default/kbench-deployment-oid-0-tid-1-778f5d498c-vn6dq"
2023-08-24T23:39:51.977090416+02:00 stderr F I0824 21:39:51.975589       1 schedule_one.go:80] "Attempting to schedule pod" pod="default/kbench-deployment-oid-0-tid-0-bdb979454-zgzqp"
2023-08-24T23:39:52.572688506+02:00 stderr F I0824 21:39:52.572489       1 round_trippers.go:553] PUT https://192.168.100.1:6443/apis/coordination.k8s.io/v1/namespaces/kube-system/leases/kube-scheduler?timeout=5s 200 OK in 6 milliseconds
2023-08-24T23:39:53.145240299+02:00 stderr F I0824 21:39:53.144613       1 eventhandlers.go:206] "Update event for scheduled pod" pod="default/kbench-deployment-oid-0-tid-1-778f5d498c-vn6dq"
2023-08-24T23:40:01.991809899+02:00 stderr F I0824 21:40:01.991544       1 schedule_one.go:80] "Attempting to schedule pod" pod="default/kbench-deployment-oid-0-tid-0-bdb979454-nw8z7"
2023-08-24T23:40:13.957448327+02:00 stderr F I0824 21:40:13.957162       1 httplog.go:132] "HTTP" verb="GET" URI="/metrics" latency="12.538982ms" userAgent="Prometheus/2.46.0" audit-ID="" srcIP="192.168.100.20:1952" resp=200
2023-08-24T23:39:54.589262343+02:00 stderr F I0824 21:39:54.589091       1 leaderelection.go:276] successfully renewed lease kube-system/kube-scheduler
2023-08-24T23:40:16.777362498+02:00 stderr F I0824 21:40:16.777017       1 round_trippers.go:553] GET https://192.168.100.1:6443/apis/coordination.k8s.io/v1/namespaces/kube-system/leases/kube-scheduler?timeout=5s 200 OK in 4 milliseconds
2023-08-24T23:40:18.804833291+02:00 stderr F I0824 21:40:18.804577       1 round_trippers.go:553] PUT https://192.168.100.1:6443/apis/coordination.k8s.io/v1/namespaces/kube-system/leases/kube-scheduler?timeout=5s 200 OK in 9 milliseconds
2023-08-24T23:40:22.94590894+02:00 stderr F I0824 21:40:22.945597       1 pathrecorder.go:241] kube-scheduler: "/metrics" satisfied by exact match
2023-08-24T23:40:12.045469966+02:00 stderr F I0824 21:40:12.045286       1 eventhandlers.go:161] "Delete event for unscheduled pod" pod="default/kbench-deployment-oid-0-tid-1-778f5d498c-f8qnc"
2023-08-24T23:40:01.957811503+02:00 stderr F I0824 21:40:01.957515       1 httplog.go:132] "HTTP" verb="GET" URI="/metrics" latency="13.369489ms" userAgent="Prometheus/2.46.0" audit-ID="" srcIP="192.168.100.20:1952" resp=200
2023-08-24T23:40:02.6654573+02:00 stderr F I0824 21:40:02.665163       1 round_trippers.go:553] PUT https://192.168.100.1:6443/apis/coordination.k8s.io/v1/namespaces/kube-system/leases/kube-scheduler?timeout=5s 200 OK in 7 milliseconds
2023-08-24T23:40:02.006803481+02:00 stderr F I0824 21:40:02.006558       1 eventhandlers.go:161] "Delete event for unscheduled pod" pod="default/kbench-deployment-oid-0-tid-1-778f5d498c-jmp8k"
2023-09-28T00:01:15.942005826+02:00 stderr F I0927 22:01:15.941856       1 leaderelection.go:276] successfully renewed lease kube-system/kube-scheduler
2023-09-28T00:01:05.85295949+02:00 stderr F I0927 22:01:05.852691       1 round_trippers.go:553] GET https://192.168.100.1:6443/apis/coordination.k8s.io/v1/namespaces/kube-system/leases/kube-scheduler?timeout=5s 200 OK in 6 milliseconds
2023-09-28T00:00:58.391154018+02:00 stderr F I0927 22:00:58.390994       1 httplog.go:132] "HTTP" verb="GET" URI="/metrics" latency="13.438034ms" userAgent="Prometheus/2.47.0" audit-ID="" srcIP="192.168.100.20:10377" resp=200
2023-09-28T00:01:22.391772759+02:00 stderr F I0927 22:01:22.391385       1 httplog.go:132] "HTTP" verb="GET" URI="/metrics" latency="10.718044ms" userAgent="Prometheus/2.47.0" audit-ID="" srcIP="192.168.100.20:10377" resp=200
2023-09-28T00:01:22.005261743+02:00 stderr F I0927 22:01:22.004919       1 round_trippers.go:553] GET https://192.168.100.1:6443/apis/coordination.k8s.io/v1/namespaces/kube-system/leases/kube-scheduler?timeout=5s 200 OK in 5 milliseconds
2023-09-28T00:00:58.107926131+02:00 stderr F I0927 22:00:58.107820       1 eventhandlers.go:206] "Update event for scheduled pod" pod="default/kbench-deployment-oid-0-tid-1-778f5d498c-xdchm"
2023-09-28T00:00:58.043908004+02:00 stderr F I0927 22:00:58.043850       1 cache.go:401] "Finished binding for pod, can be expired" podKey="3208fa62-3cd1-499a-b1c7-900aa3deac1f" pod="default/kbench-deployment-oid-0-tid-1-778f5d498c-6b466"
2023-09-28T00:01:13.927010142+02:00 stderr F I0927 22:01:13.926664       1 round_trippers.go:553] PUT https://192.168.100.1:6443/apis/coordination.k8s.io/v1/namespaces/kube-system/leases/kube-scheduler?timeout=5s 200 OK in 7 milliseconds
2023-09-28T00:00:58.043931188+02:00 stderr F I0927 22:00:58.043890       1 schedule_one.go:252] "Successfully bound pod to node" pod="default/kbench-deployment-oid-0-tid-1-778f5d498c-6b466" node="w03" evaluatedNodes=5 feasibleNodes=3
2023-09-28T00:01:07.869883901+02:00 stderr F I0927 22:01:07.869640       1 round_trippers.go:553] GET https://192.168.100.1:6443/apis/coordination.k8s.io/v1/namespaces/kube-system/leases/kube-scheduler?timeout=5s 200 OK in 4 milliseconds
2023-09-28T00:00:58.033572562+02:00 stderr F I0927 22:00:58.033455       1 round_trippers.go:553] POST https://192.168.100.1:6443/api/v1/namespaces/default/pods/kbench-deployment-oid-0-tid-2-cc4784d96-mfl7h/binding 201 Created in 21 milliseconds
2023-09-28T00:00:58.065144934+02:00 stderr F I0927 22:00:58.065070       1 round_trippers.go:553] POST https://192.168.100.1:6443/apis/events.k8s.io/v1/namespaces/default/events 201 Created in 31 milliseconds
2023-09-28T00:01:28.394140636+02:00 stderr F I0927 22:01:28.393942       1 pathrecorder.go:241] kube-scheduler: "/metrics" satisfied by exact match
2023-09-28T00:00:59.537938582+02:00 stderr F I0927 22:00:59.537678       1 eventhandlers.go:206] "Update event for scheduled pod" pod="default/kbench-deployment-oid-0-tid-2-cc4784d96-mfl7h"
2023-09-28T00:01:36.179201025+02:00 stderr F I0927 22:01:36.179057       1 round_trippers.go:553] PUT https://192.168.100.1:6443/apis/coordination.k8s.io/v1/namespaces/kube-system/leases/kube-scheduler?timeout=5s 200 OK in 9 milliseconds
2023-09-28T00:01:04.402253041+02:00 stderr F I0927 22:01:04.401994       1 httplog.go:132] "HTTP" verb="GET" URI="/metrics" latency="24.255206ms" userAgent="Prometheus/2.47.0" audit-ID="" srcIP="192.168.100.20:10377" resp=200
2023-09-28T00:00:58.006975435+02:00 stderr F I0927 22:00:58.006812       1 eventhandlers.go:118] "Add event for unscheduled pod" pod="default/kbench-deployment-oid-0-tid-1-778f5d498c-6b466"
2023-09-28T00:00:58.053059068+02:00 stderr F I0927 22:00:58.052889       1 eventhandlers.go:161] "Delete event for unscheduled pod" pod="default/kbench-deployment-oid-0-tid-1-778f5d498c-xdchm"
2023-09-28T00:00:57.792696467+02:00 stderr F I0927 22:00:57.792456       1 round_trippers.go:553] PUT https://192.168.100.1:6443/apis/coordination.k8s.io/v1/namespaces/kube-system/leases/kube-scheduler?timeout=5s 200 OK in 8 milliseconds
2023-09-28T00:01:10.377682032+02:00 stderr F I0927 22:01:10.377407       1 pathrecorder.go:241] kube-scheduler: "/metrics" satisfied by exact match
2023-09-28T00:00:58.086654698+02:00 stderr F I0927 22:00:58.086469       1 eventhandlers.go:206] "Update event for scheduled pod" pod="default/kbench-deployment-oid-0-tid-2-cc4784d96-mfl7h"
2023-09-28T00:01:31.389730807+02:00 stderr F I0927 22:01:31.389415       1 httplog.go:132] "HTTP" verb="GET" URI="/metrics" latency="10.766964ms" userAgent="Prometheus/2.47.0" audit-ID="" srcIP="192.168.100.20:10377" resp=200
2023-09-28T00:00:51.573217003+02:00 stderr F I0927 22:00:51.572960       1 httplog.go:132] "HTTP" verb="GET" URI="/healthz" latency="231.178µs" userAgent="kube-probe/1.27" audit-ID="" srcIP="127.0.0.1:34352" resp=200
2023-09-28T00:01:36.100236821+02:00 stderr F I0927 22:01:36.099063       1 eventhandlers.go:231] "Delete event for scheduled pod" pod="default/kbench-deployment-oid-0-tid-0-bdb979454-j4htl"
2023-09-28T00:01:28.072689159+02:00 stderr F I0927 22:01:28.072400       1 round_trippers.go:553] GET https://192.168.100.1:6443/apis/coordination.k8s.io/v1/namespaces/kube-system/leases/kube-scheduler?timeout=5s 200 OK in 11 milliseconds
2023-09-28T00:01:16.396235164+02:00 stderr F I0927 22:01:16.395880       1 httplog.go:132] "HTTP" verb="GET" URI="/metrics" latency="18.113412ms" userAgent="Prometheus/2.47.0" audit-ID="" srcIP="192.168.100.20:10377" resp=200
2023-09-28T00:00:52.389249329+02:00 stderr F I0927 22:00:52.388892       1 round_trippers.go:553] POST https://192.168.100.1:6443/apis/authentication.k8s.io/v1/tokenreviews 201 Created in 5 milliseconds
2023-09-28T00:01:17.981143819+02:00 stderr F I0927 22:01:17.980923       1 round_trippers.go:553] PUT https://192.168.100.1:6443/apis/coordination.k8s.io/v1/namespaces/kube-system/leases/kube-scheduler?timeout=5s 200 OK in 28 milliseconds
2023-09-28T00:00:58.007093436+02:00 stderr F I0927 22:00:58.006910       1 eventhandlers.go:118] "Add event for unscheduled pod" pod="default/kbench-deployment-oid-0-tid-2-cc4784d96-mfl7h"
2023-09-28T00:01:36.115548276+02:00 stderr F I0927 22:01:36.115146       1 eventhandlers.go:206] "Update event for scheduled pod" pod="default/kbench-deployment-oid-0-tid-2-cc4784d96-mfl7h"
2023-09-28T00:01:24.045102872+02:00 stderr F I0927 22:01:24.044727       1 round_trippers.go:553] PUT https://192.168.100.1:6443/apis/coordination.k8s.io/v1/namespaces/kube-system/leases/kube-scheduler?timeout=5s 200 OK in 10 milliseconds
2023-09-28T00:00:58.066492918+02:00 stderr F I0927 22:00:58.066313       1 schedule_one.go:252] "Successfully bound pod to node" pod="default/kbench-deployment-oid-0-tid-2-cc4784d96-nxl7k" node="w01" evaluatedNodes=5 feasibleNodes=3
2023-09-28T00:00:58.07372201+02:00 stderr F I0927 22:00:58.073589       1 round_trippers.go:553] POST https://192.168.100.1:6443/apis/events.k8s.io/v1/namespaces/default/events 201 Created in 18 milliseconds
2023-09-28T00:00:53.753444206+02:00 stderr F I0927 22:00:53.753334       1 leaderelection.go:276] successfully renewed lease kube-system/kube-scheduler
2023-09-28T00:00:55.777985432+02:00 stderr F I0927 22:00:55.777844       1 leaderelection.go:276] successfully renewed lease kube-system/kube-scheduler
2023-09-28T00:01:01.378149485+02:00 stderr F I0927 22:01:01.377737       1 pathrecorder.go:241] kube-scheduler: "/metrics" satisfied by exact match
2023-09-28T00:01:31.570132922+02:00 stderr F I0927 22:01:31.569874       1 httplog.go:132] "HTTP" verb="GET" URI="/healthz" latency="165.512µs" userAgent="kube-probe/1.27" audit-ID="" srcIP="127.0.0.1:45372" resp=200
2023-09-28T00:01:34.159734945+02:00 stderr F I0927 22:01:34.159431       1 leaderelection.go:276] successfully renewed lease kube-system/kube-scheduler
2023-09-28T00:00:51.73539489+02:00 stderr F I0927 22:00:51.735164       1 round_trippers.go:553] PUT https://192.168.100.1:6443/apis/coordination.k8s.io/v1/namespaces/kube-system/leases/kube-scheduler?timeout=5s 200 OK in 14 milliseconds
2023-09-28T00:00:55.777952139+02:00 stderr F I0927 22:00:55.777688       1 round_trippers.go:553] PUT https://192.168.100.1:6443/apis/coordination.k8s.io/v1/namespaces/kube-system/leases/kube-scheduler?timeout=5s 200 OK in 8 milliseconds
2023-09-28T00:01:13.920031298+02:00 stderr F I0927 22:01:13.918959       1 round_trippers.go:553] GET https://192.168.100.1:6443/apis/coordination.k8s.io/v1/namespaces/kube-system/leases/kube-scheduler?timeout=5s 200 OK in 5 milliseconds
2023-09-28T00:00:58.007988436+02:00 stderr F I0927 22:00:58.007875       1 scheduling_queue.go:1133] "About to try and schedule pod" pod="default/kbench-deployment-oid-0-tid-0-bdb979454-9wxp9"
2023-09-28T00:01:05.863278981+02:00 stderr F I0927 22:01:05.863132       1 round_trippers.go:553] PUT https://192.168.100.1:6443/apis/coordination.k8s.io/v1/namespaces/kube-system/leases/kube-scheduler?timeout=5s 200 OK in 9 milliseconds
2023-09-28T00:01:22.014156833+02:00 stderr F I0927 22:01:22.013975       1 round_trippers.go:553] PUT https://192.168.100.1:6443/apis/coordination.k8s.io/v1/namespaces/kube-system/leases/kube-scheduler?timeout=5s 200 OK in 8 milliseconds
2023-09-28T00:01:00.033385844+02:00 stderr F I0927 22:01:00.033135       1 eventhandlers.go:206] "Update event for scheduled pod" pod="default/kbench-deployment-oid-0-tid-0-bdb979454-9wxp9"
2023-09-28T00:01:01.568430662+02:00 stderr F I0927 22:01:01.568053       1 pathrecorder.go:241] kube-scheduler: "/healthz" satisfied by exact match
2023-09-28T00:00:58.031185862+02:00 stderr F I0927 22:00:58.031106       1 schedule_one.go:252] "Successfully bound pod to node" pod="default/kbench-deployment-oid-0-tid-0-bdb979454-9wxp9" node="w01" evaluatedNodes=5 feasibleNodes=3
2023-09-28T00:00:58.134130455+02:00 stderr F I0927 22:00:58.133205       1 eventhandlers.go:206] "Update event for scheduled pod" pod="default/kbench-deployment-oid-0-tid-2-cc4784d96-nxl7k"
2023-09-28T00:00:58.033808415+02:00 stderr F I0927 22:00:58.033738       1 schedule_one.go:252] "Successfully bound pod to node" pod="default/kbench-deployment-oid-0-tid-2-cc4784d96-mfl7h" node="w02" evaluatedNodes=5 feasibleNodes=3
2023-09-28T00:01:28.053705665+02:00 stderr F I0927 22:01:28.053434       1 eventhandlers.go:206] "Update event for scheduled pod" pod="default/kbench-deployment-oid-0-tid-0-bdb979454-j4htl"
2023-09-28T00:00:58.007999308+02:00 stderr F I0927 22:00:58.007908       1 schedule_one.go:80] "Attempting to schedule pod" pod="default/kbench-deployment-oid-0-tid-0-bdb979454-9wxp9"
2023-09-28T00:00:58.006551125+02:00 stderr F I0927 22:00:58.006395       1 eventhandlers.go:118] "Add event for unscheduled pod" pod="default/kbench-deployment-oid-0-tid-0-bdb979454-9wxp9"
2023-09-28T00:00:58.010067496+02:00 stderr F I0927 22:00:58.009966       1 scheduling_queue.go:1133] "About to try and schedule pod" pod="default/kbench-deployment-oid-0-tid-1-778f5d498c-6b466"
2023-09-28T00:00:58.067205146+02:00 stderr F I0927 22:00:58.067077       1 round_trippers.go:553] POST https://192.168.100.1:6443/apis/events.k8s.io/v1/namespaces/default/events 201 Created in 35 milliseconds
2023-09-28T00:00:58.010884039+02:00 stderr F I0927 22:00:58.010608       1 default_binder.go:53] "Attempting to bind pod to node" pod="default/kbench-deployment-oid-0-tid-1-778f5d498c-6b466" node="w03"
2023-09-28T00:00:58.043468253+02:00 stderr F I0927 22:00:58.043436       1 round_trippers.go:553] POST https://192.168.100.1:6443/api/v1/namespaces/default/pods/kbench-deployment-oid-0-tid-1-778f5d498c-6b466/binding 201 Created in 32 milliseconds
2023-09-28T00:00:58.066481086+02:00 stderr F I0927 22:00:58.066272       1 cache.go:401] "Finished binding for pod, can be expired" podKey="f4c8bd4e-57ed-4213-8ea4-b4274b5e4491" pod="default/kbench-deployment-oid-0-tid-2-cc4784d96-nxl7k"
2023-09-28T00:00:58.006580061+02:00 stderr F I0927 22:00:58.006460       1 scheduling_queue.go:419] "Pod moved to an internal scheduling queue" pod="default/kbench-deployment-oid-0-tid-0-bdb979454-9wxp9" event="PodAdd" queue="Active"
2023-09-28T00:00:58.011450572+02:00 stderr F I0927 22:00:58.011322       1 default_binder.go:53] "Attempting to bind pod to node" pod="default/kbench-deployment-oid-0-tid-2-cc4784d96-mfl7h" node="w02"
2023-09-28T00:01:34.1588296+02:00 stderr F I0927 22:01:34.158583       1 round_trippers.go:553] PUT https://192.168.100.1:6443/apis/coordination.k8s.io/v1/namespaces/kube-system/leases/kube-scheduler?timeout=5s 200 OK in 29 milliseconds
2023-09-28T00:01:34.12824157+02:00 stderr F I0927 22:01:34.127931       1 round_trippers.go:553] GET https://192.168.100.1:6443/apis/coordination.k8s.io/v1/namespaces/kube-system/leases/kube-scheduler?timeout=5s 200 OK in 5 milliseconds
2023-09-28T00:00:55.377910781+02:00 stderr F I0927 22:00:55.377488       1 pathrecorder.go:241] kube-scheduler: "/metrics" satisfied by exact match
2023-09-28T00:01:16.38815471+02:00 stderr F I0927 22:01:16.387948       1 round_trippers.go:553] POST https://192.168.100.1:6443/apis/authorization.k8s.io/v1/subjectaccessreviews?timeout=10s 201 Created in 4 milliseconds
2023-09-28T00:00:58.121072788+02:00 stderr F I0927 22:00:58.120929       1 eventhandlers.go:206] "Update event for scheduled pod" pod="default/kbench-deployment-oid-0-tid-0-bdb979454-j4htl"
2023-09-28T00:00:58.04432493+02:00 stderr F I0927 22:00:58.044204       1 schedule_one.go:252] "Successfully bound pod to node" pod="default/kbench-deployment-oid-0-tid-0-bdb979454-j4htl" node="w03" evaluatedNodes=5 feasibleNodes=3
2023-09-28T00:01:25.384093022+02:00 stderr F I0927 22:01:25.383038       1 pathrecorder.go:241] kube-scheduler: "/metrics" satisfied by exact match
2023-09-28T00:01:25.393644547+02:00 stderr F I0927 22:01:25.393270       1 httplog.go:132] "HTTP" verb="GET" URI="/metrics" latency="10.500138ms" userAgent="Prometheus/2.47.0" audit-ID="" srcIP="192.168.100.20:10377" resp=200
2023-09-28T00:00:58.042560078+02:00 stderr F I0927 22:00:58.042479       1 eventhandlers.go:186] "Add event for scheduled pod" pod="default/kbench-deployment-oid-0-tid-0-bdb979454-j4htl"
2023-09-28T00:01:19.999672141+02:00 stderr F I0927 22:01:19.998955       1 leaderelection.go:276] successfully renewed lease kube-system/kube-scheduler
2023-09-28T00:00:58.026316217+02:00 stderr F I0927 22:00:58.026227       1 eventhandlers.go:118] "Add event for unscheduled pod" pod="default/kbench-deployment-oid-0-tid-1-778f5d498c-xdchm"
2023-09-28T00:00:58.031765033+02:00 stderr F I0927 22:00:58.031361       1 eventhandlers.go:186] "Add event for scheduled pod" pod="default/kbench-deployment-oid-0-tid-0-bdb979454-9wxp9"
2023-09-28T00:00:58.377963833+02:00 stderr F I0927 22:00:58.377659       1 pathrecorder.go:241] kube-scheduler: "/metrics" satisfied by exact match
2023-09-28T00:00:58.038209766+02:00 stderr F I0927 22:00:58.037573       1 eventhandlers.go:186] "Add event for scheduled pod" pod="default/kbench-deployment-oid-0-tid-1-778f5d498c-6b466"
2023-09-28T00:01:07.391336563+02:00 stderr F I0927 22:01:07.391073       1 httplog.go:132] "HTTP" verb="GET" URI="/metrics" latency="8.956267ms" userAgent="Prometheus/2.47.0" audit-ID="" srcIP="192.168.100.20:10377" resp=200
2023-09-28T00:00:58.010086048+02:00 stderr F I0927 22:00:58.010032       1 default_binder.go:53] "Attempting to bind pod to node" pod="default/kbench-deployment-oid-0-tid-0-bdb979454-9wxp9" node="w01"
2023-09-28T00:01:36.131631869+02:00 stderr F I0927 22:01:36.131189       1 eventhandlers.go:206] "Update event for scheduled pod" pod="default/kbench-deployment-oid-0-tid-2-cc4784d96-nxl7k"
2023-09-28T00:00:58.065125109+02:00 stderr F I0927 22:00:58.065022       1 eventhandlers.go:161] "Delete event for unscheduled pod" pod="default/kbench-deployment-oid-0-tid-2-cc4784d96-nxl7k"
2023-09-28T00:01:34.38935567+02:00 stderr F I0927 22:01:34.388671       1 httplog.go:132] "HTTP" verb="GET" URI="/metrics" latency="9.380661ms" userAgent="Prometheus/2.47.0" audit-ID="" srcIP="192.168.100.20:10377" resp=200
2023-09-28T00:00:58.020421114+02:00 stderr F I0927 22:00:58.020192       1 schedule_one.go:80] "Attempting to schedule pod" pod="default/kbench-deployment-oid-0-tid-0-bdb979454-j4htl"
2023-09-28T00:01:11.91256977+02:00 stderr F I0927 22:01:11.912440       1 leaderelection.go:276] successfully renewed lease kube-system/kube-scheduler
2023-09-28T00:01:15.941964557+02:00 stderr F I0927 22:01:15.941712       1 round_trippers.go:553] PUT https://192.168.100.1:6443/apis/coordination.k8s.io/v1/namespaces/kube-system/leases/kube-scheduler?timeout=5s 200 OK in 8 milliseconds
2023-09-28T00:00:58.037720311+02:00 stderr F I0927 22:00:58.037565       1 eventhandlers.go:161] "Delete event for unscheduled pod" pod="default/kbench-deployment-oid-0-tid-1-778f5d498c-6b466"
2023-09-28T00:01:00.00759381+02:00 stderr F I0927 22:01:00.007352       1 eventhandlers.go:206] "Update event for scheduled pod" pod="default/kbench-deployment-oid-0-tid-2-cc4784d96-nxl7k"
2023-09-28T00:00:58.066241693+02:00 stderr F I0927 22:00:58.066157       1 round_trippers.go:553] POST https://192.168.100.1:6443/api/v1/namespaces/default/pods/kbench-deployment-oid-0-tid-2-cc4784d96-nxl7k/binding 201 Created in 21 milliseconds
2023-09-28T00:01:16.388522541+02:00 stderr F I0927 22:01:16.388354       1 pathrecorder.go:241] kube-scheduler: "/metrics" satisfied by exact match
2023-09-28T00:01:09.897765482+02:00 stderr F I0927 22:01:09.897481       1 round_trippers.go:553] PUT https://192.168.100.1:6443/apis/coordination.k8s.io/v1/namespaces/kube-system/leases/kube-scheduler?timeout=5s 200 OK in 10 milliseconds
2023-09-28T00:01:13.380331753+02:00 stderr F I0927 22:01:13.379998       1 pathrecorder.go:241] kube-scheduler: "/metrics" satisfied by exact match
2023-09-28T00:00:58.026345917+02:00 stderr F I0927 22:00:58.026272       1 scheduling_queue.go:419] "Pod moved to an internal scheduling queue" pod="default/kbench-deployment-oid-0-tid-1-778f5d498c-xdchm" event="PodAdd" queue="Active"
2023-09-28T00:00:58.075574758+02:00 stderr F I0927 22:00:58.075262       1 eventhandlers.go:206] "Update event for scheduled pod" pod="default/kbench-deployment-oid-0-tid-0-bdb979454-9wxp9"
2023-09-28T00:00:55.387767486+02:00 stderr F I0927 22:00:55.387128       1 httplog.go:132] "HTTP" verb="GET" URI="/metrics" latency="9.808108ms" userAgent="Prometheus/2.47.0" audit-ID="" srcIP="192.168.100.20:10377" resp=200
2023-09-28T00:00:59.730556317+02:00 stderr F I0927 22:00:59.730276       1 eventhandlers.go:206] "Update event for scheduled pod" pod="default/kbench-deployment-oid-0-tid-1-778f5d498c-6b466"
2023-09-28T00:00:53.753348438+02:00 stderr F I0927 22:00:53.753165       1 round_trippers.go:553] PUT https://192.168.100.1:6443/apis/coordination.k8s.io/v1/namespaces/kube-system/leases/kube-scheduler?timeout=5s 200 OK in 9 milliseconds
2023-09-28T00:00:58.043451463+02:00 stderr F I0927 22:00:58.043384       1 round_trippers.go:553] POST https://192.168.100.1:6443/api/v1/namespaces/default/pods/kbench-deployment-oid-0-tid-0-bdb979454-j4htl/binding 201 Created in 22 milliseconds
2023-09-28T00:00:58.010726044+02:00 stderr F I0927 22:00:58.010646       1 schedule_one.go:80] "Attempting to schedule pod" pod="default/kbench-deployment-oid-0-tid-2-cc4784d96-mfl7h"
2023-09-28T00:01:05.86349838+02:00 stderr F I0927 22:01:05.863326       1 leaderelection.go:276] successfully renewed lease kube-system/kube-scheduler
2023-09-28T00:00:58.044312924+02:00 stderr F I0927 22:00:58.044171       1 cache.go:401] "Finished binding for pod, can be expired" podKey="309a0c49-fb0a-4269-bf5b-a40dd6b2b0e2" pod="default/kbench-deployment-oid-0-tid-0-bdb979454-j4htl"
2023-09-28T00:01:04.383682869+02:00 stderr F I0927 22:01:04.383439       1 round_trippers.go:553] POST https://192.168.100.1:6443/apis/authentication.k8s.io/v1/tokenreviews 201 Created in 5 milliseconds
2023-09-28T00:00:58.026380145+02:00 stderr F I0927 22:00:58.026314       1 schedule_one.go:80] "Attempting to schedule pod" pod="default/kbench-deployment-oid-0-tid-1-778f5d498c-xdchm"
2023-09-28T00:00:58.00710408+02:00 stderr F I0927 22:00:58.007019       1 scheduling_queue.go:419] "Pod moved to an internal scheduling queue" pod="default/kbench-deployment-oid-0-tid-2-cc4784d96-mfl7h" event="PodAdd" queue="Active"
2023-09-28T00:00:55.76851139+02:00 stderr F I0927 22:00:55.768169       1 round_trippers.go:553] GET https://192.168.100.1:6443/apis/coordination.k8s.io/v1/namespaces/kube-system/leases/kube-scheduler?timeout=5s 200 OK in 5 milliseconds
2023-09-28T00:00:58.03152402+02:00 stderr F I0927 22:00:58.031339       1 eventhandlers.go:161] "Delete event for unscheduled pod" pod="default/kbench-deployment-oid-0-tid-0-bdb979454-9wxp9"
2023-09-28T00:01:30.103229351+02:00 stderr F I0927 22:01:30.103047       1 leaderelection.go:276] successfully renewed lease kube-system/kube-scheduler
2023-09-28T00:01:22.014920301+02:00 stderr F I0927 22:01:22.014605       1 leaderelection.go:276] successfully renewed lease kube-system/kube-scheduler
2023-09-28T00:01:00.059868562+02:00 stderr F I0927 22:01:00.058805       1 eventhandlers.go:206] "Update event for scheduled pod" pod="default/kbench-deployment-oid-0-tid-1-778f5d498c-xdchm"
2023-09-28T00:00:58.055043492+02:00 stderr F I0927 22:00:58.054936       1 schedule_one.go:252] "Successfully bound pod to node" pod="default/kbench-deployment-oid-0-tid-1-778f5d498c-xdchm" node="w01" evaluatedNodes=5 feasibleNodes=3
2023-09-28T00:01:11.912320456+02:00 stderr F I0927 22:01:11.912128       1 round_trippers.go:553] PUT https://192.168.100.1:6443/apis/coordination.k8s.io/v1/namespaces/kube-system/leases/kube-scheduler?timeout=5s 200 OK in 9 milliseconds
2023-09-28T00:01:01.816118846+02:00 stderr F I0927 22:01:01.815780       1 round_trippers.go:553] GET https://192.168.100.1:6443/apis/coordination.k8s.io/v1/namespaces/kube-system/leases/kube-scheduler?timeout=5s 200 OK in 5 milliseconds
2023-09-28T00:01:28.050701743+02:00 stderr F I0927 22:01:28.050561       1 eventhandlers.go:206] "Update event for scheduled pod" pod="default/kbench-deployment-oid-0-tid-1-778f5d498c-6b466"
2023-09-28T00:00:58.027296281+02:00 stderr F I0927 22:00:58.027096       1 default_binder.go:53] "Attempting to bind pod to node" pod="default/kbench-deployment-oid-0-tid-1-778f5d498c-xdchm" node="w01"
2023-09-28T00:01:01.828081452+02:00 stderr F I0927 22:01:01.826728       1 round_trippers.go:553] PUT https://192.168.100.1:6443/apis/coordination.k8s.io/v1/namespaces/kube-system/leases/kube-scheduler?timeout=5s 200 OK in 10 milliseconds
2023-09-28T00:00:58.020399083+02:00 stderr F I0927 22:00:58.020182       1 scheduling_queue.go:1133] "About to try and schedule pod" pod="default/kbench-deployment-oid-0-tid-0-bdb979454-j4htl"
2023-09-28T00:01:24.045120048+02:00 stderr F I0927 22:01:24.044869       1 leaderelection.go:276] successfully renewed lease kube-system/kube-scheduler
2023-09-28T00:00:58.053160753+02:00 stderr F I0927 22:00:58.053071       1 eventhandlers.go:186] "Add event for scheduled pod" pod="default/kbench-deployment-oid-0-tid-1-778f5d498c-xdchm"
2023-09-28T00:01:28.08815323+02:00 stderr F I0927 22:01:28.088036       1 leaderelection.go:276] successfully renewed lease kube-system/kube-scheduler
2023-09-28T00:00:52.39582719+02:00 stderr F I0927 22:00:52.395346       1 round_trippers.go:553] POST https://192.168.100.1:6443/apis/authorization.k8s.io/v1/subjectaccessreviews?timeout=10s 201 Created in 5 milliseconds
2023-09-28T00:00:59.703929452+02:00 stderr F I0927 22:00:59.703768       1 eventhandlers.go:206] "Update event for scheduled pod" pod="default/kbench-deployment-oid-0-tid-0-bdb979454-j4htl"
2023-09-28T00:01:28.053333177+02:00 stderr F I0927 22:01:28.053149       1 eventhandlers.go:206] "Update event for scheduled pod" pod="default/kbench-deployment-oid-0-tid-0-bdb979454-9wxp9"
2023-09-28T00:00:58.030941784+02:00 stderr F I0927 22:00:58.030846       1 round_trippers.go:553] POST https://192.168.100.1:6443/api/v1/namespaces/default/pods/kbench-deployment-oid-0-tid-0-bdb979454-9wxp9/binding 201 Created in 20 milliseconds
2023-09-28T00:00:58.020171792+02:00 stderr F I0927 22:00:58.019995       1 eventhandlers.go:118] "Add event for unscheduled pod" pod="default/kbench-deployment-oid-0-tid-0-bdb979454-j4htl"
2023-09-28T00:00:58.088111281+02:00 stderr F I0927 22:00:58.087993       1 round_trippers.go:553] POST https://192.168.100.1:6443/apis/events.k8s.io/v1/namespaces/default/events 201 Created in 21 milliseconds
2023-09-28T00:00:59.798957956+02:00 stderr F I0927 22:00:59.798700       1 round_trippers.go:553] GET https://192.168.100.1:6443/apis/coordination.k8s.io/v1/namespaces/kube-system/leases/kube-scheduler?timeout=5s 200 OK in 5 milliseconds
2023-09-28T00:00:58.010711864+02:00 stderr F I0927 22:00:58.010559       1 scheduling_queue.go:1133] "About to try and schedule pod" pod="default/kbench-deployment-oid-0-tid-2-cc4784d96-mfl7h"
2023-09-28T00:00:58.065291097+02:00 stderr F I0927 22:00:58.065131       1 eventhandlers.go:186] "Add event for scheduled pod" pod="default/kbench-deployment-oid-0-tid-2-cc4784d96-nxl7k"
2023-09-28T00:01:16.383137926+02:00 stderr F I0927 22:01:16.382945       1 round_trippers.go:553] POST https://192.168.100.1:6443/apis/authentication.k8s.io/v1/tokenreviews 201 Created in 4 milliseconds
2023-09-28T00:01:28.065863145+02:00 stderr F I0927 22:01:28.065674       1 eventhandlers.go:206] "Update event for scheduled pod" pod="default/kbench-deployment-oid-0-tid-2-cc4784d96-mfl7h"
2023-09-28T00:00:58.043429965+02:00 stderr F I0927 22:00:58.043321       1 scheduling_queue.go:1133] "About to try and schedule pod" pod="default/kbench-deployment-oid-0-tid-2-cc4784d96-nxl7k"
2023-09-28T00:00:59.808421481+02:00 stderr F I0927 22:00:59.808242       1 round_trippers.go:553] PUT https://192.168.100.1:6443/apis/coordination.k8s.io/v1/namespaces/kube-system/leases/kube-scheduler?timeout=5s 200 OK in 8 milliseconds
2023-09-28T00:00:51.720752784+02:00 stderr F I0927 22:00:51.720481       1 round_trippers.go:553] GET https://192.168.100.1:6443/apis/coordination.k8s.io/v1/namespaces/kube-system/leases/kube-scheduler?timeout=5s 200 OK in 6 milliseconds
2023-09-28T00:00:58.03117073+02:00 stderr F I0927 22:00:58.031044       1 cache.go:401] "Finished binding for pod, can be expired" podKey="eefaff1b-80ff-48e1-8798-004396d3be77" pod="default/kbench-deployment-oid-0-tid-0-bdb979454-9wxp9"
2023-09-28T00:01:31.37956845+02:00 stderr F I0927 22:01:31.378875       1 pathrecorder.go:241] kube-scheduler: "/metrics" satisfied by exact match
2023-09-28T00:01:13.927052401+02:00 stderr F I0927 22:01:13.926975       1 leaderelection.go:276] successfully renewed lease kube-system/kube-scheduler
2023-09-28T00:01:32.110469437+02:00 stderr F I0927 22:01:32.110089       1 round_trippers.go:553] GET https://192.168.100.1:6443/apis/coordination.k8s.io/v1/namespaces/kube-system/leases/kube-scheduler?timeout=5s 200 OK in 5 milliseconds
2023-09-28T00:00:58.006987768+02:00 stderr F I0927 22:00:58.006880       1 scheduling_queue.go:419] "Pod moved to an internal scheduling queue" pod="default/kbench-deployment-oid-0-tid-1-778f5d498c-6b466" event="PodAdd" queue="Active"
2023-09-28T00:01:34.379816195+02:00 stderr F I0927 22:01:34.379402       1 pathrecorder.go:241] kube-scheduler: "/metrics" satisfied by exact match
2023-09-28T00:01:26.060691311+02:00 stderr F I0927 22:01:26.060562       1 leaderelection.go:276] successfully renewed lease kube-system/kube-scheduler
2023-09-28T00:00:51.73577642+02:00 stderr F I0927 22:00:51.735621       1 leaderelection.go:276] successfully renewed lease kube-system/kube-scheduler
2023-09-28T00:01:15.933049046+02:00 stderr F I0927 22:01:15.932828       1 round_trippers.go:553] GET https://192.168.100.1:6443/apis/coordination.k8s.io/v1/namespaces/kube-system/leases/kube-scheduler?timeout=5s 200 OK in 5 milliseconds
2023-09-28T00:00:58.021208076+02:00 stderr F I0927 22:00:58.020871       1 default_binder.go:53] "Attempting to bind pod to node" pod="default/kbench-deployment-oid-0-tid-0-bdb979454-j4htl" node="w03"
2023-09-28T00:00:58.020375737+02:00 stderr F I0927 22:00:58.020154       1 scheduling_queue.go:419] "Pod moved to an internal scheduling queue" pod="default/kbench-deployment-oid-0-tid-0-bdb979454-j4htl" event="PodAdd" queue="Active"
2023-09-28T00:01:28.389469111+02:00 stderr F I0927 22:01:28.387646       1 round_trippers.go:553] POST https://192.168.100.1:6443/apis/authentication.k8s.io/v1/tokenreviews 201 Created in 5 milliseconds
2023-09-28T00:01:19.999646536+02:00 stderr F I0927 22:01:19.998801       1 round_trippers.go:553] PUT https://192.168.100.1:6443/apis/coordination.k8s.io/v1/namespaces/kube-system/leases/kube-scheduler?timeout=5s 200 OK in 11 milliseconds
2023-09-28T00:00:58.101418262+02:00 stderr F I0927 22:00:58.101288       1 eventhandlers.go:206] "Update event for scheduled pod" pod="default/kbench-deployment-oid-0-tid-1-778f5d498c-6b466"
2023-09-28T00:01:26.060455665+02:00 stderr F I0927 22:01:26.060325       1 round_trippers.go:553] PUT https://192.168.100.1:6443/apis/coordination.k8s.io/v1/namespaces/kube-system/leases/kube-scheduler?timeout=5s 200 OK in 8 milliseconds
2023-09-28T00:00:58.04269693+02:00 stderr F I0927 22:00:58.042638       1 eventhandlers.go:118] "Add event for unscheduled pod" pod="default/kbench-deployment-oid-0-tid-2-cc4784d96-nxl7k"
2023-09-28T00:01:36.103859644+02:00 stderr F I0927 22:01:36.103784       1 eventhandlers.go:206] "Update event for scheduled pod" pod="default/kbench-deployment-oid-0-tid-1-778f5d498c-xdchm"
2023-09-28T00:00:59.808748611+02:00 stderr F I0927 22:00:59.808600       1 leaderelection.go:276] successfully renewed lease kube-system/kube-scheduler
2023-09-28T00:01:04.3880679+02:00 stderr F I0927 22:01:04.387796       1 round_trippers.go:553] POST https://192.168.100.1:6443/apis/authorization.k8s.io/v1/subjectaccessreviews?timeout=10s 201 Created in 3 milliseconds
2023-09-28T00:01:21.566836249+02:00 stderr F I0927 22:01:21.566674       1 httplog.go:132] "HTTP" verb="GET" URI="/healthz" latency="300.574µs" userAgent="kube-probe/1.27" audit-ID="" srcIP="127.0.0.1:33718" resp=200
2023-09-28T00:01:36.16229322+02:00 stderr F I0927 22:01:36.162143       1 eventhandlers.go:231] "Delete event for scheduled pod" pod="default/kbench-deployment-oid-0-tid-2-cc4784d96-nxl7k"
2023-09-28T00:00:58.043408315+02:00 stderr F I0927 22:00:58.043193       1 scheduling_queue.go:419] "Pod moved to an internal scheduling queue" pod="default/kbench-deployment-oid-0-tid-2-cc4784d96-nxl7k" event="PodAdd" queue="Active"
2023-09-28T00:01:22.381012196+02:00 stderr F I0927 22:01:22.380784       1 pathrecorder.go:241] kube-scheduler: "/metrics" satisfied by exact match
2023-09-28T00:00:58.064851111+02:00 stderr F I0927 22:00:58.064673       1 round_trippers.go:553] POST https://192.168.100.1:6443/apis/events.k8s.io/v1/namespaces/default/events 201 Created in 20 milliseconds
2023-09-28T00:01:19.987269404+02:00 stderr F I0927 22:01:19.987042       1 round_trippers.go:553] GET https://192.168.100.1:6443/apis/coordination.k8s.io/v1/namespaces/kube-system/leases/kube-scheduler?timeout=5s 200 OK in 5 milliseconds
2023-09-28T00:01:07.878960515+02:00 stderr F I0927 22:01:07.878801       1 leaderelection.go:276] successfully renewed lease kube-system/kube-scheduler
2023-09-28T00:01:28.402209263+02:00 stderr F I0927 22:01:28.401993       1 httplog.go:132] "HTTP" verb="GET" URI="/metrics" latency="19.801812ms" userAgent="Prometheus/2.47.0" audit-ID="" srcIP="192.168.100.20:10377" resp=200
2023-09-28T00:00:57.784022409+02:00 stderr F I0927 22:00:57.783659       1 round_trippers.go:553] GET https://192.168.100.1:6443/apis/coordination.k8s.io/v1/namespaces/kube-system/leases/kube-scheduler?timeout=5s 200 OK in 4 milliseconds
2023-09-28T00:01:32.121274865+02:00 stderr F I0927 22:01:32.120996       1 leaderelection.go:276] successfully renewed lease kube-system/kube-scheduler
2023-09-28T00:00:58.034787581+02:00 stderr F I0927 22:00:58.034593       1 eventhandlers.go:161] "Delete event for unscheduled pod" pod="default/kbench-deployment-oid-0-tid-2-cc4784d96-mfl7h"
2023-09-28T00:01:04.388429798+02:00 stderr F I0927 22:01:04.388187       1 pathrecorder.go:241] kube-scheduler: "/metrics" satisfied by exact match
2023-09-28T00:01:01.385793761+02:00 stderr F I0927 22:01:01.385398       1 httplog.go:132] "HTTP" verb="GET" URI="/metrics" latency="7.785307ms" userAgent="Prometheus/2.47.0" audit-ID="" srcIP="192.168.100.20:10377" resp=200
2023-09-28T00:00:57.793041428+02:00 stderr F I0927 22:00:57.792760       1 leaderelection.go:276] successfully renewed lease kube-system/kube-scheduler
2023-09-28T00:01:21.566536236+02:00 stderr F I0927 22:01:21.566389       1 pathrecorder.go:241] kube-scheduler: "/healthz" satisfied by exact match
2023-09-28T00:00:58.042545465+02:00 stderr F I0927 22:00:58.042425       1 eventhandlers.go:161] "Delete event for unscheduled pod" pod="default/kbench-deployment-oid-0-tid-0-bdb979454-j4htl"
2023-09-28T00:00:58.045036376+02:00 stderr F I0927 22:00:58.044935       1 default_binder.go:53] "Attempting to bind pod to node" pod="default/kbench-deployment-oid-0-tid-2-cc4784d96-nxl7k" node="w01"
2023-09-28T00:01:28.087815108+02:00 stderr F I0927 22:01:28.087682       1 round_trippers.go:553] PUT https://192.168.100.1:6443/apis/coordination.k8s.io/v1/namespaces/kube-system/leases/kube-scheduler?timeout=5s 200 OK in 14 milliseconds
2023-09-28T00:00:52.396223097+02:00 stderr F I0927 22:00:52.396012       1 pathrecorder.go:241] kube-scheduler: "/metrics" satisfied by exact match
2023-09-28T00:00:58.06318168+02:00 stderr F I0927 22:00:58.063076       1 round_trippers.go:553] POST https://192.168.100.1:6443/apis/events.k8s.io/v1/namespaces/default/events 201 Created in 18 milliseconds
2023-08-24T23:36:36.893218389+02:00 stderr F I0824 21:36:36.892641       1 eventhandlers.go:206] "Update event for scheduled pod" pod="default/kbench-deployment-oid-0-tid-1-778f5d498c-qndv9"
2023-08-24T23:36:36.917958653+02:00 stderr F I0824 21:36:36.917817       1 eventhandlers.go:206] "Update event for scheduled pod" pod="default/kbench-deployment-oid-0-tid-0-bdb979454-94xsm"
2023-08-24T23:36:36.926504837+02:00 stderr F I0824 21:36:36.926409       1 round_trippers.go:553] GET https://192.168.100.1:6443/apis/coordination.k8s.io/v1/namespaces/kube-system/leases/kube-scheduler?timeout=5s 200 OK in 6 milliseconds
2023-08-24T23:36:36.933855592+02:00 stderr F I0824 21:36:36.933409       1 round_trippers.go:553] PUT https://192.168.100.1:6443/apis/coordination.k8s.io/v1/namespaces/kube-system/leases/kube-scheduler?timeout=5s 200 OK in 6 milliseconds
2023-08-24T23:36:36.933895624+02:00 stderr F I0824 21:36:36.933824       1 leaderelection.go:276] successfully renewed lease kube-system/kube-scheduler
2023-08-24T23:36:37.044511456+02:00 stderr F I0824 21:36:37.044337       1 eventhandlers.go:206] "Update event for scheduled pod" pod="default/kbench-deployment-oid-0-tid-0-bdb979454-bwdjj"
2023-08-24T23:36:37.09016355+02:00 stderr F I0824 21:36:37.090016       1 eventhandlers.go:206] "Update event for scheduled pod" pod="default/kbench-deployment-oid-0-tid-2-cc4784d96-tc7gc"
2023-08-24T23:36:37.112724993+02:00 stderr F I0824 21:36:37.112504       1 eventhandlers.go:206] "Update event for scheduled pod" pod="default/kbench-deployment-oid-0-tid-2-cc4784d96-c8wx7"
2023-08-24T23:36:37.134613169+02:00 stderr F I0824 21:36:37.134453       1 eventhandlers.go:206] "Update event for scheduled pod" pod="default/kbench-deployment-oid-0-tid-1-778f5d498c-8h8bz"
2023-08-24T23:36:38.751395109+02:00 stderr F I0824 21:36:38.751058       1 pathrecorder.go:241] kube-scheduler: "/metrics" satisfied by exact match
2023-08-24T23:36:38.76407839+02:00 stderr F I0824 21:36:38.763552       1 httplog.go:132] "HTTP" verb="GET" URI="/metrics" latency="12.646663ms" userAgent="Prometheus/2.46.0" audit-ID="" srcIP="192.168.100.20:59412" resp=200
2023-08-24T23:36:38.946158211+02:00 stderr F I0824 21:36:38.945828       1 round_trippers.go:553] GET https://192.168.100.1:6443/apis/coordination.k8s.io/v1/namespaces/kube-system/leases/kube-scheduler?timeout=5s 200 OK in 7 milliseconds
2023-08-24T23:36:38.956242818+02:00 stderr F I0824 21:36:38.955962       1 round_trippers.go:553] PUT https://192.168.100.1:6443/apis/coordination.k8s.io/v1/namespaces/kube-system/leases/kube-scheduler?timeout=5s 200 OK in 9 milliseconds
2023-08-24T23:36:38.956416768+02:00 stderr F I0824 21:36:38.956246       1 leaderelection.go:276] successfully renewed lease kube-system/kube-scheduler
2023-08-24T23:36:39.038694028+02:00 stderr F I0824 21:36:39.038219       1 pathrecorder.go:241] kube-scheduler: "/healthz" satisfied by exact match
2023-08-24T23:36:39.038721795+02:00 stderr F I0824 21:36:39.038508       1 httplog.go:132] "HTTP" verb="GET" URI="/healthz" latency="370.088µs" userAgent="kube-probe/1.27" audit-ID="" srcIP="127.0.0.1:57334" resp=200
2023-08-24T23:36:40.96396833+02:00 stderr F I0824 21:36:40.963586       1 round_trippers.go:553] GET https://192.168.100.1:6443/apis/coordination.k8s.io/v1/namespaces/kube-system/leases/kube-scheduler?timeout=5s 200 OK in 5 milliseconds
2023-08-24T23:36:40.975310874+02:00 stderr F I0824 21:36:40.975015       1 round_trippers.go:553] PUT https://192.168.100.1:6443/apis/coordination.k8s.io/v1/namespaces/kube-system/leases/kube-scheduler?timeout=5s 200 OK in 10 milliseconds
2023-08-24T23:36:40.975573123+02:00 stderr F I0824 21:36:40.975417       1 leaderelection.go:276] successfully renewed lease kube-system/kube-scheduler
2023-08-24T23:36:41.758043819+02:00 stderr F I0824 21:36:41.757708       1 round_trippers.go:553] POST https://192.168.100.1:6443/apis/authentication.k8s.io/v1/tokenreviews 201 Created in 5 milliseconds
2023-08-24T23:36:41.764158743+02:00 stderr F I0824 21:36:41.763485       1 round_trippers.go:553] POST https://192.168.100.1:6443/apis/authorization.k8s.io/v1/subjectaccessreviews?timeout=10s 201 Created in 4 milliseconds
2023-08-24T23:36:41.765037291+02:00 stderr F I0824 21:36:41.764641       1 pathrecorder.go:241] kube-scheduler: "/metrics" satisfied by exact match
2023-08-24T23:36:41.777642879+02:00 stderr F I0824 21:36:41.777358       1 httplog.go:132] "HTTP" verb="GET" URI="/metrics" latency="25.731535ms" userAgent="Prometheus/2.46.0" audit-ID="" srcIP="192.168.100.20:59412" resp=200
2023-08-24T23:36:42.987090821+02:00 stderr F I0824 21:36:42.986593       1 round_trippers.go:553] GET https://192.168.100.1:6443/apis/coordination.k8s.io/v1/namespaces/kube-system/leases/kube-scheduler?timeout=5s 200 OK in 5 milliseconds
2023-08-24T23:36:42.996267659+02:00 stderr F I0824 21:36:42.996086       1 round_trippers.go:553] PUT https://192.168.100.1:6443/apis/coordination.k8s.io/v1/namespaces/kube-system/leases/kube-scheduler?timeout=5s 200 OK in 9 milliseconds
2023-08-24T23:36:42.996588643+02:00 stderr F I0824 21:36:42.996452       1 leaderelection.go:276] successfully renewed lease kube-system/kube-scheduler
2023-08-24T23:36:44.751441179+02:00 stderr F I0824 21:36:44.751003       1 pathrecorder.go:241] kube-scheduler: "/metrics" satisfied by exact match
2023-08-24T23:36:44.766242113+02:00 stderr F I0824 21:36:44.765815       1 httplog.go:132] "HTTP" verb="GET" URI="/metrics" latency="14.983732ms" userAgent="Prometheus/2.46.0" audit-ID="" srcIP="192.168.100.20:59412" resp=200
2023-08-24T23:36:45.003184136+02:00 stderr F I0824 21:36:45.002587       1 round_trippers.go:553] GET https://192.168.100.1:6443/apis/coordination.k8s.io/v1/namespaces/kube-system/leases/kube-scheduler?timeout=5s 200 OK in 5 milliseconds
2023-08-24T23:36:45.018882735+02:00 stderr F I0824 21:36:45.018490       1 round_trippers.go:553] PUT https://192.168.100.1:6443/apis/coordination.k8s.io/v1/namespaces/kube-system/leases/kube-scheduler?timeout=5s 200 OK in 15 milliseconds
2023-08-24T23:36:45.018913208+02:00 stderr F I0824 21:36:45.018717       1 leaderelection.go:276] successfully renewed lease kube-system/kube-scheduler
2023-08-24T23:36:47.027676752+02:00 stderr F I0824 21:36:47.027406       1 round_trippers.go:553] GET https://192.168.100.1:6443/apis/coordination.k8s.io/v1/namespaces/kube-system/leases/kube-scheduler?timeout=5s 200 OK in 7 milliseconds
2023-08-24T23:36:47.037094042+02:00 stderr F I0824 21:36:47.036762       1 round_trippers.go:553] PUT https://192.168.100.1:6443/apis/coordination.k8s.io/v1/namespaces/kube-system/leases/kube-scheduler?timeout=5s 200 OK in 8 milliseconds
2023-08-24T23:36:47.037398368+02:00 stderr F I0824 21:36:47.037198       1 leaderelection.go:276] successfully renewed lease kube-system/kube-scheduler
2023-08-24T23:36:47.76611128+02:00 stderr F I0824 21:36:47.765375       1 pathrecorder.go:241] kube-scheduler: "/metrics" satisfied by exact match
2023-08-24T23:36:47.779187792+02:00 stderr F I0824 21:36:47.778810       1 httplog.go:132] "HTTP" verb="GET" URI="/metrics" latency="13.6865ms" userAgent="Prometheus/2.46.0" audit-ID="" srcIP="192.168.100.20:59412" resp=200
2023-08-24T23:36:49.033874304+02:00 stderr F I0824 21:36:49.033624       1 pathrecorder.go:241] kube-scheduler: "/healthz" satisfied by exact match
2023-08-24T23:36:49.033906302+02:00 stderr F I0824 21:36:49.033784       1 httplog.go:132] "HTTP" verb="GET" URI="/healthz" latency="205.169µs" userAgent="kube-probe/1.27" audit-ID="" srcIP="127.0.0.1:48004" resp=200
2023-08-24T23:36:49.045147604+02:00 stderr F I0824 21:36:49.044916       1 round_trippers.go:553] GET https://192.168.100.1:6443/apis/coordination.k8s.io/v1/namespaces/kube-system/leases/kube-scheduler?timeout=5s 200 OK in 6 milliseconds
2023-08-24T23:36:49.055150861+02:00 stderr F I0824 21:36:49.054988       1 round_trippers.go:553] PUT https://192.168.100.1:6443/apis/coordination.k8s.io/v1/namespaces/kube-system/leases/kube-scheduler?timeout=5s 200 OK in 9 milliseconds
2023-08-24T23:36:49.055366844+02:00 stderr F I0824 21:36:49.055217       1 leaderelection.go:276] successfully renewed lease kube-system/kube-scheduler
2023-08-24T23:36:50.752845718+02:00 stderr F I0824 21:36:50.752380       1 pathrecorder.go:241] kube-scheduler: "/metrics" satisfied by exact match
2023-08-24T23:36:50.765260869+02:00 stderr F I0824 21:36:50.764812       1 httplog.go:132] "HTTP" verb="GET" URI="/metrics" latency="12.604512ms" userAgent="Prometheus/2.46.0" audit-ID="" srcIP="192.168.100.20:59412" resp=200
2023-08-24T23:36:51.062137752+02:00 stderr F I0824 21:36:51.061684       1 round_trippers.go:553] GET https://192.168.100.1:6443/apis/coordination.k8s.io/v1/namespaces/kube-system/leases/kube-scheduler?timeout=5s 200 OK in 5 milliseconds
2023-08-24T23:36:51.073352162+02:00 stderr F I0824 21:36:51.073027       1 round_trippers.go:553] PUT https://192.168.100.1:6443/apis/coordination.k8s.io/v1/namespaces/kube-system/leases/kube-scheduler?timeout=5s 200 OK in 10 milliseconds
2023-08-24T23:36:51.073450538+02:00 stderr F I0824 21:36:51.073313       1 leaderelection.go:276] successfully renewed lease kube-system/kube-scheduler
2023-08-24T23:36:53.080774009+02:00 stderr F I0824 21:36:53.080454       1 round_trippers.go:553] GET https://192.168.100.1:6443/apis/coordination.k8s.io/v1/namespaces/kube-system/leases/kube-scheduler?timeout=5s 200 OK in 6 milliseconds
2023-08-24T23:36:53.088877056+02:00 stderr F I0824 21:36:53.088636       1 round_trippers.go:553] PUT https://192.168.100.1:6443/apis/coordination.k8s.io/v1/namespaces/kube-system/leases/kube-scheduler?timeout=5s 200 OK in 7 milliseconds
2023-08-24T23:36:53.088898918+02:00 stderr F I0824 21:36:53.088825       1 leaderelection.go:276] successfully renewed lease kube-system/kube-scheduler
2023-08-24T23:36:53.757542973+02:00 stderr F I0824 21:36:53.757338       1 round_trippers.go:553] POST https://192.168.100.1:6443/apis/authentication.k8s.io/v1/tokenreviews 201 Created in 4 milliseconds
2023-08-24T23:36:53.763318521+02:00 stderr F I0824 21:36:53.763155       1 round_trippers.go:553] POST https://192.168.100.1:6443/apis/authorization.k8s.io/v1/subjectaccessreviews?timeout=10s 201 Created in 4 milliseconds
2023-08-24T23:36:53.763903026+02:00 stderr F I0824 21:36:53.763669       1 pathrecorder.go:241] kube-scheduler: "/metrics" satisfied by exact match
2023-08-24T23:36:53.781989694+02:00 stderr F I0824 21:36:53.781532       1 httplog.go:132] "HTTP" verb="GET" URI="/metrics" latency="29.416079ms" userAgent="Prometheus/2.46.0" audit-ID="" srcIP="192.168.100.20:59412" resp=200
2023-08-24T23:36:55.096366405+02:00 stderr F I0824 21:36:55.096027       1 round_trippers.go:553] GET https://192.168.100.1:6443/apis/coordination.k8s.io/v1/namespaces/kube-system/leases/kube-scheduler?timeout=5s 200 OK in 5 milliseconds
2023-08-24T23:36:55.105418195+02:00 stderr F I0824 21:36:55.105205       1 round_trippers.go:553] PUT https://192.168.100.1:6443/apis/coordination.k8s.io/v1/namespaces/kube-system/leases/kube-scheduler?timeout=5s 200 OK in 8 milliseconds
2023-08-24T23:36:55.105603967+02:00 stderr F I0824 21:36:55.105470       1 leaderelection.go:276] successfully renewed lease kube-system/kube-scheduler
2023-08-24T23:36:56.755693989+02:00 stderr F I0824 21:36:56.755250       1 pathrecorder.go:241] kube-scheduler: "/metrics" satisfied by exact match
2023-08-24T23:36:56.770028217+02:00 stderr F I0824 21:36:56.769426       1 httplog.go:132] "HTTP" verb="GET" URI="/metrics" latency="14.324293ms" userAgent="Prometheus/2.46.0" audit-ID="" srcIP="192.168.100.20:59412" resp=200
2023-08-24T23:36:57.118357183+02:00 stderr F I0824 21:36:57.118009       1 round_trippers.go:553] GET https://192.168.100.1:6443/apis/coordination.k8s.io/v1/namespaces/kube-system/leases/kube-scheduler?timeout=5s 200 OK in 11 milliseconds
2023-08-24T23:36:57.129366709+02:00 stderr F I0824 21:36:57.129032       1 round_trippers.go:553] PUT https://192.168.100.1:6443/apis/coordination.k8s.io/v1/namespaces/kube-system/leases/kube-scheduler?timeout=5s 200 OK in 10 milliseconds
2023-08-24T23:36:57.129505491+02:00 stderr F I0824 21:36:57.129316       1 leaderelection.go:276] successfully renewed lease kube-system/kube-scheduler
2023-08-24T23:36:59.033522883+02:00 stderr F I0824 21:36:59.033206       1 pathrecorder.go:241] kube-scheduler: "/healthz" satisfied by exact match
2023-08-24T23:36:59.033800294+02:00 stderr F I0824 21:36:59.033421       1 httplog.go:132] "HTTP" verb="GET" URI="/healthz" latency="271.563µs" userAgent="kube-probe/1.27" audit-ID="" srcIP="127.0.0.1:45878" resp=200
2023-08-24T23:36:59.136339071+02:00 stderr F I0824 21:36:59.136127       1 round_trippers.go:553] GET https://192.168.100.1:6443/apis/coordination.k8s.io/v1/namespaces/kube-system/leases/kube-scheduler?timeout=5s 200 OK in 6 milliseconds
2023-08-24T23:36:59.145354059+02:00 stderr F I0824 21:36:59.145096       1 round_trippers.go:553] PUT https://192.168.100.1:6443/apis/coordination.k8s.io/v1/namespaces/kube-system/leases/kube-scheduler?timeout=5s 200 OK in 8 milliseconds
2023-08-24T23:36:59.145654712+02:00 stderr F I0824 21:36:59.145317       1 leaderelection.go:276] successfully renewed lease kube-system/kube-scheduler
2023-08-24T23:36:59.753270896+02:00 stderr F I0824 21:36:59.752884       1 pathrecorder.go:241] kube-scheduler: "/metrics" satisfied by exact match
2023-08-24T23:36:59.767857083+02:00 stderr F I0824 21:36:59.767589       1 httplog.go:132] "HTTP" verb="GET" URI="/metrics" latency="14.826691ms" userAgent="Prometheus/2.46.0" audit-ID="" srcIP="192.168.100.20:59412" resp=200
2023-08-24T23:37:01.151847561+02:00 stderr F I0824 21:37:01.151334       1 round_trippers.go:553] GET https://192.168.100.1:6443/apis/coordination.k8s.io/v1/namespaces/kube-system/leases/kube-scheduler?timeout=5s 200 OK in 5 milliseconds
2023-08-24T23:37:01.160539709+02:00 stderr F I0824 21:37:01.160382       1 round_trippers.go:553] PUT https://192.168.100.1:6443/apis/coordination.k8s.io/v1/namespaces/kube-system/leases/kube-scheduler?timeout=5s 200 OK in 8 milliseconds
2023-08-24T23:37:01.160904115+02:00 stderr F I0824 21:37:01.160755       1 leaderelection.go:276] successfully renewed lease kube-system/kube-scheduler
2023-08-24T23:37:02.765017718+02:00 stderr F I0824 21:37:02.764774       1 pathrecorder.go:241] kube-scheduler: "/metrics" satisfied by exact match
2023-08-24T23:37:02.778145543+02:00 stderr F I0824 21:37:02.777657       1 httplog.go:132] "HTTP" verb="GET" URI="/metrics" latency="13.050631ms" userAgent="Prometheus/2.46.0" audit-ID="" srcIP="192.168.100.20:59412" resp=200
2023-08-24T23:37:03.167484168+02:00 stderr F I0824 21:37:03.167280       1 round_trippers.go:553] GET https://192.168.100.1:6443/apis/coordination.k8s.io/v1/namespaces/kube-system/leases/kube-scheduler?timeout=5s 200 OK in 4 milliseconds
2023-08-24T23:37:03.178177287+02:00 stderr F I0824 21:37:03.178033       1 round_trippers.go:553] PUT https://192.168.100.1:6443/apis/coordination.k8s.io/v1/namespaces/kube-system/leases/kube-scheduler?timeout=5s 200 OK in 10 milliseconds
2023-08-24T23:37:03.178428698+02:00 stderr F I0824 21:37:03.178223       1 leaderelection.go:276] successfully renewed lease kube-system/kube-scheduler
2023-08-24T23:37:05.187341609+02:00 stderr F I0824 21:37:05.187035       1 round_trippers.go:553] GET https://192.168.100.1:6443/apis/coordination.k8s.io/v1/namespaces/kube-system/leases/kube-scheduler?timeout=5s 200 OK in 7 milliseconds
2023-08-24T23:37:05.209279728+02:00 stderr F I0824 21:37:05.208897       1 round_trippers.go:553] PUT https://192.168.100.1:6443/apis/coordination.k8s.io/v1/namespaces/kube-system/leases/kube-scheduler?timeout=5s 200 OK in 21 milliseconds
2023-08-24T23:37:05.209889045+02:00 stderr F I0824 21:37:05.209601       1 leaderelection.go:276] successfully renewed lease kube-system/kube-scheduler
2023-08-24T23:37:05.693247236+02:00 stderr F I0824 21:37:05.693094       1 eventhandlers.go:206] "Update event for scheduled pod" pod="default/kbench-deployment-oid-0-tid-1-778f5d498c-qndv9"
2023-08-24T23:37:05.704054056+02:00 stderr F I0824 21:37:05.700440       1 eventhandlers.go:206] "Update event for scheduled pod" pod="default/kbench-deployment-oid-0-tid-2-cc4784d96-tc7gc"
2023-08-24T23:37:05.70406696+02:00 stderr F I0824 21:37:05.700509       1 eventhandlers.go:206] "Update event for scheduled pod" pod="default/kbench-deployment-oid-0-tid-1-778f5d498c-8h8bz"
2023-08-24T23:37:05.710059778+02:00 stderr F I0824 21:37:05.709449       1 eventhandlers.go:206] "Update event for scheduled pod" pod="default/kbench-deployment-oid-0-tid-2-cc4784d96-c8wx7"
2023-08-24T23:37:05.722702907+02:00 stderr F I0824 21:37:05.722562       1 eventhandlers.go:206] "Update event for scheduled pod" pod="default/kbench-deployment-oid-0-tid-0-bdb979454-94xsm"
2023-08-24T23:37:05.72746345+02:00 stderr F I0824 21:37:05.727294       1 eventhandlers.go:206] "Update event for scheduled pod" pod="default/kbench-deployment-oid-0-tid-0-bdb979454-bwdjj"
2023-08-24T23:37:05.75425349+02:00 stderr F I0824 21:37:05.753797       1 round_trippers.go:553] POST https://192.168.100.1:6443/apis/authentication.k8s.io/v1/tokenreviews 201 Created in 2 milliseconds
2023-08-24T23:37:05.757545633+02:00 stderr F I0824 21:37:05.757334       1 round_trippers.go:553] POST https://192.168.100.1:6443/apis/authorization.k8s.io/v1/subjectaccessreviews?timeout=10s 201 Created in 3 milliseconds
2023-08-24T23:37:05.757598847+02:00 stderr F I0824 21:37:05.757526       1 pathrecorder.go:241] kube-scheduler: "/metrics" satisfied by exact match
2023-08-24T23:37:05.768658856+02:00 stderr F I0824 21:37:05.768263       1 httplog.go:132] "HTTP" verb="GET" URI="/metrics" latency="17.112888ms" userAgent="Prometheus/2.46.0" audit-ID="" srcIP="192.168.100.20:59412" resp=200
2023-08-24T23:37:07.217184624+02:00 stderr F I0824 21:37:07.216731       1 round_trippers.go:553] GET https://192.168.100.1:6443/apis/coordination.k8s.io/v1/namespaces/kube-system/leases/kube-scheduler?timeout=5s 200 OK in 6 milliseconds
2023-08-24T23:37:07.229463943+02:00 stderr F I0824 21:37:07.229228       1 round_trippers.go:553] PUT https://192.168.100.1:6443/apis/coordination.k8s.io/v1/namespaces/kube-system/leases/kube-scheduler?timeout=5s 200 OK in 12 milliseconds
2023-08-24T23:37:07.229709792+02:00 stderr F I0824 21:37:07.229465       1 leaderelection.go:276] successfully renewed lease kube-system/kube-scheduler
2023-08-24T23:37:08.752051824+02:00 stderr F I0824 21:37:08.751396       1 pathrecorder.go:241] kube-scheduler: "/metrics" satisfied by exact match
2023-08-24T23:37:08.766823399+02:00 stderr F I0824 21:37:08.766287       1 httplog.go:132] "HTTP" verb="GET" URI="/metrics" latency="15.04668ms" userAgent="Prometheus/2.46.0" audit-ID="" srcIP="192.168.100.20:59412" resp=200
2023-08-24T23:37:09.034550348+02:00 stderr F I0824 21:37:09.034139       1 pathrecorder.go:241] kube-scheduler: "/healthz" satisfied by exact match
2023-08-24T23:37:09.034582108+02:00 stderr F I0824 21:37:09.034324       1 httplog.go:132] "HTTP" verb="GET" URI="/healthz" latency="227.402µs" userAgent="kube-probe/1.27" audit-ID="" srcIP="127.0.0.1:59190" resp=200
2023-08-24T23:37:09.237500858+02:00 stderr F I0824 21:37:09.237019       1 round_trippers.go:553] GET https://192.168.100.1:6443/apis/coordination.k8s.io/v1/namespaces/kube-system/leases/kube-scheduler?timeout=5s 200 OK in 7 milliseconds
2023-08-24T23:37:09.249050485+02:00 stderr F I0824 21:37:09.248807       1 round_trippers.go:553] PUT https://192.168.100.1:6443/apis/coordination.k8s.io/v1/namespaces/kube-system/leases/kube-scheduler?timeout=5s 200 OK in 11 milliseconds
2023-08-24T23:37:09.249069291+02:00 stderr F I0824 21:37:09.248949       1 leaderelection.go:276] successfully renewed lease kube-system/kube-scheduler
2023-08-24T23:37:11.256820279+02:00 stderr F I0824 21:37:11.256414       1 round_trippers.go:553] GET https://192.168.100.1:6443/apis/coordination.k8s.io/v1/namespaces/kube-system/leases/kube-scheduler?timeout=5s 200 OK in 5 milliseconds
2023-08-24T23:37:11.276354066+02:00 stderr F I0824 21:37:11.276051       1 round_trippers.go:553] PUT https://192.168.100.1:6443/apis/coordination.k8s.io/v1/namespaces/kube-system/leases/kube-scheduler?timeout=5s 200 OK in 19 milliseconds
2023-08-24T23:37:11.276914083+02:00 stderr F I0824 21:37:11.276653       1 leaderelection.go:276] successfully renewed lease kube-system/kube-scheduler
2023-08-24T23:37:11.766360796+02:00 stderr F I0824 21:37:11.765948       1 pathrecorder.go:241] kube-scheduler: "/metrics" satisfied by exact match
2023-08-24T23:37:11.781612391+02:00 stderr F I0824 21:37:11.781219       1 httplog.go:132] "HTTP" verb="GET" URI="/metrics" latency="15.300888ms" userAgent="Prometheus/2.46.0" audit-ID="" srcIP="192.168.100.20:59412" resp=200
2023-08-24T23:37:13.283050431+02:00 stderr F I0824 21:37:13.282767       1 round_trippers.go:553] GET https://192.168.100.1:6443/apis/coordination.k8s.io/v1/namespaces/kube-system/leases/kube-scheduler?timeout=5s 200 OK in 4 milliseconds
2023-08-24T23:37:13.291580752+02:00 stderr F I0824 21:37:13.291409       1 round_trippers.go:553] PUT https://192.168.100.1:6443/apis/coordination.k8s.io/v1/namespaces/kube-system/leases/kube-scheduler?timeout=5s 200 OK in 8 milliseconds
2023-08-24T23:37:13.291607493+02:00 stderr F I0824 21:37:13.291544       1 leaderelection.go:276] successfully renewed lease kube-system/kube-scheduler
2023-08-24T23:37:13.728872951+02:00 stderr F I0824 21:37:13.728572       1 eventhandlers.go:206] "Update event for scheduled pod" pod="default/kbench-deployment-oid-0-tid-0-bdb979454-94xsm"
2023-08-24T23:37:13.738393289+02:00 stderr F I0824 21:37:13.738039       1 eventhandlers.go:206] "Update event for scheduled pod" pod="default/kbench-deployment-oid-0-tid-0-bdb979454-bwdjj"
2023-08-24T23:37:13.752415164+02:00 stderr F I0824 21:37:13.752242       1 eventhandlers.go:206] "Update event for scheduled pod" pod="default/kbench-deployment-oid-0-tid-1-778f5d498c-8h8bz"
2023-08-24T23:37:13.762140187+02:00 stderr F I0824 21:37:13.762019       1 eventhandlers.go:206] "Update event for scheduled pod" pod="default/kbench-deployment-oid-0-tid-1-778f5d498c-qndv9"
2023-08-24T23:37:13.772833645+02:00 stderr F I0824 21:37:13.772730       1 eventhandlers.go:206] "Update event for scheduled pod" pod="default/kbench-deployment-oid-0-tid-2-cc4784d96-c8wx7"
2023-08-24T23:37:13.778322007+02:00 stderr F I0824 21:37:13.778203       1 eventhandlers.go:231] "Delete event for scheduled pod" pod="default/kbench-deployment-oid-0-tid-0-bdb979454-94xsm"
2023-08-24T23:37:13.783326669+02:00 stderr F I0824 21:37:13.783153       1 eventhandlers.go:231] "Delete event for scheduled pod" pod="default/kbench-deployment-oid-0-tid-0-bdb979454-bwdjj"
2023-08-24T23:37:13.792694025+02:00 stderr F I0824 21:37:13.792489       1 eventhandlers.go:206] "Update event for scheduled pod" pod="default/kbench-deployment-oid-0-tid-2-cc4784d96-tc7gc"
2023-08-24T23:37:13.798984641+02:00 stderr F I0824 21:37:13.798833       1 eventhandlers.go:231] "Delete event for scheduled pod" pod="default/kbench-deployment-oid-0-tid-1-778f5d498c-8h8bz"
2023-08-24T23:37:13.801602742+02:00 stderr F I0824 21:37:13.801368       1 eventhandlers.go:231] "Delete event for scheduled pod" pod="default/kbench-deployment-oid-0-tid-1-778f5d498c-qndv9"
2023-08-24T23:37:13.812762238+02:00 stderr F I0824 21:37:13.812560       1 eventhandlers.go:231] "Delete event for scheduled pod" pod="default/kbench-deployment-oid-0-tid-2-cc4784d96-c8wx7"
2023-08-24T23:37:13.822588982+02:00 stderr F I0824 21:37:13.822392       1 eventhandlers.go:231] "Delete event for scheduled pod" pod="default/kbench-deployment-oid-0-tid-2-cc4784d96-tc7gc"
2023-08-25T21:03:29.655385465+02:00 stderr F I0825 19:03:29.655173       1 eventhandlers.go:206] "Update event for scheduled pod" pod="default/kbench-deployment-oid-0-tid-2-cc4784d96-nxzj9"
2023-08-25T21:04:00.637633777+02:00 stderr F I0825 19:04:00.637264       1 eventhandlers.go:206] "Update event for scheduled pod" pod="default/kbench-deployment-oid-0-tid-2-cc4784d96-fgg89"
2023-08-25T21:03:29.544575353+02:00 stderr F I0825 19:03:29.544373       1 eventhandlers.go:206] "Update event for scheduled pod" pod="monitoring/node-exporter-9rpw6"
2023-08-25T21:03:10.721438649+02:00 stderr F I0825 19:03:10.721225       1 scheduling_queue.go:1133] "About to try and schedule pod" pod="default/kbench-deployment-oid-0-tid-1-778f5d498c-zb2r4"
2023-08-25T21:03:56.569733461+02:00 stderr F I0825 19:03:56.569531       1 round_trippers.go:553] PUT https://192.168.100.1:6443/apis/coordination.k8s.io/v1/namespaces/kube-system/leases/kube-scheduler?timeout=5s 200 OK in 9 milliseconds
2023-08-25T21:03:36.397186733+02:00 stderr F I0825 19:03:36.397040       1 leaderelection.go:276] successfully renewed lease kube-system/kube-scheduler
2023-08-25T21:03:10.722903244+02:00 stderr F I0825 19:03:10.722775       1 default_binder.go:53] "Attempting to bind pod to node" pod="default/kbench-deployment-oid-0-tid-0-bdb979454-jl6ch" node="w03"
2023-08-25T21:03:10.746434641+02:00 stderr F I0825 19:03:10.746372       1 scheduling_queue.go:1133] "About to try and schedule pod" pod="default/kbench-deployment-oid-0-tid-2-cc4784d96-fgg89"
2023-08-25T21:03:15.259846737+02:00 stderr F I0825 19:03:15.259471       1 httplog.go:132] "HTTP" verb="GET" URI="/metrics" latency="26.619468ms" userAgent="Prometheus/2.46.0" audit-ID="" srcIP="192.168.100.20:53397" resp=200
2023-08-25T21:03:10.76940523+02:00 stderr F I0825 19:03:10.769344       1 eventhandlers.go:186] "Add event for scheduled pod" pod="default/kbench-deployment-oid-0-tid-0-bdb979454-qlmd5"
2023-08-25T21:03:42.248238825+02:00 stderr F I0825 19:03:42.247926       1 httplog.go:132] "HTTP" verb="GET" URI="/metrics" latency="13.421522ms" userAgent="Prometheus/2.46.0" audit-ID="" srcIP="192.168.100.20:53397" resp=200
2023-08-25T21:03:15.242642431+02:00 stderr F I0825 19:03:15.242374       1 round_trippers.go:553] POST https://192.168.100.1:6443/apis/authorization.k8s.io/v1/subjectaccessreviews?timeout=10s 201 Created in 3 milliseconds
2023-08-25T21:03:21.232619479+02:00 stderr F I0825 19:03:21.232258       1 pathrecorder.go:241] kube-scheduler: "/metrics" satisfied by exact match
2023-08-25T21:03:20.246810818+02:00 stderr F I0825 19:03:20.246597       1 round_trippers.go:553] PUT https://192.168.100.1:6443/apis/coordination.k8s.io/v1/namespaces/kube-system/leases/kube-scheduler?timeout=5s 200 OK in 9 milliseconds
2023-08-25T21:03:32.730722951+02:00 stderr F I0825 19:03:32.730520       1 httplog.go:132] "HTTP" verb="GET" URI="/healthz" latency="257.607µs" userAgent="kube-probe/1.27" audit-ID="" srcIP="127.0.0.1:47054" resp=200
2023-08-25T21:03:58.590187035+02:00 stderr F I0825 19:03:58.589935       1 round_trippers.go:553] PUT https://192.168.100.1:6443/apis/coordination.k8s.io/v1/namespaces/kube-system/leases/kube-scheduler?timeout=5s 200 OK in 11 milliseconds
2023-08-25T21:03:10.720001426+02:00 stderr F I0825 19:03:10.715968       1 scheduling_queue.go:419] "Pod moved to an internal scheduling queue" pod="default/kbench-deployment-oid-0-tid-2-cc4784d96-f4b9n" event="PodAdd" queue="Active"
2023-08-25T21:03:42.729364147+02:00 stderr F I0825 19:03:42.728781       1 pathrecorder.go:241] kube-scheduler: "/healthz" satisfied by exact match
2023-08-25T21:03:54.237074195+02:00 stderr F I0825 19:03:54.236502       1 pathrecorder.go:241] kube-scheduler: "/metrics" satisfied by exact match
2023-08-25T21:03:45.233230291+02:00 stderr F I0825 19:03:45.232962       1 pathrecorder.go:241] kube-scheduler: "/metrics" satisfied by exact match
2023-08-25T21:03:38.411616431+02:00 stderr F I0825 19:03:38.411444       1 leaderelection.go:276] successfully renewed lease kube-system/kube-scheduler
2023-08-25T21:03:10.747506325+02:00 stderr F I0825 19:03:10.747381       1 cache.go:401] "Finished binding for pod, can be expired" podKey="b27bfdad-74fa-4876-b39f-e7c203d552e2" pod="default/kbench-deployment-oid-0-tid-1-778f5d498c-zb2r4"
2023-08-25T21:03:10.731460874+02:00 stderr F I0825 19:03:10.731405       1 schedule_one.go:80] "Attempting to schedule pod" pod="default/kbench-deployment-oid-0-tid-1-778f5d498c-97vc6"
2023-08-25T21:03:29.556096954+02:00 stderr F I0825 19:03:29.555956       1 eventhandlers.go:206] "Update event for scheduled pod" pod="kube-flannel/kube-flannel-ds-xsz4v"
2023-08-25T21:03:11.838825962+02:00 stderr F I0825 19:03:11.838456       1 eventhandlers.go:206] "Update event for scheduled pod" pod="default/kbench-deployment-oid-0-tid-0-bdb979454-jl6ch"
2023-08-25T21:03:57.233740907+02:00 stderr F I0825 19:03:57.233390       1 pathrecorder.go:241] kube-scheduler: "/metrics" satisfied by exact match
2023-08-25T21:03:40.425885006+02:00 stderr F I0825 19:03:40.425850       1 leaderelection.go:276] successfully renewed lease kube-system/kube-scheduler
2023-08-25T21:03:14.195483795+02:00 stderr F I0825 19:03:14.195236       1 round_trippers.go:553] PUT https://192.168.100.1:6443/apis/coordination.k8s.io/v1/namespaces/kube-system/leases/kube-scheduler?timeout=5s 200 OK in 8 milliseconds
2023-08-25T21:03:58.578225124+02:00 stderr F I0825 19:03:58.577909       1 round_trippers.go:553] GET https://192.168.100.1:6443/apis/coordination.k8s.io/v1/namespaces/kube-system/leases/kube-scheduler?timeout=5s 200 OK in 6 milliseconds
2023-08-25T21:04:00.61645054+02:00 stderr F I0825 19:04:00.616213       1 round_trippers.go:553] PUT https://192.168.100.1:6443/apis/coordination.k8s.io/v1/namespaces/kube-system/leases/kube-scheduler?timeout=5s 200 OK in 11 milliseconds
2023-08-25T21:03:27.245956243+02:00 stderr F I0825 19:03:27.244799       1 pathrecorder.go:241] kube-scheduler: "/metrics" satisfied by exact match
2023-08-25T21:03:56.5698961+02:00 stderr F I0825 19:03:56.569739       1 leaderelection.go:276] successfully renewed lease kube-system/kube-scheduler
2023-08-25T21:03:48.484595068+02:00 stderr F I0825 19:03:48.484283       1 round_trippers.go:553] GET https://192.168.100.1:6443/apis/coordination.k8s.io/v1/namespaces/kube-system/leases/kube-scheduler?timeout=5s 200 OK in 6 milliseconds
2023-08-25T21:03:29.623123741+02:00 stderr F I0825 19:03:29.622979       1 eventhandlers.go:161] "Delete event for unscheduled pod" pod="default/kbench-deployment-oid-0-tid-2-cc4784d96-nxzj9"
2023-08-25T21:03:12.376541105+02:00 stderr F I0825 19:03:12.376146       1 eventhandlers.go:206] "Update event for scheduled pod" pod="default/kbench-deployment-oid-0-tid-0-bdb979454-qlmd5"
2023-08-25T21:03:26.290600266+02:00 stderr F I0825 19:03:26.290383       1 round_trippers.go:553] PUT https://192.168.100.1:6443/apis/coordination.k8s.io/v1/namespaces/kube-system/leases/kube-scheduler?timeout=5s 200 OK in 7 milliseconds
2023-08-25T21:04:00.657428428+02:00 stderr F I0825 19:04:00.657313       1 eventhandlers.go:231] "Delete event for scheduled pod" pod="default/kbench-deployment-oid-0-tid-1-778f5d498c-kf5n6"
2023-08-25T21:03:39.238092474+02:00 stderr F I0825 19:03:39.237670       1 round_trippers.go:553] POST https://192.168.100.1:6443/apis/authentication.k8s.io/v1/tokenreviews 201 Created in 3 milliseconds
2023-08-25T21:04:00.035375514+02:00 stderr F I0825 19:04:00.035209       1 eventhandlers.go:231] "Delete event for scheduled pod" pod="default/kbench-deployment-oid-0-tid-2-cc4784d96-f4b9n"
2023-08-25T21:03:16.212775647+02:00 stderr F I0825 19:03:16.212567       1 leaderelection.go:276] successfully renewed lease kube-system/kube-scheduler
2023-08-25T21:03:30.938923527+02:00 stderr F I0825 19:03:30.938054       1 eventhandlers.go:206] "Update event for scheduled pod" pod="default/kbench-deployment-oid-0-tid-1-778f5d498c-kf5n6"
2023-08-25T21:03:29.556139784+02:00 stderr F I0825 19:03:29.556062       1 eventhandlers.go:206] "Update event for scheduled pod" pod="default/kbench-deployment-oid-0-tid-1-778f5d498c-97vc6"
2023-08-25T21:03:51.24687127+02:00 stderr F I0825 19:03:51.246625       1 round_trippers.go:553] POST https://192.168.100.1:6443/apis/authorization.k8s.io/v1/subjectaccessreviews?timeout=10s 201 Created in 2 milliseconds
2023-08-25T21:03:18.229970517+02:00 stderr F I0825 19:03:18.229784       1 leaderelection.go:276] successfully renewed lease kube-system/kube-scheduler
2023-08-25T21:03:10.835620784+02:00 stderr F I0825 19:03:10.835478       1 eventhandlers.go:206] "Update event for scheduled pod" pod="default/kbench-deployment-oid-0-tid-2-cc4784d96-fgg89"
2023-08-25T21:03:48.250762732+02:00 stderr F I0825 19:03:48.250474       1 httplog.go:132] "HTTP" verb="GET" URI="/metrics" latency="16.625331ms" userAgent="Prometheus/2.46.0" audit-ID="" srcIP="192.168.100.20:53397" resp=200
2023-08-25T21:03:27.244677275+02:00 stderr F I0825 19:03:27.244483       1 round_trippers.go:553] POST https://192.168.100.1:6443/apis/authorization.k8s.io/v1/subjectaccessreviews?timeout=10s 201 Created in 3 milliseconds
2023-08-25T21:03:46.477597452+02:00 stderr F I0825 19:03:46.477389       1 leaderelection.go:276] successfully renewed lease kube-system/kube-scheduler
2023-08-25T21:04:00.604142944+02:00 stderr F I0825 19:04:00.603926       1 round_trippers.go:553] GET https://192.168.100.1:6443/apis/coordination.k8s.io/v1/namespaces/kube-system/leases/kube-scheduler?timeout=5s 200 OK in 11 milliseconds
2023-08-25T21:03:38.411596131+02:00 stderr F I0825 19:03:38.411292       1 round_trippers.go:553] PUT https://192.168.100.1:6443/apis/coordination.k8s.io/v1/namespaces/kube-system/leases/kube-scheduler?timeout=5s 200 OK in 8 milliseconds
2023-08-25T21:03:45.244357896+02:00 stderr F I0825 19:03:45.244064       1 httplog.go:132] "HTTP" verb="GET" URI="/metrics" latency="11.21723ms" userAgent="Prometheus/2.46.0" audit-ID="" srcIP="192.168.100.20:53397" resp=200
2023-08-25T21:03:24.247952825+02:00 stderr F I0825 19:03:24.247673       1 httplog.go:132] "HTTP" verb="GET" URI="/metrics" latency="13.311029ms" userAgent="Prometheus/2.46.0" audit-ID="" srcIP="192.168.100.20:53397" resp=200
2023-08-25T21:03:15.243341216+02:00 stderr F I0825 19:03:15.243042       1 pathrecorder.go:241] kube-scheduler: "/metrics" satisfied by exact match
2023-08-25T21:03:50.501775143+02:00 stderr F I0825 19:03:50.501446       1 round_trippers.go:553] GET https://192.168.100.1:6443/apis/coordination.k8s.io/v1/namespaces/kube-system/leases/kube-scheduler?timeout=5s 200 OK in 5 milliseconds
2023-08-25T21:03:16.212516804+02:00 stderr F I0825 19:03:16.212259       1 round_trippers.go:553] PUT https://192.168.100.1:6443/apis/coordination.k8s.io/v1/namespaces/kube-system/leases/kube-scheduler?timeout=5s 200 OK in 8 milliseconds
2023-08-25T21:03:16.203124498+02:00 stderr F I0825 19:03:16.202789       1 round_trippers.go:553] GET https://192.168.100.1:6443/apis/coordination.k8s.io/v1/namespaces/kube-system/leases/kube-scheduler?timeout=5s 200 OK in 6 milliseconds
2023-08-25T21:03:34.360543618+02:00 stderr F I0825 19:03:34.360332       1 round_trippers.go:553] GET https://192.168.100.1:6443/apis/coordination.k8s.io/v1/namespaces/kube-system/leases/kube-scheduler?timeout=5s 200 OK in 16 milliseconds
2023-08-25T21:03:29.625236411+02:00 stderr F I0825 19:03:29.625046       1 schedule_one.go:252] "Successfully bound pod to node" pod="default/kbench-deployment-oid-0-tid-2-cc4784d96-nxzj9" node="w02" evaluatedNodes=5 feasibleNodes=2
2023-08-25T21:03:52.538782745+02:00 stderr F I0825 19:03:52.538657       1 eventhandlers.go:206] "Update event for scheduled pod" pod="default/kbench-deployment-oid-0-tid-2-cc4784d96-fgg89"
2023-08-25T21:03:22.728065853+02:00 stderr F I0825 19:03:22.727875       1 pathrecorder.go:241] kube-scheduler: "/healthz" satisfied by exact match
2023-08-25T21:03:52.576356162+02:00 stderr F I0825 19:03:52.576262       1 eventhandlers.go:206] "Update event for scheduled pod" pod="default/kbench-deployment-oid-0-tid-0-bdb979454-jl6ch"
2023-08-25T21:04:00.625772546+02:00 stderr F I0825 19:04:00.625654       1 eventhandlers.go:206] "Update event for scheduled pod" pod="default/kbench-deployment-oid-0-tid-1-778f5d498c-zb2r4"
2023-08-25T21:03:27.255653156+02:00 stderr F I0825 19:03:27.255300       1 httplog.go:132] "HTTP" verb="GET" URI="/metrics" latency="19.304657ms" userAgent="Prometheus/2.46.0" audit-ID="" srcIP="192.168.100.20:53397" resp=200
2023-08-25T21:03:24.276811036+02:00 stderr F I0825 19:03:24.276560       1 leaderelection.go:276] successfully renewed lease kube-system/kube-scheduler
2023-08-25T21:03:54.249906044+02:00 stderr F I0825 19:03:54.249598       1 httplog.go:132] "HTTP" verb="GET" URI="/metrics" latency="13.232033ms" userAgent="Prometheus/2.46.0" audit-ID="" srcIP="192.168.100.20:53397" resp=200
2023-08-25T21:03:11.861615429+02:00 stderr F I0825 19:03:11.861331       1 eventhandlers.go:206] "Update event for scheduled pod" pod="default/kbench-deployment-oid-0-tid-2-cc4784d96-fgg89"
2023-08-25T21:03:40.418580892+02:00 stderr F I0825 19:03:40.418207       1 round_trippers.go:553] GET https://192.168.100.1:6443/apis/coordination.k8s.io/v1/namespaces/kube-system/leases/kube-scheduler?timeout=5s 200 OK in 6 milliseconds
2023-08-25T21:03:52.524701146+02:00 stderr F I0825 19:03:52.524584       1 round_trippers.go:553] PUT https://192.168.100.1:6443/apis/coordination.k8s.io/v1/namespaces/kube-system/leases/kube-scheduler?timeout=5s 200 OK in 7 milliseconds
2023-08-25T21:03:29.628677668+02:00 stderr F I0825 19:03:29.628282       1 eventhandlers.go:186] "Add event for scheduled pod" pod="default/kbench-deployment-oid-0-tid-1-778f5d498c-kf5n6"
2023-08-25T21:03:28.305918994+02:00 stderr F I0825 19:03:28.305735       1 round_trippers.go:553] PUT https://192.168.100.1:6443/apis/coordination.k8s.io/v1/namespaces/kube-system/leases/kube-scheduler?timeout=5s 200 OK in 9 milliseconds
2023-08-25T21:03:32.3319483+02:00 stderr F I0825 19:03:32.331548       1 round_trippers.go:553] GET https://192.168.100.1:6443/apis/coordination.k8s.io/v1/namespaces/kube-system/leases/kube-scheduler?timeout=5s 200 OK in 5 milliseconds
2023-08-25T21:03:44.457605405+02:00 stderr F I0825 19:03:44.457398       1 round_trippers.go:553] PUT https://192.168.100.1:6443/apis/coordination.k8s.io/v1/namespaces/kube-system/leases/kube-scheduler?timeout=5s 200 OK in 8 milliseconds
2023-08-25T21:03:12.730115944+02:00 stderr F I0825 19:03:12.729876       1 httplog.go:132] "HTTP" verb="GET" URI="/healthz" latency="151.034µs" userAgent="kube-probe/1.27" audit-ID="" srcIP="127.0.0.1:41938" resp=200
2023-08-25T21:03:10.746771937+02:00 stderr F I0825 19:03:10.746653       1 round_trippers.go:553] POST https://192.168.100.1:6443/api/v1/namespaces/default/pods/kbench-deployment-oid-0-tid-1-778f5d498c-zb2r4/binding 201 Created in 22 milliseconds
2023-08-25T21:03:29.625025891+02:00 stderr F I0825 19:03:29.623333       1 eventhandlers.go:186] "Add event for scheduled pod" pod="default/kbench-deployment-oid-0-tid-2-cc4784d96-nxzj9"
2023-08-25T21:03:36.248027677+02:00 stderr F I0825 19:03:36.247681       1 httplog.go:132] "HTTP" verb="GET" URI="/metrics" latency="14.763429ms" userAgent="Prometheus/2.46.0" audit-ID="" srcIP="192.168.100.20:53397" resp=200
2023-08-25T21:03:10.838542401+02:00 stderr F I0825 19:03:10.837831       1 eventhandlers.go:206] "Update event for scheduled pod" pod="default/kbench-deployment-oid-0-tid-1-778f5d498c-97vc6"
2023-08-25T21:03:10.783263846+02:00 stderr F I0825 19:03:10.783119       1 round_trippers.go:553] POST https://192.168.100.1:6443/apis/events.k8s.io/v1/namespaces/default/events 201 Created in 11 milliseconds
2023-08-25T21:03:52.524821764+02:00 stderr F I0825 19:03:52.524688       1 leaderelection.go:276] successfully renewed lease kube-system/kube-scheduler
2023-08-25T21:03:10.746413773+02:00 stderr F I0825 19:03:10.746308       1 eventhandlers.go:118] "Add event for unscheduled pod" pod="default/kbench-deployment-oid-0-tid-2-cc4784d96-fgg89"
2023-08-25T21:03:10.74519027+02:00 stderr F I0825 19:03:10.745000       1 default_binder.go:53] "Attempting to bind pod to node" pod="default/kbench-deployment-oid-0-tid-0-bdb979454-qlmd5" node="w02"
2023-08-25T21:03:29.639374673+02:00 stderr F I0825 19:03:29.639200       1 round_trippers.go:553] POST https://192.168.100.1:6443/apis/events.k8s.io/v1/namespaces/default/events 201 Created in 11 milliseconds
2023-08-25T21:03:36.389411013+02:00 stderr F I0825 19:03:36.389137       1 round_trippers.go:553] GET https://192.168.100.1:6443/apis/coordination.k8s.io/v1/namespaces/kube-system/leases/kube-scheduler?timeout=5s 200 OK in 5 milliseconds
2023-08-25T21:03:10.720013496+02:00 stderr F I0825 19:03:10.716001       1 scheduling_queue.go:1133] "About to try and schedule pod" pod="default/kbench-deployment-oid-0-tid-2-cc4784d96-f4b9n"
2023-08-25T21:03:39.246813355+02:00 stderr F I0825 19:03:39.243518       1 pathrecorder.go:241] kube-scheduler: "/metrics" satisfied by exact match
2023-08-25T21:03:46.468898479+02:00 stderr F I0825 19:03:46.468553       1 round_trippers.go:553] GET https://192.168.100.1:6443/apis/coordination.k8s.io/v1/namespaces/kube-system/leases/kube-scheduler?timeout=5s 200 OK in 5 milliseconds
2023-08-25T21:03:29.604187774+02:00 stderr F I0825 19:03:29.603912       1 scheduling_queue.go:419] "Pod moved to an internal scheduling queue" pod="default/kbench-deployment-oid-0-tid-2-cc4784d96-nxzj9" event="PodAdd" queue="Active"
2023-08-25T21:03:10.773459316+02:00 stderr F I0825 19:03:10.773243       1 round_trippers.go:553] POST https://192.168.100.1:6443/apis/events.k8s.io/v1/namespaces/default/events 201 Created in 9 milliseconds
2023-08-25T21:03:21.245038629+02:00 stderr F I0825 19:03:21.244755       1 httplog.go:132] "HTTP" verb="GET" URI="/metrics" latency="12.656401ms" userAgent="Prometheus/2.46.0" audit-ID="" srcIP="192.168.100.20:53397" resp=200
2023-08-25T21:04:00.233668465+02:00 stderr F I0825 19:04:00.233412       1 pathrecorder.go:241] kube-scheduler: "/metrics" satisfied by exact match
2023-08-25T21:03:29.608205552+02:00 stderr F I0825 19:03:29.607740       1 eventhandlers.go:118] "Add event for unscheduled pod" pod="default/kbench-deployment-oid-0-tid-1-778f5d498c-kf5n6"
2023-08-25T21:03:29.62412907+02:00 stderr F I0825 19:03:29.623096       1 round_trippers.go:553] POST https://192.168.100.1:6443/api/v1/namespaces/default/pods/kbench-deployment-oid-0-tid-2-cc4784d96-nxzj9/binding 201 Created in 14 milliseconds
2023-08-25T21:03:39.258018471+02:00 stderr F I0825 19:03:39.257757       1 httplog.go:132] "HTTP" verb="GET" URI="/metrics" latency="24.404348ms" userAgent="Prometheus/2.46.0" audit-ID="" srcIP="192.168.100.20:53397" resp=200
2023-08-25T21:03:40.425853695+02:00 stderr F I0825 19:03:40.425678       1 round_trippers.go:553] PUT https://192.168.100.1:6443/apis/coordination.k8s.io/v1/namespaces/kube-system/leases/kube-scheduler?timeout=5s 200 OK in 7 milliseconds
2023-08-25T21:03:10.746429655+02:00 stderr F I0825 19:03:10.746351       1 scheduling_queue.go:419] "Pod moved to an internal scheduling queue" pod="default/kbench-deployment-oid-0-tid-2-cc4784d96-fgg89" event="PodAdd" queue="Active"
2023-08-25T21:03:10.789223274+02:00 stderr F I0825 19:03:10.789089       1 eventhandlers.go:206] "Update event for scheduled pod" pod="default/kbench-deployment-oid-0-tid-0-bdb979454-jl6ch"
2023-08-25T21:03:52.553203521+02:00 stderr F I0825 19:03:52.552608       1 eventhandlers.go:206] "Update event for scheduled pod" pod="default/kbench-deployment-oid-0-tid-1-778f5d498c-zb2r4"
2023-08-25T21:03:32.341013785+02:00 stderr F I0825 19:03:32.340792       1 leaderelection.go:276] successfully renewed lease kube-system/kube-scheduler
2023-08-25T21:03:10.770221392+02:00 stderr F I0825 19:03:10.770006       1 cache.go:401] "Finished binding for pod, can be expired" podKey="75c37076-924d-4f40-844f-efd1ebfe1b13" pod="default/kbench-deployment-oid-0-tid-2-cc4784d96-fgg89"
2023-08-25T21:03:29.639410561+02:00 stderr F I0825 19:03:29.639209       1 round_trippers.go:553] POST https://192.168.100.1:6443/apis/events.k8s.io/v1/namespaces/default/events 201 Created in 13 milliseconds
2023-08-25T21:03:33.236684901+02:00 stderr F I0825 19:03:33.236300       1 pathrecorder.go:241] kube-scheduler: "/metrics" satisfied by exact match
2023-08-25T21:03:14.186558498+02:00 stderr F I0825 19:03:14.186287       1 round_trippers.go:553] GET https://192.168.100.1:6443/apis/coordination.k8s.io/v1/namespaces/kube-system/leases/kube-scheduler?timeout=5s 200 OK in 6 milliseconds
2023-08-25T21:03:36.397074548+02:00 stderr F I0825 19:03:36.396866       1 round_trippers.go:553] PUT https://192.168.100.1:6443/apis/coordination.k8s.io/v1/namespaces/kube-system/leases/kube-scheduler?timeout=5s 200 OK in 6 milliseconds
2023-08-25T21:03:29.61219458+02:00 stderr F I0825 19:03:29.611738       1 default_binder.go:53] "Attempting to bind pod to node" pod="default/kbench-deployment-oid-0-tid-1-778f5d498c-kf5n6" node="w03"
2023-08-25T21:03:10.737554159+02:00 stderr F I0825 19:03:10.737470       1 eventhandlers.go:161] "Delete event for unscheduled pod" pod="default/kbench-deployment-oid-0-tid-2-cc4784d96-f4b9n"
2023-08-25T21:03:10.799541036+02:00 stderr F I0825 19:03:10.799137       1 eventhandlers.go:206] "Update event for scheduled pod" pod="default/kbench-deployment-oid-0-tid-2-cc4784d96-f4b9n"
2023-08-25T21:03:30.247132653+02:00 stderr F I0825 19:03:30.246662       1 httplog.go:132] "HTTP" verb="GET" URI="/metrics" latency="12.042373ms" userAgent="Prometheus/2.46.0" audit-ID="" srcIP="192.168.100.20:53397" resp=200
2023-08-25T21:03:10.716464938+02:00 stderr F I0825 19:03:10.715791       1 eventhandlers.go:118] "Add event for unscheduled pod" pod="default/kbench-deployment-oid-0-tid-2-cc4784d96-f4b9n"
2023-08-25T21:03:29.62771069+02:00 stderr F I0825 19:03:29.627535       1 cache.go:401] "Finished binding for pod, can be expired" podKey="88813de0-a797-4b0c-b3d5-9618dc5a05bc" pod="default/kbench-deployment-oid-0-tid-1-778f5d498c-kf5n6"
2023-08-25T21:03:10.788855323+02:00 stderr F I0825 19:03:10.788640       1 round_trippers.go:553] POST https://192.168.100.1:6443/apis/events.k8s.io/v1/namespaces/default/events 201 Created in 18 milliseconds
2023-08-25T21:03:24.276040786+02:00 stderr F I0825 19:03:24.275840       1 round_trippers.go:553] PUT https://192.168.100.1:6443/apis/coordination.k8s.io/v1/namespaces/kube-system/leases/kube-scheduler?timeout=5s 200 OK in 7 milliseconds
2023-08-25T21:03:52.728476302+02:00 stderr F I0825 19:03:52.727991       1 pathrecorder.go:241] kube-scheduler: "/healthz" satisfied by exact match
2023-08-25T21:04:00.63381664+02:00 stderr F I0825 19:04:00.633650       1 eventhandlers.go:231] "Delete event for scheduled pod" pod="default/kbench-deployment-oid-0-tid-0-bdb979454-qlmd5"
2023-08-25T21:03:10.737245427+02:00 stderr F I0825 19:03:10.737068       1 eventhandlers.go:161] "Delete event for unscheduled pod" pod="default/kbench-deployment-oid-0-tid-0-bdb979454-jl6ch"
2023-08-25T21:03:54.543662732+02:00 stderr F I0825 19:03:54.543470       1 leaderelection.go:276] successfully renewed lease kube-system/kube-scheduler
2023-08-25T21:03:28.295622369+02:00 stderr F I0825 19:03:28.295368       1 round_trippers.go:553] GET https://192.168.100.1:6443/apis/coordination.k8s.io/v1/namespaces/kube-system/leases/kube-scheduler?timeout=5s 200 OK in 4 milliseconds
2023-08-25T21:03:10.742345539+02:00 stderr F I0825 19:03:10.742239       1 eventhandlers.go:186] "Add event for scheduled pod" pod="default/kbench-deployment-oid-0-tid-1-778f5d498c-zb2r4"
2023-08-25T21:03:20.246868079+02:00 stderr F I0825 19:03:20.246812       1 leaderelection.go:276] successfully renewed lease kube-system/kube-scheduler
2023-08-25T21:03:12.235556483+02:00 stderr F I0825 19:03:12.235192       1 eventhandlers.go:206] "Update event for scheduled pod" pod="default/kbench-deployment-oid-0-tid-1-778f5d498c-97vc6"
2023-08-25T21:04:00.617780399+02:00 stderr F I0825 19:04:00.617517       1 eventhandlers.go:206] "Update event for scheduled pod" pod="default/kbench-deployment-oid-0-tid-1-778f5d498c-kf5n6"
2023-08-25T21:04:00.617497371+02:00 stderr F I0825 19:04:00.617067       1 leaderelection.go:276] successfully renewed lease kube-system/kube-scheduler
2023-08-25T21:03:15.237850791+02:00 stderr F I0825 19:03:15.237511       1 round_trippers.go:553] POST https://192.168.100.1:6443/apis/authentication.k8s.io/v1/tokenreviews 201 Created in 4 milliseconds
2023-08-25T21:03:56.560251717+02:00 stderr F I0825 19:03:56.559611       1 round_trippers.go:553] GET https://192.168.100.1:6443/apis/coordination.k8s.io/v1/namespaces/kube-system/leases/kube-scheduler?timeout=5s 200 OK in 5 milliseconds
2023-08-25T21:03:10.769196905+02:00 stderr F I0825 19:03:10.769080       1 round_trippers.go:553] POST https://192.168.100.1:6443/apis/events.k8s.io/v1/namespaces/default/events 201 Created in 30 milliseconds
2023-08-25T21:03:29.627698554+02:00 stderr F I0825 19:03:29.627406       1 round_trippers.go:553] POST https://192.168.100.1:6443/api/v1/namespaces/default/pods/kbench-deployment-oid-0-tid-1-778f5d498c-kf5n6/binding 201 Created in 14 milliseconds
2023-08-25T21:03:10.814944109+02:00 stderr F I0825 19:03:10.814847       1 eventhandlers.go:206] "Update event for scheduled pod" pod="default/kbench-deployment-oid-0-tid-1-778f5d498c-zb2r4"
2023-08-25T21:03:10.763330375+02:00 stderr F I0825 19:03:10.763142       1 eventhandlers.go:161] "Delete event for unscheduled pod" pod="default/kbench-deployment-oid-0-tid-1-778f5d498c-97vc6"
2023-08-25T21:03:36.233383839+02:00 stderr F I0825 19:03:36.233058       1 pathrecorder.go:241] kube-scheduler: "/metrics" satisfied by exact match
2023-08-25T21:03:42.729390098+02:00 stderr F I0825 19:03:42.729159       1 httplog.go:132] "HTTP" verb="GET" URI="/healthz" latency="410.765µs" userAgent="kube-probe/1.27" audit-ID="" srcIP="127.0.0.1:36456" resp=200
2023-08-25T21:03:10.763610016+02:00 stderr F I0825 19:03:10.763286       1 schedule_one.go:252] "Successfully bound pod to node" pod="default/kbench-deployment-oid-0-tid-1-778f5d498c-97vc6" node="w01" evaluatedNodes=5 feasibleNodes=3
2023-08-25T21:03:10.720080879+02:00 stderr F I0825 19:03:10.718770       1 scheduling_queue.go:419] "Pod moved to an internal scheduling queue" pod="default/kbench-deployment-oid-0-tid-0-bdb979454-jl6ch" event="PodAdd" queue="Active"
2023-08-25T21:03:22.261140714+02:00 stderr F I0825 19:03:22.260957       1 round_trippers.go:553] PUT https://192.168.100.1:6443/apis/coordination.k8s.io/v1/namespaces/kube-system/leases/kube-scheduler?timeout=5s 200 OK in 7 milliseconds
2023-08-25T21:03:10.763346661+02:00 stderr F I0825 19:03:10.763220       1 cache.go:401] "Finished binding for pod, can be expired" podKey="74490f8a-0869-4ec7-a4db-452ce6c593f2" pod="default/kbench-deployment-oid-0-tid-1-778f5d498c-97vc6"
2023-08-25T21:03:12.049752089+02:00 stderr F I0825 19:03:12.049410       1 round_trippers.go:553] GET https://192.168.100.1:6443/apis/coordination.k8s.io/v1/namespaces/kube-system/leases/kube-scheduler?timeout=5s 200 OK in 5 milliseconds
2023-08-25T21:03:18.22983413+02:00 stderr F I0825 19:03:18.229541       1 round_trippers.go:553] PUT https://192.168.100.1:6443/apis/coordination.k8s.io/v1/namespaces/kube-system/leases/kube-scheduler?timeout=5s 200 OK in 9 milliseconds
2023-08-25T21:04:00.694951524+02:00 stderr F I0825 19:04:00.694579       1 eventhandlers.go:231] "Delete event for scheduled pod" pod="default/kbench-deployment-oid-0-tid-2-cc4784d96-nxzj9"
2023-08-25T21:03:30.312106299+02:00 stderr F I0825 19:03:30.311817       1 round_trippers.go:553] GET https://192.168.100.1:6443/apis/coordination.k8s.io/v1/namespaces/kube-system/leases/kube-scheduler?timeout=5s 200 OK in 5 milliseconds
2023-08-25T21:03:44.457628549+02:00 stderr F I0825 19:03:44.457584       1 leaderelection.go:276] successfully renewed lease kube-system/kube-scheduler
2023-08-25T21:03:10.743144484+02:00 stderr F I0825 19:03:10.743057       1 scheduling_queue.go:419] "Pod moved to an internal scheduling queue" pod="default/kbench-deployment-oid-0-tid-0-bdb979454-qlmd5" event="PodAdd" queue="Active"
2023-08-25T21:03:10.737528059+02:00 stderr F I0825 19:03:10.737381       1 eventhandlers.go:186] "Add event for scheduled pod" pod="default/kbench-deployment-oid-0-tid-2-cc4784d96-f4b9n"
2023-08-25T21:03:22.261776943+02:00 stderr F I0825 19:03:22.261504       1 leaderelection.go:276] successfully renewed lease kube-system/kube-scheduler
2023-08-25T21:03:10.731194048+02:00 stderr F I0825 19:03:10.731102       1 eventhandlers.go:118] "Add event for unscheduled pod" pod="default/kbench-deployment-oid-0-tid-1-778f5d498c-97vc6"
2023-08-25T21:03:42.432856884+02:00 stderr F I0825 19:03:42.432645       1 round_trippers.go:553] GET https://192.168.100.1:6443/apis/coordination.k8s.io/v1/namespaces/kube-system/leases/kube-scheduler?timeout=5s 200 OK in 5 milliseconds
2023-08-25T21:03:29.556118109+02:00 stderr F I0825 19:03:29.556014       1 eventhandlers.go:206] "Update event for scheduled pod" pod="default/kbench-deployment-oid-0-tid-2-cc4784d96-f4b9n"
2023-08-25T21:03:10.736847492+02:00 stderr F I0825 19:03:10.736750       1 cache.go:401] "Finished binding for pod, can be expired" podKey="55a5256c-44fe-439f-9fa0-5e855d728ded" pod="default/kbench-deployment-oid-0-tid-2-cc4784d96-f4b9n"
2023-08-25T21:03:38.403176831+02:00 stderr F I0825 19:03:38.402891       1 round_trippers.go:553] GET https://192.168.100.1:6443/apis/coordination.k8s.io/v1/namespaces/kube-system/leases/kube-scheduler?timeout=5s 200 OK in 5 milliseconds
2023-08-25T21:03:10.731328286+02:00 stderr F I0825 19:03:10.731234       1 scheduling_queue.go:419] "Pod moved to an internal scheduling queue" pod="default/kbench-deployment-oid-0-tid-1-778f5d498c-97vc6" event="PodAdd" queue="Active"
2023-08-25T21:03:42.443707544+02:00 stderr F I0825 19:03:42.443556       1 leaderelection.go:276] successfully renewed lease kube-system/kube-scheduler
2023-08-25T21:03:10.736809934+02:00 stderr F I0825 19:03:10.736623       1 round_trippers.go:553] POST https://192.168.100.1:6443/api/v1/namespaces/default/pods/kbench-deployment-oid-0-tid-2-cc4784d96-f4b9n/binding 201 Created in 15 milliseconds
2023-08-25T21:04:00.017547881+02:00 stderr F I0825 19:04:00.016548       1 eventhandlers.go:231] "Delete event for scheduled pod" pod="default/kbench-deployment-oid-0-tid-1-778f5d498c-97vc6"
2023-08-25T21:03:46.47734257+02:00 stderr F I0825 19:03:46.477177       1 round_trippers.go:553] PUT https://192.168.100.1:6443/apis/coordination.k8s.io/v1/namespaces/kube-system/leases/kube-scheduler?timeout=5s 200 OK in 8 milliseconds
2023-08-25T21:03:10.720060916+02:00 stderr F I0825 19:03:10.718417       1 eventhandlers.go:118] "Add event for unscheduled pod" pod="default/kbench-deployment-oid-0-tid-1-778f5d498c-zb2r4"
2023-08-25T21:03:29.655337617+02:00 stderr F I0825 19:03:29.655102       1 eventhandlers.go:206] "Update event for scheduled pod" pod="default/kbench-deployment-oid-0-tid-1-778f5d498c-97vc6"
2023-08-25T21:03:18.255586378+02:00 stderr F I0825 19:03:18.255162       1 pathrecorder.go:241] kube-scheduler: "/metrics" satisfied by exact match
2023-08-25T21:03:34.382883307+02:00 stderr F I0825 19:03:34.382781       1 leaderelection.go:276] successfully renewed lease kube-system/kube-scheduler
2023-08-25T21:03:29.591200831+02:00 stderr F I0825 19:03:29.590907       1 eventhandlers.go:206] "Update event for scheduled pod" pod="default/kbench-deployment-oid-0-tid-1-778f5d498c-97vc6"
2023-08-25T21:04:00.580314326+02:00 stderr F I0825 19:04:00.580115       1 eventhandlers.go:206] "Update event for scheduled pod" pod="default/kbench-deployment-oid-0-tid-0-bdb979454-jl6ch"
2023-08-25T21:03:10.72145157+02:00 stderr F I0825 19:03:10.721260       1 schedule_one.go:80] "Attempting to schedule pod" pod="default/kbench-deployment-oid-0-tid-1-778f5d498c-zb2r4"
2023-08-25T21:03:10.770237326+02:00 stderr F I0825 19:03:10.770056       1 schedule_one.go:252] "Successfully bound pod to node" pod="default/kbench-deployment-oid-0-tid-2-cc4784d96-fgg89" node="w03" evaluatedNodes=5 feasibleNodes=3
2023-08-25T21:03:12.269549565+02:00 stderr F I0825 19:03:12.268747       1 eventhandlers.go:206] "Update event for scheduled pod" pod="default/kbench-deployment-oid-0-tid-2-cc4784d96-f4b9n"
2023-08-25T21:03:10.771481482+02:00 stderr F I0825 19:03:10.771277       1 round_trippers.go:553] POST https://192.168.100.1:6443/api/v1/namespaces/default/pods/kbench-deployment-oid-0-tid-0-bdb979454-qlmd5/binding 201 Created in 25 milliseconds
2023-08-25T21:03:34.382868617+02:00 stderr F I0825 19:03:34.382672       1 round_trippers.go:553] PUT https://192.168.100.1:6443/apis/coordination.k8s.io/v1/namespaces/kube-system/leases/kube-scheduler?timeout=5s 200 OK in 21 milliseconds
2023-08-25T21:03:10.738439694+02:00 stderr F I0825 19:03:10.738380       1 schedule_one.go:252] "Successfully bound pod to node" pod="default/kbench-deployment-oid-0-tid-0-bdb979454-jl6ch" node="w03" evaluatedNodes=5 feasibleNodes=3
2023-08-25T21:04:00.586975827+02:00 stderr F I0825 19:04:00.586877       1 eventhandlers.go:206] "Update event for scheduled pod" pod="default/kbench-deployment-oid-0-tid-0-bdb979454-qlmd5"
2023-08-25T21:03:51.243269819+02:00 stderr F I0825 19:03:51.243027       1 round_trippers.go:553] POST https://192.168.100.1:6443/apis/authentication.k8s.io/v1/tokenreviews 201 Created in 2 milliseconds
2023-08-25T21:03:10.742357137+02:00 stderr F I0825 19:03:10.742307       1 eventhandlers.go:161] "Delete event for unscheduled pod" pod="default/kbench-deployment-oid-0-tid-1-778f5d498c-zb2r4"
2023-08-25T21:03:59.928160451+02:00 stderr F I0825 19:03:59.927841       1 eventhandlers.go:231] "Delete event for scheduled pod" pod="kube-flannel/kube-flannel-ds-xsz4v"
